Workbook

Sheet Overall
Y1: Notes: 1. The overall view of temperature-based scenarios shows dry seasons as the conditions most likely to drive threshold crossings. Specifically, across all the Delta regions, Angling (18.42C), Boating, and Day use (19C) have the highest exceedance percentages, followed by wetlands bird species (20C) risk thresholds at the Delta-wide scale and, more specifically, at Central Delta and South Delta locations across BAU, BAF, ECO, and NGW. In words, dry seasons drive dangerous threshold-crossing days for activities and recreation important species alike. Cold water, by contrast, applies only to day use (<18C) and crosses threshold days across four exceedance models during the wet seasons, Delta-wide at over 90% rates. 2. RMA scenario -5 to 5 rankings show that all four models are evenly distributed across most breakdowns, Delta-wide and regional, with notable exceptions: ECO and NGW performing well in Suisun Marsh, with a 1% increase for Day use and Boating Total Run, and in dry seasons. Likewise, they showed positive moves for birding and angling during wet seasons. Negative moves of (-1%) during the dry season also appear in Suisun Marsh, making it the only region affected under the -5 to 5 scoring scenario, with both waterfowl and Angling performing worse than BAU. Takeaways from this analysis show that Suisun Marsh is the most affected region, either negatively or positively, depending on seasonality and recreational use. 3. Red-highlighted cells reflect 25% values for ease of assessment.
C2: TOTAL RUN SCORES | J2: WET SEASON SCORES | Q2: DRY SEASON SCORES
D3: REGION | E3: BAU | F3: BAF | G3: ECO | H3: NGW | K3: REGION | L3: BAU | M3: BAF | N3: ECO | O3: NGW | R3: REGION | S3: BAU | T3: BAF | U3: ECO | V3: NGW
C4: BOATING & DAY USE | D4: Delta-Wide | E4: =-MAX(-5,MIN(5,ROUND(($D$42-$D$42)*100,0))) -> 0 | F4: =-MAX(-5,MIN(5,ROUND(($D$51-$D$42)*100,0))) -> 0 | G4: =-MAX(-5,MIN(5,ROUND(($D$78-$D$42)*100,0))) -> 0 | H4: =-MAX(-5,MIN(5,ROUND(($D$87-$D$42)*100,0))) -> 0 | J4: BOATING & DAY USE | K4: Delta-Wide | L4: =-MAX(-5,MIN(5,ROUND(($I$42-$I$42)*100,0))) -> 0 | M4: =-MAX(-5,MIN(5,ROUND(($I$51-$I$42)*100,0))) -> 0 | N4: =-MAX(-5,MIN(5,ROUND(($I$78-$I$42)*100,0))) -> 0 | O4: =-MAX(-5,MIN(5,ROUND(($I$87-$I$42)*100,0))) -> 0 | Q4: BOATING & DAY USE | R4: Delta-Wide | S4: =-MAX(-5,MIN(5,ROUND(($N$42-$N$42)*100,0))) -> 0 | T4: =-MAX(-5,MIN(5,ROUND(($N$51-$N$42)*100,0))) -> 0 | U4: =-MAX(-5,MIN(5,ROUND(($N$78-$N$42)*100,0))) -> 0 | V4: =-MAX(-5,MIN(5,ROUND(($N$87-$N$42)*100,0))) -> 0
D5: Suisun | E5: =-MAX(-5,MIN(5,ROUND(($E$42-$E$42)*100,0))) -> 0 | F5: =-MAX(-5,MIN(5,ROUND(($E$51-$E$42)*100,0))) -> 0 | G5: =-MAX(-5,MIN(5,ROUND(($E$78-$E$42)*100,0))) -> 0 | H5: =-MAX(-5,MIN(5,ROUND(($E$87-$E$42)*100,0))) -> 0 | K5: Suisun | L5: =-MAX(-5,MIN(5,ROUND(($J$42-$J$42)*100,0))) -> 0 | M5: =-MAX(-5,MIN(5,ROUND(($J$51-$J$42)*100,0))) -> 0 | N5: =-MAX(-5,MIN(5,ROUND(($J$78-$J$42)*100,0))) -> 1 | O5: =-MAX(-5,MIN(5,ROUND(($J$87-$J$42)*100,0))) -> 1 | R5: Suisun | S5: =-MAX(-5,MIN(5,ROUND(($O$42-$O$42)*100,0))) -> 0 | T5: =-MAX(-5,MIN(5,ROUND(($O$51-$O$42)*100,0))) -> 0 | U5: =-MAX(-5,MIN(5,ROUND(($O$78-$O$42)*100,0))) -> -1 | V5: =-MAX(-5,MIN(5,ROUND(($O$87-$O$42)*100,0))) -> -1
D6: Central | E6: =-MAX(-5,MIN(5,ROUND(($F$42-$F$42)*100,0))) -> 0 | F6: =-MAX(-5,MIN(5,ROUND(($F$51-$F$42)*100,0))) -> 0 | G6: =-MAX(-5,MIN(5,ROUND(($F$78-$F$42)*100,0))) -> 0 | H6: =-MAX(-5,MIN(5,ROUND(($F$87-$F$42)*100,0))) -> 0 | K6: Central | L6: =-MAX(-5,MIN(5,ROUND(($K$42-$K$42)*100,0))) -> 0 | M6: =-MAX(-5,MIN(5,ROUND(($K$51-$K$42)*100,0))) -> 0 | N6: =-MAX(-5,MIN(5,ROUND(($K$78-$K$42)*100,0))) -> 0 | O6: =-MAX(-5,MIN(5,ROUND(($K$87-$K$42)*100,0))) -> 0 | R6: Central | S6: =-MAX(-5,MIN(5,ROUND(($P$42-$P$42)*100,0))) -> 0 | T6: =-MAX(-5,MIN(5,ROUND(($P$51-$P$42)*100,0))) -> 0 | U6: =-MAX(-5,MIN(5,ROUND(($P$78-$P$42)*100,0))) -> 0 | V6: =-MAX(-5,MIN(5,ROUND(($P$87-$P$42)*100,0))) -> 0
D7: North | E7: =-MAX(-5,MIN(5,ROUND(($G$42-$G$42)*100,0))) -> 0 | F7: =-MAX(-5,MIN(5,ROUND(($G$51-$G$42)*100,0))) -> 0 | G7: =-MAX(-5,MIN(5,ROUND(($G$78-$G$42)*100,0))) -> 0 | H7: =-MAX(-5,MIN(5,ROUND(($G$87-$G$42)*100,0))) -> 0 | K7: North | L7: =-MAX(-5,MIN(5,ROUND(($L$42-$L$42)*100,0))) -> 0 | M7: =-MAX(-5,MIN(5,ROUND(($L$51-$L$42)*100,0))) -> 0 | N7: =-MAX(-5,MIN(5,ROUND(($L$78-$L$42)*100,0))) -> 0 | O7: =-MAX(-5,MIN(5,ROUND(($L$87-$L$42)*100,0))) -> 0 | R7: North | S7: =-MAX(-5,MIN(5,ROUND(($Q$42-$Q$42)*100,0))) -> 0 | T7: =-MAX(-5,MIN(5,ROUND(($Q$51-$Q$42)*100,0))) -> 0 | U7: =-MAX(-5,MIN(5,ROUND(($Q$78-$Q$42)*100,0))) -> 0 | V7: =-MAX(-5,MIN(5,ROUND(($Q$87-$Q$42)*100,0))) -> 0
D8: South | E8: =-MAX(-5,MIN(5,ROUND(($H$42-$H$42)*100,0))) -> 0 | F8: =-MAX(-5,MIN(5,ROUND(($H$51-$H$42)*100,0))) -> 0 | G8: =-MAX(-5,MIN(5,ROUND(($H$78-$H$42)*100,0))) -> 0 | H8: =-MAX(-5,MIN(5,ROUND(($H$87-$H$42)*100,0))) -> 0 | K8: South | L8: =-MAX(-5,MIN(5,ROUND(($M$42-$M$42)*100,0))) -> 0 | M8: =-MAX(-5,MIN(5,ROUND(($M$51-$M$42)*100,0))) -> 0 | N8: =-MAX(-5,MIN(5,ROUND(($M$78-$M$42)*100,0))) -> 0 | O8: =-MAX(-5,MIN(5,ROUND(($M$87-$M$42)*100,0))) -> 0 | R8: South | S8: =-MAX(-5,MIN(5,ROUND(($R$42-$R$42)*100,0))) -> 0 | T8: =-MAX(-5,MIN(5,ROUND(($R$51-$R$42)*100,0))) -> 0 | U8: =-MAX(-5,MIN(5,ROUND(($R$78-$R$42)*100,0))) -> 0 | V8: =-MAX(-5,MIN(5,ROUND(($R$87-$R$42)*100,0))) -> 0
D9: REGION | E9: BAU | F9: BAF | G9: ECO | H9: NGW | K9: REGION | L9: BAU | M9: BAF | N9: ECO | O9: NGW | R9: REGION | S9: BAU | T9: BAF | U9: ECO | V9: NGW
C10: BIRDING | D10: Delta-Wide | E10: =-MAX(-5,MIN(5,ROUND(($D$39-$D$39)*100,0))) -> 0 | F10: =-MAX(-5,MIN(5,ROUND(($D$48-$D$39)*100,0))) -> 0 | G10: =-MAX(-5,MIN(5,ROUND(($D$75-$D$39)*100,0))) -> 0 | H10: =-MAX(-5,MIN(5,ROUND(($D$84-$D$39)*100,0))) -> 0 | J10: BIRDING | K10: Delta-Wide | L10: =-MAX(-5,MIN(5,ROUND(($I$39-$I$39)*100,0))) -> 0 | M10: =-MAX(-5,MIN(5,ROUND(($I$48-$I$39)*100,0))) -> 0 | N10: =-MAX(-5,MIN(5,ROUND(($I$75-$I$39)*100,0))) -> 0 | O10: =-MAX(-5,MIN(5,ROUND(($I$84-$I$39)*100,0))) -> 0 | Q10: BIRDING | R10: Delta-Wide | S10: =-MAX(-5,MIN(5,ROUND(($N$39-$N$39)*100,0))) -> 0 | T10: =-MAX(-5,MIN(5,ROUND(($N$48-$N$39)*100,0))) -> 0 | U10: =-MAX(-5,MIN(5,ROUND(($N$75-$N$39)*100,0))) -> 0 | V10: =-MAX(-5,MIN(5,ROUND(($N$84-$N$39)*100,0))) -> 0
D11: Suisun | E11: =-MAX(-5,MIN(5,ROUND(($E$39-$E$39)*100,0))) -> 0 | F11: =-MAX(-5,MIN(5,ROUND(($E$48-$E$39)*100,0))) -> 0 | G11: =-MAX(-5,MIN(5,ROUND(($E$75-$E$39)*100,0))) -> 0 | H11: =-MAX(-5,MIN(5,ROUND(($E$84-$E$39)*100,0))) -> 0 | K11: Suisun | L11: =-MAX(-5,MIN(5,ROUND(($J$39-$J$39)*100,0))) -> 0 | M11: =-MAX(-5,MIN(5,ROUND(($J$48-$J$39)*100,0))) -> 0 | N11: =-MAX(-5,MIN(5,ROUND(($J$75-$J$39)*100,0))) -> 1 | O11: =-MAX(-5,MIN(5,ROUND(($J$84-$J$39)*100,0))) -> 1 | R11: Suisun | S11: =-MAX(-5,MIN(5,ROUND(($O$39-$O$39)*100,0))) -> 0 | T11: =-MAX(-5,MIN(5,ROUND(($O$48-$O$39)*100,0))) -> 0 | U11: =-MAX(-5,MIN(5,ROUND(($O$75-$O$39)*100,0))) -> 0 | V11: =-MAX(-5,MIN(5,ROUND(($O$84-$O$39)*100,0))) -> 0
D12: Central | E12: =-MAX(-5,MIN(5,ROUND(($F$39-$F$39)*100,0))) -> 0 | F12: =-MAX(-5,MIN(5,ROUND(($F$48-$F$39)*100,0))) -> 0 | G12: =-MAX(-5,MIN(5,ROUND(($F$75-$F$39)*100,0))) -> 0 | H12: =-MAX(-5,MIN(5,ROUND(($F$84-$F$39)*100,0))) -> 0 | K12: Central | L12: =-MAX(-5,MIN(5,ROUND(($K$39-$K$39)*100,0))) -> 0 | M12: =-MAX(-5,MIN(5,ROUND(($K$48-$K$39)*100,0))) -> 0 | N12: =-MAX(-5,MIN(5,ROUND(($K$75-$K$39)*100,0))) -> 0 | O12: =-MAX(-5,MIN(5,ROUND(($K$84-$K$39)*100,0))) -> 0 | R12: Central | S12: =-MAX(-5,MIN(5,ROUND(($P$39-$P$39)*100,0))) -> 0 | T12: =-MAX(-5,MIN(5,ROUND(($P$48-$P$39)*100,0))) -> 0 | U12: =-MAX(-5,MIN(5,ROUND(($P$75-$P$39)*100,0))) -> 0 | V12: =-MAX(-5,MIN(5,ROUND(($P$84-$P$39)*100,0))) -> 0
D13: North | E13: =-MAX(-5,MIN(5,ROUND(($G$39-$G$39)*100,0))) -> 0 | F13: =-MAX(-5,MIN(5,ROUND(($G$48-$G$39)*100,0))) -> 0 | G13: =-MAX(-5,MIN(5,ROUND(($G$75-$G$39)*100,0))) -> 0 | H13: =-MAX(-5,MIN(5,ROUND(($G$84-$G$39)*100,0))) -> 0 | K13: North | L13: =-MAX(-5,MIN(5,ROUND(($L$39-$L$39)*100,0))) -> 0 | M13: =-MAX(-5,MIN(5,ROUND(($L$48-$L$39)*100,0))) -> 0 | N13: =-MAX(-5,MIN(5,ROUND(($L$75-$L$39)*100,0))) -> 0 | O13: =-MAX(-5,MIN(5,ROUND(($L$84-$L$39)*100,0))) -> 0 | R13: North | S13: =-MAX(-5,MIN(5,ROUND(($Q$39-$Q$39)*100,0))) -> 0 | T13: =-MAX(-5,MIN(5,ROUND(($Q$48-$Q$39)*100,0))) -> 0 | U13: =-MAX(-5,MIN(5,ROUND(($Q$75-$Q$39)*100,0))) -> 0 | V13: =-MAX(-5,MIN(5,ROUND(($Q$84-$Q$39)*100,0))) -> 0
D14: South | E14: =-MAX(-5,MIN(5,ROUND(($H$39-$H$39)*100,0))) -> 0 | F14: =-MAX(-5,MIN(5,ROUND(($H$48-$H$39)*100,0))) -> 0 | G14: =-MAX(-5,MIN(5,ROUND(($H$75-$H$39)*100,0))) -> 0 | H14: =-MAX(-5,MIN(5,ROUND(($H$84-$H$39)*100,0))) -> 0 | K14: South | L14: =-MAX(-5,MIN(5,ROUND(($M$39-$M$39)*100,0))) -> 0 | M14: =-MAX(-5,MIN(5,ROUND(($M$48-$M$39)*100,0))) -> 0 | N14: =-MAX(-5,MIN(5,ROUND(($M$75-$M$39)*100,0))) -> 0 | O14: =-MAX(-5,MIN(5,ROUND(($M$84-$M$39)*100,0))) -> 0 | R14: South | S14: =-MAX(-5,MIN(5,ROUND(($R$39-$R$39)*100,0))) -> 0 | T14: =-MAX(-5,MIN(5,ROUND(($R$48-$R$39)*100,0))) -> 0 | U14: =-MAX(-5,MIN(5,ROUND(($R$75-$R$39)*100,0))) -> 0 | V14: =-MAX(-5,MIN(5,ROUND(($R$84-$R$39)*100,0))) -> 0
D15: REGION | E15: BAU | F15: BAF | G15: ECO | H15: NGW | K15: REGION | L15: BAU | M15: BAF | N15: ECO | O15: NGW | R15: REGION | S15: BAU | T15: BAF | U15: ECO | V15: NGW
C16: WATERFOWL | D16: Delta-Wide | E16: =-MAX(-5,MIN(5,ROUND(($D$40-$D$40)*100,0))) -> 0 | F16: =-MAX(-5,MIN(5,ROUND(($D$49-$D$40)*100,0))) -> 0 | G16: =-MAX(-5,MIN(5,ROUND(($D$76-$D$40)*100,0))) -> 0 | H16: =-MAX(-5,MIN(5,ROUND(($D$85-$D$40)*100,0))) -> 0 | J16: WATERFOWL | K16: Delta-Wide | L16: =-MAX(-5,MIN(5,ROUND(($I$40-$I$40)*100,0))) -> 0 | M16: =-MAX(-5,MIN(5,ROUND(($I$49-$I$40)*100,0))) -> 0 | N16: =-MAX(-5,MIN(5,ROUND(($I$76-$I$40)*100,0))) -> 0 | O16: =-MAX(-5,MIN(5,ROUND(($I$85-$I$40)*100,0))) -> 0 | Q16: WATERFOWL | R16: Delta-Wide | S16: =-MAX(-5,MIN(5,ROUND(($N$40-$N$40)*100,0))) -> 0 | T16: =-MAX(-5,MIN(5,ROUND(($N$49-$N$40)*100,0))) -> 0 | U16: =-MAX(-5,MIN(5,ROUND(($N$76-$N$40)*100,0))) -> 0 | V16: =-MAX(-5,MIN(5,ROUND(($N$85-$N$40)*100,0))) -> 0
D17: Suisun | E17: =-MAX(-5,MIN(5,ROUND(($E$40-$E$40)*100,0))) -> 0 | F17: =-MAX(-5,MIN(5,ROUND(($E$49-$E$40)*100,0))) -> 0 | G17: =-MAX(-5,MIN(5,ROUND(($E$76-$E$40)*100,0))) -> 0 | H17: =-MAX(-5,MIN(5,ROUND(($E$85-$E$40)*100,0))) -> 0 | K17: Suisun | L17: =-MAX(-5,MIN(5,ROUND(($J$40-$J$40)*100,0))) -> 0 | M17: =-MAX(-5,MIN(5,ROUND(($J$49-$J$40)*100,0))) -> 0 | N17: =-MAX(-5,MIN(5,ROUND(($J$76-$J$40)*100,0))) -> 0 | O17: =-MAX(-5,MIN(5,ROUND(($J$85-$J$40)*100,0))) -> 0 | R17: Suisun | S17: =-MAX(-5,MIN(5,ROUND(($O$40-$O$40)*100,0))) -> 0 | T17: =-MAX(-5,MIN(5,ROUND(($O$49-$O$40)*100,0))) -> 0 | U17: =-MAX(-5,MIN(5,ROUND(($O$76-$O$40)*100,0))) -> -1 | V17: =-MAX(-5,MIN(5,ROUND(($O$85-$O$40)*100,0))) -> -1
D18: Central | E18: =-MAX(-5,MIN(5,ROUND(($F$40-$F$40)*100,0))) -> 0 | F18: =-MAX(-5,MIN(5,ROUND(($F$49-$F$40)*100,0))) -> 0 | G18: =-MAX(-5,MIN(5,ROUND(($F$76-$F$40)*100,0))) -> 0 | H18: =-MAX(-5,MIN(5,ROUND(($F$85-$F$40)*100,0))) -> 0 | K18: Central | L18: =-MAX(-5,MIN(5,ROUND(($K$40-$K$40)*100,0))) -> 0 | M18: =-MAX(-5,MIN(5,ROUND(($K$49-$K$40)*100,0))) -> 0 | N18: =-MAX(-5,MIN(5,ROUND(($K$76-$K$40)*100,0))) -> 0 | O18: =-MAX(-5,MIN(5,ROUND(($K$85-$K$40)*100,0))) -> 0 | R18: Central | S18: =-MAX(-5,MIN(5,ROUND(($P$40-$P$40)*100,0))) -> 0 | T18: =-MAX(-5,MIN(5,ROUND(($P$49-$P$40)*100,0))) -> 0 | U18: =-MAX(-5,MIN(5,ROUND(($P$76-$P$40)*100,0))) -> 0 | V18: =-MAX(-5,MIN(5,ROUND(($P$85-$P$40)*100,0))) -> 0
D19: North | E19: =-MAX(-5,MIN(5,ROUND(($G$40-$G$40)*100,0))) -> 0 | F19: =-MAX(-5,MIN(5,ROUND(($G$49-$G$40)*100,0))) -> 0 | G19: =-MAX(-5,MIN(5,ROUND(($G$76-$G$40)*100,0))) -> 0 | H19: =-MAX(-5,MIN(5,ROUND(($G$85-$G$40)*100,0))) -> 0 | K19: North | L19: =-MAX(-5,MIN(5,ROUND(($L$40-$L$40)*100,0))) -> 0 | M19: =-MAX(-5,MIN(5,ROUND(($L$49-$L$40)*100,0))) -> 0 | N19: =-MAX(-5,MIN(5,ROUND(($L$76-$L$40)*100,0))) -> 0 | O19: =-MAX(-5,MIN(5,ROUND(($L$85-$L$40)*100,0))) -> 0 | R19: North | S19: =-MAX(-5,MIN(5,ROUND(($Q$40-$Q$40)*100,0))) -> 0 | T19: =-MAX(-5,MIN(5,ROUND(($Q$49-$Q$40)*100,0))) -> 0 | U19: =-MAX(-5,MIN(5,ROUND(($Q$76-$Q$40)*100,0))) -> 0 | V19: =-MAX(-5,MIN(5,ROUND(($Q$85-$Q$40)*100,0))) -> 0
D20: South | E20: =-MAX(-5,MIN(5,ROUND(($H$40-$H$40)*100,0))) -> 0 | F20: =-MAX(-5,MIN(5,ROUND(($H$49-$H$40)*100,0))) -> 0 | G20: =-MAX(-5,MIN(5,ROUND(($H$76-$H$40)*100,0))) -> 0 | H20: =-MAX(-5,MIN(5,ROUND(($H$85-$H$40)*100,0))) -> 0 | K20: South | L20: =-MAX(-5,MIN(5,ROUND(($M$40-$M$40)*100,0))) -> 0 | M20: =-MAX(-5,MIN(5,ROUND(($M$49-$M$40)*100,0))) -> 0 | N20: =-MAX(-5,MIN(5,ROUND(($M$76-$M$40)*100,0))) -> 0 | O20: =-MAX(-5,MIN(5,ROUND(($M$85-$M$40)*100,0))) -> 0 | R20: South | S20: =-MAX(-5,MIN(5,ROUND(($R$40-$R$40)*100,0))) -> 0 | T20: =-MAX(-5,MIN(5,ROUND(($R$49-$R$40)*100,0))) -> 0 | U20: =-MAX(-5,MIN(5,ROUND(($R$76-$R$40)*100,0))) -> 0 | V20: =-MAX(-5,MIN(5,ROUND(($R$85-$R$40)*100,0))) -> 0
D21: REGION | E21: BAU | F21: BAF | G21: ECO | H21: NGW | K21: REGION | L21: BAU | M21: BAF | N21: ECO | O21: NGW | R21: REGION | S21: BAU | T21: BAF | U21: ECO | V21: NGW
C22: ANGLING | D22: Delta-Wide | E22: =-MAX(-5,MIN(5,ROUND(($D$41-$D$41)*100,0))) -> 0 | F22: =-MAX(-5,MIN(5,ROUND(($D$50-$D$41)*100,0))) -> 0 | G22: =-MAX(-5,MIN(5,ROUND(($D$77-$D$41)*100,0))) -> 0 | H22: =-MAX(-5,MIN(5,ROUND(($D$86-$D$41)*100,0))) -> 0 | J22: ANGLING | K22: Delta-Wide | L22: =-MAX(-5,MIN(5,ROUND(($I$41-$I$41)*100,0))) -> 0 | M22: =-MAX(-5,MIN(5,ROUND(($I$50-$I$41)*100,0))) -> 0 | N22: =-MAX(-5,MIN(5,ROUND(($I$77-$I$41)*100,0))) -> 0 | O22: =-MAX(-5,MIN(5,ROUND(($I$86-$I$41)*100,0))) -> 0 | Q22: ANGLING | R22: Delta-Wide | S22: =-MAX(-5,MIN(5,ROUND(($N$41-$N$41)*100,0))) -> 0 | T22: =-MAX(-5,MIN(5,ROUND(($N$50-$N$41)*100,0))) -> 0 | U22: =-MAX(-5,MIN(5,ROUND(($N$77-$N$41)*100,0))) -> 0 | V22: =-MAX(-5,MIN(5,ROUND(($N$86-$N$41)*100,0))) -> 0
D23: Suisun | E23: =-MAX(-5,MIN(5,ROUND(($E$41-$E$41)*100,0))) -> 0 | F23: =-MAX(-5,MIN(5,ROUND(($E$50-$E$41)*100,0))) -> 0 | G23: =-MAX(-5,MIN(5,ROUND(($E$77-$E$41)*100,0))) -> 0 | H23: =-MAX(-5,MIN(5,ROUND(($E$86-$E$41)*100,0))) -> 0 | K23: Suisun | L23: =-MAX(-5,MIN(5,ROUND(($J$41-$J$41)*100,0))) -> 0 | M23: =-MAX(-5,MIN(5,ROUND(($J$50-$J$41)*100,0))) -> 0 | N23: =-MAX(-5,MIN(5,ROUND(($J$77-$J$41)*100,0))) -> 1 | O23: =-MAX(-5,MIN(5,ROUND(($J$86-$J$41)*100,0))) -> 1 | R23: Suisun | S23: =-MAX(-5,MIN(5,ROUND(($O$41-$O$41)*100,0))) -> 0 | T23: =-MAX(-5,MIN(5,ROUND(($O$50-$O$41)*100,0))) -> 0 | U23: =-MAX(-5,MIN(5,ROUND(($O$77-$O$41)*100,0))) -> -1 | V23: =-MAX(-5,MIN(5,ROUND(($O$86-$O$41)*100,0))) -> -1
D24: Central | E24: =-MAX(-5,MIN(5,ROUND(($F$41-$F$41)*100,0))) -> 0 | F24: =-MAX(-5,MIN(5,ROUND(($F$50-$F$41)*100,0))) -> 0 | G24: =-MAX(-5,MIN(5,ROUND(($F$77-$F$41)*100,0))) -> 0 | H24: =-MAX(-5,MIN(5,ROUND(($F$86-$F$41)*100,0))) -> 0 | K24: Central | L24: =-MAX(-5,MIN(5,ROUND(($K$41-$K$41)*100,0))) -> 0 | M24: =-MAX(-5,MIN(5,ROUND(($K$50-$K$41)*100,0))) -> 0 | N24: =-MAX(-5,MIN(5,ROUND(($K$77-$K$41)*100,0))) -> 0 | O24: =-MAX(-5,MIN(5,ROUND(($K$86-$K$41)*100,0))) -> 0 | R24: Central | S24: =-MAX(-5,MIN(5,ROUND(($P$41-$P$41)*100,0))) -> 0 | T24: =-MAX(-5,MIN(5,ROUND(($P$50-$P$41)*100,0))) -> 0 | U24: =-MAX(-5,MIN(5,ROUND(($P$77-$P$41)*100,0))) -> 0 | V24: =-MAX(-5,MIN(5,ROUND(($P$86-$P$41)*100,0))) -> 0
D25: North | E25: =-MAX(-5,MIN(5,ROUND(($G$41-$G$41)*100,0))) -> 0 | F25: =-MAX(-5,MIN(5,ROUND(($G$50-$G$41)*100,0))) -> 0 | G25: =-MAX(-5,MIN(5,ROUND(($G$77-$G$41)*100,0))) -> 0 | H25: =-MAX(-5,MIN(5,ROUND(($G$86-$G$41)*100,0))) -> 0 | K25: North | L25: =-MAX(-5,MIN(5,ROUND(($L$41-$L$41)*100,0))) -> 0 | M25: =-MAX(-5,MIN(5,ROUND(($L$50-$L$41)*100,0))) -> 0 | N25: =-MAX(-5,MIN(5,ROUND(($L$77-$L$41)*100,0))) -> 0 | O25: =-MAX(-5,MIN(5,ROUND(($L$86-$L$41)*100,0))) -> 0 | R25: North | S25: =-MAX(-5,MIN(5,ROUND(($Q$41-$Q$41)*100,0))) -> 0 | T25: =-MAX(-5,MIN(5,ROUND(($Q$50-$Q$41)*100,0))) -> 0 | U25: =-MAX(-5,MIN(5,ROUND(($Q$77-$Q$41)*100,0))) -> 0 | V25: =-MAX(-5,MIN(5,ROUND(($Q$86-$Q$41)*100,0))) -> 0
D26: South | E26: =-MAX(-5,MIN(5,ROUND(($H$41-$H$41)*100,0))) -> 0 | F26: =-MAX(-5,MIN(5,ROUND(($H$50-$H$41)*100,0))) -> 0 | G26: =-MAX(-5,MIN(5,ROUND(($H$77-$H$41)*100,0))) -> 0 | H26: =-MAX(-5,MIN(5,ROUND(($H$86-$H$41)*100,0))) -> 0 | K26: South | L26: =-MAX(-5,MIN(5,ROUND(($M$41-$M$41)*100,0))) -> 0 | M26: =-MAX(-5,MIN(5,ROUND(($M$50-$M$41)*100,0))) -> 0 | N26: =-MAX(-5,MIN(5,ROUND(($M$77-$M$41)*100,0))) -> 0 | O26: =-MAX(-5,MIN(5,ROUND(($M$86-$M$41)*100,0))) -> 0 | R26: South | S26: =-MAX(-5,MIN(5,ROUND(($R$41-$R$41)*100,0))) -> 0 | T26: =-MAX(-5,MIN(5,ROUND(($R$50-$R$41)*100,0))) -> 0 | U26: =-MAX(-5,MIN(5,ROUND(($R$77-$R$41)*100,0))) -> 0 | V26: =-MAX(-5,MIN(5,ROUND(($R$86-$R$41)*100,0))) -> 0
D27: REGION | E27: BAU | F27: BAF | G27: ECO | H27: NGW | K27: REGION | L27: BAU | M27: BAF | N27: ECO | O27: NGW | R27: REGION | S27: BAU | T27: BAF | U27: ECO | V27: NGW
C28: DAY USE | D28: Delta-Wide | E28: =-MAX(-5,MIN(5,ROUND(($D$38-$D$38)*100,0))) -> 0 | F28: =-MAX(-5,MIN(5,ROUND(($D$47-$D$38)*100,0))) -> 0 | G28: =-MAX(-5,MIN(5,ROUND(($D$74-$D$38)*100,0))) -> 0 | H28: =-MAX(-5,MIN(5,ROUND(($D$83-$D$38)*100,0))) -> 0 | J28: DAY USE | K28: Delta-Wide | L28: =-MAX(-5,MIN(5,ROUND(($I$38-$I$38)*100,0))) -> 0 | M28: =-MAX(-5,MIN(5,ROUND(($I$47-$I$38)*100,0))) -> 0 | N28: =-MAX(-5,MIN(5,ROUND(($I$74-$I$38)*100,0))) -> 0 | O28: =-MAX(-5,MIN(5,ROUND(($I$83-$I$38)*100,0))) -> 0 | Q28: DAY USE | R28: Delta-Wide | S28: =-MAX(-5,MIN(5,ROUND(($N$38-$N$38)*100,0))) -> 0 | T28: =-MAX(-5,MIN(5,ROUND(($N$47-$N$38)*100,0))) -> 0 | U28: =-MAX(-5,MIN(5,ROUND(($N$74-$N$38)*100,0))) -> 0 | V28: =-MAX(-5,MIN(5,ROUND(($N$83-$N$38)*100,0))) -> 0
D29: Suisun | E29: =-MAX(-5,MIN(5,ROUND(($E$38-$E$38)*100,0))) -> 0 | F29: =-MAX(-5,MIN(5,ROUND(($E$47-$E$38)*100,0))) -> 0 | G29: =-MAX(-5,MIN(5,ROUND(($E$74-$E$38)*100,0))) -> 1 | H29: =-MAX(-5,MIN(5,ROUND(($E$83-$E$38)*100,0))) -> 1 | K29: Suisun | L29: =-MAX(-5,MIN(5,ROUND(($J$38-$J$38)*100,0))) -> 0 | M29: =-MAX(-5,MIN(5,ROUND(($J$47-$J$38)*100,0))) -> 0 | N29: =-MAX(-5,MIN(5,ROUND(($J$74-$J$38)*100,0))) -> 0 | O29: =-MAX(-5,MIN(5,ROUND(($J$83-$J$38)*100,0))) -> 0 | R29: Suisun | S29: =-MAX(-5,MIN(5,ROUND(($O$38-$O$38)*100,0))) -> 0 | T29: =-MAX(-5,MIN(5,ROUND(($O$47-$O$38)*100,0))) -> 0 | U29: =-MAX(-5,MIN(5,ROUND(($O$74-$O$38)*100,0))) -> 1 | V29: =-MAX(-5,MIN(5,ROUND(($O$83-$O$38)*100,0))) -> 1
D30: Central | E30: =-MAX(-5,MIN(5,ROUND(($F$38-$F$38)*100,0))) -> 0 | F30: =-MAX(-5,MIN(5,ROUND(($F$47-$F$38)*100,0))) -> 0 | G30: =-MAX(-5,MIN(5,ROUND(($F$74-$F$38)*100,0))) -> 0 | H30: =-MAX(-5,MIN(5,ROUND(($F$83-$F$38)*100,0))) -> 0 | K30: Central | L30: =-MAX(-5,MIN(5,ROUND(($K$38-$K$38)*100,0))) -> 0 | M30: =-MAX(-5,MIN(5,ROUND(($K$47-$K$38)*100,0))) -> 0 | N30: =-MAX(-5,MIN(5,ROUND(($K$74-$K$38)*100,0))) -> 0 | O30: =-MAX(-5,MIN(5,ROUND(($K$83-$K$38)*100,0))) -> 0 | R30: Central | S30: =-MAX(-5,MIN(5,ROUND(($P$38-$P$38)*100,0))) -> 0 | T30: =-MAX(-5,MIN(5,ROUND(($P$47-$P$38)*100,0))) -> 0 | U30: =-MAX(-5,MIN(5,ROUND(($P$74-$P$38)*100,0))) -> 0 | V30: =-MAX(-5,MIN(5,ROUND(($P$83-$P$38)*100,0))) -> 0
D31: North | E31: =-MAX(-5,MIN(5,ROUND(($G$38-$G$38)*100,0))) -> 0 | F31: =-MAX(-5,MIN(5,ROUND(($G$47-$G$38)*100,0))) -> 0 | G31: =-MAX(-5,MIN(5,ROUND(($G$74-$G$38)*100,0))) -> 0 | H31: =-MAX(-5,MIN(5,ROUND(($G$83-$G$38)*100,0))) -> 0 | K31: North | L31: =-MAX(-5,MIN(5,ROUND(($L$38-$L$38)*100,0))) -> 0 | M31: =-MAX(-5,MIN(5,ROUND(($L$47-$L$38)*100,0))) -> 0 | N31: =-MAX(-5,MIN(5,ROUND(($L$74-$L$38)*100,0))) -> 0 | O31: =-MAX(-5,MIN(5,ROUND(($L$83-$L$38)*100,0))) -> 0 | R31: North | S31: =-MAX(-5,MIN(5,ROUND(($Q$38-$Q$38)*100,0))) -> 0 | T31: =-MAX(-5,MIN(5,ROUND(($Q$47-$Q$38)*100,0))) -> 0 | U31: =-MAX(-5,MIN(5,ROUND(($Q$74-$Q$38)*100,0))) -> 0 | V31: =-MAX(-5,MIN(5,ROUND(($Q$83-$Q$38)*100,0))) -> 0
D32: South | E32: =-MAX(-5,MIN(5,ROUND(($H$38-$H$38)*100,0))) -> 0 | F32: =-MAX(-5,MIN(5,ROUND(($H$47-$H$38)*100,0))) -> 0 | G32: =-MAX(-5,MIN(5,ROUND(($H$74-$H$38)*100,0))) -> 0 | H32: =-MAX(-5,MIN(5,ROUND(($H$83-$H$38)*100,0))) -> 0 | K32: South | L32: =-MAX(-5,MIN(5,ROUND(($M$38-$M$38)*100,0))) -> 0 | M32: =-MAX(-5,MIN(5,ROUND(($M$47-$M$38)*100,0))) -> 0 | N32: =-MAX(-5,MIN(5,ROUND(($M$74-$M$38)*100,0))) -> 0 | O32: =-MAX(-5,MIN(5,ROUND(($M$83-$M$38)*100,0))) -> 0 | R32: South | S32: =-MAX(-5,MIN(5,ROUND(($R$38-$R$38)*100,0))) -> 0 | T32: =-MAX(-5,MIN(5,ROUND(($R$47-$R$38)*100,0))) -> 0 | U32: =-MAX(-5,MIN(5,ROUND(($R$74-$R$38)*100,0))) -> 0 | V32: =-MAX(-5,MIN(5,ROUND(($R$83-$R$38)*100,0))) -> 0
C35: BAU % EXCEEDANCES
D36: Total Run | I36: Wet Seasons | N36: Dry Seasons
D37: Delta-Wide | E37: Suisun | F37: Central Delta | G37: North Delta | H37: South Delta | I37: Delta-Wide | J37: Suisun | K37: Central Delta | L37: North Delta | M37: South Delta | N37: Delta-Wide | O37: Suisun | P37: Central Delta | Q37: North Delta | R37: South Delta
C38: Day Use | D38: =BAU!AK871 -> 0.5411795 | E38: =BAU!AL871 -> 0.52218019 | F38: =BAU!AM871 -> 0.53629833 | G38: =BAU!AN871 -> 0.56602476 | H38: =BAU!AO871 -> 0.54638545 | I38: =BAU!AS871 -> 0.93429709 | J38: =BAU!AT871 -> 0.90616343 | K38: =BAU!AU871 -> 0.93628809 | L38: =BAU!AV871 -> 0.98661127 | M38: =BAU!AW871 -> 0.92243767 | N38: =BAU!BA871 -> 0.15343238 | O38: =BAU!BB871 -> 0.14344262 | P38: =BAU!BC871 -> 0.14177292 | Q38: =BAU!BD871 -> 0.15118397 | R38: =BAU!BE871 -> 0.17547055
C39: Birding | D39: =BAU!AK819 -> 0.36769257 | E39: =BAU!AL819 -> 0.36795048 | F39: =BAU!AM819 -> 0.37750267 | G39: =BAU!AN819 -> 0.34181568 | H39: =BAU!AO819 -> 0.37490448 | I39: =BAU!AS819 -> 0.005367036 | J39: =BAU!AT819 -> 0.011772853 | K39: =BAU!AU819 -> 0.00061557402 | L39: =BAU!AV819 -> 0 | M39: =BAU!AW819 -> 0.0080024623 | N39: =BAU!BA819 -> 0.72506831 | O39: =BAU!BB819 -> 0.7192623 | P39: =BAU!BC819 -> 0.74924104 | Q39: =BAU!BD819 -> 0.67896175 | R39: =BAU!BE819 -> 0.73679417
C40: Waterfowl | D40: =BAU!AK836 -> 0.12138927 | E40: =BAU!AL836 -> 0.050550206 | F40: =BAU!AM836 -> 0.13082684 | G40: =BAU!AN836 -> 0.069692801 | H40: =BAU!AO836 -> 0.20938407 | I40: =BAU!AS836 -> 0 | J40: =BAU!AT836 -> 0 | K40: =BAU!AU836 -> 0 | L40: =BAU!AV836 -> 0 | M40: =BAU!AW836 -> 0 | N40: =BAU!BA836 -> 0.24112022 | O40: =BAU!BB836 -> 0.10040984 | P40: =BAU!BC836 -> 0.25986642 | Q40: =BAU!BD836 -> 0.13843352 | R40: =BAU!BE836 -> 0.41590771
C41: Angling | D41: =BAU!AK802 -> 0.44179849 | E41: =BAU!AL802 -> 0.45787483 | F41: =BAU!AM802 -> 0.44780682 | G41: =BAU!AN802 -> 0.41746905 | H41: =BAU!AO802 -> 0.4377197 | I41: =BAU!AS802 -> 0.049342105 | J41: =BAU!AT802 -> 0.076523546 | K41: =BAU!AU802 -> 0.045860265 | L41: =BAU!AV802 -> 0.0078485688 | M41: =BAU!AW802 -> 0.056325023 | N41: =BAU!BA802 -> 0.82889344 | O41: =BAU!BB802 -> 0.83401639 | P41: =BAU!BC802 -> 0.8442623 | Q41: =BAU!BD802 -> 0.82149362 | R41: =BAU!BE802 -> 0.81390407
C42: Boating & Day Use | D42: =BAU!AK853 -> 0.41583563 | E42: =BAU!AL853 -> 0.42314305 | F42: =BAU!AM853 -> 0.42228336 | G42: =BAU!AN853 -> 0.39133425 | H42: =BAU!AO853 -> 0.41922665 | I42: =BAU!AS853 -> 0.030730609 | J42: =BAU!AT853 -> 0.046052632 | K42: =BAU!AU853 -> 0.027700831 | L42: =BAU!AV853 -> 0.0027700831 | M42: =BAU!AW853 -> 0.038781163 | N42: =BAU!BA853 -> 0.79567964 | O42: =BAU!BB853 -> 0.79508197 | P42: =BAU!BC853 -> 0.81147541 | Q42: =BAU!BD853 -> 0.77459016 | R42: =BAU!BE853 -> 0.7944748
...

Sheet BAU
B1: Suisun | J1: Central Delta | S1: North Delta | Y1: South Delta
A2: Date | B2: CHADBOURNE SLOUGH AT SUNRISE DUCK CLUB | C2: MONTEZUMA SLOUGH AT NATIONAL STEEL | D2: MONTEZUMA SLOUGH NEAR BELDENS LANDING | E2: SUISUN SLOUGH 300' SOUTH OF VOLANTI SLOUGH | F2: HONKER BAY | G2: SUISUN BAY AT VAN SICKLE ISLAND | H2: SUISUN BAY WEST REACH | I2: GRIZZLY BAY BUOY | J2: DUTCH SL BELOW JERSEY ISLAND | K2: FALSE RIVER NEAR OAKLEY | L2: OLD RIVER AT FRANKS TRACT | M2: PITTSBURG | N2: SACRAMENTO RIVER AT EMMATON | O2: SAN ANDREAS LANDING | P2: SAN JOAQUIN RIVER AT JERSEY POINT | Q2: SUISUN BAY AT CHANNEL MARKER 5 AT COLLINSVILLE | R2: BRANNAN MARINAS AT SAN JOAQUIN RIVER | S2: LIBERTY CUT AT FIVE POINTS | T2: CACHE SLOUGH ABOVE RYER ISLAND FERRY | U2: DELTA CROSS CHANNEL NEAR WALNUT GROVE | V2: SACRAMENTO RIVER DOWNSTREAM OF ISLETON | W2: COURTLAND AT SACRAMENTO RIVER | X2: VIERAS RESORT AT SACRAMENTO RIVER | Y2: GRANT LINE CANAL NEAR CLIFTON COURT FORE | Z2: LITTLE POTATO SLOUGH AT TERMINOUS | AA2: MIDDLE RIVER AT MILDRED ISLAND | AB2: OLD RIVER AT CLIFTON COURT | AC2: SAN JOAQUIN RIVER AT BRANDT BRIDGE | AD2: SAN JOAQUIN RIVER AT PRISONERS POINT | AE2: SAN JOAQUIN RIVER NEAR VERNALIS | AF2: SAN JOAQUIN RVER AT ROUGH AND READY ISLAND | AG2: VICTORIA CANAL BEFORE CLIFTON COURT FORE
A3: 43378 | B3: 19.881892 | C3: 19.946822 | D3: 20.022306 | E3: 19.878851 | F3: 19.270751 | G3: 19.35747 | H3: 19.204487 | I3: 19.187432 | J3: 20.129403 | K3: 19.927536 | L3: 19.790056 | M3: 19.378354 | N3: 19.467616 | O3: 19.483382 | P3: 19.884368 | Q3: 19.412066 | R3: 19.778003 | S3: 19.397607 | T3: 19.11019 | U3: 18.044802 | V3: 18.659678 | W3: 17.89473 | X3: 18.443941 | Y3: 21.256297 | Z3: 19.968507 | AA3: 20.514354 | AB3: 20.86557 | AC3: 21.612907 | AD3: 19.794133 | AE3: 20.827559 | AF3: 21.917801 | AG3: 20.919337
A4: 43379 | B4: 20.084911 | C4: 20.077475 | D4: 20.098871 | E4: 19.94807 | F4: 19.348607 | G4: 19.387284 | H4: 19.227404 | I4: 19.227057 | J4: 19.990958 | K4: 19.846132 | L4: 19.651565 | M4: 19.406646 | N4: 19.418079 | O4: 19.384662 | P4: 19.817333 | Q4: 19.425428 | R4: 19.68839 | S4: 19.408166 | T4: 19.039153 | U4: 17.909433 | V4: 18.661773 | W4: 17.707632 | X4: 18.466893 | Y4: 20.931894 | Z4: 19.792722 | AA4: 20.315943 | AB4: 20.602913 | AC4: 21.272815 | AD4: 19.680926 | AE4: 20.37743 | AF4: 21.632797 | AG4: 20.668715
A5: 43380 | B5: 19.936263 | C5: 20.08238 | D5: 20.074227 | E5: 19.912039 | F5: 19.240344 | G5: 19.346987 | H5: 19.191479 | I5: 19.034106 | J5: 19.295939 | K5: 19.507502 | L5: 19.346094 | M5: 19.369132 | N5: 19.173392 | O5: 19.100842 | P5: 19.519943 | Q5: 19.363121 | R5: 19.416142 | S5: 19.066744 | T5: 18.814004 | U5: 17.495592 | V5: 18.42336 | W5: 17.345313 | X5: 18.216693 | Y5: 20.023635 | Z5: 19.229766 | AA5: 19.775541 | AB5: 19.800401 | AC5: 20.00129 | AD5: 19.401746 | AE5: 19.278456 | AF5: 20.835331 | AG5: 19.802995
A6: 43381 | B6: 20.09799 | C6: 20.139727 | D6: 20.0854 | E6: 19.918991 | F6: 19.275052 | G6: 19.330752 | H6: 19.167662 | I6: 19.101572 | J6: 18.944653 | K6: 19.291079 | L6: 19.147354 | M6: 19.345004 | N6: 19.057465 | O6: 18.924499 | P6: 19.314517 | Q6: 19.331455 | R6: 19.231487 | S6: 18.676753 | T6: 18.546547 | U6: 17.248097 | V6: 18.163 | W6: 17.110716 | X6: 17.920385 | Y6: 19.516894 | Z6: 18.871749 | AA6: 19.500501 | AB6: 19.414865 | AC6: 19.114844 | AD6: 19.15668 | AE6: 18.671517 | AF6: 20.159111 | AG6: 19.393992
A7: 43382 | B7: 20.168098 | C7: 20.267648 | D7: 20.149036 | E7: 19.993576 | F7: 19.292437 | G7: 19.352269 | H7: 19.180327 | I7: 19.236646 | J7: 19.229145 | K7: 19.32946 | L7: 19.150725 | M7: 19.364663 | N7: 19.100631 | O7: 18.940155 | P7: 19.343707 | Q7: 19.357399 | R7: 19.238596 | S7: 18.647005 | T7: 18.411193 | U7: 17.230317 | V7: 18.083322 | W7: 17.104754 | X7: 17.836505 | Y7: 19.636749 | Z7: 18.854365 | AA7: 19.539839 | AB7: 19.552302 | AC7: 19.051296 | AD7: 19.098443 | AE7: 18.906943 | AF7: 19.960106 | AG7: 19.631687
A8: 43383 | B8: 19.483807 | C8: 19.83647 | D8: 19.763056 | E8: 19.566944 | F8: 18.916382 | G8: 19.144585 | H8: 18.959819 | I8: 18.583755 | J8: 19.074357 | K8: 19.207875 | L8: 19.031299 | M8: 19.161348 | N8: 18.953971 | O8: 18.81381 | P8: 19.217041 | Q8: 19.159454 | R8: 19.126319 | S8: 18.248992 | T8: 18.153421 | U8: 17.253432 | V8: 17.875972 | W8: 17.20229 | X8: 17.645953 | Y8: 19.716448 | Z8: 18.67757 | AA8: 19.536758 | AB8: 19.61944 | AC8: 19.225258 | AD8: 18.973668 | AE8: 19.229105 | AF8: 19.86216 | AG8: 19.730873
A9: 43384 | B9: 18.89508 | C9: 19.294374 | D9: 19.252875 | E9: 19.018874 | F9: 18.546659 | G9: 18.869663 | H9: 18.681205 | I9: 17.908099 | J9: 18.670463 | K9: 18.96967 | L9: 18.820145 | M9: 18.887914 | N9: 18.696954 | O9: 18.528218 | P9: 18.976471 | Q9: 18.882807 | R9: 18.880894 | S9: 17.70047 | T9: 17.797064 | U9: 17.289461 | V9: 17.581621 | W9: 17.259852 | X9: 17.395768 | Y9: 19.707803 | Z9: 18.426789 | AA9: 19.460037 | AB9: 19.61957 | AC9: 19.286815 | AD9: 18.770006 | AE9: 19.255034 | AF9: 19.755101 | AG9: 19.707933
A10: 43385 | B10: 18.921097 | C10: 19.165071 | D10: 19.059235 | E10: 18.840806 | F10: 18.521031 | G10: 18.748492 | H10: 18.56931 | I10: 17.877404 | J10: 18.572834 | K10: 18.850242 | L10: 18.674818 | M10: 18.762219 | N10: 18.555644 | O10: 18.365561 | P10: 18.85209 | Q10: 18.752639 | R10: 18.706899 | S10: 17.698354 | T10: 17.67492 | U10: 17.36847 | V10: 17.580944 | W10: 17.326208 | X10: 17.484324 | Y10: 19.64983 | Z10: 18.349254 | AA10: 19.325675 | AB10: 19.548231 | AC10: 19.338728 | AD10: 18.62445 | AE10: 19.132824 | AF10: 19.66039 | AG10: 19.640317
A11: 43386 | B11: 18.88267 | C11: 19.195327 | D11: 18.999353 | E11: 18.807819 | F11: 18.475541 | G11: 18.656264 | H11: 18.491916 | I11: 17.906205 | J11: 18.646738 | K11: 18.795591 | L11: 18.582899 | M11: 18.668782 | N11: 18.453386 | O11: 18.375562 | P11: 18.783853 | Q11: 18.666364 | R11: 18.647112 | S11: 17.927199 | T11: 17.728002 | U11: 17.458275 | V11: 17.670932 | W11: 17.329703 | X11: 17.610923 | Y11: 19.555516 | Z11: 18.356029 | AA11: 19.190973 | AB11: 19.400513 | AC11: 19.340619 | AD11: 18.545357 | AE11: 18.980072 | AF11: 19.604763 | AG11: 19.564797
A12: 43387 | B12: 18.586327 | C12: 18.962372 | D12: 18.797949 | E12: 18.61634 | F12: 18.288202 | G12: 18.482992 | H12: 18.339534 | I12: 17.648789 | J12: 18.273209 | K12: 18.578043 | L12: 18.355722 | M12: 18.496386 | N12: 18.226321 | O12: 18.24213 | P12: 18.577457 | Q12: 18.486258 | R12: 18.485773 | S12: 17.669215 | T12: 17.598488 | U12: 17.225961 | V12: 17.515017 | W12: 16.981206 | X12: 17.459041 | Y12: 19.313833 | Z12: 18.214375 | AA12: 19.009064 | AB12: 19.136732 | AC12: 19.10681 | AD12: 18.37472 | AE12: 18.413826 | AF12: 19.458502 | AG12: 19.34975
A13: 43388 | B13: 18.677809 | C13: 18.887914 | D13: 18.750515 | E13: 18.597129 | F13: 18.28139 | G13: 18.384709 | H13: 18.269205 | I13: 17.71427 | J13: 17.477001 | K13: 18.203211 | L13: 18.023363 | M13: 18.397196 | N13: 17.953577 | O13: 17.928461 | P13: 18.242245 | Q13: 18.359915 | R13: 18.165104 | S13: 16.896866 | T13: 17.246175 | U13: 16.607321 | V13: 17.164059 | W13: 16.285049 | X13: 17.096064 | Y13: 18.854767 | Z13: 17.782918 | AA13: 18.669327 | AB13: 18.692849 | AC13: 18.497206 | AD13: 18.06276 | AE13: 17.309574 | AF13: 19.045945 | AG13: 18.870661
A14: 43389 | B14: 18.599486 | C14: 18.847694 | D14: 18.718129 | E14: 18.583307 | F14: 18.243193 | G14: 18.26679 | H14: 18.184644 | I14: 17.622116 | J14: 17.349396 | K14: 18.043329 | L14: 17.929911 | M14: 18.282717 | N14: 17.8331 | O14: 17.841547 | P14: 18.066187 | Q14: 18.246411 | R14: 18.034102 | S14: 16.684613 | T14: 17.086122 | U14: 16.111823 | V14: 16.976885 | W14: 15.749395 | X14: 16.855547 | Y14: 18.550158 | Z14: 17.674215 | AA14: 18.420153 | AB14: 18.418605 | AC14: 17.902128 | AD14: 17.901278 | AE14: 16.819056 | AF14: 18.70471 | AG14: 18.605267
... A786: 44161 | B786: 11.100417 | C786: 12.041448 | D786: 11.789509 | E786: 11.656343 | F786: 11.753402 | G786: 12.140761 | H786: 12.125061 | I786: 10.741018 | J786: 11.431143 | K786: 12.137514 | L786: 12.153171 | M786: 12.150971 | N786: 11.610029 | O786: 12.061409 | P786: 12.142152 | Q786: 12.05347 | R786: 12.288611 | S786: 10.352564 | T786: 11.251497 | U786: 10.937339 | V786: 11.317329 | W786: 10.776823 | X786: 11.315218 | Y786: 11.177569 | Z786: 11.244733 | AA786: 12.003395 | AB786: 11.613107 | AC786: 10.851594 | AD786: 12.232988 | AE786: 11.208901 | AF786: 11.596925 | AG786: 11.491769
A787: TOTAL EXCEEDANCES | B787: =COUNTIF(B$3:B$729,">=18.42") -> 352 | C787: =COUNTIF(C$3:C$729,">=18.42") -> 331 | D787: =COUNTIF(D$3:D$729,">=18.42") -> 343 | E787: =COUNTIF(E$3:E$729,">=18.42") -> 344 | F787: =COUNTIF(F$3:F$729,">=18.42") -> 324 | G787: =COUNTIF(G$3:G$729,">=18.42") -> 325 | H787: =COUNTIF(H$3:H$729,">=18.42") -> 323 | I787: =COUNTIF(I$3:I$729,">=18.42") -> 321 | ... AG787: =COUNTIF(AG$3:AG$729,">=18.42") -> 355
A788: WET 1 | B788: =COUNTIF(B$3:B$180,">=18.42") -> 15 | C788: =COUNTIF(C$3:C$180,">=18.42") -> 13 | D788: =COUNTIF(D$3:D$180,">=18.42") -> 16 | E788: =COUNTIF(E$3:E$180,">=18.42") -> 16 | F788: =COUNTIF(F$3:F$180,">=18.42") -> 9 | G788: =COUNTIF(G$3:G$180,">=18.42") -> 10 | H788: =COUNTIF(H$3:H$180,">=18.42") -> 9 | I788: =COUNTIF(I$3:I$180,">=18.42") -> 6 | ... AG788: =COUNTIF(AG$3:AG$180,">=18.42") -> 17 | AH788: OCT 2018 - MARCH 2019
A789: WET 2 | B789: =COUNTIF(B$364:B$546,">=18.42") -> 19 | C789: =COUNTIF(C$364:C$546,">=18.42") -> 17 | D789: =COUNTIF(D$364:D$546,">=18.42") -> 19 | E789: =COUNTIF(E$364:E$546,">=18.42") -> 17 | F789: =COUNTIF(F$364:F$546,">=18.42") -> 14 | G789: =COUNTIF(G$364:G$546,">=18.42") -> 14 | H789: =COUNTIF(H$364:H$546,">=18.42") -> 15 | I789: =COUNTIF(I$364:I$546,">=18.42") -> 12 | ... AG789: =COUNTIF(AG$364:AG$546,">=18.42") -> 21 | AH789: OCT 2019 - MARCH 2020
A790: DRY 1 | B790: =COUNTIF(B$181:B$363,">=18.42") -> 156 | C790: =COUNTIF(C$181:C$363,">=18.42") -> 141 | D790: =COUNTIF(D$181:D$363,">=18.42") -> 147 | E790: =COUNTIF(E$181:E$363,">=18.42") -> 150 | F790: =COUNTIF(F$181:F$363,">=18.42") -> 142 | G790: =COUNTIF(G$181:G$363,">=18.42") -> 143 | H790: =COUNTIF(H$181:H$363,">=18.42") -> 142 | I790: =COUNTIF(I$181:I$363,">=18.42") -> 143 | ... AG790: =COUNTIF(AG$181:AG$363,">=18.42") -> 147 | AH790: APRIL 2019 - SEPTEMBER 2019
A791: DRY 2 | B791: =COUNTIF(B$547:B$729,">=18.42") -> 162 | C791: =COUNTIF(C$547:C$729,">=18.42") -> 160 | D791: =COUNTIF(D$547:D$729,">=18.42") -> 161 | E791: =COUNTIF(E$547:E$729,">=18.42") -> 161 | F791: =COUNTIF(F$547:F$729,">=18.42") -> 159 | G791: =COUNTIF(G$547:G$729,">=18.42") -> 158 | H791: =COUNTIF(H$547:H$729,">=18.42") -> 157 | I791: =COUNTIF(I$547:I$729,">=18.42") -> 160 | ... AG791: =COUNTIF(AG$547:AG$729,">=18.42") -> 170 | AH791: APRIL 2020 - SEPTEMBER 2020
A792: ALL WET | B792: =SUM(B788,B789) -> 34 | C792: =SUM(C788,C789) -> 30 | D792: =SUM(D788,D789) -> 35 | E792: =SUM(E788,E789) -> 33 | F792: =SUM(F788,F789) -> 23 | G792: =SUM(G788,G789) -> 24 | H792: =SUM(H788,H789) -> 24 | I792: =SUM(I788,I789) -> 18 | ... AG792: =SUM(AG788,AG789) -> 38
A793: ALL DRY | B793: =SUM(B790,B791) -> 318 | C793: =SUM(C790,C791) -> 301 | D793: =SUM(D790,D791) -> 308 | E793: =SUM(E790,E791) -> 311 | F793: =SUM(F790,F791) -> 301 | G793: =SUM(G790,G791) -> 301 | H793: =SUM(H790,H791) -> 299 | I793: =SUM(I790,I791) -> 303 | ... AG793: =SUM(AG790,AG791) -> 317
D796: Angling 18.42C | F796: THRESHOLD: 18.42C WATER TEMP | S796: ANGLING 18.42C | AA796: ANGLING 18.42C | AE796: ANGLING 18.42C | AI796: ANGLING 18.42C | AQ796: ANGLING 18.42C | AY796: ANGLING 18.42C
F797: WET SEASON | S797: TOTAL RUN | AA797: WET SEASONS | AE797: DRY SEASONS | AI797: TOTAL RUN | AK797: Delta-Wide | AL797: Suisun | AM797: Central Delta | AN797: North Delta | AO797: South Delta | AQ797: WET SEASONS | AS797: Delta-Wide | AT797: Suisun | AU797: Central Delta | AV797: North Delta | AW797: South Delta | AY797: DRY SEASONS | BA797: Delta-Wide | BB797: Suisun | BC797: Central Delta | BD797: North Delta | BE797: South Delta
F798: OCTOBER 1 - MARCH 31 | M798: DRY SEASON | S798: Total points | U798: =COUNTIF($B$2:$AG$2,"<>") -> 32 | AA798: Total points | AC798: =U798 -> 32 | AE798: Total points | AG798: =U798 -> 32 | AI798: Total points | AK798: =COUNTIF($B$2:$AG$2,"<>") -> 32 | AL798: =COUNTIF($B$2:$I$2,"<>") -> 8 | AM798: =COUNTIF($J$2:$R$2,"<>") -> 9 | AN798: =COUNTIF($S$2:$X$2,"<>") -> 6 | AO798: =COUNTIF($Y$2:$AG$2,"<>") -> 9 | AQ798: Total points | AS798: =COUNTIF($B$2:$AG$2,"<>") -> 32 | AT798: =COUNTIF($B$2:$I$2,"<>") -> 8 | AU798: =COUNTIF($J$2:$R$2,"<>") -> 9 | AV798: =COUNTIF($S$2:$X$2,"<>") -> 6 | AW798: =COUNTIF($Y$2:$AG$2,"<>") -> 9 | AY798: Total points | BA798: =COUNTIF($B$2:$AG$2,"<>") -> 32 | BB798: =COUNTIF($B$2:$I$2,"<>") -> 8 | BC798: =COUNTIF($J$2:$R$2,"<>") -> 9 | BD798: =COUNTIF($S$2:$X$2,"<>") -> 6 | BE798: =COUNTIF($Y$2:$AG$2,"<>") -> 9
F799: WET SEASON 1 | H799: 10/5/18 - 3/31/19 | J799: =COUNTIF($A$3:$A$180,"<>") -> 178 | M799: APRIL 1 - SEPTEMBER 30 | S799: Days in run | U799: =COUNTIF($A$3:$A$729,"<>") -> 727 | AA799: Days in run | AC799: =SUM($J$799:$J$800) -> 361 | AE799: Days in run | AG799: =SUM($Q$800:$Q$801) -> 366 | AI799: Days in run | AK799: =COUNTIF($A$3:$A$729,"<>") -> 727 | AL799: =COUNTIF($A$3:$A$729,"<>") -> 727 | AM799: =COUNTIF($A$3:$A$729,"<>") -> 727 | AN799: =COUNTIF($A$3:$A$729,"<>") -> 727 | AO799: =COUNTIF($A$3:$A$729,"<>") -> 727 | AQ799: Days in run | AS799: =SUM($J$799:$J$800) -> 361 | AT799: =SUM($J$799:$J$800) -> 361 | AU799: =SUM($J$799:$J$800) -> 361 | AV799: =SUM($J$799:$J$800) -> 361 | AW799: =SUM($J$799:$J$800) -> 361 | AY799: Days in run | BA799: =SUM($Q$800:$Q$801) -> 366 | BB799: =SUM($Q$800:$Q$801) -> 366 | BC799: =SUM($Q$800:$Q$801) -> 366 | BD799: =SUM($Q$800:$Q$801) -> 366 | BE799: =SUM($Q$800:$Q$801) -> 366
F800: WET SEASON 2 | H800: 10/1/19 - 3/31/20 | J800: =COUNTIF($A$364:$A$546,"<>") -> 183 | M800: DRY SEASON 1 | O800: 4/1/19 - 9/30/19 | Q800: =COUNTIF($A$181:$A$363,"<>") -> 183 | S800: Total measurements | U800: =U799*U798 -> 23264 | V800: DENOMINATOR FOR EXCEEDANCE % | AA800: Total measurements | AC800: =AC799*AC798 -> 11552 | AE800: Total measurements | AG800: =AG798*AG799 -> 11712 | AI800: Total measurements | AK800: =AK799*AK798 -> 23264 | AL800: =AL799*AL798 -> 5816 | AM800: =AM799*AM798 -> 6543 | AN800: =AN799*AN798 -> 4362 | AO800: =AO799*AO798 -> 6543 | AQ800: Total measurements | AS800: =AS799*AS798 -> 11552 | AT800: =AT799*AT798 -> 2888 | AU800: =AU799*AU798 -> 3249 | AV800: =AV799*AV798 -> 2166 | AW800: =AW799*AW798 -> 3249 | AY800: Total measurements | BA800: =BA799*BA798 -> 11712 | BB800: =BB799*BB798 -> 2928 | BC800: =BC799*BC798 -> 3294 | BD800: =BD799*BD798 -> 2196 | BE800: =BE799*BE798 -> 3294
F801: WET SEASON 3 (not in totals) | H801: 10/1/20 - 11/26/20 | J801: =COUNTIF($A$730:$A$786,"<>") -> 57 | M801: DRY SEASON 2 | O801: 4/1/20 - 9/30/20 | Q801: =COUNTIF($A$547:$A$729,"<>") -> 183 | S801: Measurements >= 18.42C | U801: =SUM(B787:AG787) -> 10278 | V801: NUMERATOR FOR EXCEEDANCE % | AA801: Measurements >= 18.42C | AC801: =SUM(B792:AG792) -> 570 | AE801: Measurements >= 18.42C | AG801: =SUM(B793:AG793) -> 9708 | AI801: Measurements >= 18.42C | AK801: =SUM(B787:AG787) -> 10278 | AL801: =SUM(B787:I787) -> 2663 | AM801: =SUM(J787:R787) -> 2930 | AN801: =SUM(S787:X787) -> 1821 | AO801: =SUM(Y787:AG787) -> 2864 | AQ801: Measurements >= 18.42C | AS801: =SUM(B792:AG792) -> 570 | AT801: =SUM(B792:I792) -> 221 | AU801: =SUM(J792:R792) -> 149 | AV801: =SUM(S792:X792) -> 17 | AW801: =SUM(Y792:AG792) -> 183 | AY801: Measurements >= 18.42C | BA801: =SUM(B793:AG793) -> 9708 | BB801: =SUM(B793:I793) -> 2442 | BC801: =SUM(J793:R793) -> 2781 | BD801: =SUM(S793:X793) -> 1804 | BE801: =SUM(Y793:AG793) -> 2681
S802: % Total Run Exceedances | U802: =$U801/$U800 -> 0.44179849 | AA802: % WET Exceedances | AC802: =AC801/AC800 -> 0.049342105 | AE802: % DRY Exceedances | AG802: =AG801/AG800 -> 0.82889344 | AI802: % Total Run Exceedances | AK802: =AK801/AK800 -> 0.44179849 | AL802: =AL801/AL800 -> 0.45787483 | AM802: =AM801/AM800 -> 0.44780682 | AN802: =AN801/AN800 -> 0.41746905 | AO802: =AO801/AO800 -> 0.4377197 | AQ802: % WET Exceedances | AS802: =AS801/AS800 -> 0.049342105 | AT802: =AT801/AT800 -> 0.076523546 | AU802: =AU801/AU800 -> 0.045860265 | AV802: =AV801/AV800 -> 0.0078485688 | AW802: =AW801/AW800 -> 0.056325023 | AY802: % DRY Exceedances | BA802: =BA801/BA800 -> 0.82889344 | BB802: =BB801/BB800 -> 0.83401639 | BC802: =BC801/BC800 -> 0.8442623 | BD802: =BD801/BD800 -> 0.82149362 | BE802: =BE801/BE800 -> 0.81390407
A804: TOTAL EXCEEDANCES | B804: =COUNTIF(B$3:B$729,">=20") -> 292 | C804: =COUNTIF(C$3:C$729,">=20") -> 277 | D804: =COUNTIF(D$3:D$729,">=20") -> 285 | E804: =COUNTIF(E$3:E$729,">=20") -> 278 | F804: =COUNTIF(F$3:F$729,">=20") -> 249 | G804: =COUNTIF(G$3:G$729,">=20") -> 253 | H804: =COUNTIF(H$3:H$729,">=20") -> 247 | I804: =COUNTIF(I$3:I$729,">=20") -> 259 | ... AG804: =COUNTIF(AG$3:AG$729,">=20") -> 294
A805: WET 1 | B805: =COUNTIF(B$3:B$180,">=20") -> 3 | C805: =COUNTIF(C$3:C$180,">=20") -> 4 | D805: =COUNTIF(D$3:D$180,">=20") -> 5 | E805: =COUNTIF(E$3:E$180,">=20") -> 0 | F805: =COUNTIF(F$3:F$180,">=20") -> 0 | G805: =COUNTIF(G$3:G$180,">=20") -> 0 | H805: =COUNTIF(H$3:H$180,">=20") -> 0 | I805: =COUNTIF(I$3:I$180,">=20") -> 0 | ... AG805: =COUNTIF(AG$3:AG$180,">=20") -> 2 | AH805: OCT 2018 - MARCH 2019
A806: WET 2 | B806: =COUNTIF(B$364:B$546,">=20") -> 6 | C806: =COUNTIF(C$364:C$546,">=20") -> 3 | D806: =COUNTIF(D$364:D$546,">=20") -> 6 | E806: =COUNTIF(E$364:E$546,">=20") -> 5 | F806: =COUNTIF(F$364:F$546,">=20") -> 0 | G806: =COUNTIF(G$364:G$546,">=20") -> 0 | H806: =COUNTIF(H$364:H$546,">=20") -> 0 | I806: =COUNTIF(I$364:I$546,">=20") -> 2 | ... AG806: =COUNTIF(AG$364:AG$546,">=20") -> 3 | AH806: OCT 2019 - MARCH 2020
A807: DRY 1 | B807: =COUNTIF(B$181:B$363,">=20") -> 134 | C807: =COUNTIF(C$181:C$363,">=20") -> 118 | D807: =COUNTIF(D$181:D$363,">=20") -> 128 | E807: =COUNTIF(E$181:E$363,">=20") -> 128 | F807: =COUNTIF(F$181:F$363,">=20") -> 117 | G807: =COUNTIF(G$181:G$363,">=20") -> 118 | H807: =COUNTIF(H$181:H$363,">=20") -> 117 | I807: =COUNTIF(I$181:I$363,">=20") -> 122 | ... AG807: =COUNTIF(AG$181:AG$363,">=20") -> 124 | AH807: APRIL 2019 - SEPTEMBER 2019
A808: DRY 2 | B808: =COUNTIF(B$547:B$729,">=20") -> 149 | C808: =COUNTIF(C$547:C$729,">=20") -> 152 | D808: =COUNTIF(D$547:D$729,">=20") -> 146 | E808: =COUNTIF(E$547:E$729,">=20") -> 145 | F808: =COUNTIF(F$547:F$729,">=20") -> 132 | G808: =COUNTIF(G$547:G$729,">=20") -> 135 | H808: =COUNTIF(H$547:H$729,">=20") -> 130 | I808: =COUNTIF(I$547:I$729,">=20") -> 135 | ... AG808: =COUNTIF(AG$547:AG$729,">=20") -> 165 | AH808: APRIL 2020 - SEPTEMBER 2020
A809: ALL WET | B809: =SUM(B805,B806) -> 9 | C809: =SUM(C805,C806) -> 7 | D809: =SUM(D805,D806) -> 11 | E809: =SUM(E805,E806) -> 5 | F809: =SUM(F805,F806) -> 0 | G809: =SUM(G805,G806) -> 0 | H809: =SUM(H805,H806) -> 0 | I809: =SUM(I805,I806) -> 2 | ... AG809: =SUM(AG805,AG806) -> 5
A810: ALL DRY | B810: =SUM(B807,B808) -> 283 | C810: =SUM(C807,C808) -> 270 | D810: =SUM(D807,D808) -> 274 | E810: =SUM(E807,E808) -> 273 | F810: =SUM(F807,F808) -> 249 | G810: =SUM(G807,G808) -> 253 | H810: =SUM(H807,H808) -> 247 | I810: =SUM(I807,I808) -> 257 | ... AG810: =SUM(AG807,AG808) -> 289
D813: Birding 20C | F813: THRESHOLD: 20C WATER TEMP | S813: BIRDING 20C | AA813: BIRDING 20C | AE813: BIRDING 20C | AI813: BIRDING 20C | AQ813: BIRDING 20C | AY813: BIRDING 20C
F814: WET SEASON | S814: TOTAL RUN | AA814: WET SEASONS | AE814: DRY SEASONS | AI814: TOTAL RUN | AK814: Delta-Wide | AL814: Suisun | AM814: Central Delta | AN814: North Delta | AO814: South Delta | AQ814: WET SEASONS | AS814: Delta-Wide | AT814: Suisun | AU814: Central Delta | AV814: North Delta | AW814: South Delta | AY814: DRY SEASONS | BA814: Delta-Wide | BB814: Suisun | BC814: Central Delta | BD814: North Delta | BE814: South Delta
F815: OCTOBER 1 - MARCH 31 | M815: DRY SEASON | S815: Total points | U815: =COUNTIF($B$2:$AG$2,"<>") -> 32 | AA815: Total points | AC815: =U815 -> 32 | AE815: Total points | AG815: =U815 -> 32 | AI815: Total points | AK815: =COUNTIF($B$2:$AG$2,"<>") -> 32 | AL815: =COUNTIF($B$2:$I$2,"<>") -> 8 | AM815: =COUNTIF($J$2:$R$2,"<>") -> 9 | AN815: =COUNTIF($S$2:$X$2,"<>") -> 6 | AO815: =COUNTIF($Y$2:$AG$2,"<>") -> 9 | AQ815: Total points | AS815: =COUNTIF($B$2:$AG$2,"<>") -> 32 | AT815: =COUNTIF($B$2:$I$2,"<>") -> 8 | AU815: =COUNTIF($J$2:$R$2,"<>") -> 9 | AV815: =COUNTIF($S$2:$X$2,"<>") -> 6 | AW815: =COUNTIF($Y$2:$AG$2,"<>") -> 9 | AY815: Total points | BA815: =COUNTIF($B$2:$AG$2,"<>") -> 32 | BB815: =COUNTIF($B$2:$I$2,"<>") -> 8 | BC815: =COUNTIF($J$2:$R$2,"<>") -> 9 | BD815: =COUNTIF($S$2:$X$2,"<>") -> 6 | BE815: =COUNTIF($Y$2:$AG$2,"<>") -> 9
F816: WET SEASON 1 | H816: 10/5/18 - 3/31/19 | J816: =COUNTIF($A$3:$A$180,"<>") -> 178 | M816: APRIL 1 - SEPTEMBER 30 | S816: Days in run | U816: =COUNTIF($A$3:$A$729,"<>") -> 727 | AA816: Days in run | AC816: =SUM($J$816:$J$817) -> 361 | AE816: Days in run | AG816: =SUM($Q$817:$Q$818) -> 366 | AI816: Days in run | AK816: =COUNTIF($A$3:$A$729,"<>") -> 727 | AL816: =COUNTIF($A$3:$A$729,"<>") -> 727 | AM816: =COUNTIF($A$3:$A$729,"<>") -> 727 | AN816: =COUNTIF($A$3:$A$729,"<>") -> 727 | AO816: =COUNTIF($A$3:$A$729,"<>") -> 727 | AQ816: Days in run | AS816: =SUM($J$816:$J$817) -> 361 | AT816: =SUM($J$816:$J$817) -> 361 | AU816: =SUM($J$816:$J$817) -> 361 | AV816: =SUM($J$816:$J$817) -> 361 | AW816: =SUM($J$816:$J$817) -> 361 | AY816: Days in run | BA816: =SUM($Q$817:$Q$818) -> 366 | BB816: =SUM($Q$817:$Q$818) -> 366 | BC816: =SUM($Q$817:$Q$818) -> 366 | BD816: =SUM($Q$817:$Q$818) -> 366 | BE816: =SUM($Q$817:$Q$818) -> 366
...

Sheet Bolster & Fortify
B1: Suisun | J1: Central Delta | S1: North Delta | Y1: South Delta
A2: Date | B2: CHADBOURNE SLOUGH AT SUNRISE DUCK CLUB | C2: MONTEZUMA SLOUGH AT NATIONAL STEEL | D2: MONTEZUMA SLOUGH NEAR BELDENS LANDING | E2: SUISUN SLOUGH 300' SOUTH OF VOLANTI SLOUGH | F2: HONKER BAY | G2: SUISUN BAY AT VAN SICKLE ISLAND | H2: SUISUN BAY WEST REACH | I2: GRIZZLY BAY BUOY | J2: DUTCH SL BELOW JERSEY ISLAND | K2: FALSE RIVER NEAR OAKLEY | L2: OLD RIVER AT FRANKS TRACT | M2: PITTSBURG | N2: SACRAMENTO RIVER AT EMMATON | O2: SAN ANDREAS LANDING | P2: SAN JOAQUIN RIVER AT JERSEY POINT | Q2: SUISUN BAY AT CHANNEL MARKER 5 AT COLLINSVILLE | R2: BRANNAN MARINAS AT SAN JOAQUIN RIVER | S2: LIBERTY CUT AT FIVE POINTS | T2: CACHE SLOUGH ABOVE RYER ISLAND FERRY | U2: DELTA CROSS CHANNEL NEAR WALNUT GROVE | V2: SACRAMENTO RIVER DOWNSTREAM OF ISLETON | W2: COURTLAND AT SACRAMENTO RIVER | X2: VIERAS RESORT AT SACRAMENTO RIVER | Y2: GRANT LINE CANAL NEAR CLIFTON COURT FORE | Z2: LITTLE POTATO SLOUGH AT TERMINOUS | AA2: MIDDLE RIVER AT MILDRED ISLAND | AB2: OLD RIVER AT CLIFTON COURT | AC2: SAN JOAQUIN RIVER AT BRANDT BRIDGE | AD2: SAN JOAQUIN RIVER AT PRISONERS POINT | AE2: SAN JOAQUIN RIVER NEAR VERNALIS | AF2: SAN JOAQUIN RVER AT ROUGH AND READY ISLAND | AG2: VICTORIA CANAL BEFORE CLIFTON COURT FORE
A3: 43378 | B3: 19.881677 | C3: 19.954249 | D3: 20.022137 | E3: 19.875781 | F3: 19.276937 | G3: 19.367602 | H3: 19.207814 | I3: 19.1854 | J3: 20.199141 | K3: 20.063547 | L3: 19.811314 | M3: 19.392862 | N3: 19.474622 | O3: 19.510915 | P3: 19.975834 | Q3: 19.422887 | R3: 19.792742 | S3: 19.391347 | T3: 19.126039 | U3: 18.043128 | V3: 18.692572 | W3: 17.894525 | X3: 18.47322 | Y3: 21.240605 | Z3: 19.879068 | AA3: 20.472396 | AB3: 20.765446 | AC3: 21.616805 | AD3: 19.79124 | AE3: 20.827559 | AF3: 21.918788 | AG3: 20.878489
A4: 43379 | B4: 20.084553 | C4: 20.081328 | D4: 20.097516 | E4: 19.94478 | F4: 19.354167 | G4: 19.397832 | H4: 19.23036 | I4: 19.22601 | J4: 20.057026 | K4: 19.98167 | L4: 19.674439 | M4: 19.421068 | N4: 19.42715 | O4: 19.41156 | P4: 19.915054 | Q4: 19.437303 | R4: 19.698389 | S4: 19.403271 | T4: 19.055259 | U4: 17.908516 | V4: 18.691824 | W4: 17.707416 | X4: 18.494005 | Y4: 20.905659 | Z4: 19.700832 | AA4: 20.267073 | AB4: 20.503389 | AC4: 21.274915 | AD4: 19.669407 | AE4: 20.37743 | AF4: 21.628962 | AG4: 20.633455
A5: 43380 | B5: 19.935963 | C5: 20.085044 | D5: 20.071368 | E5: 19.908369 | F5: 19.245314 | G5: 19.358405 | H5: 19.194368 | I5: 19.033947 | J5: 19.348104 | K5: 19.662129 | L5: 19.336622 | M5: 19.384996 | N5: 19.185648 | O5: 19.120668 | P5: 19.642365 | Q5: 19.376847 | R5: 19.413018 | S5: 19.061917 | T5: 18.828009 | U5: 17.496202 | V5: 18.452598 | W5: 17.345313 | X5: 18.244854 | Y5: 19.997531 | Z5: 19.149856 | AA5: 19.720652 | AB5: 19.716668 | AC5: 19.997482 | AD5: 19.375071 | AE5: 19.278456 | AF5: 20.82584 | AG5: 19.775361
A6: 43381 | B6: 20.097143 | C6: 20.14298 | D6: 20.081782 | E6: 19.915088 | F6: 19.28019 | G6: 19.3424 | H6: 19.170536 | I6: 19.102547 | J6: 18.976455 | K6: 19.429399 | L6: 19.13968 | M6: 19.360201 | N6: 19.074303 | O6: 18.941496 | P6: 19.431056 | Q6: 19.347018 | R6: 19.231682 | S6: 18.672679 | T6: 18.56282 | U6: 17.248405 | V6: 18.202006 | W6: 17.110495 | X6: 17.959626 | Y6: 19.493442 | Z6: 18.789818 | AA6: 19.441079 | AB6: 19.348773 | AC6: 19.105206 | AD6: 19.130622 | AE6: 18.671517 | AF6: 20.138256 | AG6: 19.363712
A7: 43382 | B7: 20.166654 | C7: 20.27099 | D7: 20.144093 | E7: 19.98976 | F7: 19.298235 | G7: 19.36297 | H7: 19.182736 | I7: 19.239324 | J7: 19.268133 | K7: 19.436217 | L7: 19.146918 | M7: 19.377949 | N7: 19.121182 | O7: 18.956562 | P7: 19.435605 | Q7: 19.373661 | R7: 19.251132 | S7: 18.644084 | T7: 18.433546 | U7: 17.230785 | V7: 18.131019 | W7: 17.104487 | X7: 17.883556 | Y7: 19.616386 | Z7: 18.75479 | AA7: 19.476118 | AB7: 19.505337 | AC7: 19.043816 | AD7: 19.094355 | AE7: 18.906943 | AF7: 19.931662 | AG7: 19.594085
A8: 43383 | B8: 19.483621 | C8: 19.84374 | D8: 19.758006 | E8: 19.561664 | F8: 18.920283 | G8: 19.15453 | H8: 18.96183 | I8: 18.586524 | J8: 19.117317 | K8: 19.314372 | L8: 19.034616 | M8: 19.173768 | N8: 18.97612 | O8: 18.840293 | P8: 19.304681 | Q8: 19.175753 | R8: 19.147091 | S8: 18.245161 | T8: 18.18017 | U8: 17.255232 | V8: 17.925421 | W8: 17.201996 | X8: 17.691875 | Y8: 19.694126 | Z8: 18.553632 | AA8: 19.469737 | AB8: 19.587256 | AC8: 19.223705 | AD8: 18.985382 | AE8: 19.229105 | AF8: 19.832784 | AG8: 19.699772
A9: 43384 | B9: 18.894413 | C9: 19.30315 | D9: 19.248599 | E9: 19.012069 | F9: 18.548942 | G9: 18.88027 | H9: 18.683326 | I9: 17.910516 | J9: 18.700524 | K9: 19.087785 | L9: 18.817889 | M9: 18.901191 | N9: 18.718214 | O9: 18.566887 | P9: 19.073907 | Q9: 18.899682 | R9: 18.899859 | S9: 17.696662 | T9: 17.824469 | U9: 17.291637 | V9: 17.623584 | W9: 17.259692 | X9: 17.429097 | Y9: 19.6831 | Z9: 18.304749 | AA9: 19.401475 | AB9: 19.587457 | AC9: 19.282318 | AD9: 18.773741 | AE9: 19.255034 | AF9: 19.727428 | AG9: 19.680798
A10: 43385 | B10: 18.917662 | C10: 19.168875 | D10: 19.054624 | E10: 18.833742 | F10: 18.523668 | G10: 18.760506 | H10: 18.572095 | I10: 17.88027 | J10: 18.588224 | K10: 18.957072 | L10: 18.676177 | M10: 18.776905 | N10: 18.576338 | O10: 18.413276 | P10: 18.943786 | Q10: 18.770051 | R10: 18.725891 | S10: 17.696727 | T10: 17.698656 | U10: 17.370676 | V10: 17.60814 | W10: 17.326128 | X10: 17.500192 | Y10: 19.62529 | Z10: 18.251109 | AA10: 19.280944 | AB10: 19.509708 | AC10: 19.334356 | AD10: 18.618356 | AE10: 19.132824 | AF10: 19.635877 | AG10: 19.610732
A11: 43386 | B11: 18.877216 | C11: 19.198275 | D11: 18.994049 | E11: 18.801252 | F11: 18.479689 | G11: 18.669246 | H11: 18.495333 | I11: 17.909856 | J11: 18.661456 | K11: 18.886734 | L11: 18.596246 | M11: 18.684259 | N11: 18.475007 | O11: 18.426013 | P11: 18.860663 | Q11: 18.683824 | R11: 18.672905 | S11: 17.92633 | T11: 17.747834 | U11: 17.460615 | V11: 17.694074 | W11: 17.329298 | X11: 17.625693 | Y11: 19.52712 | Z11: 18.283795 | AA11: 19.157406 | AB11: 19.3568 | AC11: 19.335502 | AD11: 18.544323 | AE11: 18.980072 | AF11: 19.582839 | AG11: 19.532826
A12: 43387 | B12: 18.58154 | C12: 18.967454 | D12: 18.792735 | E12: 18.609798 | F12: 18.292395 | G12: 18.496926 | H12: 18.343687 | I12: 17.652699 | J12: 18.290192 | K12: 18.667815 | L12: 18.39012 | M12: 18.512814 | N12: 18.247777 | O12: 18.278265 | P12: 18.654707 | Q12: 18.504529 | R12: 18.503962 | S12: 17.667279 | T12: 17.614389 | U12: 17.228006 | V12: 17.534261 | W12: 16.980849 | X12: 17.471921 | Y12: 19.286866 | Z12: 18.159202 | AA12: 18.977139 | AB12: 19.098857 | AC12: 19.10222 | AD12: 18.373323 | AE12: 18.413826 | AF12: 19.439672 | AG12: 19.317565
A13: 43388 | B13: 18.672935 | C13: 18.893038 | D13: 18.745725 | E13: 18.591369 | F13: 18.286622 | G13: 18.400118 | H13: 18.274362 | I13: 17.718281 | J13: 17.480301 | K13: 18.298631 | L13: 18.063061 | M13: 18.414796 | N13: 17.976991 | O13: 17.96038 | P13: 18.331326 | Q13: 18.379528 | R13: 18.172318 | S13: 16.895119 | T13: 17.258285 | U13: 16.609082 | V13: 17.18101 | W13: 16.284793 | X13: 17.108894 | Y13: 18.829854 | Z13: 17.743993 | AA13: 18.645118 | AB13: 18.666949 | AC13: 18.495398 | AD13: 18.053139 | AE13: 17.309574 | AF13: 19.027012 | AG13: 18.843732
A14: 43389 | B14: 18.594733 | C14: 18.854128 | D14: 18.713691 | E14: 18.578597 | F14: 18.249475 | G14: 18.282637 | H14: 18.189716 | I14: 17.625916 | J14: 17.328038 | K14: 18.129749 | L14: 17.962601 | M14: 18.299888 | N14: 17.860146 | O14: 17.862838 | P14: 18.146661 | Q14: 18.267489 | R14: 18.038945 | S14: 16.68453 | T14: 17.099096 | U14: 16.114025 | V14: 17.00311 | W14: 15.749154 | X14: 16.881654 | Y14: 18.540019 | Z14: 17.643913 | AA14: 18.404776 | AB14: 18.402073 | AC14: 17.899675 | AD14: 17.89961 | AE14: 16.819056 | AF14: 18.685127 | AG14: 18.576672
... A786: 44161 | B786: 11.105213 | C786: 12.058644 | D786: 11.78719 | E786: 11.654645 | F786: 11.753511 | G786: 12.151026 | H786: 12.129501 | I786: 10.736259 | J786: 11.385237 | K786: 12.163546 | L786: 12.185139 | M786: 12.159897 | N786: 11.620794 | O786: 12.057908 | P786: 12.148502 | Q786: 12.068162 | R786: 12.248899 | S786: 10.347796 | T786: 11.25186 | U786: 10.939331 | V786: 11.318819 | W786: 10.776628 | X786: 11.316719 | Y786: 11.185822 | Z786: 11.186448 | AA786: 11.998872 | AB786: 11.670095 | AC786: 10.85321 | AD786: 12.218822 | AE786: 11.208901 | AF786: 11.595947 | AG786: 11.496196
A787: TOTAL EXCEEDANCES | B787: =COUNTIF(B$3:B$729,">=18.42") -> 352 | C787: =COUNTIF(C$3:C$729,">=18.42") -> 332 | D787: =COUNTIF(D$3:D$729,">=18.42") -> 343 | E787: =COUNTIF(E$3:E$729,">=18.42") -> 344 | F787: =COUNTIF(F$3:F$729,">=18.42") -> 324 | G787: =COUNTIF(G$3:G$729,">=18.42") -> 325 | H787: =COUNTIF(H$3:H$729,">=18.42") -> 323 | I787: =COUNTIF(I$3:I$729,">=18.42") -> 321 | ... AG787: =COUNTIF(AG$3:AG$729,">=18.42") -> 355
A788: WET 1 | B788: =COUNTIF(B$3:B$180,">=18.42") -> 15 | C788: =COUNTIF(C$3:C$180,">=18.42") -> 14 | D788: =COUNTIF(D$3:D$180,">=18.42") -> 16 | E788: =COUNTIF(E$3:E$180,">=18.42") -> 16 | F788: =COUNTIF(F$3:F$180,">=18.42") -> 9 | G788: =COUNTIF(G$3:G$180,">=18.42") -> 10 | H788: =COUNTIF(H$3:H$180,">=18.42") -> 9 | I788: =COUNTIF(I$3:I$180,">=18.42") -> 6 | ... AG788: =COUNTIF(AG$3:AG$180,">=18.42") -> 17 | AH788: OCT 2018 - MARCH 2019
A789: WET 2 | B789: =COUNTIF(B$364:B$546,">=18.42") -> 19 | C789: =COUNTIF(C$364:C$546,">=18.42") -> 17 | D789: =COUNTIF(D$364:D$546,">=18.42") -> 19 | E789: =COUNTIF(E$364:E$546,">=18.42") -> 17 | F789: =COUNTIF(F$364:F$546,">=18.42") -> 14 | G789: =COUNTIF(G$364:G$546,">=18.42") -> 14 | H789: =COUNTIF(H$364:H$546,">=18.42") -> 15 | I789: =COUNTIF(I$364:I$546,">=18.42") -> 12 | ... AG789: =COUNTIF(AG$364:AG$546,">=18.42") -> 21 | AH789: OCT 2019 - MARCH 2020
A790: DRY 1 | B790: =COUNTIF(B$181:B$363,">=18.42") -> 156 | C790: =COUNTIF(C$181:C$363,">=18.42") -> 141 | D790: =COUNTIF(D$181:D$363,">=18.42") -> 147 | E790: =COUNTIF(E$181:E$363,">=18.42") -> 150 | F790: =COUNTIF(F$181:F$363,">=18.42") -> 142 | G790: =COUNTIF(G$181:G$363,">=18.42") -> 143 | H790: =COUNTIF(H$181:H$363,">=18.42") -> 142 | I790: =COUNTIF(I$181:I$363,">=18.42") -> 143 | ... AG790: =COUNTIF(AG$181:AG$363,">=18.42") -> 147 | AH790: APRIL 2019 - SEPTEMBER 2019
A791: DRY 2 | B791: =COUNTIF(B$547:B$729,">=18.42") -> 162 | C791: =COUNTIF(C$547:C$729,">=18.42") -> 160 | D791: =COUNTIF(D$547:D$729,">=18.42") -> 161 | E791: =COUNTIF(E$547:E$729,">=18.42") -> 161 | F791: =COUNTIF(F$547:F$729,">=18.42") -> 159 | G791: =COUNTIF(G$547:G$729,">=18.42") -> 158 | H791: =COUNTIF(H$547:H$729,">=18.42") -> 157 | I791: =COUNTIF(I$547:I$729,">=18.42") -> 160 | ... AG791: =COUNTIF(AG$547:AG$729,">=18.42") -> 170 | AH791: APRIL 2020 - SEPTEMBER 2020
A792: ALL WET | B792: =SUM(B788,B789) -> 34 | C792: =SUM(C788,C789) -> 31 | D792: =SUM(D788,D789) -> 35 | E792: =SUM(E788,E789) -> 33 | F792: =SUM(F788,F789) -> 23 | G792: =SUM(G788,G789) -> 24 | H792: =SUM(H788,H789) -> 24 | I792: =SUM(I788,I789) -> 18 | ... AG792: =SUM(AG788,AG789) -> 38
A793: ALL DRY | B793: =SUM(B790,B791) -> 318 | C793: =SUM(C790,C791) -> 301 | D793: =SUM(D790,D791) -> 308 | E793: =SUM(E790,E791) -> 311 | F793: =SUM(F790,F791) -> 301 | G793: =SUM(G790,G791) -> 301 | H793: =SUM(H790,H791) -> 299 | I793: =SUM(I790,I791) -> 303 | ... AG793: =SUM(AG790,AG791) -> 317
D796: Angling 18.42C | F796: THRESHOLD: 18.42C WATER TEMP | S796: ANGLING 18.42C | AA796: ANGLING 18.42C | AE796: ANGLING 18.42C | AI796: ANGLING 18.42C | AQ796: ANGLING 18.42C | AY796: ANGLING 18.42C
F797: WET SEASON | S797: TOTAL RUN | AA797: WET SEASONS | AE797: DRY SEASONS | AI797: TOTAL RUN | AK797: Delta-Wide | AL797: Suisun | AM797: Central Delta | AN797: North Delta | AO797: South Delta | AQ797: WET SEASONS | AS797: Delta-Wide | AT797: Suisun | AU797: Central Delta | AV797: North Delta | AW797: South Delta | AY797: DRY SEASONS | BA797: Delta-Wide | BB797: Suisun | BC797: Central Delta | BD797: North Delta | BE797: South Delta
F798: OCTOBER 1 - MARCH 31 | M798: DRY SEASON | S798: Total points | U798: =COUNTIF($B$2:$AG$2,"<>") -> 32 | AA798: Total points | AC798: =U798 -> 32 | AE798: Total points | AG798: =U798 -> 32 | AI798: Total points | AK798: =COUNTIF($B$2:$AG$2,"<>") -> 32 | AL798: =COUNTIF($B$2:$I$2,"<>") -> 8 | AM798: =COUNTIF($J$2:$R$2,"<>") -> 9 | AN798: =COUNTIF($S$2:$X$2,"<>") -> 6 | AO798: =COUNTIF($Y$2:$AG$2,"<>") -> 9 | AQ798: Total points | AS798: =COUNTIF($B$2:$AG$2,"<>") -> 32 | AT798: =COUNTIF($B$2:$I$2,"<>") -> 8 | AU798: =COUNTIF($J$2:$R$2,"<>") -> 9 | AV798: =COUNTIF($S$2:$X$2,"<>") -> 6 | AW798: =COUNTIF($Y$2:$AG$2,"<>") -> 9 | AY798: Total points | BA798: =COUNTIF($B$2:$AG$2,"<>") -> 32 | BB798: =COUNTIF($B$2:$I$2,"<>") -> 8 | BC798: =COUNTIF($J$2:$R$2,"<>") -> 9 | BD798: =COUNTIF($S$2:$X$2,"<>") -> 6 | BE798: =COUNTIF($Y$2:$AG$2,"<>") -> 9
F799: WET SEASON 1 | H799: 10/5/18 - 3/31/19 | J799: =COUNTIF($A$3:$A$180,"<>") -> 178 | M799: APRIL 1 - SEPTEMBER 30 | S799: Days in run | U799: =COUNTIF($A$3:$A$729,"<>") -> 727 | AA799: Days in run | AC799: =SUM($J$799:$J$800) -> 361 | AE799: Days in run | AG799: =SUM($Q$800:$Q$801) -> 366 | AI799: Days in run | AK799: =COUNTIF($A$3:$A$729,"<>") -> 727 | AL799: =COUNTIF($A$3:$A$729,"<>") -> 727 | AM799: =COUNTIF($A$3:$A$729,"<>") -> 727 | AN799: =COUNTIF($A$3:$A$729,"<>") -> 727 | AO799: =COUNTIF($A$3:$A$729,"<>") -> 727 | AQ799: Days in run | AS799: =SUM($J$799:$J$800) -> 361 | AT799: =SUM($J$799:$J$800) -> 361 | AU799: =SUM($J$799:$J$800) -> 361 | AV799: =SUM($J$799:$J$800) -> 361 | AW799: =SUM($J$799:$J$800) -> 361 | AY799: Days in run | BA799: =SUM($Q$800:$Q$801) -> 366 | BB799: =SUM($Q$800:$Q$801) -> 366 | BC799: =SUM($Q$800:$Q$801) -> 366 | BD799: =SUM($Q$800:$Q$801) -> 366 | BE799: =SUM($Q$800:$Q$801) -> 366
F800: WET SEASON 2 | H800: 10/1/19 - 3/31/20 | J800: =COUNTIF($A$364:$A$546,"<>") -> 183 | M800: DRY SEASON 1 | O800: 4/1/19 - 9/30/19 | Q800: =COUNTIF($A$181:$A$363,"<>") -> 183 | S800: Total measurements | U800: =U799*U798 -> 23264 | V800: DENOMINATOR FOR EXCEEDANCE % | AA800: Total measurements | AC800: =AC799*AC798 -> 11552 | AE800: Total measurements | AG800: =AG798*AG799 -> 11712 | AI800: Total measurements | AK800: =AK799*AK798 -> 23264 | AL800: =AL799*AL798 -> 5816 | AM800: =AM799*AM798 -> 6543 | AN800: =AN799*AN798 -> 4362 | AO800: =AO799*AO798 -> 6543 | AQ800: Total measurements | AS800: =AS799*AS798 -> 11552 | AT800: =AT799*AT798 -> 2888 | AU800: =AU799*AU798 -> 3249 | AV800: =AV799*AV798 -> 2166 | AW800: =AW799*AW798 -> 3249 | AY800: Total measurements | BA800: =BA799*BA798 -> 11712 | BB800: =BB799*BB798 -> 2928 | BC800: =BC799*BC798 -> 3294 | BD800: =BD799*BD798 -> 2196 | BE800: =BE799*BE798 -> 3294
