Workbook

Sheet OVERALL
AD1: Notes: 1. The overall view of salinity-based exceedances is mostly concentrated in Suisun Marsh and the Central Delta. The North Delta and Southern Delta show 0% exceedances across all activities at the Total and Seasonal breakdowns, with brief threshold spikes in the South Delta under the Total window for Boating and Day use under COR (1%) and Tunnel (4%). Under BAU Total Run, Suisun exceeds 80% for Day use and boating, our lowest exceedance score (1,000 µS/cm), 68% for birding, 63% for waterfowl, and 28% for Angling, our highest exceedance score (9,130 µS/cm). In words, the lower thresholds are crossed most often, mostly happening in Suisun, and for day use and boating, happening in the Central Delta during the wet seasons. 2. Scenario rankings (-5 to 5 vs BAU) reflect that BAF is effectively the same as BAU, scoring at 0, except for one instance for Central Delta Day use (Total Run). Tunnel performs the worst, scoring -2 to -5 across both Suisun Marsh and the Central Delta, and is the only scenario that pushes Southern Delta boating and day uses over the threshold during wet seasons (84%) or greater than a -5 move on the charts. Calling on Reserves (COR) is the second worst scenario across Suisun and the Central Delta, but having one surprising movement of (+2) in the wet seasons. 3. Seasonally, it was surprising to see our wet season model runs exceed thresholds more often than during the dry seasons. Further impacts on the -5 to 5 scale show Tunnel as the worst-performing scenario during the wet season. A final takeaway shows that Suisun Marsh is the most sensitive region to salinity (EC) exceedances and is affected in every scenario at higher intensity across the salinity-threshold gradient. 3. Red-highlighted cells reflect 25% values for ease of assessment.
C2: TOTAL RUN SCORES | L2: WET SEASON SCORES | U2: DRY SEASON SCORES
C3: SP DAY USE & BOATING | D3: REGION | E3: BAU | F3: BAF | G3: COR | H3: Tunnel | I3: ECO | J3: NGW | L3: SP DAY USE & BOATING | M3: REGION | N3: BAU | O3: BAF | P3: COR | Q3: Tunnel | R3: ECO | S3: NGW | U3: SP DAY USE & BOATING | V3: REGION | W3: BAU | X3: BAF | Y3: COR | Z3: Tunnel | AA3: ECO | AB3: NGW
D4: Delta-Wide | E4: =-MAX(-5,MIN(5,ROUND((D$33-D$33)*100,0))) -> 0 | F4: =-MAX(-5,MIN(5,ROUND((D$41-D$33)*100,0))) -> 0 | G4: =-MAX(-5,MIN(5,ROUND((D$49-D$33)*100,0))) -> -2 | H4: =-MAX(-5,MIN(5,ROUND((D$57-D$33)*100,0))) -> -4 | I4: =-MAX(-5,MIN(5,ROUND((D$65-D$33)*100,0))) -> 0 | J4: =-MAX(-5,MIN(5,ROUND((D$73-D$33)*100,0))) -> 0 | M4: Delta-Wide | N4: =-MAX(-5,MIN(5,ROUND((I$33-I$33)*100,0))) -> 0 | O4: =-MAX(-5,MIN(5,ROUND((I$41-I$33)*100,0))) -> 0 | P4: =-MAX(-5,MIN(5,ROUND((I$49-I$33)*100,0))) -> -2 | Q4: =-MAX(-5,MIN(5,ROUND((I$57-I$33)*100,0))) -> -5 | R4: =-MAX(-5,MIN(5,ROUND((I$65-I$33)*100,0))) -> 0 | S4: =-MAX(-5,MIN(5,ROUND((I$73-I$33)*100,0))) -> 0 | V4: Delta-Wide | W4: =-MAX(-5,MIN(5,ROUND((N$33-N$33)*100,0))) -> 0 | X4: =-MAX(-5,MIN(5,ROUND((N$41-N$33)*100,0))) -> 0 | Y4: =-MAX(-5,MIN(5,ROUND((N$49-N$33)*100,0))) -> -1 | Z4: =-MAX(-5,MIN(5,ROUND((N$57-N$33)*100,0))) -> -2 | AA4: =-MAX(-5,MIN(5,ROUND((N$65-N$33)*100,0))) -> 0 | AB4: =-MAX(-5,MIN(5,ROUND((N$73-N$33)*100,0))) -> 0
D5: Suisun | E5: =-MAX(-5,MIN(5,ROUND((E$33-E$33)*100,0))) -> 0 | F5: =-MAX(-5,MIN(5,ROUND((E$41-E$33)*100,0))) -> 0 | G5: =-MAX(-5,MIN(5,ROUND((E$49-E$33)*100,0))) -> -1 | H5: =-MAX(-5,MIN(5,ROUND((E$57-E$33)*100,0))) -> -3 | I5: =-MAX(-5,MIN(5,ROUND((E$65-E$33)*100,0))) -> -2 | J5: =-MAX(-5,MIN(5,ROUND((E$73-E$33)*100,0))) -> -2 | M5: Suisun | N5: =-MAX(-5,MIN(5,ROUND((J$33-J$33)*100,0))) -> 0 | O5: =-MAX(-5,MIN(5,ROUND((J$41-J$33)*100,0))) -> 0 | P5: =-MAX(-5,MIN(5,ROUND((J$49-J$33)*100,0))) -> 2 | Q5: =-MAX(-5,MIN(5,ROUND((J$57-J$33)*100,0))) -> -1 | R5: =-MAX(-5,MIN(5,ROUND((J$65-J$33)*100,0))) -> -3 | S5: =-MAX(-5,MIN(5,ROUND((J$73-J$33)*100,0))) -> -3 | V5: Suisun | W5: =-MAX(-5,MIN(5,ROUND((O$33-O$33)*100,0))) -> 0 | X5: =-MAX(-5,MIN(5,ROUND((O$41-O$33)*100,0))) -> 0 | Y5: =-MAX(-5,MIN(5,ROUND((O$49-O$33)*100,0))) -> -4 | Z5: =-MAX(-5,MIN(5,ROUND((O$57-O$33)*100,0))) -> -5 | AA5: =-MAX(-5,MIN(5,ROUND((O$65-O$33)*100,0))) -> -2 | AB5: =-MAX(-5,MIN(5,ROUND((O$73-O$33)*100,0))) -> -2
D6: Central | E6: =-MAX(-5,MIN(5,ROUND((F$33-F$33)*100,0))) -> 0 | F6: =-MAX(-5,MIN(5,ROUND((F$41-F$33)*100,0))) -> -1 | G6: =-MAX(-5,MIN(5,ROUND((F$49-F$33)*100,0))) -> -4 | H6: =-MAX(-5,MIN(5,ROUND((F$57-F$33)*100,0))) -> -5 | I6: =-MAX(-5,MIN(5,ROUND((F$65-F$33)*100,0))) -> 2 | J6: =-MAX(-5,MIN(5,ROUND((F$73-F$33)*100,0))) -> 2 | M6: Central | N6: =-MAX(-5,MIN(5,ROUND((K$33-K$33)*100,0))) -> 0 | O6: =-MAX(-5,MIN(5,ROUND((K$41-K$33)*100,0))) -> 0 | P6: =-MAX(-5,MIN(5,ROUND((K$49-K$33)*100,0))) -> -5 | Q6: =-MAX(-5,MIN(5,ROUND((K$57-K$33)*100,0))) -> -5 | R6: =-MAX(-5,MIN(5,ROUND((K$65-K$33)*100,0))) -> 3 | S6: =-MAX(-5,MIN(5,ROUND((K$73-K$33)*100,0))) -> 3 | V6: Central | W6: =-MAX(-5,MIN(5,ROUND((P$33-P$33)*100,0))) -> 0 | X6: =-MAX(-5,MIN(5,ROUND((P$41-P$33)*100,0))) -> 0 | Y6: =-MAX(-5,MIN(5,ROUND((P$49-P$33)*100,0))) -> 0 | Z6: =-MAX(-5,MIN(5,ROUND((P$57-P$33)*100,0))) -> -1 | AA6: =-MAX(-5,MIN(5,ROUND((P$65-P$33)*100,0))) -> 2 | AB6: =-MAX(-5,MIN(5,ROUND((P$73-P$33)*100,0))) -> 2
D7: North | E7: =-MAX(-5,MIN(5,ROUND((G$33-G$33)*100,0))) -> 0 | F7: =-MAX(-5,MIN(5,ROUND((G$41-G$33)*100,0))) -> 0 | G7: =-MAX(-5,MIN(5,ROUND((G$49-G$33)*100,0))) -> 0 | H7: =-MAX(-5,MIN(5,ROUND((G$57-G$33)*100,0))) -> 0 | I7: =-MAX(-5,MIN(5,ROUND((G$65-G$33)*100,0))) -> 0 | J7: =-MAX(-5,MIN(5,ROUND((G$73-G$33)*100,0))) -> 0 | M7: North | N7: =-MAX(-5,MIN(5,ROUND((L$33-L$33)*100,0))) -> 0 | O7: =-MAX(-5,MIN(5,ROUND((L$41-L$33)*100,0))) -> 0 | P7: =-MAX(-5,MIN(5,ROUND((L$49-L$33)*100,0))) -> 0 | Q7: =-MAX(-5,MIN(5,ROUND((L$57-L$33)*100,0))) -> 0 | R7: =-MAX(-5,MIN(5,ROUND((L$65-L$33)*100,0))) -> 0 | S7: =-MAX(-5,MIN(5,ROUND((L$73-L$33)*100,0))) -> 0 | V7: North | W7: =-MAX(-5,MIN(5,ROUND((Q$33-Q$33)*100,0))) -> 0 | X7: =-MAX(-5,MIN(5,ROUND((Q$41-Q$33)*100,0))) -> 0 | Y7: =-MAX(-5,MIN(5,ROUND((Q$49-Q$33)*100,0))) -> 0 | Z7: =-MAX(-5,MIN(5,ROUND((Q$57-Q$33)*100,0))) -> 0 | AA7: =-MAX(-5,MIN(5,ROUND((Q$65-Q$33)*100,0))) -> 0 | AB7: =-MAX(-5,MIN(5,ROUND((Q$73-Q$33)*100,0))) -> 0
D8: South | E8: =-MAX(-5,MIN(5,ROUND((H$33-H$33)*100,0))) -> 0 | F8: =-MAX(-5,MIN(5,ROUND((H$41-H$33)*100,0))) -> 0 | G8: =-MAX(-5,MIN(5,ROUND((H$49-H$33)*100,0))) -> -1 | H8: =-MAX(-5,MIN(5,ROUND((H$57-H$33)*100,0))) -> -3 | I8: =-MAX(-5,MIN(5,ROUND((H$65-H$33)*100,0))) -> 0 | J8: =-MAX(-5,MIN(5,ROUND((H$73-H$33)*100,0))) -> 0 | M8: South | N8: =-MAX(-5,MIN(5,ROUND((M$33-M$33)*100,0))) -> 0 | O8: =-MAX(-5,MIN(5,ROUND((M$41-M$33)*100,0))) -> 0 | P8: =-MAX(-5,MIN(5,ROUND((M$49-M$33)*100,0))) -> -2 | Q8: =-MAX(-5,MIN(5,ROUND((M$57-M$33)*100,0))) -> -5 | R8: =-MAX(-5,MIN(5,ROUND((M$65-M$33)*100,0))) -> 0 | S8: =-MAX(-5,MIN(5,ROUND((M$73-M$33)*100,0))) -> 0 | V8: South | W8: =-MAX(-5,MIN(5,ROUND((R$33-R$33)*100,0))) -> 0 | X8: =-MAX(-5,MIN(5,ROUND((R$41-R$33)*100,0))) -> 0 | Y8: =-MAX(-5,MIN(5,ROUND((R$49-R$33)*100,0))) -> 0 | Z8: =-MAX(-5,MIN(5,ROUND((R$57-R$33)*100,0))) -> 0 | AA8: =-MAX(-5,MIN(5,ROUND((R$65-R$33)*100,0))) -> 0 | AB8: =-MAX(-5,MIN(5,ROUND((R$73-R$33)*100,0))) -> 0
C9: BIRDING | D9: REGION | E9: BAU | F9: BAF | G9: COR | H9: Tunnel | I9: ECO | J9: NGW | L9: BIRDING | M9: REGION | N9: BAU | O9: BAF | P9: COR | Q9: Tunnel | R9: ECO | S9: NGW | U9: BIRDING | V9: REGION | W9: BAU | X9: BAF | Y9: COR | Z9: Tunnel | AA9: ECO | AB9: NGW
D10: Delta-Wide | E10: =-MAX(-5,MIN(5,ROUND((D$34-D$34)*100,0))) -> 0 | F10: =-MAX(-5,MIN(5,ROUND((D$42-D$34)*100,0))) -> 0 | G10: =-MAX(-5,MIN(5,ROUND((D$50-D$34)*100,0))) -> -2 | H10: =-MAX(-5,MIN(5,ROUND((D$58-D$34)*100,0))) -> -4 | I10: =-MAX(-5,MIN(5,ROUND((D$66-D$34)*100,0))) -> -1 | J10: =-MAX(-5,MIN(5,ROUND((D$74-D$34)*100,0))) -> -1 | M10: Delta-Wide | N10: =-MAX(-5,MIN(5,ROUND((I$34-I$34)*100,0))) -> 0 | O10: =-MAX(-5,MIN(5,ROUND((I$42-I$34)*100,0))) -> 0 | P10: =-MAX(-5,MIN(5,ROUND((I$50-I$34)*100,0))) -> -2 | Q10: =-MAX(-5,MIN(5,ROUND((I$58-I$34)*100,0))) -> -5 | R10: =-MAX(-5,MIN(5,ROUND((I$66-I$34)*100,0))) -> -2 | S10: =-MAX(-5,MIN(5,ROUND((I$74-I$34)*100,0))) -> -1 | V10: Delta-Wide | W10: =-MAX(-5,MIN(5,ROUND((N$34-N$34)*100,0))) -> 0 | X10: =-MAX(-5,MIN(5,ROUND((N$42-N$34)*100,0))) -> 0 | Y10: =-MAX(-5,MIN(5,ROUND((N$50-N$34)*100,0))) -> -3 | Z10: =-MAX(-5,MIN(5,ROUND((N$58-N$34)*100,0))) -> -3 | AA10: =-MAX(-5,MIN(5,ROUND((N$66-N$34)*100,0))) -> -1 | AB10: =-MAX(-5,MIN(5,ROUND((N$74-N$34)*100,0))) -> -1
D11: Suisun | E11: =-MAX(-5,MIN(5,ROUND((E$34-E$34)*100,0))) -> 0 | F11: =-MAX(-5,MIN(5,ROUND((E$42-E$34)*100,0))) -> 0 | G11: =-MAX(-5,MIN(5,ROUND((E$50-E$34)*100,0))) -> -4 | H11: =-MAX(-5,MIN(5,ROUND((E$58-E$34)*100,0))) -> -5 | I11: =-MAX(-5,MIN(5,ROUND((E$66-E$34)*100,0))) -> -5 | J11: =-MAX(-5,MIN(5,ROUND((E$74-E$34)*100,0))) -> -5 | M11: Suisun | N11: =-MAX(-5,MIN(5,ROUND((J$34-J$34)*100,0))) -> 0 | O11: =-MAX(-5,MIN(5,ROUND((J$42-J$34)*100,0))) -> 0 | P11: =-MAX(-5,MIN(5,ROUND((J$50-J$34)*100,0))) -> -2 | Q11: =-MAX(-5,MIN(5,ROUND((J$58-J$34)*100,0))) -> -5 | R11: =-MAX(-5,MIN(5,ROUND((J$66-J$34)*100,0))) -> -5 | S11: =-MAX(-5,MIN(5,ROUND((J$74-J$34)*100,0))) -> -5 | V11: Suisun | W11: =-MAX(-5,MIN(5,ROUND((O$34-O$34)*100,0))) -> 0 | X11: =-MAX(-5,MIN(5,ROUND((O$42-O$34)*100,0))) -> 0 | Y11: =-MAX(-5,MIN(5,ROUND((O$50-O$34)*100,0))) -> -5 | Z11: =-MAX(-5,MIN(5,ROUND((O$58-O$34)*100,0))) -> -5 | AA11: =-MAX(-5,MIN(5,ROUND((O$66-O$34)*100,0))) -> -3 | AB11: =-MAX(-5,MIN(5,ROUND((O$74-O$34)*100,0))) -> -3
D12: Central | E12: =-MAX(-5,MIN(5,ROUND((F$34-F$34)*100,0))) -> 0 | F12: =-MAX(-5,MIN(5,ROUND((F$42-F$34)*100,0))) -> 0 | G12: =-MAX(-5,MIN(5,ROUND((F$50-F$34)*100,0))) -> -4 | H12: =-MAX(-5,MIN(5,ROUND((F$58-F$34)*100,0))) -> -5 | I12: =-MAX(-5,MIN(5,ROUND((F$66-F$34)*100,0))) -> 1 | J12: =-MAX(-5,MIN(5,ROUND((F$74-F$34)*100,0))) -> 1 | M12: Central | N12: =-MAX(-5,MIN(5,ROUND((K$34-K$34)*100,0))) -> 0 | O12: =-MAX(-5,MIN(5,ROUND((K$42-K$34)*100,0))) -> 0 | P12: =-MAX(-5,MIN(5,ROUND((K$50-K$34)*100,0))) -> -3 | Q12: =-MAX(-5,MIN(5,ROUND((K$58-K$34)*100,0))) -> -5 | R12: =-MAX(-5,MIN(5,ROUND((K$66-K$34)*100,0))) -> 1 | S12: =-MAX(-5,MIN(5,ROUND((K$74-K$34)*100,0))) -> 1 | V12: Central | W12: =-MAX(-5,MIN(5,ROUND((P$34-P$34)*100,0))) -> 0 | X12: =-MAX(-5,MIN(5,ROUND((P$42-P$34)*100,0))) -> 0 | Y12: =-MAX(-5,MIN(5,ROUND((P$50-P$34)*100,0))) -> -4 | Z12: =-MAX(-5,MIN(5,ROUND((P$58-P$34)*100,0))) -> -3 | AA12: =-MAX(-5,MIN(5,ROUND((P$66-P$34)*100,0))) -> 1 | AB12: =-MAX(-5,MIN(5,ROUND((P$74-P$34)*100,0))) -> 1
D13: North | E13: =-MAX(-5,MIN(5,ROUND((G$34-G$34)*100,0))) -> 0 | F13: =-MAX(-5,MIN(5,ROUND((G$42-G$34)*100,0))) -> 0 | G13: =-MAX(-5,MIN(5,ROUND((G$50-G$34)*100,0))) -> 0 | H13: =-MAX(-5,MIN(5,ROUND((G$58-G$34)*100,0))) -> 0 | I13: =-MAX(-5,MIN(5,ROUND((G$66-G$34)*100,0))) -> 0 | J13: =-MAX(-5,MIN(5,ROUND((G$74-G$34)*100,0))) -> 0 | M13: North | N13: =-MAX(-5,MIN(5,ROUND((L$34-L$34)*100,0))) -> 0 | O13: =-MAX(-5,MIN(5,ROUND((L$42-L$34)*100,0))) -> 0 | P13: =-MAX(-5,MIN(5,ROUND((L$50-L$34)*100,0))) -> 0 | Q13: =-MAX(-5,MIN(5,ROUND((L$58-L$34)*100,0))) -> 0 | R13: =-MAX(-5,MIN(5,ROUND((L$66-L$34)*100,0))) -> 0 | S13: =-MAX(-5,MIN(5,ROUND((L$74-L$34)*100,0))) -> 0 | V13: North | W13: =-MAX(-5,MIN(5,ROUND((Q$34-Q$34)*100,0))) -> 0 | X13: =-MAX(-5,MIN(5,ROUND((Q$42-Q$34)*100,0))) -> 0 | Y13: =-MAX(-5,MIN(5,ROUND((Q$50-Q$34)*100,0))) -> 0 | Z13: =-MAX(-5,MIN(5,ROUND((Q$58-Q$34)*100,0))) -> 0 | AA13: =-MAX(-5,MIN(5,ROUND((Q$66-Q$34)*100,0))) -> 0 | AB13: =-MAX(-5,MIN(5,ROUND((Q$74-Q$34)*100,0))) -> 0
D14: South | E14: =-MAX(-5,MIN(5,ROUND((H$34-H$34)*100,0))) -> 0 | F14: =-MAX(-5,MIN(5,ROUND((H$42-H$34)*100,0))) -> 0 | G14: =-MAX(-5,MIN(5,ROUND((H$50-H$34)*100,0))) -> 0 | H14: =-MAX(-5,MIN(5,ROUND((H$58-H$34)*100,0))) -> 0 | I14: =-MAX(-5,MIN(5,ROUND((H$66-H$34)*100,0))) -> 0 | J14: =-MAX(-5,MIN(5,ROUND((H$74-H$34)*100,0))) -> 0 | M14: South | N14: =-MAX(-5,MIN(5,ROUND((M$34-M$34)*100,0))) -> 0 | O14: =-MAX(-5,MIN(5,ROUND((M$42-M$34)*100,0))) -> 0 | P14: =-MAX(-5,MIN(5,ROUND((M$50-M$34)*100,0))) -> 0 | Q14: =-MAX(-5,MIN(5,ROUND((M$58-M$34)*100,0))) -> 0 | R14: =-MAX(-5,MIN(5,ROUND((M$66-M$34)*100,0))) -> 0 | S14: =-MAX(-5,MIN(5,ROUND((M$74-M$34)*100,0))) -> 0 | V14: South | W14: =-MAX(-5,MIN(5,ROUND((R$34-R$34)*100,0))) -> 0 | X14: =-MAX(-5,MIN(5,ROUND((R$42-R$34)*100,0))) -> 0 | Y14: =-MAX(-5,MIN(5,ROUND((R$50-R$34)*100,0))) -> 0 | Z14: =-MAX(-5,MIN(5,ROUND((R$58-R$34)*100,0))) -> 0 | AA14: =-MAX(-5,MIN(5,ROUND((R$66-R$34)*100,0))) -> 0 | AB14: =-MAX(-5,MIN(5,ROUND((R$74-R$34)*100,0))) -> 0
C15: WATERFOWL | D15: REGION | E15: BAU | F15: BAF | G15: COR | H15: Tunnel | I15: ECO | J15: NGW | L15: WATERFOWL | M15: REGION | N15: BAU | O15: BAF | P15: COR | Q15: Tunnel | R15: ECO | S15: NGW | U15: WATERFOWL | V15: REGION | W15: BAU | X15: BAF | Y15: COR | Z15: Tunnel | AA15: ECO | AB15: NGW
D16: Delta-Wide | E16: =-MAX(-5,MIN(5,ROUND((D$35-D$35)*100,0))) -> 0 | F16: =-MAX(-5,MIN(5,ROUND((D$43-D$35)*100,0))) -> 0 | G16: =-MAX(-5,MIN(5,ROUND((D$51-D$35)*100,0))) -> -2 | H16: =-MAX(-5,MIN(5,ROUND((D$59-D$35)*100,0))) -> -3 | I16: =-MAX(-5,MIN(5,ROUND((D$67-D$35)*100,0))) -> -1 | J16: =-MAX(-5,MIN(5,ROUND((D$75-D$35)*100,0))) -> -1 | M16: Delta-Wide | N16: =-MAX(-5,MIN(5,ROUND((I$35-I$35)*100,0))) -> 0 | O16: =-MAX(-5,MIN(5,ROUND((I$43-I$35)*100,0))) -> 0 | P16: =-MAX(-5,MIN(5,ROUND((I$51-I$35)*100,0))) -> -2 | Q16: =-MAX(-5,MIN(5,ROUND((I$59-I$35)*100,0))) -> -4 | R16: =-MAX(-5,MIN(5,ROUND((I$67-I$35)*100,0))) -> -2 | S16: =-MAX(-5,MIN(5,ROUND((I$75-I$35)*100,0))) -> -2 | V16: Delta-Wide | W16: =-MAX(-5,MIN(5,ROUND((N$35-N$35)*100,0))) -> 0 | X16: =-MAX(-5,MIN(5,ROUND((N$43-N$35)*100,0))) -> 0 | Y16: =-MAX(-5,MIN(5,ROUND((N$51-N$35)*100,0))) -> -3 | Z16: =-MAX(-5,MIN(5,ROUND((N$59-N$35)*100,0))) -> -3 | AA16: =-MAX(-5,MIN(5,ROUND((N$67-N$35)*100,0))) -> 0 | AB16: =-MAX(-5,MIN(5,ROUND((N$75-N$35)*100,0))) -> 0
D17: Suisun | E17: =-MAX(-5,MIN(5,ROUND((E$35-E$35)*100,0))) -> 0 | F17: =-MAX(-5,MIN(5,ROUND((E$43-E$35)*100,0))) -> 0 | G17: =-MAX(-5,MIN(5,ROUND((E$51-E$35)*100,0))) -> -5 | H17: =-MAX(-5,MIN(5,ROUND((E$59-E$35)*100,0))) -> -5 | I17: =-MAX(-5,MIN(5,ROUND((E$67-E$35)*100,0))) -> -4 | J17: =-MAX(-5,MIN(5,ROUND((E$75-E$35)*100,0))) -> -4 | M17: Suisun | N17: =-MAX(-5,MIN(5,ROUND((J$35-J$35)*100,0))) -> 0 | O17: =-MAX(-5,MIN(5,ROUND((J$43-J$35)*100,0))) -> 0 | P17: =-MAX(-5,MIN(5,ROUND((J$51-J$35)*100,0))) -> -5 | Q17: =-MAX(-5,MIN(5,ROUND((J$59-J$35)*100,0))) -> -5 | R17: =-MAX(-5,MIN(5,ROUND((J$67-J$35)*100,0))) -> -5 | S17: =-MAX(-5,MIN(5,ROUND((J$75-J$35)*100,0))) -> -5 | V17: Suisun | W17: =-MAX(-5,MIN(5,ROUND((O$35-O$35)*100,0))) -> 0 | X17: =-MAX(-5,MIN(5,ROUND((O$43-O$35)*100,0))) -> 0 | Y17: =-MAX(-5,MIN(5,ROUND((O$51-O$35)*100,0))) -> -5 | Z17: =-MAX(-5,MIN(5,ROUND((O$59-O$35)*100,0))) -> -5 | AA17: =-MAX(-5,MIN(5,ROUND((O$67-O$35)*100,0))) -> -3 | AB17: =-MAX(-5,MIN(5,ROUND((O$75-O$35)*100,0))) -> -3
D18: Central | E18: =-MAX(-5,MIN(5,ROUND((F$35-F$35)*100,0))) -> 0 | F18: =-MAX(-5,MIN(5,ROUND((F$43-F$35)*100,0))) -> 0 | G18: =-MAX(-5,MIN(5,ROUND((F$51-F$35)*100,0))) -> -3 | H18: =-MAX(-5,MIN(5,ROUND((F$59-F$35)*100,0))) -> -4 | I18: =-MAX(-5,MIN(5,ROUND((F$67-F$35)*100,0))) -> 1 | J18: =-MAX(-5,MIN(5,ROUND((F$75-F$35)*100,0))) -> 1 | M18: Central | N18: =-MAX(-5,MIN(5,ROUND((K$35-K$35)*100,0))) -> 0 | O18: =-MAX(-5,MIN(5,ROUND((K$43-K$35)*100,0))) -> 0 | P18: =-MAX(-5,MIN(5,ROUND((K$51-K$35)*100,0))) -> -3 | Q18: =-MAX(-5,MIN(5,ROUND((K$59-K$35)*100,0))) -> -5 | R18: =-MAX(-5,MIN(5,ROUND((K$67-K$35)*100,0))) -> 0 | S18: =-MAX(-5,MIN(5,ROUND((K$75-K$35)*100,0))) -> 0 | V18: Central | W18: =-MAX(-5,MIN(5,ROUND((P$35-P$35)*100,0))) -> 0 | X18: =-MAX(-5,MIN(5,ROUND((P$43-P$35)*100,0))) -> 0 | Y18: =-MAX(-5,MIN(5,ROUND((P$51-P$35)*100,0))) -> -3 | Z18: =-MAX(-5,MIN(5,ROUND((P$59-P$35)*100,0))) -> -2 | AA18: =-MAX(-5,MIN(5,ROUND((P$67-P$35)*100,0))) -> 1 | AB18: =-MAX(-5,MIN(5,ROUND((P$75-P$35)*100,0))) -> 1
D19: North | E19: =-MAX(-5,MIN(5,ROUND((G$35-G$35)*100,0))) -> 0 | F19: =-MAX(-5,MIN(5,ROUND((G$43-G$35)*100,0))) -> 0 | G19: =-MAX(-5,MIN(5,ROUND((G$51-G$35)*100,0))) -> 0 | H19: =-MAX(-5,MIN(5,ROUND((G$59-G$35)*100,0))) -> 0 | I19: =-MAX(-5,MIN(5,ROUND((G$67-G$35)*100,0))) -> 0 | J19: =-MAX(-5,MIN(5,ROUND((G$75-G$35)*100,0))) -> 0 | M19: North | N19: =-MAX(-5,MIN(5,ROUND((L$35-L$35)*100,0))) -> 0 | O19: =-MAX(-5,MIN(5,ROUND((L$43-L$35)*100,0))) -> 0 | P19: =-MAX(-5,MIN(5,ROUND((L$51-L$35)*100,0))) -> 0 | Q19: =-MAX(-5,MIN(5,ROUND((L$59-L$35)*100,0))) -> 0 | R19: =-MAX(-5,MIN(5,ROUND((L$67-L$35)*100,0))) -> 0 | S19: =-MAX(-5,MIN(5,ROUND((L$75-L$35)*100,0))) -> 0 | V19: North | W19: =-MAX(-5,MIN(5,ROUND((Q$35-Q$35)*100,0))) -> 0 | X19: =-MAX(-5,MIN(5,ROUND((Q$43-Q$35)*100,0))) -> 0 | Y19: =-MAX(-5,MIN(5,ROUND((Q$51-Q$35)*100,0))) -> 0 | Z19: =-MAX(-5,MIN(5,ROUND((Q$59-Q$35)*100,0))) -> 0 | AA19: =-MAX(-5,MIN(5,ROUND((Q$67-Q$35)*100,0))) -> 0 | AB19: =-MAX(-5,MIN(5,ROUND((Q$75-Q$35)*100,0))) -> 0
D20: South | E20: =-MAX(-5,MIN(5,ROUND((H$35-H$35)*100,0))) -> 0 | F20: =-MAX(-5,MIN(5,ROUND((H$43-H$35)*100,0))) -> 0 | G20: =-MAX(-5,MIN(5,ROUND((H$51-H$35)*100,0))) -> 0 | H20: =-MAX(-5,MIN(5,ROUND((H$59-H$35)*100,0))) -> 0 | I20: =-MAX(-5,MIN(5,ROUND((H$67-H$35)*100,0))) -> 0 | J20: =-MAX(-5,MIN(5,ROUND((H$75-H$35)*100,0))) -> 0 | M20: South | N20: =-MAX(-5,MIN(5,ROUND((M$35-M$35)*100,0))) -> 0 | O20: =-MAX(-5,MIN(5,ROUND((M$43-M$35)*100,0))) -> 0 | P20: =-MAX(-5,MIN(5,ROUND((M$51-M$35)*100,0))) -> 0 | Q20: =-MAX(-5,MIN(5,ROUND((M$59-M$35)*100,0))) -> 0 | R20: =-MAX(-5,MIN(5,ROUND((M$67-M$35)*100,0))) -> 0 | S20: =-MAX(-5,MIN(5,ROUND((M$75-M$35)*100,0))) -> 0 | V20: South | W20: =-MAX(-5,MIN(5,ROUND((R$35-R$35)*100,0))) -> 0 | X20: =-MAX(-5,MIN(5,ROUND((R$43-R$35)*100,0))) -> 0 | Y20: =-MAX(-5,MIN(5,ROUND((R$51-R$35)*100,0))) -> 0 | Z20: =-MAX(-5,MIN(5,ROUND((R$59-R$35)*100,0))) -> 0 | AA20: =-MAX(-5,MIN(5,ROUND((R$67-R$35)*100,0))) -> 0 | AB20: =-MAX(-5,MIN(5,ROUND((R$75-R$35)*100,0))) -> 0
C21: ANGLING | D21: REGION | E21: BAU | F21: BAF | G21: COR | H21: Tunnel | I21: ECO | J21: NGW | L21: ANGLING | M21: REGION | N21: BAU | O21: BAF | P21: COR | Q21: Tunnel | R21: ECO | S21: NGW | U21: ANGLING | V21: REGION | W21: BAU | X21: BAF | Y21: COR | Z21: Tunnel | AA21: ECO | AB21: NGW
D22: Delta-Wide | E22: =-MAX(-5,MIN(5,ROUND((D$36-D$36)*100,0))) -> 0 | F22: =-MAX(-5,MIN(5,ROUND((D$44-D$36)*100,0))) -> 0 | G22: =-MAX(-5,MIN(5,ROUND((D$52-D$36)*100,0))) -> -4 | H22: =-MAX(-5,MIN(5,ROUND((D$60-D$36)*100,0))) -> -5 | I22: =-MAX(-5,MIN(5,ROUND((D$68-D$36)*100,0))) -> -2 | J22: =-MAX(-5,MIN(5,ROUND((D$76-D$36)*100,0))) -> -2 | M22: Delta-Wide | N22: =-MAX(-5,MIN(5,ROUND((I$36-I$36)*100,0))) -> 0 | O22: =-MAX(-5,MIN(5,ROUND((I$44-I$36)*100,0))) -> 0 | P22: =-MAX(-5,MIN(5,ROUND((I$52-I$36)*100,0))) -> -5 | Q22: =-MAX(-5,MIN(5,ROUND((I$60-I$36)*100,0))) -> -5 | R22: =-MAX(-5,MIN(5,ROUND((I$68-I$36)*100,0))) -> -3 | S22: =-MAX(-5,MIN(5,ROUND((I$76-I$36)*100,0))) -> -3 | V22: Delta-Wide | W22: =-MAX(-5,MIN(5,ROUND((N$36-N$36)*100,0))) -> 0 | X22: =-MAX(-5,MIN(5,ROUND((N$44-N$36)*100,0))) -> 0 | Y22: =-MAX(-5,MIN(5,ROUND((N$52-N$36)*100,0))) -> -3 | Z22: =-MAX(-5,MIN(5,ROUND((N$60-N$36)*100,0))) -> -3 | AA22: =-MAX(-5,MIN(5,ROUND((N$68-N$36)*100,0))) -> -1 | AB22: =-MAX(-5,MIN(5,ROUND((N$76-N$36)*100,0))) -> -1
D23: Suisun | E23: =-MAX(-5,MIN(5,ROUND((E$36-E$36)*100,0))) -> 0 | F23: =-MAX(-5,MIN(5,ROUND((E$44-E$36)*100,0))) -> 0 | G23: =-MAX(-5,MIN(5,ROUND((E$52-E$36)*100,0))) -> -5 | H23: =-MAX(-5,MIN(5,ROUND((E$60-E$36)*100,0))) -> -5 | I23: =-MAX(-5,MIN(5,ROUND((E$68-E$36)*100,0))) -> -5 | J23: =-MAX(-5,MIN(5,ROUND((E$76-E$36)*100,0))) -> -5 | M23: Suisun | N23: =-MAX(-5,MIN(5,ROUND((J$36-J$36)*100,0))) -> 0 | O23: =-MAX(-5,MIN(5,ROUND((J$44-J$36)*100,0))) -> 0 | P23: =-MAX(-5,MIN(5,ROUND((J$52-J$36)*100,0))) -> -5 | Q23: =-MAX(-5,MIN(5,ROUND((J$60-J$36)*100,0))) -> -5 | R23: =-MAX(-5,MIN(5,ROUND((J$68-J$36)*100,0))) -> -5 | S23: =-MAX(-5,MIN(5,ROUND((J$76-J$36)*100,0))) -> -5 | V23: Suisun | W23: =-MAX(-5,MIN(5,ROUND((O$36-O$36)*100,0))) -> 0 | X23: =-MAX(-5,MIN(5,ROUND((O$44-O$36)*100,0))) -> 0 | Y23: =-MAX(-5,MIN(5,ROUND((O$52-O$36)*100,0))) -> -5 | Z23: =-MAX(-5,MIN(5,ROUND((O$60-O$36)*100,0))) -> -5 | AA23: =-MAX(-5,MIN(5,ROUND((O$68-O$36)*100,0))) -> -5 | AB23: =-MAX(-5,MIN(5,ROUND((O$76-O$36)*100,0))) -> -5
D24: Central | E24: =-MAX(-5,MIN(5,ROUND((F$36-F$36)*100,0))) -> 0 | F24: =-MAX(-5,MIN(5,ROUND((F$44-F$36)*100,0))) -> 0 | G24: =-MAX(-5,MIN(5,ROUND((F$52-F$36)*100,0))) -> -2 | H24: =-MAX(-5,MIN(5,ROUND((F$60-F$36)*100,0))) -> -2 | I24: =-MAX(-5,MIN(5,ROUND((F$68-F$36)*100,0))) -> 0 | J24: =-MAX(-5,MIN(5,ROUND((F$76-F$36)*100,0))) -> 0 | M24: Central | N24: =-MAX(-5,MIN(5,ROUND((K$36-K$36)*100,0))) -> 0 | O24: =-MAX(-5,MIN(5,ROUND((K$44-K$36)*100,0))) -> 0 | P24: =-MAX(-5,MIN(5,ROUND((K$52-K$36)*100,0))) -> -3 | Q24: =-MAX(-5,MIN(5,ROUND((K$60-K$36)*100,0))) -> -4 | R24: =-MAX(-5,MIN(5,ROUND((K$68-K$36)*100,0))) -> 1 | S24: =-MAX(-5,MIN(5,ROUND((K$76-K$36)*100,0))) -> 1 | V24: Central | W24: =-MAX(-5,MIN(5,ROUND((P$36-P$36)*100,0))) -> 0 | X24: =-MAX(-5,MIN(5,ROUND((P$44-P$36)*100,0))) -> 0 | Y24: =-MAX(-5,MIN(5,ROUND((P$52-P$36)*100,0))) -> 0 | Z24: =-MAX(-5,MIN(5,ROUND((P$60-P$36)*100,0))) -> -1 | AA24: =-MAX(-5,MIN(5,ROUND((P$68-P$36)*100,0))) -> 0 | AB24: =-MAX(-5,MIN(5,ROUND((P$76-P$36)*100,0))) -> 0
D25: North | E25: =-MAX(-5,MIN(5,ROUND((G$36-G$36)*100,0))) -> 0 | F25: =-MAX(-5,MIN(5,ROUND((G$44-G$36)*100,0))) -> 0 | G25: =-MAX(-5,MIN(5,ROUND((G$52-G$36)*100,0))) -> 0 | H25: =-MAX(-5,MIN(5,ROUND((G$60-G$36)*100,0))) -> 0 | I25: =-MAX(-5,MIN(5,ROUND((G$68-G$36)*100,0))) -> 0 | J25: =-MAX(-5,MIN(5,ROUND((G$76-G$36)*100,0))) -> 0 | M25: North | N25: =-MAX(-5,MIN(5,ROUND((L$36-L$36)*100,0))) -> 0 | O25: =-MAX(-5,MIN(5,ROUND((L$44-L$36)*100,0))) -> 0 | P25: =-MAX(-5,MIN(5,ROUND((L$52-L$36)*100,0))) -> 0 | Q25: =-MAX(-5,MIN(5,ROUND((L$60-L$36)*100,0))) -> 0 | R25: =-MAX(-5,MIN(5,ROUND((L$68-L$36)*100,0))) -> 0 | S25: =-MAX(-5,MIN(5,ROUND((L$76-L$36)*100,0))) -> 0 | V25: North | W25: =-MAX(-5,MIN(5,ROUND((Q$36-Q$36)*100,0))) -> 0 | X25: =-MAX(-5,MIN(5,ROUND((Q$44-Q$36)*100,0))) -> 0 | Y25: =-MAX(-5,MIN(5,ROUND((Q$52-Q$36)*100,0))) -> 0 | Z25: =-MAX(-5,MIN(5,ROUND((Q$60-Q$36)*100,0))) -> 0 | AA25: =-MAX(-5,MIN(5,ROUND((Q$68-Q$36)*100,0))) -> 0 | AB25: =-MAX(-5,MIN(5,ROUND((Q$76-Q$36)*100,0))) -> 0
D26: South | E26: =-MAX(-5,MIN(5,ROUND((H$36-H$36)*100,0))) -> 0 | F26: =-MAX(-5,MIN(5,ROUND((H$44-H$36)*100,0))) -> 0 | G26: =-MAX(-5,MIN(5,ROUND((H$52-H$36)*100,0))) -> 0 | H26: =-MAX(-5,MIN(5,ROUND((H$60-H$36)*100,0))) -> 0 | I26: =-MAX(-5,MIN(5,ROUND((H$68-H$36)*100,0))) -> 0 | J26: =-MAX(-5,MIN(5,ROUND((H$76-H$36)*100,0))) -> 0 | M26: South | N26: =-MAX(-5,MIN(5,ROUND((M$36-M$36)*100,0))) -> 0 | O26: =-MAX(-5,MIN(5,ROUND((M$44-M$36)*100,0))) -> 0 | P26: =-MAX(-5,MIN(5,ROUND((M$52-M$36)*100,0))) -> 0 | Q26: =-MAX(-5,MIN(5,ROUND((M$60-M$36)*100,0))) -> 0 | R26: =-MAX(-5,MIN(5,ROUND((M$68-M$36)*100,0))) -> 0 | S26: =-MAX(-5,MIN(5,ROUND((M$76-M$36)*100,0))) -> 0 | V26: South | W26: =-MAX(-5,MIN(5,ROUND((R$36-R$36)*100,0))) -> 0 | X26: =-MAX(-5,MIN(5,ROUND((R$44-R$36)*100,0))) -> 0 | Y26: =-MAX(-5,MIN(5,ROUND((R$52-R$36)*100,0))) -> 0 | Z26: =-MAX(-5,MIN(5,ROUND((R$60-R$36)*100,0))) -> 0 | AA26: =-MAX(-5,MIN(5,ROUND((R$68-R$36)*100,0))) -> 0 | AB26: =-MAX(-5,MIN(5,ROUND((R$76-R$36)*100,0))) -> 0
C30: BAU % EXCEEDANCES
D31: Total Run | I31: Wet Seasons | N31: Dry Seasons
D32: Delta-Wide | E32: Suisun | F32: Central Delta | G32: North Delta | H32: South Delta | I32: Delta-Wide | J32: Suisun | K32: Central Delta | L32: North Delta | M32: South Delta | N32: Delta-Wide | O32: Suisun | P32: Central Delta | Q32: North Delta | R32: South Delta
C33: Day Use & Boating | D33: =BAU!AK811 -> 0.27687579 | E33: =BAU!AL811 -> 0.80107188 | F33: =BAU!AM811 -> 0.27224324 | G33: =BAU!AN811 -> 0 | H33: =BAU!AO811 -> 0.00014011489 | I33: =BAU!AS811 -> 0.27919521 | J33: =BAU!AT811 -> 0.82636986 | K33: =BAU!AU811 -> 0.25783866 | L33: =BAU!AV811 -> 0 | M33: =BAU!AW811 -> 0.000304414 | N33: =BAU!BA811 -> 0.24743852 | O33: =BAU!BB811 -> 0.74214481 | P33: =BAU!BC811 -> 0.22009715 | Q33: =BAU!BD811 -> 0 | R33: =BAU!BE811 -> 0
C34: Birding | D34: =BAU!AK827 -> 0.20058323 | E34: =BAU!AL827 -> 0.68474149 | F34: =BAU!AM827 -> 0.10452571 | G34: =BAU!AN827 -> 0 | H34: =BAU!AO827 -> 0 | I34: =BAU!AS827 -> 0.19743151 | J34: =BAU!AT827 -> 0.68082192 | K34: =BAU!AU827 -> 0.096803653 | L34: =BAU!AV827 -> 0 | M34: =BAU!AW827 -> 0 | N34: =BAU!BA827 -> 0.18391393 | O34: =BAU!BB827 -> 0.6352459 | P34: =BAU!BC827 -> 0.089253188 | Q34: =BAU!BD827 -> 0 | R34: =BAU!BE827 -> 0
C35: Waterfowl | D35: =BAU!AK843 -> 0.18080076 | E35: =BAU!AL843 -> 0.62736444 | F35: =BAU!AM843 -> 0.085189856 | G35: =BAU!AN843 -> 0 | H35: =BAU!AO843 -> 0 | I35: =BAU!AS843 -> 0.1739726 | J35: =BAU!AT843 -> 0.61369863 | K35: =BAU!AU843 -> 0.073059361 | L35: =BAU!AV843 -> 0 | M35: =BAU!AW843 -> 0 | N35: =BAU!BA843 -> 0.16530055 | O35: =BAU!BB843 -> 0.57786885 | P35: =BAU!BC843 -> 0.074074074 | Q35: =BAU!BD843 -> 0 | R35: =BAU!BE843 -> 0
C36: Angling | D36: =BAU!AK859 -> 0.077395965 | E36: =BAU!AL859 -> 0.28452081 | F36: =BAU!AM859 -> 0.022278268 | G36: =BAU!AN859 -> 0 | H36: =BAU!AO859 -> 0 | I36: =BAU!AS859 -> 0.058304795 | J36: =BAU!AT859 -> 0.21472603 | K36: =BAU!AU859 -> 0.016438356 | L36: =BAU!AV859 -> 0 | M36: =BAU!AW859 -> 0 | N36: =BAU!BA859 -> 0.068562158 | O36: =BAU!BB859 -> 0.26195355 | P36: =BAU!BC859 -> 0.010928962 | Q36: =BAU!BD859 -> 0 | R36: =BAU!BE859 -> 0
C38: BAF % EXCEEDANCES
D39: Total Run | I39: Wet Seasons | N39: Dry Seasons
D40: Delta-Wide | E40: Suisun | F40: Central Delta | G40: North Delta | H40: South Delta | I40: Delta-Wide | J40: Suisun | K40: Central Delta | L40: North Delta | M40: South Delta | N40: Delta-Wide | O40: Suisun | P40: Central Delta | Q40: North Delta | R40: South Delta
C41: Day Use & Boating | D41: ='Bolster Fortify'!AK811 -> 0.27888556 | E41: ='Bolster Fortify'!AL811 -> 0.80122951 | F41: ='Bolster Fortify'!AM811 -> 0.27924898 | G41: ='Bolster Fortify'!AN811 -> 0 | H41: ='Bolster Fortify'!AO811 -> 0.00014011489 | I41: ='Bolster Fortify'!AS811 -> 0.2802226 | J41: ='Bolster Fortify'!AT811 -> 0.82671233 | K41: ='Bolster Fortify'!AU811 -> 0.26118721 | L41: ='Bolster Fortify'!AV811 -> 0 | M41: ='Bolster Fortify'!AW811 -> 0.000304414 | N41: ='Bolster Fortify'!BA811 -> 0.24837773 | O41: ='Bolster Fortify'!BB811 -> 0.74214481 | P41: ='Bolster Fortify'!BC811 -> 0.22343655 | Q41: ='Bolster Fortify'!BD811 -> 0 | R41: ='Bolster Fortify'!BE811 -> 0
C42: Birding | D42: ='Bolster Fortify'!AK827 -> 0.20081967 | E42: ='Bolster Fortify'!AL827 -> 0.68474149 | F42: ='Bolster Fortify'!AM827 -> 0.1053664 | G42: ='Bolster Fortify'!AN827 -> 0 | H42: ='Bolster Fortify'!AO827 -> 0 | I42: ='Bolster Fortify'!AS827 -> 0.19760274 | J42: ='Bolster Fortify'!AT827 -> 0.68082192 | K42: ='Bolster Fortify'!AU827 -> 0.097412481 | L42: ='Bolster Fortify'!AV827 -> 0 | M42: ='Bolster Fortify'!AW827 -> 0 | N42: ='Bolster Fortify'!BA827 -> 0.18391393 | O42: ='Bolster Fortify'!BB827 -> 0.6352459 | P42: ='Bolster Fortify'!BC827 -> 0.089253188 | Q42: ='Bolster Fortify'!BD827 -> 0 | R42: ='Bolster Fortify'!BE827 -> 0
C43: Waterfowl | D43: ='Bolster Fortify'!AK843 -> 0.18087957 | E43: ='Bolster Fortify'!AL843 -> 0.62736444 | F43: ='Bolster Fortify'!AM843 -> 0.085470085 | G43: ='Bolster Fortify'!AN843 -> 0 | H43: ='Bolster Fortify'!AO843 -> 0 | I43: ='Bolster Fortify'!AS843 -> 0.17405822 | J43: ='Bolster Fortify'!AT843 -> 0.6140411 | K43: ='Bolster Fortify'!AU843 -> 0.073059361 | L43: ='Bolster Fortify'!AV843 -> 0 | M43: ='Bolster Fortify'!AW843 -> 0 | N43: ='Bolster Fortify'!BA843 -> 0.16521516 | O43: ='Bolster Fortify'!BB843 -> 0.57752732 | P43: ='Bolster Fortify'!BC843 -> 0.074074074 | Q43: ='Bolster Fortify'!BD843 -> 0 | R43: ='Bolster Fortify'!BE843 -> 0
C44: Angling | D44: ='Bolster Fortify'!AK859 -> 0.077711223 | E44: ='Bolster Fortify'!AL859 -> 0.2860971 | F44: ='Bolster Fortify'!AM859 -> 0.021998038 | G44: ='Bolster Fortify'!AN859 -> 0 | H44: ='Bolster Fortify'!AO859 -> 0 | I44: ='Bolster Fortify'!AS859 -> 0.058989726 | J44: ='Bolster Fortify'!AT859 -> 0.21746575 | K44: ='Bolster Fortify'!AU859 -> 0.016438356 | L44: ='Bolster Fortify'!AV859 -> 0 | M44: ='Bolster Fortify'!AW859 -> 0 | N44: ='Bolster Fortify'!BA859 -> 0.068220628 | O44: ='Bolster Fortify'!BB859 -> 0.26127049 | P44: ='Bolster Fortify'!BC859 -> 0.010321797 | Q44: ='Bolster Fortify'!BD859 -> 0 | R44: ='Bolster Fortify'!BE859 -> 0
...

Sheet BAU
B1: Suisun | J1: Central Delta | S1: North Delta | Y1: South Delta
A2: Date | B2: CHADBOURNE SLOUGH AT SUNRISE DUCK CLUB | C2: MONTEZUMA SLOUGH AT NATIONAL STEEL | D2: MONTEZUMA SLOUGH NEAR BELDENS LANDING | E2: SUISUN SLOUGH 300' SOUTH OF VOLANTI SLOUGH | F2: HONKER BAY | G2: SUISUN BAY AT VAN SICKLE ISLAND | H2: SUISUN BAY WEST REACH | I2: GRIZZLY BAY BUOY | J2: DUTCH SL BELOW JERSEY ISLAND | K2: FALSE RIVER NEAR OAKLEY | L2: OLD RIVER AT FRANKS TRACT | M2: PITTSBURG | N2: SACRAMENTO RIVER AT EMMATON | O2: SAN ANDREAS LANDING | P2: SAN JOAQUIN RIVER AT JERSEY POINT | Q2: SUISUN BAY AT CHANNEL MARKER 5 AT COLLINSVILLE | R2: BRANNAN MARINAS AT SAN JOAQUIN RIVER | S2: LIBERTY CUT AT FIVE POINTS | T2: CACHE SLOUGH ABOVE RYER ISLAND FERRY | U2: DELTA CROSS CHANNEL NEAR WALNUT GROVE | V2: SACRAMENTO RIVER DOWNSTREAM OF ISLETON | W2: COURTLAND AT SACRAMENTO RIVER | X2: VIERAS RESORT AT SACRAMENTO RIVER | Y2: GRANT LINE CANAL NEAR CLIFTON COURT FORE | Z2: LITTLE POTATO SLOUGH AT TERMINOUS | AA2: MIDDLE RIVER AT MILDRED ISLAND | AB2: OLD RIVER AT CLIFTON COURT | AC2: SAN JOAQUIN RIVER AT BRANDT BRIDGE | AD2: SAN JOAQUIN RIVER AT PRISONERS POINT | AE2: SAN JOAQUIN RIVER NEAR VERNALIS | AF2: SAN JOAQUIN RIVER AT ROUGH AND READY ISLAND | AG2: VICTORIA CANAL BEFORE CLIFTON COURT FORE
A3: 43374 | B3: 14187.383 | C3: 5698.8164 | D3: 12355.245 | E3: 14046.185 | F3: 10633.861 | G3: 8007.693 | H3: 15622.194 | I3: 15095.698 | J3: 1219.0382 | K3: 1161.465 | L3: 435.27225 | M3: 7799.5005 | N3: 770.9231 | O3: 456.03146 | P3: 1317.1952 | Q3: 4931.7085 | R3: 635.5381 | S3: 275.34708 | T3: 138.55081 | U3: 109.65274 | V3: 120.88114 | W3: 110.69525 | X3: 112.63609 | Y3: 418.25137 | Z3: 130.39493 | AA3: 356.73343 | AB3: 599.4254 | AC3: 363.5233 | AD3: 361.20343 | AE3: 448.86038 | AF3: 439.94876 | AG3: 377.09177
A4: 43375 | B4: 14312.37 | C4: 5757.194 | D4: 12513.481 | E4: 14166.19 | F4: 10820.237 | G4: 8235.589 | H4: 15852.543 | I4: 15122.071 | J4: 1214.0515 | K4: 1186.4553 | L4: 452.53064 | M4: 8009.733 | N4: 829.1106 | O4: 473.36716 | P4: 1350.6161 | Q4: 5086.025 | R4: 656.3133 | S4: 264.6232 | T4: 137.65321 | U4: 110.01963 | V4: 120.66956 | W4: 109.07987 | X4: 112.15948 | Y4: 426.77908 | Z4: 130.83943 | AA4: 354.6108 | AB4: 591.02905 | AC4: 388.14706 | AD4: 366.8185 | AE4: 480.7754 | AF4: 440.8119 | AG4: 368.50876
A5: 43376 | B5: 14450.278 | C5: 5845.321 | D5: 12600.597 | E5: 14245.867 | F5: 10854.677 | G5: 8089.8257 | H5: 15619.519 | I5: 15159.218 | J5: 1212.2634 | K5: 1169.2101 | L5: 462.56424 | M5: 7739.151 | N5: 777.2413 | O5: 457.60263 | P5: 1330.2776 | Q5: 4966.151 | R5: 655.1888 | S5: 258.52426 | T5: 136.17984 | U5: 109.27357 | V5: 120.45316 | W5: 109.16311 | X5: 113.37368 | Y5: 444.67325 | Z5: 131.48375 | AA5: 351.58084 | AB5: 581.34564 | AC5: 415.26416 | AD5: 367.47043 | AE5: 498.2621 | AF5: 439.05997 | AG5: 363.36145
A6: 43377 | B6: 14584.979 | C6: 5970.309 | D6: 12674.753 | E6: 14316.688 | F6: 10776.868 | G6: 7870.0605 | H6: 15407.769 | I6: 15241.491 | J6: 1211.474 | K6: 1149.9884 | L6: 457.89023 | M6: 7483.197 | N6: 725.3548 | O6: 439.37784 | P6: 1309.7123 | Q6: 4796.3726 | R6: 640.49225 | S6: 250.99828 | T6: 134.4734 | U6: 109.47665 | V6: 118.64306 | W6: 108.9845 | X6: 112.14017 | Y6: 463.1201 | Z6: 131.2286 | AA6: 347.92276 | AB6: 575.9542 | AC6: 450.60254 | AD6: 366.58176 | AE6: 445.90475 | AF6: 435.94003 | AG6: 360.2229
A7: 43378 | B7: 14684.136 | C7: 6032.5684 | D7: 12725.691 | E7: 14369.622 | F7: 10466.176 | G7: 7468.6094 | H7: 14984.667 | I7: 15296.032 | J7: 1205.6431 | K7: 1128.1835 | L7: 446.7924 | M7: 7092.797 | N7: 688.4665 | O7: 409.95316 | P7: 1277.1769 | Q7: 4498.8755 | R7: 604.28326 | S7: 243.71443 | T7: 134.14763 | U7: 104.71906 | V7: 119.05249 | W7: 104.58044 | X7: 112.54816 | Y7: 469.92664 | Z7: 130.77672 | AA7: 343.9622 | AB7: 567.9567 | AC7: 467.0072 | AD7: 359.6229 | AE7: 449.29773 | AF7: 437.10605 | AG7: 357.11496
A8: 43379 | B8: 14794.378 | C8: 6084.4546 | D8: 12944.927 | E8: 14526.547 | F8: 10488.189 | G8: 7787.9194 | H8: 15453.487 | I8: 15304.161 | J8: 1199.1674 | K8: 1143.672 | L8: 427.0299 | M8: 7391.4824 | N8: 777.7011 | O8: 426.28085 | P8: 1294.358 | Q8: 4760.63 | R8: 618.24896 | S8: 230.4969 | T8: 134.05022 | U8: 111.13791 | V8: 119.55851 | W8: 121.00964 | X8: 111.82087 | Y8: 478.2972 | Z8: 130.84283 | AA8: 340.34744 | AB8: 568.89514 | AC8: 450.6768 | AD8: 347.91202 | AE8: 465.14456 | AF8: 455.70364 | AG8: 353.5863
A9: 43380 | B9: 14878.117 | C9: 6276.2104 | D9: 13093.491 | E9: 14610.055 | F9: 10416.193 | G9: 7678.1465 | H9: 15186.117 | I9: 15346.734 | J9: 1186.5724 | K9: 1092.2133 | L9: 441.5967 | M9: 7132.1914 | N9: 734.4672 | O9: 429.96704 | P9: 1254.3558 | Q9: 4656.2417 | R9: 622.46356 | S9: 219.70349 | T9: 133.20244 | U9: 119.84649 | V9: 120.23069 | W9: 114.60101 | X9: 113.6182 | Y9: 488.58127 | Z9: 130.53159 | AA9: 337.319 | AB9: 584.13184 | AC9: 458.01086 | AD9: 333.92673 | AE9: 457.11743 | AF9: 461.68588 | AG9: 353.3546
A10: 43381 | B10: 15019.18 | C10: 6403.57 | D10: 13400.945 | E10: 14827.288 | F10: 10478.157 | G10: 8099.153 | H10: 15966.746 | I10: 15277.366 | J10: 1174.0088 | K10: 1124.8434 | L10: 404.36276 | M10: 7708.595 | N10: 842.4233 | O10: 442.0245 | P10: 1275.3693 | Q10: 4974.5366 | R10: 628.6731 | S10: 210.98564 | T10: 134.98347 | U10: 112.64117 | V10: 129.73003 | W10: 114.09754 | X10: 123.51954 | Y10: 502.5359 | Z10: 131.50117 | AA10: 335.24402 | AB10: 577.7066 | AC10: 463.1936 | AD10: 335.71854 | AE10: 433.6356 | AF10: 463.27975 | AG10: 355.20346
A11: 43382 | B11: 15218.124 | C11: 6634.595 | D11: 13793.761 | E11: 15101.648 | F11: 11538.761 | G11: 9509.97 | H11: 17543.213 | I11: 15400.868 | J11: 1174.2898 | K11: 1213.3485 | L11: 428.3662 | M11: 9039.882 | N11: 1255.3463 | O11: 508.6411 | P11: 1382.3029 | Q11: 6114.599 | R11: 689.55615 | S11: 202.83699 | T11: 139.91754 | U11: 115.0918 | V11: 135.17451 | W11: 117.67828 | X11: 123.31998 | Y11: 495.16895 | Z11: 132.7838 | AA11: 333.4232 | AB11: 551.95703 | AC11: 436.99435 | AD11: 358.251 | AE11: 425.36978 | AF11: 468.7676 | AG11: 353.0652
A12: 43383 | B12: 15439.983 | C12: 6966.775 | D12: 14124.935 | E12: 15392.586 | F12: 12960.223 | G12: 10695.536 | H12: 18631.53 | I12: 15753.007 | J12: 1194.4717 | K12: 1306.524 | L12: 473.77 | M12: 10209.936 | N12: 1693.201 | O12: 558.14606 | P12: 1513.4535 | Q12: 7199.436 | R12: 741.116 | S12: 197.28282 | T12: 145.06657 | U12: 128.53471 | V12: 140.00359 | W12: 124.38033 | X12: 124.11303 | Y12: 490.9098 | Z12: 135.20982 | AA12: 330.94846 | AB12: 543.14276 | AC12: 429.94888 | AD12: 389.73865 | AE12: 448.22903 | AF12: 465.99252 | AG12: 350.3453
A13: 43384 | B13: 15624.944 | C13: 7132.1074 | D13: 14255.854 | E13: 15587.438 | F13: 13389.091 | G13: 10706.545 | H13: 18563.125 | I13: 16131.722 | J13: 1214.172 | K13: 1304.3502 | L13: 493.47598 | M13: 10212.286 | N13: 1699.2719 | O13: 523.18695 | P13: 1517.8322 | Q13: 7297.4785 | R13: 717.5357 | S13: 193.93675 | T13: 145.10295 | U13: 120.59975 | V13: 139.71547 | W13: 119.65432 | X13: 125.52331 | Y13: 495.6581 | Z13: 136.31464 | AA13: 328.3578 | AB13: 539.86206 | AC13: 430.9399 | AD13: 394.6786 | AE13: 473.5988 | AF13: 458.73843 | AG13: 346.90256
A14: 43385 | B14: 15787.129 | C14: 7280.0396 | D14: 14342.988 | E14: 15730.602 | F14: 13170.633 | G14: 10238.89 | H14: 18040.254 | I14: 16536.375 | J14: 1221.2947 | K14: 1275.7789 | L14: 475.20178 | M14: 9791.062 | N14: 1498.5835 | O14: 479.68552 | P14: 1475.8828 | Q14: 6894.8047 | R14: 674.33575 | S14: 189.54889 | T14: 143.5006 | U14: 121.00289 | V14: 140.07732 | W14: 115.94214 | X14: 129.66745 | Y14: 492.83707 | Z14: 136.24867 | AA14: 326.6619 | AB14: 543.6301 | AC14: 467.5012 | AD14: 383.33908 | AE14: 482.0358 | AF14: 451.40652 | AG14: 346.5051
... A795: 44166 | B795: 13931.319 | C795: 7101.8716 | D795: 7028.721 | E795: 12877.281 | F795: 15030.647 | G795: 6349.2354 | H795: 12537.686 | I795: 18525.531 | J795: 1418.6486 | K795: 1282.1018 | L795: 824.3591 | M795: 5749.4688 | N795: 1197.3696 | O795: 283.23718 | P795: 1326.0695 | Q795: 2914.284 | R795: 535.70404 | S795: 152.76317 | T795: 156.05252 | U795: 134.59422 | V795: 145.04791 | W795: 145.08557 | X795: 144.67583 | Y795: 736.3665 | Z795: 172.32137 | AA795: 540.0816 | AB795: 764.4203 | AC795: 700.45135 | AD795: 490.31287 | AE795: 799.69885 | AF795: 492.08087 | AG795: 539.761
A796: TOTAL EXCEEDANCES | B796: =COUNTIF(B$3:B$795,">=1000") -> 664 | C796: =COUNTIF(C$3:C$795,">=1000") -> 558 | D796: =COUNTIF(D$3:D$795,">=1000") -> 633 | E796: =COUNTIF(E$3:E$795,">=1000") -> 663 | F796: =COUNTIF(F$3:F$795,">=1000") -> 630 | G796: =COUNTIF(G$3:G$795,">=1000") -> 623 | H796: =COUNTIF(H$3:H$795,">=1000") -> 656 | I796: =COUNTIF(I$3:I$795,">=1000") -> 655 | ... AG796: =COUNTIF(AG$3:AG$795,">=1000") -> 0
A797: WET 1 | B797: =COUNTIF(B$3:B$184,">=1000") -> 144 | C797: =COUNTIF(C$3:C$184,">=1000") -> 103 | D797: =COUNTIF(D$3:D$184,">=1000") -> 115 | E797: =COUNTIF(E$3:E$184,">=1000") -> 142 | F797: =COUNTIF(F$3:F$184,">=1000") -> 112 | G797: =COUNTIF(G$3:G$184,">=1000") -> 107 | H797: =COUNTIF(H$3:H$184,">=1000") -> 122 | I797: =COUNTIF(I$3:I$184,">=1000") -> 131 | ... AG797: =COUNTIF(AG$3:AG$184,">=1000") -> 0 | AH797: OCT 2018 - MARCH 2019
A798: WET 2 | B798: =COUNTIF(B$368:B$550,">=1000") -> 183 | C798: =COUNTIF(C$368:C$550,">=1000") -> 157 | D798: =COUNTIF(D$368:D$550,">=1000") -> 183 | E798: =COUNTIF(E$368:E$550,">=1000") -> 183 | F798: =COUNTIF(F$368:F$550,">=1000") -> 183 | G798: =COUNTIF(G$368:G$550,">=1000") -> 182 | H798: =COUNTIF(H$368:H$550,">=1000") -> 183 | I798: =COUNTIF(I$368:I$550,">=1000") -> 183 | ... AG798: =COUNTIF(AG$368:AG$550,">=1000") -> 0 | AH798: OCT 2019 - MARCH 2020
A799: DRY 1 | B799: =COUNTIF(B$185:B$367,">=1000") -> 92 | C799: =COUNTIF(C$185:C$367,">=1000") -> 72 | D799: =COUNTIF(D$185:D$367,">=1000") -> 90 | E799: =COUNTIF(E$185:E$367,">=1000") -> 93 | F799: =COUNTIF(F$185:F$367,">=1000") -> 90 | G799: =COUNTIF(G$185:G$367,">=1000") -> 89 | H799: =COUNTIF(H$185:H$367,">=1000") -> 106 | I799: =COUNTIF(I$185:I$367,">=1000") -> 96 | ... AG799: =COUNTIF(AG$185:AG$367,">=1000") -> 0 | AH799: APRIL 2019 - SEPTEMBER 2019
A800: DRY 2 | B800: =COUNTIF(B$551:B$733,">=1000") -> 183 | C800: =COUNTIF(C$551:C$733,">=1000") -> 164 | D800: =COUNTIF(D$551:D$733,">=1000") -> 183 | E800: =COUNTIF(E$551:E$733,">=1000") -> 183 | F800: =COUNTIF(F$551:F$733,">=1000") -> 183 | G800: =COUNTIF(G$551:G$733,">=1000") -> 183 | H800: =COUNTIF(H$551:H$733,">=1000") -> 183 | I800: =COUNTIF(I$551:I$733,">=1000") -> 183 | ... AG800: =COUNTIF(AG$551:AG$733,">=1000") -> 0 | AH800: APRIL 2020 - SEPTEMBER 2020
A801: ALL WET | B801: =SUM(B$797,B$798) -> 327 | C801: =SUM(C$797,C$798) -> 260 | D801: =SUM(D$797,D$798) -> 298 | E801: =SUM(E$797,E$798) -> 325 | F801: =SUM(F$797,F$798) -> 295 | G801: =SUM(G$797,G$798) -> 289 | H801: =SUM(H$797,H$798) -> 305 | I801: =SUM(I$797,I$798) -> 314 | ... AG801: =SUM(AG$797,AG$798) -> 0
A802: ALL DRY | B802: =SUM(B$799,B$800) -> 275 | C802: =SUM(C$799,C$800) -> 236 | D802: =SUM(D$799,D$800) -> 273 | E802: =SUM(E$799,E$800) -> 276 | F802: =SUM(F$799,F$800) -> 273 | G802: =SUM(G$799,G$800) -> 272 | H802: =SUM(H$799,H$800) -> 289 | I802: =SUM(I$799,I$800) -> 279 | ... AG802: =SUM(AG$799,AG$800) -> 0
D805: Day Use & Boating | F805: THRESHOLD: 1,000 MICROSIEMENS/CM (EC) | S805: SP DAY USE & BOATING | AA805: SP DAY USE & BOATING | AE805: SP DAY USE & BOATING | AI805: SP DAY USE & BOATING | AQ805: SP DAY USE & BOATING | AY805: SP DAY USE & BOATING
F806: WET SEASON | S806: TOTAL RUN | AA806: WET SEASONS | AE806: DRY SEASONS | AI806: TOTAL RUN | AK806: Delta-Wide | AL806: Suisun | AM806: Central Delta | AN806: North Delta | AO806: South Delta | AQ806: WET SEASONS | AS806: Delta-Wide | AT806: Suisun | AU806: Central Delta | AV806: North Delta | AW806: South Delta | AY806: DRY SEASONS | BA806: Delta-Wide | BB806: Suisun | BC806: Central Delta | BD806: North Delta | BE806: South Delta
F807: OCTOBER 1 - MARCH 31 | M807: DRY SEASON | S807: Total points | U807: =COUNTIF(B3:AG3,"<>") -> 32 | AA807: Total points | AC807: =$U$807 -> 32 | AE807: Total points | AG807: =$U$807 -> 32 | AI807: Total points | AK807: =COUNTIF(B2:AG2,"<>") -> 32 | AL807: =COUNTIF(B2:I2,"<>") -> 8 | AM807: =COUNTIF(J2:R2,"<>") -> 9 | AN807: =COUNTIF(S2:X2,"<>") -> 6 | AO807: =COUNTIF(Y2:AG2,"<>") -> 9 | AQ807: Total points | AS807: =$U$807 -> 32 | AT807: 8 | AU807: 9 | AV807: 6 | AW807: 9 | AY807: Total points | BA807: =$U$807 -> 32 | BB807: 8 | BC807: 9 | BD807: 6 | BE807: 9
F808: WET SEASON 1 | H808: 10/1/18 - 3/31/19 | J808: =COUNTIF($A$3:$A$184,"<>") -> 182 | M808: APRIL 1 - SEPTEMBER 30 | S808: Days in run | U808: =COUNTIF($A$3:$A$795,"<>") -> 793 | AA808: Days in run | AC808: =SUM($J$808:$J$809) -> 365 | AE808: Days in run | AG808: =SUM($Q$809:$Q$810) -> 366 | AI808: Days in run | AK808: =COUNTIF($A$3:$A$795,"<>") -> 793 | AL808: =COUNTIF($A$3:$A$795,"<>") -> 793 | AM808: =COUNTIF($A$3:$A$795,"<>") -> 793 | AN808: =COUNTIF($A$3:$A$795,"<>") -> 793 | AO808: =COUNTIF($A$3:$A$795,"<>") -> 793 | AQ808: Days in run | AS808: =SUM($J$808:$J$809) -> 365 | AT808: =SUM($J$808:$J$809) -> 365 | AU808: =SUM($J$808:$J$809) -> 365 | AV808: =SUM($J$808:$J$809) -> 365 | AW808: =SUM($J$808:$J$809) -> 365 | AY808: Days in run | BA808: =SUM($Q$809:$Q$810) -> 366 | BB808: =SUM($Q$809:$Q$810) -> 366 | BC808: =SUM($Q$809:$Q$810) -> 366 | BD808: =SUM($Q$809:$Q$810) -> 366 | BE808: =SUM($Q$809:$Q$810) -> 366
F809: WET SEASON 2 | H809: 10/1/19 - 3/31/20 | J809: =COUNTIF($A$368:$A$550,"<>") -> 183 | M809: DRY SEASON 2 | O809: 4/1/19 - 9/30/19 | Q809: =COUNTIF($A$185:$A$367,"<>") -> 183 | S809: Total measurements | U809: =U808*U807 -> 25376 | V809: DENOMINATOR FOR EXCEEDANCE % | AA809: Total measurements | AC809: =AC808*AC807 -> 11680 | AE809: Total measurements | AG809: =$AG$808*$AG$807 -> 11712 | AI809: Total measurements | AK809: =AK808*AK807 -> 25376 | AL809: =AL808*AL807 -> 6344 | AM809: =AM808*AM807 -> 7137 | AN809: =AN808*AN807 -> 4758 | AO809: =AO808*AO807 -> 7137 | AQ809: Total measurements | AS809: =AS808*AS807 -> 11680 | AT809: =AT808*AT807 -> 2920 | AU809: =AU808*AU807 -> 3285 | AV809: =AV808*AV807 -> 2190 | AW809: =AW808*AW807 -> 3285 | AY809: Total measurements | BA809: =BA808*BA807 -> 11712 | BB809: =BB808*BB807 -> 2928 | BC809: =BC808*BC807 -> 3294 | BD809: =BD808*BD807 -> 2196 | BE809: =BE808*BE807 -> 3294
F810: WET SEASON 3 | H810: 10/1/20 - 12/1/20 | J810: =COUNTIF($A$734:$A$795,"<>") -> 62 | M810: DRY SEASON 3 | O810: 4/1/20 - 9/30/20 | Q810: =COUNTIF($A$551:$A$733,"<>") -> 183 | S810: Measurements >= 1000 | U810: =SUM(B796:AG796) -> 7026 | V810: NUMERATOR FOR EXCEEDANCE % | AA810: Measurements >= 1000 | AC810: =SUM($B$801:$AG$801) -> 3261 | AE810: Measurements >= 1000 | AG810: =SUM($B$802:$AG$802) -> 2898 | AI810: Measurements >= 1000 | AK810: =SUM(B796:AG796) -> 7026 | AL810: =SUM(B796:I796) -> 5082 | AM810: =SUM(J796:R796) -> 1943 | AN810: =SUM(S796:X796) -> 0 | AO810: =SUM(Y796:AG796) -> 1 | AQ810: Measurements >= 1000 | AS810: =SUM($B$801:$AG$801) -> 3261 | AT810: =SUM(B801:I801) -> 2413 | AU810: =SUM(J801:R801) -> 847 | AV810: =SUM(S801:X801) -> 0 | AW810: =SUM(Y801:AG801) -> 1 | AY810: Measurements >= 1000 | BA810: =SUM($B$802:$AG$802) -> 2898 | BB810: =SUM(B802:I802) -> 2173 | BC810: =SUM(J802:R802) -> 725 | BD810: =SUM(S802:X802) -> 0 | BE810: =SUM(Y802:AG802) -> 0
S811: % Total Run Exceedances | U811: =$U810/$U809 -> 0.27687579 | AA811: % WET Exceedances | AC811: =AC810/AC809 -> 0.27919521 | AE811: % DRY Exceedances | AG811: =AG810/AG809 -> 0.24743852 | AI811: % Total Run Exceedances | AK811: =AK810/AK809 -> 0.27687579 | AL811: =AL810/AL809 -> 0.80107188 | AM811: =AM810/AM809 -> 0.27224324 | AN811: =AN810/AN809 -> 0 | AO811: =AO810/AO809 -> 0.00014011489 | AQ811: % WET Exceedances | AS811: =AS810/AS809 -> 0.27919521 | AT811: =AT810/AT809 -> 0.82636986 | AU811: =AU810/AU809 -> 0.25783866 | AV811: =AV810/AV809 -> 0 | AW811: =AW810/AW809 -> 0.000304414 | AY811: % DRY Exceedances | BA811: =BA810/BA809 -> 0.24743852 | BB811: =BB810/BB809 -> 0.74214481 | BC811: =BC810/BC809 -> 0.22009715 | BD811: =BD810/BD809 -> 0 | BE811: =BE810/BE809 -> 0
A813: TOTAL EXCEEDANCES | B813: =COUNTIF(B$3:B$795,">=2640") -> 624 | C813: =COUNTIF(C$3:C$795,">=2640") -> 287 | D813: =COUNTIF(D$3:D$795,">=2640") -> 506 | E813: =COUNTIF(E$3:E$795,">=2640") -> 624 | F813: =COUNTIF(F$3:F$795,">=2640") -> 584 | G813: =COUNTIF(G$3:G$795,">=2640") -> 458 | H813: =COUNTIF(H$3:H$795,">=2640") -> 632 | I813: =COUNTIF(I$3:I$795,">=2640") -> 629 | ... AG813: =COUNTIF(AG$3:AG$795,">=2640") -> 0
A814: WET 1 | B814: =COUNTIF(B$3:B$184,">=2640") -> 115 | C814: =COUNTIF(C$3:C$184,">=2640") -> 89 | D814: =COUNTIF(D$3:D$184,">=2640") -> 104 | E814: =COUNTIF(E$3:E$184,">=2640") -> 115 | F814: =COUNTIF(F$3:F$184,">=2640") -> 106 | G814: =COUNTIF(G$3:G$184,">=2640") -> 102 | H814: =COUNTIF(H$3:H$184,">=2640") -> 112 | I814: =COUNTIF(I$3:I$184,">=2640") -> 115 | ... AG814: =COUNTIF(AG$3:AG$184,">=2640") -> 0 | AH814: OCT 2018 - MARCH 2019
A815: WET 2 | B815: =COUNTIF(B$368:B$550,">=2640") -> 183 | C815: =COUNTIF(C$368:C$550,">=2640") -> 21 | D815: =COUNTIF(D$368:D$550,">=2640") -> 108 | E815: =COUNTIF(E$368:E$550,">=2640") -> 183 | F815: =COUNTIF(F$368:F$550,">=2640") -> 162 | G815: =COUNTIF(G$368:G$550,">=2640") -> 107 | H815: =COUNTIF(H$368:H$550,">=2640") -> 183 | I815: =COUNTIF(I$368:I$550,">=2640") -> 183 | ... AG815: =COUNTIF(AG$368:AG$550,">=2640") -> 0 | AH815: OCT 2019 - MARCH 2020
A816: DRY 1 | B816: =COUNTIF(B$185:B$367,">=2640") -> 81 | C816: =COUNTIF(C$185:C$367,">=2640") -> 0 | D816: =COUNTIF(D$185:D$367,">=2640") -> 77 | E816: =COUNTIF(E$185:E$367,">=2640") -> 81 | F816: =COUNTIF(F$185:F$367,">=2640") -> 71 | G816: =COUNTIF(G$185:G$367,">=2640") -> 19 | H816: =COUNTIF(H$185:H$367,">=2640") -> 92 | I816: =COUNTIF(I$185:I$367,">=2640") -> 86 | ... AG816: =COUNTIF(AG$185:AG$367,">=2640") -> 0 | AH816: APRIL 2019 - SEPTEMBER 2019
A817: DRY 2 | B817: =COUNTIF(B$551:B$733,">=2640") -> 183 | C817: =COUNTIF(C$551:C$733,">=2640") -> 115 | D817: =COUNTIF(D$551:D$733,">=2640") -> 155 | E817: =COUNTIF(E$551:E$733,">=2640") -> 183 | F817: =COUNTIF(F$551:F$733,">=2640") -> 183 | G817: =COUNTIF(G$551:G$733,">=2640") -> 168 | H817: =COUNTIF(H$551:H$733,">=2640") -> 183 | I817: =COUNTIF(I$551:I$733,">=2640") -> 183 | ... AG817: =COUNTIF(AG$551:AG$733,">=2640") -> 0 | AH817: APRIL 2020 - SEPTEMBER 2020
A818: ALL WET | B818: =SUM(B814,B815) -> 298 | C818: =SUM(C814,C815) -> 110 | D818: =SUM(D814,D815) -> 212 | E818: =SUM(E814,E815) -> 298 | F818: =SUM(F814,F815) -> 268 | G818: =SUM(G814,G815) -> 209 | H818: =SUM(H814,H815) -> 295 | I818: =SUM(I814,I815) -> 298 | ... AG818: =SUM(AG814,AG815) -> 0
A819: ALL DRY | B819: =SUM(B816,B817) -> 264 | C819: =SUM(C816,C817) -> 115 | D819: =SUM(D816,D817) -> 232 | E819: =SUM(E816,E817) -> 264 | F819: =SUM(F816,F817) -> 254 | G819: =SUM(G816,G817) -> 187 | H819: =SUM(H816,H817) -> 275 | I819: =SUM(I816,I817) -> 269 | ... AG819: =SUM(AG816,AG817) -> 0
D821: Birding | F821: THRESHOLD: 2,640 MICROSIEMENS/CM (EC) | S821: BIRDING | AA821: BIRDING | AE821: BIRDING | AI821: BIRDING | AQ821: BIRDING | AY821: BIRDING
F822: WET SEASON | S822: TOTAL RUN | AA822: WET SEASONS | AE822: DRY SEASONS | AI822: TOTAL RUN | AK822: Delta-Wide | AL822: Suisun | AM822: Central Delta | AN822: North Delta | AO822: South Delta | AQ822: WET SEASONS | AS822: Delta-Wide | AT822: Suisun | AU822: Central Delta | AV822: North Delta | AW822: South Delta | AY822: DRY SEASONS | BA822: Delta-Wide | BB822: Suisun | BC822: Central Delta | BD822: North Delta | BE822: South Delta
F823: OCTOBER 1 - MARCH 31 | M823: DRY SEASON | S823: Total points | U823: =COUNTIF(B3:AG3,"<>") -> 32 | AA823: Total points | AC823: =$U$807 -> 32 | AE823: Total points | AG823: =$U$807 -> 32 | AI823: Total points | AK823: =COUNTIF(B18:AG18,"<>") -> 32 | AL823: =COUNTIF(B18:I18,"<>") -> 8 | AM823: =COUNTIF(J18:R18,"<>") -> 9 | AN823: =COUNTIF(S18:X18,"<>") -> 6 | AO823: =COUNTIF(Y18:AG18,"<>") -> 9 | AQ823: Total points | AS823: =$U$807 -> 32 | AT823: 8 | AU823: 9 | AV823: 6 | AW823: 9 | AY823: Total points | BA823: =$U$807 -> 32 | BB823: 8 | BC823: 9 | BD823: 6 | BE823: 9
F824: WET SEASON 1 | H824: 10/1/18 - 3/31/19 | J824: =COUNTIF($A$3:$A$184,"<>") -> 182 | M824: APRIL 1 - SEPTEMBER 30 | S824: Days in run | U824: =COUNTIF($A$3:$A$795,"<>") -> 793 | AA824: Days in run | AC824: =SUM($J$808:$J$809) -> 365 | AE824: Days in run | AG824: =SUM($Q$809:$Q$810) -> 366 | AI824: Days in run | AK824: =COUNTIF($A$3:$A$795,"<>") -> 793 | AL824: =COUNTIF($A$3:$A$795,"<>") -> 793 | AM824: =COUNTIF($A$3:$A$795,"<>") -> 793 | AN824: =COUNTIF($A$3:$A$795,"<>") -> 793 | AO824: =COUNTIF($A$3:$A$795,"<>") -> 793 | AQ824: Days in run | AS824: =SUM($J$808:$J$809) -> 365 | AT824: =SUM($J$808:$J$809) -> 365 | AU824: =SUM($J$808:$J$809) -> 365 | AV824: =SUM($J$808:$J$809) -> 365 | AW824: =SUM($J$808:$J$809) -> 365 | AY824: Days in run | BA824: =SUM($Q$809:$Q$810) -> 366 | BB824: =SUM($Q$809:$Q$810) -> 366 | BC824: =SUM($Q$809:$Q$810) -> 366 | BD824: =SUM($Q$809:$Q$810) -> 366 | BE824: =SUM($Q$809:$Q$810) -> 366
...

Sheet Bolster Fortify
B1: Suisun | J1: Central Delta | S1: North Delta | Y1: South Delta
A2: Date | B2: CHADBOURNE SLOUGH AT SUNRISE DUCK CLUB | C2: MONTEZUMA SLOUGH AT NATIONAL STEEL | D2: MONTEZUMA SLOUGH NEAR BELDENS LANDING | E2: SUISUN SLOUGH 300' SOUTH OF VOLANTI SLOUGH | F2: GRIZZLY BAY BUOY | G2: HONKER BAY | H2: SUISUN BAY AT VAN SICKLE ISLAND | I2: SUISUN BAY WEST REACH | J2: DUTCH SL BELOW JERSEY ISLAND | K2: FALSE RIVER NEAR OAKLEY | L2: OLD RIVER AT FRANKS TRACT | M2: PITTSBURG | N2: SACRAMENTO RIVER AT EMMATON | O2: SAN ANDREAS LANDING | P2: SAN JOAQUIN RIVER AT JERSEY POINT | Q2: SUISUN BAY AT CHANNEL MARKER 5 AT COLLINSVILLE | R2: BRANNAN MARINAS AT SAN JOAQUIN RIVER | S2: LIBERTY CUT AT FIVE POINTS | T2: CACHE SLOUGH ABOVE RYER ISLAND FERRY | U2: DELTA CROSS CHANNEL NEAR WALNUT GROVE | V2: SACRAMENTO RIVER DOWNSTREAM OF ISLETON | W2: VIERAS RESORT AT SACRAMENTO RIVER | X2: COURTLAND AT SACRAMENTO RIVER | Y2: GRANT LINE CANAL NEAR CLIFTON COURT FORE | Z2: LITTLE POTATO SLOUGH AT TERMINOUS | AA2: MIDDLE RIVER AT MILDRED ISLAND | AB2: OLD RIVER AT CLIFTON COURT | AC2: SAN JOAQUIN RIVER AT BRANDT BRIDGE | AD2: SAN JOAQUIN RIVER AT PRISONERS POINT | AE2: SAN JOAQUIN RIVER NEAR VERNALIS | AF2: SAN JOAQUIN RIVER AT ROUGH AND READY ISLAND | AG2: VICTORIA CANAL BEFORE CLIFTON COURT FORE
A3: 43374 | B3: 14321.553 | C3: 5706.8403 | D3: 12520.614 | E3: 14187.232 | F3: 15148.203 | G3: 10655.466 | H3: 8013.963 | I3: 15694.54 | J3: 1133.366 | K3: 1069.204 | L3: 542.13715 | M3: 7760.5713 | N3: 821.77405 | O3: 552.9224 | P3: 1221.1774 | Q3: 4965.1626 | R3: 723.77155 | S3: 273.36807 | T3: 139.59776 | U3: 109.6813 | V3: 123.10805 | W3: 113.64913 | X3: 110.69087 | Y3: 391.21814 | Z3: 128.44174 | AA3: 425.56857 | AB3: 478.7061 | AC3: 362.3325 | AD3: 475.60983 | AE3: 448.86038 | AF3: 443.2505 | AG3: 428.43448
A4: 43375 | B4: 14447.8 | C4: 5749.6714 | D4: 12672.714 | E4: 14305.218 | F4: 15172.559 | G4: 10838.541 | H4: 8246.828 | I4: 15926.844 | J4: 1132.2997 | K4: 1083.7064 | L4: 559.5728 | M4: 7978.367 | N4: 879.42523 | O4: 568.4035 | P4: 1254.1282 | Q4: 5121.2544 | R4: 744.8874 | S4: 262.62088 | T4: 138.9172 | U4: 110.0315 | V4: 123.01475 | W4: 113.12945 | X4: 109.07975 | Y4: 398.87387 | Z4: 129.71867 | AA4: 417.9481 | AB4: 471.68457 | AC4: 386.03848 | AD4: 485.7715 | AE4: 480.7754 | AF4: 444.6111 | AG4: 422.25525
A5: 43376 | B5: 14584.004 | C5: 5822.2163 | D5: 12756.046 | E5: 14382.883 | F5: 15210.8 | G5: 10880.132 | H5: 8109.7617 | I5: 15704.55 | J5: 1132.4152 | K5: 1081.869 | L5: 565.191 | M5: 7716.567 | N5: 826.6885 | O5: 553.16113 | P5: 1237.3528 | Q5: 5004.457 | R5: 744.73224 | S5: 256.49304 | T5: 137.44916 | U5: 109.26992 | V5: 122.4476 | W5: 114.23953 | X5: 109.16321 | Y5: 411.67163 | Z5: 130.02048 | AA5: 411.80283 | AB5: 464.58505 | AC5: 412.5964 | AD5: 488.00827 | AE5: 498.2621 | AF5: 442.95874 | AG5: 418.08817
A6: 43377 | B6: 14716.187 | C6: 5935.53 | D6: 12828.438 | E6: 14452.984 | F6: 15296.933 | G6: 10808.062 | H6: 7892.2793 | I6: 15493.226 | J6: 1133.2463 | K6: 1073.3359 | L6: 559.75446 | M6: 7456.397 | N6: 769.0629 | O6: 534.4545 | P6: 1226.9983 | Q6: 4840.263 | R6: 732.21136 | S6: 249.00732 | T6: 135.61397 | U6: 109.47053 | V6: 120.6894 | W6: 113.00086 | X6: 108.98261 | Y6: 429.5515 | Z6: 129.30083 | AA6: 408.61734 | AB6: 460.44983 | AC6: 447.2164 | AD6: 486.449 | AE6: 445.90475 | AF6: 439.53336 | AG6: 414.21353
A7: 43378 | B7: 14813.95 | C7: 5997.367 | D7: 12882.569 | E7: 14507.31 | F7: 15352.849 | G7: 10500.546 | H7: 7488.7383 | I7: 15064.548 | J7: 1130.3114 | K7: 1068.2096 | L7: 543.7625 | M7: 7052.3516 | N7: 728.34235 | O7: 502.16397 | P7: 1211.6647 | Q7: 4548.3706 | R7: 697.8899 | S7: 241.65997 | T7: 135.30429 | U7: 104.75945 | V7: 121.06879 | W7: 113.37565 | X7: 104.56965 | Y7: 440.397 | Z7: 128.82367 | AA7: 408.80563 | AB7: 455.1006 | AC7: 465.88632 | AD7: 473.5299 | AE7: 449.29773 | AF7: 437.8901 | AG7: 409.22818
A8: 43379 | B8: 14924.171 | C8: 6057.348 | D8: 13103.528 | E8: 14664.567 | F8: 15360.089 | G8: 10522.382 | H8: 7799.2925 | I8: 15526.831 | J8: 1130.6499 | K8: 1082.5385 | L8: 529.511 | M8: 7342.43 | N8: 823.6604 | O8: 516.66156 | P8: 1229.3287 | Q8: 4808.9087 | R8: 710.6018 | S8: 228.56189 | T8: 135.48085 | U8: 111.06251 | V8: 122.06235 | W8: 113.04601 | X8: 121.00797 | Y8: 444.84024 | Z8: 129.14021 | AA8: 409.98734 | AB8: 455.4486 | AC8: 450.12918 | AD8: 462.1263 | AE8: 465.14456 | AF8: 456.28793 | AG8: 405.99536
A9: 43380 | B9: 15009.376 | C9: 6270.3574 | D9: 13256.673 | E9: 14749.617 | F9: 15407.97 | G9: 10455.975 | H9: 7690.828 | I9: 15262.069 | J9: 1132.08 | K9: 1074.2217 | L9: 511.00247 | M9: 7072.5425 | N9: 780.14105 | O9: 501.73376 | P9: 1218.378 | Q9: 4711.309 | R9: 692.4318 | S9: 217.91402 | T9: 134.44897 | U9: 119.87954 | V9: 122.18496 | W9: 114.38364 | X9: 114.59048 | Y9: 452.57468 | Z9: 129.19 | AA9: 408.02017 | AB9: 458.94974 | AC9: 458.14807 | AD9: 440.67664 | AE9: 457.11743 | AF9: 462.58508 | AG9: 405.89725
A10: 43381 | B10: 15152.077 | C10: 6416.93 | D10: 13566.253 | E10: 14967.312 | F10: 15337.647 | G10: 10511.155 | H10: 8099.974 | I10: 16036.718 | J10: 1130.1022 | K10: 1085.3802 | L10: 492.83688 | M10: 7644.7407 | N10: 897.25055 | O10: 519.1922 | P10: 1225.5656 | Q10: 5021.7505 | R10: 708.19507 | S10: 209.27632 | T10: 136.43048 | U10: 112.63412 | V10: 132.15895 | W10: 124.35653 | X10: 114.10156 | Y10: 457.11874 | Z10: 129.74695 | AA10: 399.8577 | AB10: 457.05103 | AC10: 463.0204 | AD10: 437.09155 | AE10: 433.6356 | AF10: 463.7913 | AG10: 407.12537
A11: 43382 | B11: 15351.218 | C11: 6673.926 | D11: 13959.965 | E11: 15240.999 | F11: 15462.321 | G11: 11566.485 | H11: 9506.806 | I11: 17609.967 | J11: 1134.5845 | K11: 1122.7163 | L11: 534.4342 | M11: 8972.762 | N11: 1346.9327 | O11: 603.41046 | P11: 1295.1288 | Q11: 6161.969 | R11: 788.55646 | S11: 201.23657 | T11: 141.81543 | U11: 115.09921 | V11: 138.87051 | W11: 125.3753 | X11: 117.74416 | Y11: 452.30124 | Z11: 131.06346 | AA11: 389.88977 | AB11: 450.9298 | AC11: 436.88394 | AD11: 471.28723 | AE11: 425.36978 | AF11: 469.72916 | AG11: 402.5233
A12: 43383 | B12: 15572.89 | C12: 7026.8384 | D12: 14292.938 | E12: 15532.243 | F12: 15815.68 | G12: 12996.66 | H12: 10702.308 | I12: 18709.627 | J12: 1146.3744 | K12: 1176.6838 | L12: 592.5179 | M12: 10148.761 | N12: 1833.9243 | O12: 665.0274 | P12: 1399.4478 | Q12: 7259.8276 | R12: 851.12775 | S12: 195.73566 | T12: 147.96268 | U12: 128.61362 | V12: 145.17946 | W12: 126.75653 | X12: 124.35388 | Y12: 444.69016 | Z12: 133.92113 | AA12: 386.32288 | AB12: 444.68076 | AC12: 429.70618 | AD12: 519.5756 | AE12: 448.22903 | AF12: 466.66837 | AG12: 395.81458
A13: 43384 | B13: 15758.543 | C13: 7186.567 | D13: 14428.089 | E13: 15729.433 | F13: 16193.802 | G13: 13434.071 | H13: 10724.368 | I13: 18656.816 | J13: 1159.0104 | K13: 1204.3263 | L13: 592.3052 | M13: 10162.686 | N13: 1860.4088 | O13: 631.3143 | P13: 1426.6221 | Q13: 7374.9556 | R13: 830.8083 | S13: 192.45857 | T13: 148.73178 | U13: 120.75497 | V13: 145.31227 | W13: 127.6458 | X13: 119.66 | Y13: 442.63623 | Z13: 134.78221 | AA13: 388.21115 | AB13: 439.4093 | AC13: 431.04428 | AD13: 519.7243 | AE13: 473.5988 | AF13: 458.9111 | AG13: 392.9971
A14: 43385 | B14: 15922.48 | C14: 7320.3745 | D14: 14516.339 | E14: 15874.848 | F14: 16599.084 | G14: 13213.339 | H14: 10257.622 | I14: 18133.736 | J14: 1167.5221 | K14: 1205.9133 | L14: 565.0921 | M14: 9743.588 | N14: 1646.5953 | O14: 585.16376 | P14: 1412.4796 | Q14: 6973.109 | R14: 786.5942 | S14: 188.22899 | T14: 146.96144 | U14: 120.97439 | V14: 144.90501 | W14: 131.33633 | X14: 115.96235 | Y14: 441.58423 | Z14: 134.32726 | AA14: 393.9751 | AB14: 435.41043 | AC14: 468.0076 | AD14: 497.6357 | AE14: 482.0358 | AF14: 451.13635 | AG14: 392.24466
... A795: 44166 | B795: 14118.241 | C795: 7194.5513 | D795: 7159.5547 | E795: 13055.374 | F795: 18572.334 | G795: 15013.439 | H795: 6447.386 | I795: 12601.139 | J795: 1432.2358 | K795: 1489.52 | L795: 679.0698 | M795: 5696.6978 | N795: 1277.2974 | O795: 338.37527 | P795: 1507.0571 | Q795: 3074.9346 | R795: 649.0083 | S795: 157.88863 | T795: 160.8029 | U795: 135.05478 | V795: 145.3979 | W795: 144.70383 | X795: 145.09996 | Y795: 663.8597 | Z795: 169.67973 | AA795: 536.2163 | AB795: 546.05615 | AC795: 691.14417 | AD795: 615.1121 | AE795: 799.69885 | AF795: 489.24573 | AG795: 514.9853
A796: TOTAL EXCEEDANCES | B796: =COUNTIF(B$3:B$795,">=1000") -> 664 | C796: =COUNTIF(C$3:C$795,">=1000") -> 558 | D796: =COUNTIF(D$3:D$795,">=1000") -> 633 | E796: =COUNTIF(E$3:E$795,">=1000") -> 663 | F796: =COUNTIF(F$3:F$795,">=1000") -> 656 | G796: =COUNTIF(G$3:G$795,">=1000") -> 630 | H796: =COUNTIF(H$3:H$795,">=1000") -> 623 | I796: =COUNTIF(I$3:I$795,">=1000") -> 656 | ... AG796: =COUNTIF(AG$3:AG$795,">=1000") -> 0
A797: WET 1 | B797: =COUNTIF(B$3:B$184,">=1000") -> 144 | C797: =COUNTIF(C$3:C$184,">=1000") -> 103 | D797: =COUNTIF(D$3:D$184,">=1000") -> 115 | E797: =COUNTIF(E$3:E$184,">=1000") -> 142 | F797: =COUNTIF(F$3:F$184,">=1000") -> 132 | G797: =COUNTIF(G$3:G$184,">=1000") -> 112 | H797: =COUNTIF(H$3:H$184,">=1000") -> 107 | I797: =COUNTIF(I$3:I$184,">=1000") -> 122 | ... AG797: =COUNTIF(AG$3:AG$184,">=1000") -> 0 | AH797: OCT 2018 - MARCH 2019
A798: WET 2 | B798: =COUNTIF(B$368:B$550,">=1000") -> 183 | C798: =COUNTIF(C$368:C$550,">=1000") -> 157 | D798: =COUNTIF(D$368:D$550,">=1000") -> 183 | E798: =COUNTIF(E$368:E$550,">=1000") -> 183 | F798: =COUNTIF(F$368:F$550,">=1000") -> 183 | G798: =COUNTIF(G$368:G$550,">=1000") -> 183 | H798: =COUNTIF(H$368:H$550,">=1000") -> 182 | I798: =COUNTIF(I$368:I$550,">=1000") -> 183 | ... AG798: =COUNTIF(AG$368:AG$550,">=1000") -> 0 | AH798: OCT 2019 - MARCH 2020
A799: DRY 1 | B799: =COUNTIF(B$185:B$367,">=1000") -> 92 | C799: =COUNTIF(C$185:C$367,">=1000") -> 72 | D799: =COUNTIF(D$185:D$367,">=1000") -> 90 | E799: =COUNTIF(E$185:E$367,">=1000") -> 93 | F799: =COUNTIF(F$185:F$367,">=1000") -> 96 | G799: =COUNTIF(G$185:G$367,">=1000") -> 90 | H799: =COUNTIF(H$185:H$367,">=1000") -> 89 | I799: =COUNTIF(I$185:I$367,">=1000") -> 106 | ... AG799: =COUNTIF(AG$185:AG$367,">=1000") -> 0 | AH799: APRIL 2019 - SEPTEMBER 2019
