Workbook

Sheet Overall
Y1: Notes: 1. Exceedances are lowest in Suisun and highest in the South Delta during dry-season activity windows: Day Use and Boating. Angling has the highest dry-season exceedance rate (83% Delta-wide) and Waterfowl the lowest (28%). 2. Scenario rankings (-5 to 5 vs. Historical Baseline) stay between -2 and +2, with most region and activity combinations scoring 0. Suisun shows the most movement: over the total run, both +30% and -10% Outflow score -1 (about 1% more exceedances than baseline) for Day Use and Boating, Birding, and Angling, while Day Use improves (+1 under both). +30% Outflow deviates from baseline more often than -10% Outflow, particularly in dry seasons, where it scores -1 Delta-wide for Day Use and Boating, Birding, and Angling. Waterfowl's only total-run shift is a +1 for +30% Outflow in the South Delta. 3. Under seasonality analysis, dry seasons exceed thresholds far more often than wet seasons for Day Use and Boating (80% vs. 9% Delta-wide), Birding (71% vs. 5%), Waterfowl (28% vs. <1%), and Angling (83% vs. 11%). Day Use is again inverted, exceeding 88% of the time in wet seasons vs. 14% in dry seasons.
C2: TOTAL RUN SCORES | I2: WET SEASON SCORES | O2: DRY SEASON SCORES
D3: REGION | E3: Historical Baseline | F3: +30% Outflow | G3: -10% Outflow | J3: REGION | K3: Historical Baseline | L3: +30% Outflow | M3: -10% Outflow | P3: REGION | Q3: Historical Baseline | R3: +30% Outflow | S3: -10% Outflow
C4: SP DAY USE & BOATING | D4: Delta-Wide | E4: =-MAX(-5,MIN(5,ROUND((D$39-D$39)*100,0))) -> 0 | F4: =-MAX(-5,MIN(5,ROUND((D$48-D$39)*100,0))) -> 0 | G4: =-MAX(-5,MIN(5,ROUND((D$57-D$39)*100,0))) -> 0 | I4: SP DAY USE & BOATING | J4: Delta-Wide | K4: =-MAX(-5,MIN(5,ROUND((I$39-I$39)*100,0))) -> 0 | L4: =-MAX(-5,MIN(5,ROUND((I$48-I$39)*100,0))) -> 0 | M4: =-MAX(-5,MIN(5,ROUND((I$57-I$39)*100,0))) -> 0 | O4: SP DAY USE & BOATING | P4: Delta-Wide | Q4: =-MAX(-5,MIN(5,ROUND((N$39-N$39)*100,0))) -> 0 | R4: =-MAX(-5,MIN(5,ROUND((N$48-N$39)*100,0))) -> -1 | S4: =-MAX(-5,MIN(5,ROUND((N$57-N$39)*100,0))) -> 0
D5: Suisun | E5: =-MAX(-5,MIN(5,ROUND((E$39-E$39)*100,0))) -> 0 | F5: =-MAX(-5,MIN(5,ROUND((E$48-E$39)*100,0))) -> -1 | G5: =-MAX(-5,MIN(5,ROUND((E$57-E$39)*100,0))) -> -1 | J5: Suisun | K5: =-MAX(-5,MIN(5,ROUND((J$39-J$39)*100,0))) -> 0 | L5: =-MAX(-5,MIN(5,ROUND((J$48-J$39)*100,0))) -> 0 | M5: =-MAX(-5,MIN(5,ROUND((J$57-J$39)*100,0))) -> 0 | P5: Suisun | Q5: =-MAX(-5,MIN(5,ROUND((O$39-O$39)*100,0))) -> 0 | R5: =-MAX(-5,MIN(5,ROUND((O$48-O$39)*100,0))) -> -2 | S5: =-MAX(-5,MIN(5,ROUND((O$57-O$39)*100,0))) -> -1
D6: Central | E6: =-MAX(-5,MIN(5,ROUND((F$39-F$39)*100,0))) -> 0 | F6: =-MAX(-5,MIN(5,ROUND((F$48-F$39)*100,0))) -> 0 | G6: =-MAX(-5,MIN(5,ROUND((F$57-F$39)*100,0))) -> 0 | J6: Central | K6: =-MAX(-5,MIN(5,ROUND((K$39-K$39)*100,0))) -> 0 | L6: =-MAX(-5,MIN(5,ROUND((K$48-K$39)*100,0))) -> 0 | M6: =-MAX(-5,MIN(5,ROUND((K$57-K$39)*100,0))) -> 0 | P6: Central | Q6: =-MAX(-5,MIN(5,ROUND((P$39-P$39)*100,0))) -> 0 | R6: =-MAX(-5,MIN(5,ROUND((P$48-P$39)*100,0))) -> -1 | S6: =-MAX(-5,MIN(5,ROUND((P$57-P$39)*100,0))) -> 0
D7: North | E7: =-MAX(-5,MIN(5,ROUND((G$39-G$39)*100,0))) -> 0 | F7: =-MAX(-5,MIN(5,ROUND((G$48-G$39)*100,0))) -> 0 | G7: =-MAX(-5,MIN(5,ROUND((G$57-G$39)*100,0))) -> 0 | J7: North | K7: =-MAX(-5,MIN(5,ROUND((L$39-L$39)*100,0))) -> 0 | L7: =-MAX(-5,MIN(5,ROUND((L$48-L$39)*100,0))) -> 1 | M7: =-MAX(-5,MIN(5,ROUND((L$57-L$39)*100,0))) -> -1 | P7: North | Q7: =-MAX(-5,MIN(5,ROUND((Q$39-Q$39)*100,0))) -> 0 | R7: =-MAX(-5,MIN(5,ROUND((Q$48-Q$39)*100,0))) -> 0 | S7: =-MAX(-5,MIN(5,ROUND((Q$57-Q$39)*100,0))) -> 0
D8: South | E8: =-MAX(-5,MIN(5,ROUND((H$39-H$39)*100,0))) -> 0 | F8: =-MAX(-5,MIN(5,ROUND((H$48-H$39)*100,0))) -> 0 | G8: =-MAX(-5,MIN(5,ROUND((H$57-H$39)*100,0))) -> 0 | J8: South | K8: =-MAX(-5,MIN(5,ROUND((M$39-M$39)*100,0))) -> 0 | L8: =-MAX(-5,MIN(5,ROUND((M$48-M$39)*100,0))) -> 0 | M8: =-MAX(-5,MIN(5,ROUND((M$57-M$39)*100,0))) -> 0 | P8: South | Q8: =-MAX(-5,MIN(5,ROUND((R$39-R$39)*100,0))) -> 0 | R8: =-MAX(-5,MIN(5,ROUND((R$48-R$39)*100,0))) -> 0 | S8: =-MAX(-5,MIN(5,ROUND((R$57-R$39)*100,0))) -> 0
D9: REGION | E9: Historical Baseline | F9: +30% Outflow | G9: -10% Outflow | J9: REGION | K9: Historical Baseline | L9: +30% Outflow | M9: -10% Outflow | P9: REGION | Q9: Historical Baseline | R9: +30% Outflow | S9: -10% Outflow
C10: BIRDING | D10: Delta-Wide | E10: =-MAX(-5,MIN(5,ROUND((D$40-D$40)*100,0))) -> 0 | F10: =-MAX(-5,MIN(5,ROUND((D$49-D$40)*100,0))) -> 0 | G10: =-MAX(-5,MIN(5,ROUND((D$58-D$40)*100,0))) -> 0 | I10: BIRDING | J10: Delta-Wide | K10: =-MAX(-5,MIN(5,ROUND((I$40-I$40)*100,0))) -> 0 | L10: =-MAX(-5,MIN(5,ROUND((I$49-I$40)*100,0))) -> 0 | M10: =-MAX(-5,MIN(5,ROUND((I$58-I$40)*100,0))) -> 0 | O10: BIRDING | P10: Delta-Wide | Q10: =-MAX(-5,MIN(5,ROUND((N$40-N$40)*100,0))) -> 0 | R10: =-MAX(-5,MIN(5,ROUND((N$49-N$40)*100,0))) -> -1 | S10: =-MAX(-5,MIN(5,ROUND((N$58-N$40)*100,0))) -> 0
D11: Suisun | E11: =-MAX(-5,MIN(5,ROUND((E$40-E$40)*100,0))) -> 0 | F11: =-MAX(-5,MIN(5,ROUND((E$49-E$40)*100,0))) -> -1 | G11: =-MAX(-5,MIN(5,ROUND((E$58-E$40)*100,0))) -> -1 | J11: Suisun | K11: =-MAX(-5,MIN(5,ROUND((J$40-J$40)*100,0))) -> 0 | L11: =-MAX(-5,MIN(5,ROUND((J$49-J$40)*100,0))) -> 0 | M11: =-MAX(-5,MIN(5,ROUND((J$58-J$40)*100,0))) -> 0 | P11: Suisun | Q11: =-MAX(-5,MIN(5,ROUND((O$40-O$40)*100,0))) -> 0 | R11: =-MAX(-5,MIN(5,ROUND((O$49-O$40)*100,0))) -> -2 | S11: =-MAX(-5,MIN(5,ROUND((O$58-O$40)*100,0))) -> -2
D12: Central | E12: =-MAX(-5,MIN(5,ROUND((F$40-F$40)*100,0))) -> 0 | F12: =-MAX(-5,MIN(5,ROUND((F$49-F$40)*100,0))) -> 0 | G12: =-MAX(-5,MIN(5,ROUND((F$58-F$40)*100,0))) -> 0 | J12: Central | K12: =-MAX(-5,MIN(5,ROUND((K$40-K$40)*100,0))) -> 0 | L12: =-MAX(-5,MIN(5,ROUND((K$49-K$40)*100,0))) -> 1 | M12: =-MAX(-5,MIN(5,ROUND((K$58-K$40)*100,0))) -> 0 | P12: Central | Q12: =-MAX(-5,MIN(5,ROUND((P$40-P$40)*100,0))) -> 0 | R12: =-MAX(-5,MIN(5,ROUND((P$49-P$40)*100,0))) -> 0 | S12: =-MAX(-5,MIN(5,ROUND((P$58-P$40)*100,0))) -> 0
D13: North | E13: =-MAX(-5,MIN(5,ROUND((G$40-G$40)*100,0))) -> 0 | F13: =-MAX(-5,MIN(5,ROUND((G$49-G$40)*100,0))) -> 0 | G13: =-MAX(-5,MIN(5,ROUND((G$58-G$40)*100,0))) -> 0 | J13: North | K13: =-MAX(-5,MIN(5,ROUND((L$40-L$40)*100,0))) -> 0 | L13: =-MAX(-5,MIN(5,ROUND((L$49-L$40)*100,0))) -> 0 | M13: =-MAX(-5,MIN(5,ROUND((L$58-L$40)*100,0))) -> 0 | P13: North | Q13: =-MAX(-5,MIN(5,ROUND((Q$40-Q$40)*100,0))) -> 0 | R13: =-MAX(-5,MIN(5,ROUND((Q$49-Q$40)*100,0))) -> 0 | S13: =-MAX(-5,MIN(5,ROUND((Q$58-Q$40)*100,0))) -> 0
D14: South | E14: =-MAX(-5,MIN(5,ROUND((H$40-H$40)*100,0))) -> 0 | F14: =-MAX(-5,MIN(5,ROUND((H$49-H$40)*100,0))) -> 0 | G14: =-MAX(-5,MIN(5,ROUND((H$58-H$40)*100,0))) -> 0 | J14: South | K14: =-MAX(-5,MIN(5,ROUND((M$40-M$40)*100,0))) -> 0 | L14: =-MAX(-5,MIN(5,ROUND((M$49-M$40)*100,0))) -> 0 | M14: =-MAX(-5,MIN(5,ROUND((M$58-M$40)*100,0))) -> 0 | P14: South | Q14: =-MAX(-5,MIN(5,ROUND((R$40-R$40)*100,0))) -> 0 | R14: =-MAX(-5,MIN(5,ROUND((R$49-R$40)*100,0))) -> 0 | S14: =-MAX(-5,MIN(5,ROUND((R$58-R$40)*100,0))) -> 0
D15: REGION | E15: Historical Baseline | F15: +30% Outflow | G15: -10% Outflow | J15: REGION | K15: Historical Baseline | L15: +30% Outflow | M15: -10% Outflow | P15: REGION | Q15: Historical Baseline | R15: +30% Outflow | S15: -10% Outflow
C16: WATERFOWL | D16: Delta-Wide | E16: =-MAX(-5,MIN(5,ROUND((D$41-D$41)*100,0))) -> 0 | F16: =-MAX(-5,MIN(5,ROUND((D$50-D$41)*100,0))) -> 0 | G16: =-MAX(-5,MIN(5,ROUND((D$59-D$41)*100,0))) -> 0 | I16: WATERFOWL | J16: Delta-Wide | K16: =-MAX(-5,MIN(5,ROUND((I$41-I$41)*100,0))) -> 0 | L16: =-MAX(-5,MIN(5,ROUND((I$50-I$41)*100,0))) -> 0 | M16: =-MAX(-5,MIN(5,ROUND((I$59-I$41)*100,0))) -> 0 | O16: WATERFOWL | P16: Delta-Wide | Q16: =-MAX(-5,MIN(5,ROUND((N$41-N$41)*100,0))) -> 0 | R16: =-MAX(-5,MIN(5,ROUND((N$50-N$41)*100,0))) -> 0 | S16: =-MAX(-5,MIN(5,ROUND((N$59-N$41)*100,0))) -> 0
D17: Suisun | E17: =-MAX(-5,MIN(5,ROUND((E$41-E$41)*100,0))) -> 0 | F17: =-MAX(-5,MIN(5,ROUND((E$50-E$41)*100,0))) -> 0 | G17: =-MAX(-5,MIN(5,ROUND((E$59-E$41)*100,0))) -> 0 | J17: Suisun | K17: =-MAX(-5,MIN(5,ROUND((J$41-J$41)*100,0))) -> 0 | L17: =-MAX(-5,MIN(5,ROUND((J$50-J$41)*100,0))) -> 0 | M17: =-MAX(-5,MIN(5,ROUND((J$59-J$41)*100,0))) -> 0 | P17: Suisun | Q17: =-MAX(-5,MIN(5,ROUND((O$41-O$41)*100,0))) -> 0 | R17: =-MAX(-5,MIN(5,ROUND((O$50-O$41)*100,0))) -> 0 | S17: =-MAX(-5,MIN(5,ROUND((O$59-O$41)*100,0))) -> 0
D18: Central | E18: =-MAX(-5,MIN(5,ROUND((F$41-F$41)*100,0))) -> 0 | F18: =-MAX(-5,MIN(5,ROUND((F$50-F$41)*100,0))) -> 0 | G18: =-MAX(-5,MIN(5,ROUND((F$59-F$41)*100,0))) -> 0 | J18: Central | K18: =-MAX(-5,MIN(5,ROUND((K$41-K$41)*100,0))) -> 0 | L18: =-MAX(-5,MIN(5,ROUND((K$50-K$41)*100,0))) -> 0 | M18: =-MAX(-5,MIN(5,ROUND((K$59-K$41)*100,0))) -> 0 | P18: Central | Q18: =-MAX(-5,MIN(5,ROUND((P$41-P$41)*100,0))) -> 0 | R18: =-MAX(-5,MIN(5,ROUND((P$50-P$41)*100,0))) -> 0 | S18: =-MAX(-5,MIN(5,ROUND((P$59-P$41)*100,0))) -> 0
D19: North | E19: =-MAX(-5,MIN(5,ROUND((G$41-G$41)*100,0))) -> 0 | F19: =-MAX(-5,MIN(5,ROUND((G$50-G$41)*100,0))) -> 0 | G19: =-MAX(-5,MIN(5,ROUND((G$59-G$41)*100,0))) -> 0 | J19: North | K19: =-MAX(-5,MIN(5,ROUND((L$41-L$41)*100,0))) -> 0 | L19: =-MAX(-5,MIN(5,ROUND((L$50-L$41)*100,0))) -> 0 | M19: =-MAX(-5,MIN(5,ROUND((L$59-L$41)*100,0))) -> 0 | P19: North | Q19: =-MAX(-5,MIN(5,ROUND((Q$41-Q$41)*100,0))) -> 0 | R19: =-MAX(-5,MIN(5,ROUND((Q$50-Q$41)*100,0))) -> 0 | S19: =-MAX(-5,MIN(5,ROUND((Q$59-Q$41)*100,0))) -> 1
D20: South | E20: =-MAX(-5,MIN(5,ROUND((H$41-H$41)*100,0))) -> 0 | F20: =-MAX(-5,MIN(5,ROUND((H$50-H$41)*100,0))) -> 1 | G20: =-MAX(-5,MIN(5,ROUND((H$59-H$41)*100,0))) -> 0 | J20: South | K20: =-MAX(-5,MIN(5,ROUND((M$41-M$41)*100,0))) -> 0 | L20: =-MAX(-5,MIN(5,ROUND((M$50-M$41)*100,0))) -> 0 | M20: =-MAX(-5,MIN(5,ROUND((M$59-M$41)*100,0))) -> 0 | P20: South | Q20: =-MAX(-5,MIN(5,ROUND((R$41-R$41)*100,0))) -> 0 | R20: =-MAX(-5,MIN(5,ROUND((R$50-R$41)*100,0))) -> 1 | S20: =-MAX(-5,MIN(5,ROUND((R$59-R$41)*100,0))) -> 0
D21: REGION | E21: Historical Baseline | F21: +30% Outflow | G21: -10% Outflow | J21: REGION | K21: Historical Baseline | L21: +30% Outflow | M21: -10% Outflow | P21: REGION | Q21: Historical Baseline | R21: +30% Outflow | S21: -10% Outflow
C22: ANGLING | D22: Delta-Wide | E22: =-MAX(-5,MIN(5,ROUND((D$42-D$42)*100,0))) -> 0 | F22: =-MAX(-5,MIN(5,ROUND((D$51-D$42)*100,0))) -> 0 | G22: =-MAX(-5,MIN(5,ROUND((D$60-D$42)*100,0))) -> 0 | I22: ANGLING | J22: Delta-Wide | K22: =-MAX(-5,MIN(5,ROUND((I$42-I$42)*100,0))) -> 0 | L22: =-MAX(-5,MIN(5,ROUND((I$51-I$42)*100,0))) -> 0 | M22: =-MAX(-5,MIN(5,ROUND((I$60-I$42)*100,0))) -> 0 | O22: ANGLING | P22: Delta-Wide | Q22: =-MAX(-5,MIN(5,ROUND((N$42-N$42)*100,0))) -> 0 | R22: =-MAX(-5,MIN(5,ROUND((N$51-N$42)*100,0))) -> -1 | S22: =-MAX(-5,MIN(5,ROUND((N$60-N$42)*100,0))) -> 0
D23: Suisun | E23: =-MAX(-5,MIN(5,ROUND((E$42-E$42)*100,0))) -> 0 | F23: =-MAX(-5,MIN(5,ROUND((E$51-E$42)*100,0))) -> -1 | G23: =-MAX(-5,MIN(5,ROUND((E$60-E$42)*100,0))) -> -1 | J23: Suisun | K23: =-MAX(-5,MIN(5,ROUND((J$42-J$42)*100,0))) -> 0 | L23: =-MAX(-5,MIN(5,ROUND((J$51-J$42)*100,0))) -> 0 | M23: =-MAX(-5,MIN(5,ROUND((J$60-J$42)*100,0))) -> 0 | P23: Suisun | Q23: =-MAX(-5,MIN(5,ROUND((O$42-O$42)*100,0))) -> 0 | R23: =-MAX(-5,MIN(5,ROUND((O$51-O$42)*100,0))) -> -1 | S23: =-MAX(-5,MIN(5,ROUND((O$60-O$42)*100,0))) -> -1
D24: Central | E24: =-MAX(-5,MIN(5,ROUND((F$42-F$42)*100,0))) -> 0 | F24: =-MAX(-5,MIN(5,ROUND((F$51-F$42)*100,0))) -> 0 | G24: =-MAX(-5,MIN(5,ROUND((F$60-F$42)*100,0))) -> 0 | J24: Central | K24: =-MAX(-5,MIN(5,ROUND((K$42-K$42)*100,0))) -> 0 | L24: =-MAX(-5,MIN(5,ROUND((K$51-K$42)*100,0))) -> 0 | M24: =-MAX(-5,MIN(5,ROUND((K$60-K$42)*100,0))) -> 0 | P24: Central | Q24: =-MAX(-5,MIN(5,ROUND((P$42-P$42)*100,0))) -> 0 | R24: =-MAX(-5,MIN(5,ROUND((P$51-P$42)*100,0))) -> -1 | S24: =-MAX(-5,MIN(5,ROUND((P$60-P$42)*100,0))) -> 0
D25: North | E25: =-MAX(-5,MIN(5,ROUND((G$42-G$42)*100,0))) -> 0 | F25: =-MAX(-5,MIN(5,ROUND((G$51-G$42)*100,0))) -> 0 | G25: =-MAX(-5,MIN(5,ROUND((G$60-G$42)*100,0))) -> 0 | J25: North | K25: =-MAX(-5,MIN(5,ROUND((L$42-L$42)*100,0))) -> 0 | L25: =-MAX(-5,MIN(5,ROUND((L$51-L$42)*100,0))) -> 1 | M25: =-MAX(-5,MIN(5,ROUND((L$60-L$42)*100,0))) -> 0 | P25: North | Q25: =-MAX(-5,MIN(5,ROUND((Q$42-Q$42)*100,0))) -> 0 | R25: =-MAX(-5,MIN(5,ROUND((Q$51-Q$42)*100,0))) -> -1 | S25: =-MAX(-5,MIN(5,ROUND((Q$60-Q$42)*100,0))) -> 0
D26: South | E26: =-MAX(-5,MIN(5,ROUND((H$42-H$42)*100,0))) -> 0 | F26: =-MAX(-5,MIN(5,ROUND((H$51-H$42)*100,0))) -> 0 | G26: =-MAX(-5,MIN(5,ROUND((H$60-H$42)*100,0))) -> 0 | J26: South | K26: =-MAX(-5,MIN(5,ROUND((M$42-M$42)*100,0))) -> 0 | L26: =-MAX(-5,MIN(5,ROUND((M$51-M$42)*100,0))) -> 0 | M26: =-MAX(-5,MIN(5,ROUND((M$60-M$42)*100,0))) -> 0 | P26: South | Q26: =-MAX(-5,MIN(5,ROUND((R$42-R$42)*100,0))) -> 0 | R26: =-MAX(-5,MIN(5,ROUND((R$51-R$42)*100,0))) -> 0 | S26: =-MAX(-5,MIN(5,ROUND((R$60-R$42)*100,0))) -> 0
D27: REGION | E27: Historical Baseline | F27: +30% Outflow | G27: -10% Outflow | J27: REGION | K27: Historical Baseline | L27: +30% Outflow | M27: -10% Outflow | P27: REGION | Q27: Historical Baseline | R27: +30% Outflow | S27: -10% Outflow
C28: DAY USE | D28: Delta-Wide | E28: =-MAX(-5,MIN(5,ROUND((D$43-D$43)*100,0))) -> 0 | F28: =-MAX(-5,MIN(5,ROUND((D$52-D$43)*100,0))) -> 0 | G28: =-MAX(-5,MIN(5,ROUND((D$61-D$43)*100,0))) -> 0 | I28: DAY USE | J28: Delta-Wide | K28: =-MAX(-5,MIN(5,ROUND((I$43-I$43)*100,0))) -> 0 | L28: =-MAX(-5,MIN(5,ROUND((I$52-I$43)*100,0))) -> 0 | M28: =-MAX(-5,MIN(5,ROUND((I$61-I$43)*100,0))) -> 0 | O28: DAY USE | P28: Delta-Wide | Q28: =-MAX(-5,MIN(5,ROUND((N$43-N$43)*100,0))) -> 0 | R28: =-MAX(-5,MIN(5,ROUND((N$52-N$43)*100,0))) -> 1 | S28: =-MAX(-5,MIN(5,ROUND((N$61-N$43)*100,0))) -> 0
D29: Suisun | E29: =-MAX(-5,MIN(5,ROUND((E$43-E$43)*100,0))) -> 0 | F29: =-MAX(-5,MIN(5,ROUND((E$52-E$43)*100,0))) -> 1 | G29: =-MAX(-5,MIN(5,ROUND((E$61-E$43)*100,0))) -> 1 | J29: Suisun | K29: =-MAX(-5,MIN(5,ROUND((J$43-J$43)*100,0))) -> 0 | L29: =-MAX(-5,MIN(5,ROUND((J$52-J$43)*100,0))) -> 0 | M29: =-MAX(-5,MIN(5,ROUND((J$61-J$43)*100,0))) -> 0 | P29: Suisun | Q29: =-MAX(-5,MIN(5,ROUND((O$43-O$43)*100,0))) -> 0 | R29: =-MAX(-5,MIN(5,ROUND((O$52-O$43)*100,0))) -> 2 | S29: =-MAX(-5,MIN(5,ROUND((O$61-O$43)*100,0))) -> 1
D30: Central | E30: =-MAX(-5,MIN(5,ROUND((F$43-F$43)*100,0))) -> 0 | F30: =-MAX(-5,MIN(5,ROUND((F$52-F$43)*100,0))) -> 0 | G30: =-MAX(-5,MIN(5,ROUND((F$61-F$43)*100,0))) -> 0 | J30: Central | K30: =-MAX(-5,MIN(5,ROUND((K$43-K$43)*100,0))) -> 0 | L30: =-MAX(-5,MIN(5,ROUND((K$52-K$43)*100,0))) -> 0 | M30: =-MAX(-5,MIN(5,ROUND((K$61-K$43)*100,0))) -> 0 | P30: Central | Q30: =-MAX(-5,MIN(5,ROUND((P$43-P$43)*100,0))) -> 0 | R30: =-MAX(-5,MIN(5,ROUND((P$52-P$43)*100,0))) -> 0 | S30: =-MAX(-5,MIN(5,ROUND((P$61-P$43)*100,0))) -> 0
D31: North | E31: =-MAX(-5,MIN(5,ROUND((G$43-G$43)*100,0))) -> 0 | F31: =-MAX(-5,MIN(5,ROUND((G$52-G$43)*100,0))) -> 0 | G31: =-MAX(-5,MIN(5,ROUND((G$61-G$43)*100,0))) -> 0 | J31: North | K31: =-MAX(-5,MIN(5,ROUND((L$43-L$43)*100,0))) -> 0 | L31: =-MAX(-5,MIN(5,ROUND((L$52-L$43)*100,0))) -> 0 | M31: =-MAX(-5,MIN(5,ROUND((L$61-L$43)*100,0))) -> 0 | P31: North | Q31: =-MAX(-5,MIN(5,ROUND((Q$43-Q$43)*100,0))) -> 0 | R31: =-MAX(-5,MIN(5,ROUND((Q$52-Q$43)*100,0))) -> 1 | S31: =-MAX(-5,MIN(5,ROUND((Q$61-Q$43)*100,0))) -> 0
D32: South | E32: =-MAX(-5,MIN(5,ROUND((H$43-H$43)*100,0))) -> 0 | F32: =-MAX(-5,MIN(5,ROUND((H$52-H$43)*100,0))) -> 0 | G32: =-MAX(-5,MIN(5,ROUND((H$61-H$43)*100,0))) -> 0 | J32: South | K32: =-MAX(-5,MIN(5,ROUND((M$43-M$43)*100,0))) -> 0 | L32: =-MAX(-5,MIN(5,ROUND((M$52-M$43)*100,0))) -> 0 | M32: =-MAX(-5,MIN(5,ROUND((M$61-M$43)*100,0))) -> 0 | P32: South | Q32: =-MAX(-5,MIN(5,ROUND((R$43-R$43)*100,0))) -> 0 | R32: =-MAX(-5,MIN(5,ROUND((R$52-R$43)*100,0))) -> 0 | S32: =-MAX(-5,MIN(5,ROUND((R$61-R$43)*100,0))) -> 0
C36: RUN 15 % EXCEEDANCES
D37: Total Run | I37: Wet Seasons | N37: Dry Seasons
D38: Delta-Wide | E38: Suisun | F38: Central Delta | G38: North Delta | H38: South Delta | I38: Delta-Wide | J38: Suisun | K38: Central Delta | L38: North Delta | M38: South Delta | N38: Delta-Wide | O38: Suisun | P38: Central Delta | Q38: North Delta | R38: South Delta
C39: Day Use & Boating | D39: ='Run 15 Temp'!AK527 -> 0.41441552 | E39: ='Run 15 Temp'!AL527 -> 0.37033399 | F39: ='Run 15 Temp'!AM527 -> 0.43418468 | G39: ='Run 15 Temp'!AN527 -> 0.39980354 | H39: ='Run 15 Temp'!AO527 -> 0.44357127 | I39: ='Run 15 Temp'!AS527 -> 0.090568182 | J39: ='Run 15 Temp'!AT527 -> 0.084545455 | K39: ='Run 15 Temp'!AU527 -> 0.11070707 | L39: ='Run 15 Temp'!AV527 -> 0.046666667 | M39: ='Run 15 Temp'!AW527 -> 0.10505051 | N39: ='Run 15 Temp'!BA527 -> 0.79500534 | O39: ='Run 15 Temp'!BB527 -> 0.70619658 | P39: ='Run 15 Temp'!BC527 -> 0.81433998 | Q39: ='Run 15 Temp'!BD527 -> 0.81481481 | R39: ='Run 15 Temp'!BE527 -> 0.84140551
C40: Birding | D40: ='Run 15 Temp'!AK544 -> 0.35025786 | E40: ='Run 15 Temp'!AL544 -> 0.27946955 | F40: ='Run 15 Temp'!AM544 -> 0.37349924 | G40: ='Run 15 Temp'!AN544 -> 0.33791749 | H40: ='Run 15 Temp'!AO544 -> 0.39816634 | I40: ='Run 15 Temp'!AS544 -> 0.046363636 | J40: ='Run 15 Temp'!AT544 -> 0.025454545 | K40: ='Run 15 Temp'!AU544 -> 0.054949495 | L40: ='Run 15 Temp'!AV544 -> 0.016969697 | M40: ='Run 15 Temp'!AW544 -> 0.075959596 | N40: ='Run 15 Temp'!BA544 -> 0.7073985 | O40: ='Run 15 Temp'!BB544 -> 0.57799145 | P40: ='Run 15 Temp'!BC544 -> 0.74786325 | Q40: ='Run 15 Temp'!BD544 -> 0.71509972 | R40: ='Run 15 Temp'!BE544 -> 0.77682811
C41: Waterfowl | D41: ='Run 15 Temp'!AK561 -> 0.12794695 | E41: ='Run 15 Temp'!AL561 -> 0.014734774 | F41: ='Run 15 Temp'!AM561 -> 0.11831478 | G41: ='Run 15 Temp'!AN561 -> 0.11198428 | H41: ='Run 15 Temp'!AO561 -> 0.24885396 | I41: ='Run 15 Temp'!AS561 -> 0.0019318182 | J41: ='Run 15 Temp'!AT561 -> 0 | K41: ='Run 15 Temp'!AU561 -> 0 | L41: ='Run 15 Temp'!AV561 -> 0 | M41: ='Run 15 Temp'!AW561 -> 0.0068686869 | N41: ='Run 15 Temp'!BA561 -> 0.27604167 | O41: ='Run 15 Temp'!BB561 -> 0.032051282 | P41: ='Run 15 Temp'!BC561 -> 0.25735992 | Q41: ='Run 15 Temp'!BD561 -> 0.24358974 | R41: ='Run 15 Temp'!BE561 -> 0.53323837
C42: Angling | D42: ='Run 15 Temp'!AK578 -> 0.4410609 | E42: ='Run 15 Temp'!AL578 -> 0.40643418 | F42: ='Run 15 Temp'!AM578 -> 0.45426763 | G42: ='Run 15 Temp'!AN578 -> 0.43123772 | H42: ='Run 15 Temp'!AO578 -> 0.46518227 | I42: ='Run 15 Temp'!AS578 -> 0.10613636 | J42: ='Run 15 Temp'!AT578 -> 0.099545455 | K42: ='Run 15 Temp'!AU578 -> 0.12121212 | L42: ='Run 15 Temp'!AV578 -> 0.078181818 | M42: ='Run 15 Temp'!AW578 -> 0.11555556 | N42: ='Run 15 Temp'!BA578 -> 0.8346688 | O42: ='Run 15 Temp'!BB578 -> 0.76709402 | P42: ='Run 15 Temp'!BC578 -> 0.84567901 | Q42: ='Run 15 Temp'!BD578 -> 0.84615385 | R42: ='Run 15 Temp'!BE578 -> 0.87606838
C43: Day Use | D43: ='Run 15 Temp'!AK595 -> 0.54236248 | E43: ='Run 15 Temp'!AL595 -> 0.57293713 | F43: ='Run 15 Temp'!AM595 -> 0.53285309 | G43: ='Run 15 Temp'!AN595 -> 0.5481336 | H43: ='Run 15 Temp'!AO595 -> 0.52084698 | I43: ='Run 15 Temp'!AS595 -> 0.88477273 | J43: ='Run 15 Temp'!AT595 -> 0.88863636 | K43: ='Run 15 Temp'!AU595 -> 0.87555556 | L43: ='Run 15 Temp'!AV595 -> 0.90363636 | M43: ='Run 15 Temp'!AW595 -> 0.8779798 | N43: ='Run 15 Temp'!BA595 -> 0.13995726 | O43: ='Run 15 Temp'!BB595 -> 0.20192308 | P43: ='Run 15 Temp'!BC595 -> 0.13010446 | Q43: ='Run 15 Temp'!BD595 -> 0.13034188 | R43: ='Run 15 Temp'!BE595 -> 0.1011396
...

Sheet Run 15 Temp
B1: Suisun | J1: Central Delta | S1: North Delta | Y1: South Delta
A2: Date | B2: CHADBOURNE SLOUGH AT SUNRISE DUCK CLUB | C2: MONTEZUMA SLOUGH AT NATIONAL STEEL | D2: MONTEZUMA SLOUGH NEAR BELDENS LANDING | E2: SUISUN SLOUGH 300' SOUTH OF VOLANTI SLOUGH | F2: HONKER BAY | G2: SUISUN BAY AT VAN SICKLE ISLAND | H2: SUISUN BAY WEST REACH | I2: GRIZZLY BAY BUOY | J2: DUTCH SL BELOW JERSEY ISLAND | K2: FALSE RIVER NEAR OAKLEY | L2: OLD RIVER AT FRANKS TRACT | M2: PITTSBURG | N2: SACRAMENTO RIVER AT EMMATON | O2: SAN ANDREAS LANDING | P2: SAN JOAQUIN RIVER AT JERSEY POINT | Q2: SUISUN BAY AT CHANNEL MARKER 5 AT COLLINSVILLE | R2: BRANNAN MARINAS AT SAN JOAQUIN RIVER | S2: LIBERTY CUT AT FIVE POINTS | T2: CACHE SLOUGH ABOVE RYER ISLAND FERRY | U2: DELTA CROSS CHANNEL NEAR WALNUT GROVE | V2: SACRAMENTO RIVER DOWNSTREAM OF ISLETON | W2: COURTLAND AT SACRAMENTO RIVER | X2: VIERAS RESORT AT SACRAMENTO RIVER | Y2: GRANT LINE CANAL NEAR CLIFTON COURT FORE | Z2: LITTLE POTATO SLOUGH AT TERMINOUS | AA2: MIDDLE RIVER AT MILDRED ISLAND | AB2: OLD RIVER AT CLIFTON COURT | AC2: SAN JOAQUIN RIVER AT BRANDT BRIDGE | AD2: SAN JOAQUIN RIVER AT PRISONERS POINT | AE2: SAN JOAQUIN RIVER NEAR VERNALIS | AF2: SAN JOAQUIN RVER AT ROUGH AND READY ISLAND | AG2: VICTORIA CANAL BEFORE CLIFTON COURT FORE
A3: 44054 | B3: 22.560719 | C3: 21.900648 | D3: 22.431389 | E3: 22.658714 | F3: 20.75524 | G3: 21.305857 | H3: 20.295202 | I3: 20.915861 | J3: 23.262445 | K3: 22.902473 | L3: 23.922964 | M3: 21.527151 | N3: 22.213202 | O3: 23.735006 | P3: 22.804567 | Q3: 21.600937 | R3: 23.54745 | S3: 22.026196 | T3: 23.29572 | U3: 23.667978 | V3: 23.213514 | W3: 23.66995 | X3: 23.269175 | Y3: 25.640173 | Z3: 24.26068 | AA3: 25.027071 | AB3: 25.589693 | AC3: 26.869522 | AD3: 24.10965 | AE3: 25.979967 | AF3: 26.154995 | AG3: 25.606325
A4: 44055 | B4: 22.739912 | C4: 22.155111 | D4: 22.397194 | E4: 22.5373 | F4: 21.16598 | G4: 21.157377 | H4: 20.243769 | I4: 20.55503 | J4: 23.011925 | K4: 22.667818 | L4: 23.85344 | M4: 21.424437 | N4: 22.068024 | O4: 23.59082 | P4: 22.581625 | Q4: 21.46926 | R4: 23.378042 | S4: 20.784887 | T4: 22.953972 | U4: 23.724304 | V4: 23.259924 | W4: 23.36482 | X4: 23.422892 | Y4: 25.615448 | Z4: 24.218538 | AA4: 25.272188 | AB4: 25.54409 | AC4: 26.657736 | AD4: 24.079405 | AE4: 25.707533 | AF4: 26.24801 | AG4: 25.345695
A5: 44056 | B5: 23.227676 | C5: 22.35205 | D5: 22.43637 | E5: 22.548384 | F5: 21.408422 | G5: 21.251328 | H5: 20.410093 | I5: 20.448364 | J5: 23.281563 | K5: 22.730005 | L5: 23.942904 | M5: 21.526625 | N5: 22.257273 | O5: 23.713293 | P5: 22.65417 | Q5: 21.508867 | R5: 23.5129 | S5: 20.763334 | T5: 23.121704 | U5: 22.964577 | V5: 23.730822 | W5: 22.521544 | X5: 23.964296 | Y5: 25.698175 | Z5: 24.458727 | AA5: 25.611536 | AB5: 25.637253 | AC5: 26.675486 | AD5: 24.163912 | AE5: 26.152246 | AF5: 26.414827 | AG5: 25.396624
A6: 44057 | B6: 23.840057 | C6: 22.694908 | D6: 22.733244 | E6: 22.770119 | F6: 21.935898 | G6: 21.548586 | H6: 20.724192 | I6: 21.006432 | J6: 24.054495 | K6: 23.0748 | L6: 24.251646 | M6: 21.839668 | N6: 22.685484 | O6: 24.096367 | P6: 22.984106 | Q6: 21.796463 | R6: 23.84558 | S6: 21.776558 | T6: 23.538622 | U6: 23.142832 | V6: 24.154821 | W6: 23.039896 | X6: 24.30001 | Y6: 25.989782 | Z6: 24.861982 | AA6: 25.995596 | AB6: 25.884329 | AC6: 26.967077 | AD6: 24.432518 | AE6: 26.818068 | AF6: 26.646027 | AG6: 25.840902
A7: 44058 | B7: 24.281813 | C7: 23.174995 | D7: 23.204924 | E7: 23.123146 | F7: 22.39657 | G7: 21.97497 | H7: 21.066353 | I7: 21.656698 | J7: 25.029356 | K7: 23.57975 | L7: 24.65758 | M7: 22.225037 | N7: 23.122927 | O7: 24.535685 | P7: 23.482897 | Q7: 22.21683 | R7: 24.237135 | S7: 22.918768 | T7: 23.999128 | U7: 23.634409 | V7: 24.141739 | W7: 23.389128 | X7: 24.08676 | Y7: 26.449183 | Z7: 25.438887 | AA7: 26.462904 | AB7: 26.328062 | AC7: 27.530146 | AD7: 24.795313 | AE7: 27.46213 | AF7: 26.986258 | AG7: 26.443237
A8: 44059 | B8: 24.509966 | C8: 23.590952 | D8: 23.614134 | E8: 23.450705 | F8: 22.67335 | G8: 22.303003 | H8: 21.381083 | I8: 21.962128 | J8: 25.597261 | K8: 23.951654 | L8: 24.969856 | M8: 22.554659 | N8: 23.469828 | O8: 24.815407 | P8: 23.863012 | Q8: 22.559542 | R8: 24.574678 | S8: 23.739466 | T8: 24.3893 | U8: 23.974413 | V8: 24.514875 | W8: 23.712234 | X8: 24.484407 | Y8: 26.965797 | Z8: 25.94053 | AA8: 26.871763 | AB8: 26.808157 | AC8: 28.098 | AD8: 25.131979 | AE8: 28.402702 | AF8: 27.327997 | AG8: 26.940863
A9: 44060 | B9: 24.85507 | C9: 24.0712 | D9: 24.047922 | E9: 23.837427 | F9: 23.09302 | G9: 22.710968 | H9: 21.832273 | I9: 22.50768 | J9: 26.115595 | K9: 24.362688 | L9: 25.32635 | M9: 22.971693 | N9: 23.957277 | O9: 25.136274 | P9: 24.279638 | Q9: 22.98346 | R9: 24.968393 | S9: 24.500174 | T9: 24.861044 | U9: 24.256035 | V9: 24.914984 | W9: 24.048447 | X9: 24.893 | Y9: 27.533842 | Z9: 26.23104 | AA9: 27.23993 | AB9: 27.370674 | AC9: 28.524664 | AD9: 25.48691 | AE9: 28.705622 | AF9: 27.580446 | AG9: 27.304735
A10: 44061 | B10: 25.198141 | C10: 24.541618 | D10: 24.43999 | E10: 24.188673 | F10: 23.452795 | G10: 23.15109 | H10: 22.2083 | I10: 22.917253 | J10: 26.573137 | K10: 24.804052 | L10: 25.70014 | M10: 23.390284 | N10: 24.40564 | O10: 25.495157 | P10: 24.734735 | Q10: 23.429277 | R10: 25.33979 | S10: 25.240845 | T10: 25.318077 | U10: 24.467108 | V10: 25.257345 | W10: 24.110903 | X10: 25.21148 | Y10: 27.936655 | Z10: 26.471693 | AA10: 27.553703 | AB10: 27.739882 | AC10: 28.836077 | AD10: 25.843393 | AE10: 28.104952 | AF10: 27.854095 | AG10: 27.595673
A11: 44062 | B11: 24.848429 | C11: 24.674429 | D11: 24.455687 | E11: 24.129639 | F11: 23.308508 | G11: 23.324371 | H11: 22.266718 | I11: 22.500954 | J11: 26.555681 | K11: 25.001135 | L11: 25.77772 | M11: 23.516459 | N11: 24.49459 | O11: 25.512346 | P11: 24.942802 | Q11: 23.605207 | R11: 25.408295 | S11: 24.888184 | T11: 25.387405 | U11: 24.063833 | V11: 25.26802 | W11: 23.568087 | X11: 25.244326 | Y11: 27.892027 | Z11: 26.448921 | AA11: 27.629526 | AB11: 27.712599 | AC11: 28.84313 | AD11: 25.948568 | AE11: 27.2163 | AF11: 28.002249 | AG11: 27.547499
A12: 44063 | B12: 24.178434 | C12: 24.29785 | D12: 24.039276 | E12: 23.705942 | F12: 22.916418 | G12: 23.134447 | H12: 22.10438 | I12: 21.778498 | J12: 25.513931 | K12: 24.699091 | L12: 25.50866 | M12: 23.276808 | N12: 24.093092 | O12: 25.239153 | P12: 24.659407 | Q12: 23.374428 | R12: 25.20356 | S12: 23.591848 | T12: 24.99254 | U12: 23.215128 | V12: 24.77482 | W12: 22.765879 | X12: 24.729406 | Y12: 27.474554 | Z12: 26.063576 | AA12: 27.376772 | AB12: 27.33925 | AC12: 28.325293 | AD12: 25.762466 | AE12: 25.900314 | AF12: 27.909018 | AG12: 27.241083
A13: 44064 | B13: 24.023169 | C13: 24.157736 | D13: 23.743187 | E13: 23.440458 | F13: 22.88079 | G13: 22.98615 | H13: 21.991135 | I13: 21.557655 | J13: 25.154442 | K13: 24.605589 | L13: 25.368517 | M13: 23.145395 | N13: 23.989935 | O13: 25.104034 | P13: 24.543526 | Q13: 23.240507 | R13: 25.12768 | S13: 22.895178 | T13: 24.628405 | U13: 22.349714 | V13: 24.228182 | W13: 22.040825 | X13: 24.0394 | Y13: 27.106047 | Z13: 25.616209 | AA13: 27.05285 | AB13: 27.036257 | AC13: 27.892324 | AD13: 25.585197 | AE13: 24.465899 | AF13: 27.822348 | AG13: 27.022058
A14: 44065 | B14: 24.176657 | C14: 24.264376 | D14: 23.727865 | E14: 23.485445 | F14: 23.01442 | G14: 23.055857 | H14: 22.03905 | I14: 21.68489 | J14: 25.41903 | K14: 24.70488 | L14: 25.412682 | M14: 23.236748 | N14: 24.180597 | O14: 25.043678 | P14: 24.63443 | Q14: 23.342237 | R14: 25.194723 | S14: 23.060776 | T14: 24.47654 | U14: 21.91371 | V14: 23.761095 | W14: 21.574099 | X14: 23.399553 | Y14: 27.22255 | Z14: 25.366083 | AA14: 27.084555 | AB14: 27.120428 | AC14: 28.017693 | AD14: 25.585375 | AE14: 24.230787 | AF14: 27.908964 | AG14: 27.072287
... A511: 44562 | B511: 7.4037156 | C511: 7.9538527 | D511: 7.816447 | E511: 7.833184 | F511: 8.022569 | G511: 8.187101 | H511: 8.421983 | I511: 7.537015 | J511: 7.2228208 | K511: 8.366747 | L511: 8.070345 | M511: 8.19537 | N511: 7.800579 | O511: 7.9759173 | P511: 8.18126 | Q511: 8.069019 | R511: 8.117914 | S511: 6.850876 | T511: 7.514671 | U511: 7.9121075 | V511: 7.8408065 | W511: 7.801318 | X511: 7.847797 | Y511: 9.836859 | Z511: 8.036249 | AA511: 8.0523205 | AB511: 8.920491 | AC511: 10.871181 | AD511: 8.134985 | AE511: 8.781851 | AF511: 8.149474 | AG511: 7.752743
A512: TOTAL EXCEEDANCES | B512: =COUNTIF(B$3:B$511,">=19") -> 199 | C512: =COUNTIF(C$3:C$511,">=19") -> 204 | D512: =COUNTIF(D$3:D$511,">=19") -> 196 | E512: =COUNTIF(E$3:E$511,">=19") -> 194 | F512: =COUNTIF(F$3:F$511,">=19") -> 198 | G512: =COUNTIF(G$3:G$511,">=19") -> 198 | H512: =COUNTIF(H$3:H$511,">=19") -> 158 | I512: =COUNTIF(I$3:I$511,">=19") -> 161 | ... AG512: =COUNTIF(AG$3:AG$511,">=19") -> 232
A513: WET 1 | B513: =COUNTIF(B$54:B$235,">=19") -> 22 | C513: =COUNTIF(C$54:C$235,">=19") -> 23 | D513: =COUNTIF(D$54:D$235,">=19") -> 23 | E513: =COUNTIF(E$54:E$235,">=19") -> 22 | F513: =COUNTIF(F$54:F$235,">=19") -> 22 | G513: =COUNTIF(G$54:G$235,">=19") -> 23 | H513: =COUNTIF(H$54:H$235,">=19") -> 12 | I513: =COUNTIF(I$54:I$235,">=19") -> 6 | ... AG513: =COUNTIF(AG$54:AG$235,">=19") -> 24 | AH513: OCTOBER 2020 - MARCH 2021
A514: WET 2 | B514: =COUNTIF(B$419:B$511,">=19") -> 5 | C514: =COUNTIF(C$419:C$511,">=19") -> 6 | D514: =COUNTIF(D$419:D$511,">=19") -> 5 | E514: =COUNTIF(E$419:E$511,">=19") -> 4 | F514: =COUNTIF(F$419:F$511,">=19") -> 5 | G514: =COUNTIF(G$419:G$511,">=19") -> 5 | H514: =COUNTIF(H$419:H$511,">=19") -> 0 | I514: =COUNTIF(I$419:I$511,">=19") -> 3 | ... AG514: =COUNTIF(AG$419:AG$511,">=19") -> 8 | AH514: OCTOBER 2021 - JANUARY 2022
A515: DRY 1 | B515: =COUNTIF(B$3:B$53,">=19") -> 51 | C515: =COUNTIF(C$3:C$53,">=19") -> 51 | D515: =COUNTIF(D$3:D$53,">=19") -> 51 | E515: =COUNTIF(E$3:E$53,">=19") -> 51 | F515: =COUNTIF(F$3:F$53,">=19") -> 51 | G515: =COUNTIF(G$3:G$53,">=19") -> 51 | H515: =COUNTIF(H$3:H$53,">=19") -> 51 | I515: =COUNTIF(I$3:I$53,">=19") -> 49 | ... AG515: =COUNTIF(AG$3:AG$53,">=19") -> 51 | AH515: AUGUST 2020 - SEPTEMBER 2020
A516: DRY 2 | B516: =COUNTIF(B$236:B$418,">=19") -> 121 | C516: =COUNTIF(C$236:C$418,">=19") -> 124 | D516: =COUNTIF(D$236:D$418,">=19") -> 117 | E516: =COUNTIF(E$236:E$418,">=19") -> 117 | F516: =COUNTIF(F$236:F$418,">=19") -> 120 | G516: =COUNTIF(G$236:G$418,">=19") -> 119 | H516: =COUNTIF(H$236:H$418,">=19") -> 95 | I516: =COUNTIF(I$236:I$418,">=19") -> 103 | ... AG516: =COUNTIF(AG$236:AG$418,">=19") -> 149 | AH516: APRIL 2021 - SEPTEMBER 2021
A517: ALL WET | B517: =SUM(B$513,B$514) -> 27 | C517: =SUM(C$513,C$514) -> 29 | D517: =SUM(D$513,D$514) -> 28 | E517: =SUM(E$513,E$514) -> 26 | F517: =SUM(F$513,F$514) -> 27 | G517: =SUM(G$513,G$514) -> 28 | H517: =SUM(H$513,H$514) -> 12 | I517: =SUM(I$513,I$514) -> 9 | ... AG517: =SUM(AG$513,AG$514) -> 32
A518: ALL DRY | B518: =SUM(B$515,B$516) -> 172 | C518: =SUM(C$515,C$516) -> 175 | D518: =SUM(D$515,D$516) -> 168 | E518: =SUM(E$515,E$516) -> 168 | F518: =SUM(F$515,F$516) -> 171 | G518: =SUM(G$515,G$516) -> 170 | H518: =SUM(H$515,H$516) -> 146 | I518: =SUM(I$515,I$516) -> 152 | ... AG518: =SUM(AG$515,AG$516) -> 200
D521: Day Use & Boating 19C | F521: THRESHOLD: 19C | S521: SP DAY USE & BOATING | AA521: SP DAY USE & BOATING | AE521: SP DAY USE & BOATING | AI521: SP DAY USE & BOATING | AQ521: SP DAY USE & BOATING | AY521: SP DAY USE & BOATING
F522: WET SEASON | S522: TOTAL RUN | AA522: WET SEASONS | AE522: DRY SEASONS | AI522: TOTAL RUN | AK522: Delta-Wide | AL522: Suisun | AM522: Central Delta | AN522: North Delta | AO522: South Delta | AQ522: WET SEASONS | AS522: Delta-Wide | AT522: Suisun | AU522: Central Delta | AV522: North Delta | AW522: South Delta | AY522: DRY SEASONS | BA522: Delta-Wide | BB522: Suisun | BC522: Central Delta | BD522: North Delta | BE522: South Delta
F523: OCTOBER 1 - MARCH 31 | M523: DRY SEASON | S523: Total points | U523: =COUNTIF(B2:AG2,"<>") -> 32 | AA523: Total points | AC523: =COUNTIF(B2:AG2,"<>") -> 32 | AE523: Total points | AG523: =COUNTIF(B2:AG2,"<>") -> 32 | AI523: Total points | AK523: =COUNTIF($B$2:$AG$2,"<>") -> 32 | AL523: =COUNTIF($B$2:$I$2,"<>") -> 8 | AM523: =COUNTIF($J$2:$R$2,"<>") -> 9 | AN523: =COUNTIF($S$2:$X$2,"<>") -> 6 | AO523: =COUNTIF($Y$2:$AG$2,"<>") -> 9 | AQ523: Total points | AS523: =COUNTIF($B$2:$AG$2,"<>") -> 32 | AT523: =COUNTIF($B$2:$I$2,"<>") -> 8 | AU523: =COUNTIF($J$2:$R$2,"<>") -> 9 | AV523: =COUNTIF($S$2:$X$2,"<>") -> 6 | AW523: =COUNTIF($Y$2:$AG$2,"<>") -> 9 | AY523: Total points | BA523: =COUNTIF($B$2:$AG$2,"<>") -> 32 | BB523: =COUNTIF($B$2:$I$2,"<>") -> 8 | BC523: =COUNTIF($J$2:$R$2,"<>") -> 9 | BD523: =COUNTIF($S$2:$X$2,"<>") -> 6 | BE523: =COUNTIF($Y$2:$AG$2,"<>") -> 9
F524: WET SEASON 1 | H524: 10/1/20 - 3/31/21 | J524: =COUNTIF($B$54:$B$235,"<>") -> 182 | M524: APRIL 1 - SEPTEMBER 30 | S524: Days in run | U524: =COUNTIF($A$3:$A$511,"<>") -> 509 | AA524: Days in run | AC524: =SUM($J$524:$J$525) -> 275 | AE524: Days in run | AG524: =SUM($Q$525:$Q$526) -> 234 | AI524: Days in run | AK524: =COUNTIF($A$3:$A$511,"<>") -> 509 | AL524: =COUNTIF($A$3:$A$511,"<>") -> 509 | AM524: =COUNTIF($A$3:$A$511,"<>") -> 509 | AN524: =COUNTIF($A$3:$A$511,"<>") -> 509 | AO524: =COUNTIF($A$3:$A$511,"<>") -> 509 | AQ524: Days in run | AS524: =SUM($J$524:$J$525) -> 275 | AT524: =SUM($J$524:$J$525) -> 275 | AU524: =SUM($J$524:$J$525) -> 275 | AV524: =SUM($J$524:$J$525) -> 275 | AW524: =SUM($J$524:$J$525) -> 275 | AY524: Days in run | BA524: =SUM($Q$525:$Q$526) -> 234 | BB524: =SUM($Q$525:$Q$526) -> 234 | BC524: =SUM($Q$525:$Q$526) -> 234 | BD524: =SUM($Q$525:$Q$526) -> 234 | BE524: =SUM($Q$525:$Q$526) -> 234
F525: WET SEASON 2 | H525: 10/1/21 - 1/1/22 | J525: =COUNTIF($B$419:$B$511,"<>") -> 93 | M525: DRY SEASON 1 | O525: 8/11/20 - 9/30/20 | Q525: =COUNTIF($B$3:$B$53,"<>") -> 51 | S525: Total measurements | U525: =U524*U523 -> 16288 | V525: DENOMINATOR FOR EXCEEDANCE % | AA525: Total measurements | AC525: =AC524*AC523 -> 8800 | AE525: Total measurements | AG525: =AG523*AG524 -> 7488 | AI525: Total measurements | AK525: =AK524*AK523 -> 16288 | AL525: =AL524*AL523 -> 4072 | AM525: =AM524*AM523 -> 4581 | AN525: =AN524*AN523 -> 3054 | AO525: =AO524*AO523 -> 4581 | AQ525: Total measurements | AS525: =AS524*AS523 -> 8800 | AT525: =AT524*AT523 -> 2200 | AU525: =AU524*AU523 -> 2475 | AV525: =AV524*AV523 -> 1650 | AW525: =AW524*AW523 -> 2475 | AY525: Total measurements | BA525: =BA524*BA523 -> 7488 | BB525: =BB524*BB523 -> 1872 | BC525: =BC524*BC523 -> 2106 | BD525: =BD524*BD523 -> 1404 | BE525: =BE524*BE523 -> 2106
F526: WET SEASON 3 | H526: N/A (outside run period) | J526: =COUNTIF($A$737:$A$798,"<>") -> 0 | M526: DRY SEASON 2 | O526: 4/1/21 - 9/30/21 | Q526: =COUNTIF($B$236:$B$418,"<>") -> 183 | S526: Measurements >= 19C | U526: =SUM(B512:AG512) -> 6750 | V526: NUMERATOR FOR EXCEEDANCE % | AA526: Measurements >= 19C | AC526: =SUM($B$517:$AG$517) -> 797 | AE526: Measurements >= 19C | AG526: =SUM($B$518:$AG$518) -> 5953 | AI526: Measurements >= 19C | AK526: =SUM(B512:AG512) -> 6750 | AL526: =SUM(B512:I512) -> 1508 | AM526: =SUM(J512:R512) -> 1989 | AN526: =SUM(S512:X512) -> 1221 | AO526: =SUM(Y512:AG512) -> 2032 | AQ526: Measurements >= 19C | AS526: =SUM(B517:AG517) -> 797 | AT526: =SUM(B517:I517) -> 186 | AU526: =SUM(J517:R517) -> 274 | AV526: =SUM(S517:X517) -> 77 | AW526: =SUM(Y517:AG517) -> 260 | AY526: Measurements >= 19C | BA526: =SUM($B518:$AG518) -> 5953 | BB526: =SUM(B518:I518) -> 1322 | BC526: =SUM(J518:R518) -> 1715 | BD526: =SUM(S518:X518) -> 1144 | BE526: =SUM(Y518:AG518) -> 1772
S527: % Total Run Exceedances | U527: =$U526/$U525 -> 0.41441552 | AA527: % WET Exceedances | AC527: =AC526/AC525 -> 0.090568182 | AE527: % DRY Exceedances | AG527: =AG526/AG525 -> 0.79500534 | AI527: % Total Run Exceedances | AK527: =AK526/AK525 -> 0.41441552 | AL527: =AL526/AL525 -> 0.37033399 | AM527: =AM526/AM525 -> 0.43418468 | AN527: =AN526/AN525 -> 0.39980354 | AO527: =AO526/AO525 -> 0.44357127 | AQ527: % WET Exceedances | AS527: =AS526/AS525 -> 0.090568182 | AT527: =AT526/AT525 -> 0.084545455 | AU527: =AU526/AU525 -> 0.11070707 | AV527: =AV526/AV525 -> 0.046666667 | AW527: =AW526/AW525 -> 0.10505051 | AY527: % DRY Exceedances | BA527: =BA526/BA525 -> 0.79500534 | BB527: =BB526/BB525 -> 0.70619658 | BC527: =BC526/BC525 -> 0.81433998 | BD527: =BD526/BD525 -> 0.81481481 | BE527: =BE526/BE525 -> 0.84140551
A529: TOTAL EXCEEDANCES | B529: =COUNTIF(B$3:B$511,">=20") -> 152 | C529: =COUNTIF(C$3:C$511,">=20") -> 172 | D529: =COUNTIF(D$3:D$511,">=20") -> 147 | E529: =COUNTIF(E$3:E$511,">=20") -> 139 | F529: =COUNTIF(F$3:F$511,">=20") -> 159 | G529: =COUNTIF(G$3:G$511,">=20") -> 161 | H529: =COUNTIF(H$3:H$511,">=20") -> 105 | I529: =COUNTIF(I$3:I$511,">=20") -> 103 | ... AG529: =COUNTIF(AG$3:AG$511,">=20") -> 221
A530: WET 1 | B530: =COUNTIF(B$54:B$235,">=20") -> 8 | C530: =COUNTIF(C$54:C$235,">=20") -> 9 | D530: =COUNTIF(D$54:D$235,">=20") -> 9 | E530: =COUNTIF(E$54:E$235,">=20") -> 7 | F530: =COUNTIF(F$54:F$235,">=20") -> 7 | G530: =COUNTIF(G$54:G$235,">=20") -> 8 | H530: =COUNTIF(H$54:H$235,">=20") -> 5 | I530: =COUNTIF(I$54:I$235,">=20") -> 3 | ... AG530: =COUNTIF(AG$54:AG$235,">=20") -> 21 | AH530: OCTOBER 2020 - MARCH 2021
A531: WET 2 | B531: =COUNTIF(B$419:B$511,">=20") -> 0 | C531: =COUNTIF(C$419:C$511,">=20") -> 0 | D531: =COUNTIF(D$419:D$511,">=20") -> 0 | E531: =COUNTIF(E$419:E$511,">=20") -> 0 | F531: =COUNTIF(F$419:F$511,">=20") -> 0 | G531: =COUNTIF(G$419:G$511,">=20") -> 0 | H531: =COUNTIF(H$419:H$511,">=20") -> 0 | I531: =COUNTIF(I$419:I$511,">=20") -> 0 | ... AG531: =COUNTIF(AG$419:AG$511,">=20") -> 6 | AH531: OCTOBER 2021 - JANUARY 2022
A532: DRY 1 | B532: =COUNTIF(B$3:B$53,">=20") -> 51 | C532: =COUNTIF(C$3:C$53,">=20") -> 51 | D532: =COUNTIF(D$3:D$53,">=20") -> 51 | E532: =COUNTIF(E$3:E$53,">=20") -> 51 | F532: =COUNTIF(F$3:F$53,">=20") -> 51 | G532: =COUNTIF(G$3:G$53,">=20") -> 51 | H532: =COUNTIF(H$3:H$53,">=20") -> 46 | I532: =COUNTIF(I$3:I$53,">=20") -> 24 | ... AG532: =COUNTIF(AG$3:AG$53,">=20") -> 51 | AH532: AUGUST 2020 - SEPTEMBER 2020
A533: DRY 2 | B533: =COUNTIF(B$236:B$418,">=20") -> 93 | C533: =COUNTIF(C$236:C$418,">=20") -> 112 | D533: =COUNTIF(D$236:D$418,">=20") -> 87 | E533: =COUNTIF(E$236:E$418,">=20") -> 81 | F533: =COUNTIF(F$236:F$418,">=20") -> 101 | G533: =COUNTIF(G$236:G$418,">=20") -> 102 | H533: =COUNTIF(H$236:H$418,">=20") -> 54 | I533: =COUNTIF(I$236:I$418,">=20") -> 76 | ... AG533: =COUNTIF(AG$236:AG$418,">=20") -> 143 | AH533: APRIL 2021 - SEPTEMBER 2021
A534: ALL WET | B534: =SUM(B530,B531) -> 8 | C534: =SUM(C530,C531) -> 9 | D534: =SUM(D530,D531) -> 9 | E534: =SUM(E530,E531) -> 7 | F534: =SUM(F530,F531) -> 7 | G534: =SUM(G530,G531) -> 8 | H534: =SUM(H530,H531) -> 5 | I534: =SUM(I530,I531) -> 3 | ... AG534: =SUM(AG530,AG531) -> 27
A535: ALL DRY | B535: =SUM(B532,B533) -> 144 | C535: =SUM(C532,C533) -> 163 | D535: =SUM(D532,D533) -> 138 | E535: =SUM(E532,E533) -> 132 | F535: =SUM(F532,F533) -> 152 | G535: =SUM(G532,G533) -> 153 | H535: =SUM(H532,H533) -> 100 | I535: =SUM(I532,I533) -> 100 | ... AG535: =SUM(AG532,AG533) -> 194
D538: Birding 20C | F538: THRESHOLD: 20C | S538: BIRDING | AA538: BIRDING | AE538: BIRDING | AI538: BIRDING | AQ538: BIRDING | AY538: BIRDING
F539: WET SEASON | S539: TOTAL RUN | AA539: WET SEASONS | AE539: DRY SEASONS | AI539: TOTAL RUN | AK539: Delta-Wide | AL539: Suisun | AM539: Central Delta | AN539: North Delta | AO539: South Delta | AQ539: WET SEASONS | AS539: Delta-Wide | AT539: Suisun | AU539: Central Delta | AV539: North Delta | AW539: South Delta | AY539: DRY SEASONS | BA539: Delta-Wide | BB539: Suisun | BC539: Central Delta | BD539: North Delta | BE539: South Delta
F540: OCTOBER 1 - MARCH 31 | M540: DRY SEASON | S540: Total points | U540: =COUNTIF(B18:AG18,"<>") -> 32 | AA540: Total points | AC540: =COUNTIF(B18:AG18,"<>") -> 32 | AE540: Total points | AG540: =COUNTIF(B18:AG18,"<>") -> 32 | AI540: Total points | AK540: =COUNTIF($B$2:$AG$2,"<>") -> 32 | AL540: =COUNTIF($B$2:$I$2,"<>") -> 8 | AM540: =COUNTIF($J$2:$R$2,"<>") -> 9 | AN540: =COUNTIF($S$2:$X$2,"<>") -> 6 | AO540: =COUNTIF($Y$2:$AG$2,"<>") -> 9 | AQ540: Total points | AS540: =COUNTIF($B$2:$AG$2,"<>") -> 32 | AT540: =COUNTIF($B$2:$I$2,"<>") -> 8 | AU540: =COUNTIF($J$2:$R$2,"<>") -> 9 | AV540: =COUNTIF($S$2:$X$2,"<>") -> 6 | AW540: =COUNTIF($Y$2:$AG$2,"<>") -> 9 | AY540: Total points | BA540: =COUNTIF($B$2:$AG$2,"<>") -> 32 | BB540: =COUNTIF($B$2:$I$2,"<>") -> 8 | BC540: =COUNTIF($J$2:$R$2,"<>") -> 9 | BD540: =COUNTIF($S$2:$X$2,"<>") -> 6 | BE540: =COUNTIF($Y$2:$AG$2,"<>") -> 9
F541: WET SEASON 1 | H541: 10/1/20 - 3/31/21 | J541: =COUNTIF($B$54:$B$235,"<>") -> 182 | M541: APRIL 1 - SEPTEMBER 30 | S541: Days in run | U541: =COUNTIF($A$3:$A$511,"<>") -> 509 | AA541: Days in run | AC541: =SUM($J$524:$J$525) -> 275 | AE541: Days in run | AG541: =SUM($Q$525:$Q$526) -> 234 | AI541: Days in run | AK541: =COUNTIF($A$3:$A$511,"<>") -> 509 | AL541: =COUNTIF($A$3:$A$511,"<>") -> 509 | AM541: =COUNTIF($A$3:$A$511,"<>") -> 509 | AN541: =COUNTIF($A$3:$A$511,"<>") -> 509 | AO541: =COUNTIF($A$3:$A$511,"<>") -> 509 | AQ541: Days in run | AS541: =SUM($J$524:$J$525) -> 275 | AT541: =SUM($J$524:$J$525) -> 275 | AU541: =SUM($J$524:$J$525) -> 275 | AV541: =SUM($J$524:$J$525) -> 275 | AW541: =SUM($J$524:$J$525) -> 275 | AY541: Days in run | BA541: =SUM($Q$525:$Q$526) -> 234 | BB541: =SUM($Q$525:$Q$526) -> 234 | BC541: =SUM($Q$525:$Q$526) -> 234 | BD541: =SUM($Q$525:$Q$526) -> 234 | BE541: =SUM($Q$525:$Q$526) -> 234
...

Sheet Run 16 Temp
B1: Suisun | J1: Central Delta | S1: North Delta | Y1: South Delta
A2: Date | B2: CHADBOURNE SLOUGH AT SUNRISE DUCK CLUB | C2: MONTEZUMA SLOUGH AT NATIONAL STEEL | D2: MONTEZUMA SLOUGH NEAR BELDENS LANDING | E2: SUISUN SLOUGH 300' SOUTH OF VOLANTI SLOUGH | F2: HONKER BAY | G2: SUISUN BAY AT VAN SICKLE ISLAND | H2: SUISUN BAY WEST REACH | I2: GRIZZLY BAY BUOY | J2: DUTCH SL BELOW JERSEY ISLAND | K2: FALSE RIVER NEAR OAKLEY | L2: OLD RIVER AT FRANKS TRACT | M2: PITTSBURG | N2: SACRAMENTO RIVER AT EMMATON | O2: SAN ANDREAS LANDING | P2: SAN JOAQUIN RIVER AT JERSEY POINT | Q2: SUISUN BAY AT CHANNEL MARKER 5 AT COLLINSVILLE | R2: BRANNAN MARINAS AT SAN JOAQUIN RIVER | S2: LIBERTY CUT AT FIVE POINTS | T2: CACHE SLOUGH ABOVE RYER ISLAND FERRY | U2: DELTA CROSS CHANNEL NEAR WALNUT GROVE | V2: SACRAMENTO RIVER DOWNSTREAM OF ISLETON | W2: COURTLAND AT SACRAMENTO RIVER | X2: VIERAS RESORT AT SACRAMENTO RIVER | Y2: GRANT LINE CANAL NEAR CLIFTON COURT FORE | Z2: LITTLE POTATO SLOUGH AT TERMINOUS | AA2: MIDDLE RIVER AT MILDRED ISLAND | AB2: OLD RIVER AT CLIFTON COURT | AC2: SAN JOAQUIN RIVER AT BRANDT BRIDGE | AD2: SAN JOAQUIN RIVER AT PRISONERS POINT | AE2: SAN JOAQUIN RIVER NEAR VERNALIS | AF2: SAN JOAQUIN RVER AT ROUGH AND READY ISLAND | AG2: VICTORIA CANAL BEFORE CLIFTON COURT FORE
A3: 44054 | B3: 22.560764 | C3: 21.901028 | D3: 22.4312 | E3: 22.658598 | F3: 20.75539 | G3: 21.305948 | H3: 20.295216 | I3: 20.915659 | J3: 23.26238 | K3: 22.90294 | L3: 23.922787 | M3: 21.527235 | N3: 22.213596 | O3: 23.735483 | P3: 22.804697 | Q3: 21.601511 | R3: 23.547873 | S3: 22.027601 | T3: 23.297243 | U3: 23.66891 | V3: 23.21523 | W3: 23.670118 | X3: 23.27483 | Y3: 25.640064 | Z3: 24.2612 | AA3: 25.027302 | AB3: 25.589695 | AC3: 26.869406 | AD3: 24.109734 | AE3: 25.979967 | AF3: 26.154945 | AG3: 25.606352
A4: 44055 | B4: 22.74026 | C4: 22.16088 | D4: 22.396257 | E4: 22.537186 | F4: 21.16958 | G4: 21.16175 | H4: 20.25052 | I4: 20.55522 | J4: 23.017015 | K4: 22.673159 | L4: 23.855062 | M4: 21.429705 | N4: 22.086098 | O4: 23.60781 | P4: 22.58709 | Q4: 21.476517 | R4: 23.388723 | S4: 20.774557 | T4: 22.965813 | U4: 23.64268 | V4: 23.318651 | W4: 23.051378 | X4: 23.477995 | Y4: 25.61482 | Z4: 24.201597 | AA4: 25.273102 | AB4: 25.543482 | AC4: 26.659304 | AD4: 24.081526 | AE4: 25.70756 | AF4: 26.247673 | AG4: 25.344595
A5: 44056 | B5: 23.228073 | C5: 22.339315 | D5: 22.433441 | E5: 22.549416 | F5: 21.422049 | G5: 21.264738 | H5: 20.43134 | I5: 20.449097 | J5: 23.294321 | K5: 22.747 | L5: 23.951431 | M5: 21.545158 | N5: 22.320557 | O5: 23.746199 | P5: 22.671034 | Q5: 21.532883 | R5: 23.541008 | S5: 20.764603 | T5: 23.153511 | U5: 22.764887 | V5: 23.825712 | W5: 22.629766 | X5: 23.979155 | Y5: 25.697533 | Z5: 24.40624 | AA5: 25.613426 | AB5: 25.63624 | AC5: 26.678125 | AD5: 24.171957 | AE5: 26.15229 | AF5: 26.41411 | AG5: 25.39831
A6: 44057 | B6: 23.841951 | C6: 22.668238 | D6: 22.728258 | E6: 22.772902 | F6: 21.960457 | G6: 21.57727 | H6: 20.751507 | I6: 21.008295 | J6: 24.071884 | K6: 23.106833 | L6: 24.272509 | M6: 21.873283 | N6: 22.787416 | O6: 24.147898 | P6: 23.015291 | Q6: 21.841024 | R6: 23.893824 | S6: 21.783737 | T6: 23.509127 | U6: 23.068491 | V6: 23.667595 | W6: 23.059807 | X6: 23.5445 | Y6: 25.990313 | Z6: 24.791716 | AA6: 25.997332 | AB6: 25.884878 | AC6: 26.968628 | AD6: 24.453478 | AE6: 26.818085 | AF6: 26.645119 | AG6: 25.84265
A7: 44058 | B7: 24.282633 | C7: 23.144928 | D7: 23.201914 | E7: 23.128492 | F7: 22.431137 | G7: 22.022814 | H7: 21.105097 | I7: 21.660944 | J7: 25.048159 | K7: 23.626219 | L7: 24.680328 | M7: 22.276548 | N7: 23.243156 | O7: 24.551588 | P7: 23.530298 | Q7: 22.283571 | R7: 24.29923 | S7: 22.924967 | T7: 23.94551 | U7: 23.356192 | V7: 24.091797 | W7: 23.362852 | X7: 24.036806 | Y7: 26.452002 | Z7: 25.36624 | AA7: 26.463362 | AB7: 26.331007 | AC7: 27.530197 | AD7: 24.801788 | AE7: 27.462126 | AF7: 26.98506 | AG7: 26.444122
A8: 44059 | B8: 24.511553 | C8: 23.558043 | D8: 23.615625 | E8: 23.457327 | F8: 22.716246 | G8: 22.36535 | H8: 21.42375 | I8: 21.972761 | J8: 25.619974 | K8: 24.006134 | L8: 24.97956 | M8: 22.623062 | N8: 23.598162 | O8: 24.743021 | P8: 23.921164 | Q8: 22.645021 | R8: 24.603151 | S8: 23.745516 | T8: 24.32715 | U8: 23.653284 | V8: 24.438606 | W8: 23.576994 | X8: 24.402243 | Y8: 26.96913 | Z8: 25.72804 | AA8: 26.86989 | AB8: 26.81058 | AC8: 28.0981 | AD8: 25.133097 | AE8: 28.402681 | AF8: 27.326546 | AG8: 26.941017
A9: 44060 | B9: 24.85686 | C9: 24.033407 | D9: 24.052687 | E9: 23.843224 | F9: 23.14627 | G9: 22.789331 | H9: 21.880861 | I9: 22.524742 | J9: 26.141968 | K9: 24.422327 | L9: 25.314978 | M9: 23.056992 | N9: 24.08844 | O9: 25.087265 | P9: 24.344328 | Q9: 23.08755 | R9: 24.988703 | S9: 24.508545 | T9: 24.784311 | U9: 23.968636 | V9: 24.782694 | W9: 23.9217 | X9: 24.70414 | Y9: 27.538603 | Z9: 25.90671 | AA9: 27.236214 | AB9: 27.373941 | AC9: 28.523125 | AD9: 25.473557 | AE9: 28.705618 | AF9: 27.579254 | AG9: 27.304337
A10: 44061 | B10: 25.198862 | C10: 24.49031 | D10: 24.450106 | E10: 24.191694 | F10: 23.517641 | G10: 23.243582 | H10: 22.263247 | I10: 22.93872 | J10: 26.608551 | K10: 24.867676 | L10: 25.675987 | M10: 23.48989 | N10: 24.53449 | O10: 25.419203 | P10: 24.803148 | Q10: 23.547876 | R10: 25.345892 | S10: 25.24801 | T10: 25.220503 | U10: 24.032446 | V10: 25.076942 | W10: 23.670975 | X10: 24.962358 | Y10: 27.941727 | Z10: 26.1657 | AA10: 27.549492 | AB10: 27.743147 | AC10: 28.833565 | AD10: 25.817263 | AE10: 28.104956 | AF10: 27.85272 | AG10: 27.594496
A11: 44062 | B11: 24.849474 | C11: 24.584152 | D11: 24.469538 | E11: 24.136864 | F11: 23.379396 | G11: 23.424997 | H11: 22.325048 | I11: 22.526693 | J11: 26.596476 | K11: 25.062271 | L11: 25.743216 | M11: 23.625986 | N11: 24.6139 | O11: 25.41337 | P11: 25.010305 | Q11: 23.731232 | R11: 25.400438 | S11: 24.896223 | T11: 25.250742 | U11: 23.50763 | V11: 24.961884 | W11: 23.068542 | X11: 24.81096 | Y11: 27.898796 | Z11: 26.128 | AA11: 27.626877 | AB11: 27.719154 | AC11: 28.839968 | AD11: 25.908815 | AE11: 27.216301 | AF11: 28.001925 | AG11: 27.545258
A12: 44063 | B12: 24.181025 | C12: 24.190928 | D12: 24.054182 | E12: 23.722275 | F12: 22.9955 | G12: 23.241041 | H12: 22.163567 | I12: 21.805223 | J12: 25.559675 | K12: 24.754305 | L12: 25.460958 | M12: 23.393305 | N12: 24.198265 | O12: 25.107874 | P12: 24.72368 | Q12: 23.501165 | R12: 25.181997 | S12: 23.604044 | T12: 24.775286 | U12: 22.67867 | V12: 24.23918 | W12: 22.29455 | X12: 24.016058 | Y12: 27.481466 | Z12: 25.704996 | AA12: 27.376192 | AB12: 27.343744 | AC12: 28.322058 | AD12: 25.703506 | AE12: 25.900322 | AF12: 27.90954 | AG12: 27.239008
A13: 44064 | B13: 24.03367 | C13: 24.05277 | D13: 23.762474 | E13: 23.465853 | F13: 22.967981 | G13: 23.102026 | H13: 22.048706 | I13: 21.578987 | J13: 25.203253 | K13: 24.65799 | L13: 25.28081 | M13: 23.269087 | N13: 24.066282 | O13: 24.866686 | P13: 24.605555 | Q13: 23.374681 | R13: 25.069075 | S13: 22.910276 | T13: 24.308355 | U13: 21.991999 | V13: 23.523874 | W13: 21.6825 | X13: 23.207993 | Y13: 27.115082 | Z13: 25.151873 | AA13: 27.053368 | AB13: 27.040365 | AC13: 27.888601 | AD13: 25.482048 | AE13: 24.46592 | AF13: 27.823557 | AG13: 27.021057
A14: 44065 | B14: 24.19333 | C14: 24.177889 | D14: 23.746378 | E14: 23.51375 | F14: 23.113817 | G14: 23.181772 | H14: 22.10407 | I14: 21.709673 | J14: 25.465437 | K14: 24.745155 | L14: 25.23278 | M14: 23.374517 | N14: 24.183577 | O14: 24.688118 | P14: 24.686918 | Q14: 23.487831 | R14: 25.066374 | S14: 23.074623 | T14: 24.063133 | U14: 21.552675 | V14: 22.990992 | W14: 21.185953 | X14: 22.626669 | Y14: 27.232054 | Z14: 24.679049 | AA14: 27.084753 | AB14: 27.125933 | AC14: 28.016075 | AD14: 25.413351 | AE14: 24.230787 | AF14: 27.910486 | AG14: 27.071169
... A511: 44562 | B511: 7.4353485 | C511: 8.05548 | D511: 7.837817 | E511: 7.881651 | F511: 7.985317 | G511: 8.121688 | H511: 8.874166 | I511: 7.5504565 | J511: 7.202124 | K511: 8.403389 | L511: 8.053358 | M511: 8.230301 | N511: 7.7664433 | O511: 7.923712 | P511: 8.190391 | Q511: 7.966086 | R511: 8.083178 | S511: 6.853958 | T511: 7.549032 | U511: 7.9171634 | V511: 7.815271 | W511: 7.745185 | X511: 7.824097 | Y511: 8.213229 | Z511: 7.9778776 | AA511: 8.045062 | AB511: 7.7070727 | AC511: 11.915046 | AD511: 8.12681 | AE511: 8.781848 | AF511: 7.661792 | AG511: 7.7270126
A512: TOTAL EXCEEDANCES | B512: =COUNTIF(B$3:B$511,">=19") -> 199 | C512: =COUNTIF(C$3:C$511,">=19") -> 210 | D512: =COUNTIF(D$3:D$511,">=19") -> 199 | E512: =COUNTIF(E$3:E$511,">=19") -> 198 | F512: =COUNTIF(F$3:F$511,">=19") -> 201 | G512: =COUNTIF(G$3:G$511,">=19") -> 206 | H512: =COUNTIF(H$3:H$511,">=19") -> 171 | I512: =COUNTIF(I$3:I$511,">=19") -> 161 | ... AG512: =COUNTIF(AG$3:AG$511,">=19") -> 232
A513: WET 1 | B513: =COUNTIF(B$54:B$235,">=19") -> 22 | C513: =COUNTIF(C$54:C$235,">=19") -> 23 | D513: =COUNTIF(D$54:D$235,">=19") -> 23 | E513: =COUNTIF(E$54:E$235,">=19") -> 22 | F513: =COUNTIF(F$54:F$235,">=19") -> 22 | G513: =COUNTIF(G$54:G$235,">=19") -> 23 | H513: =COUNTIF(H$54:H$235,">=19") -> 8 | I513: =COUNTIF(I$54:I$235,">=19") -> 6 | ... AG513: =COUNTIF(AG$54:AG$235,">=19") -> 24 | AH513: OCTOBER 2020 - MARCH 2021
A514: WET 2 | B514: =COUNTIF(B$419:B$511,">=19") -> 5 | C514: =COUNTIF(C$419:C$511,">=19") -> 6 | D514: =COUNTIF(D$419:D$511,">=19") -> 5 | E514: =COUNTIF(E$419:E$511,">=19") -> 4 | F514: =COUNTIF(F$419:F$511,">=19") -> 5 | G514: =COUNTIF(G$419:G$511,">=19") -> 6 | H514: =COUNTIF(H$419:H$511,">=19") -> 4 | I514: =COUNTIF(I$419:I$511,">=19") -> 3 | ... AG514: =COUNTIF(AG$419:AG$511,">=19") -> 8 | AH514: OCTOBER 2021 - JANUARY 2022
A515: DRY 1 | B515: =COUNTIF(B$3:B$53,">=19") -> 51 | C515: =COUNTIF(C$3:C$53,">=19") -> 51 | D515: =COUNTIF(D$3:D$53,">=19") -> 51 | E515: =COUNTIF(E$3:E$53,">=19") -> 51 | F515: =COUNTIF(F$3:F$53,">=19") -> 51 | G515: =COUNTIF(G$3:G$53,">=19") -> 51 | H515: =COUNTIF(H$3:H$53,">=19") -> 51 | I515: =COUNTIF(I$3:I$53,">=19") -> 49 | ... AG515: =COUNTIF(AG$3:AG$53,">=19") -> 51 | AH515: AUGUST 2020 - SEPTEMBER 2020
A516: DRY 2 | B516: =COUNTIF(B$236:B$418,">=19") -> 121 | C516: =COUNTIF(C$236:C$418,">=19") -> 130 | D516: =COUNTIF(D$236:D$418,">=19") -> 120 | E516: =COUNTIF(E$236:E$418,">=19") -> 121 | F516: =COUNTIF(F$236:F$418,">=19") -> 123 | G516: =COUNTIF(G$236:G$418,">=19") -> 126 | H516: =COUNTIF(H$236:H$418,">=19") -> 108 | I516: =COUNTIF(I$236:I$418,">=19") -> 103 | ... AG516: =COUNTIF(AG$236:AG$418,">=19") -> 149 | AH516: APRIL 2021 - SEPTEMBER 2021
A517: ALL WET | B517: =SUM(B$513,B$514) -> 27 | C517: =SUM(C$513,C$514) -> 29 | D517: =SUM(D$513,D$514) -> 28 | E517: =SUM(E$513,E$514) -> 26 | F517: =SUM(F$513,F$514) -> 27 | G517: =SUM(G$513,G$514) -> 29 | H517: =SUM(H$513,H$514) -> 12 | I517: =SUM(I$513,I$514) -> 9 | ... AG517: =SUM(AG$513,AG$514) -> 32
A518: ALL DRY | B518: =SUM(B$515,B$516) -> 172 | C518: =SUM(C$515,C$516) -> 181 | D518: =SUM(D$515,D$516) -> 171 | E518: =SUM(E$515,E$516) -> 172 | F518: =SUM(F$515,F$516) -> 174 | G518: =SUM(G$515,G$516) -> 177 | H518: =SUM(H$515,H$516) -> 159 | I518: =SUM(I$515,I$516) -> 152 | ... AG518: =SUM(AG$515,AG$516) -> 200
D521: Day Use & Boating 19C | F521: THRESHOLD: 19C | S521: SP DAY USE & BOATING | AA521: SP DAY USE & BOATING | AE521: SP DAY USE & BOATING | AI521: SP DAY USE & BOATING | AQ521: SP DAY USE & BOATING | AY521: SP DAY USE & BOATING
F522: WET SEASON | S522: TOTAL RUN | AA522: WET SEASONS | AE522: DRY SEASONS | AI522: TOTAL RUN | AK522: Delta-Wide | AL522: Suisun | AM522: Central Delta | AN522: North Delta | AO522: South Delta | AQ522: WET SEASONS | AS522: Delta-Wide | AT522: Suisun | AU522: Central Delta | AV522: North Delta | AW522: South Delta | AY522: DRY SEASONS | BA522: Delta-Wide | BB522: Suisun | BC522: Central Delta | BD522: North Delta | BE522: South Delta
F523: OCTOBER 1 - MARCH 31 | M523: DRY SEASON | S523: Total points | U523: =COUNTIF(B2:AG2,"<>") -> 32 | AA523: Total points | AC523: =COUNTIF(B2:AG2,"<>") -> 32 | AE523: Total points | AG523: =COUNTIF(B2:AG2,"<>") -> 32 | AI523: Total points | AK523: =COUNTIF($B$2:$AG$2,"<>") -> 32 | AL523: =COUNTIF($B$2:$I$2,"<>") -> 8 | AM523: =COUNTIF($J$2:$R$2,"<>") -> 9 | AN523: =COUNTIF($S$2:$X$2,"<>") -> 6 | AO523: =COUNTIF($Y$2:$AG$2,"<>") -> 9 | AQ523: Total points | AS523: =COUNTIF($B$2:$AG$2,"<>") -> 32 | AT523: =COUNTIF($B$2:$I$2,"<>") -> 8 | AU523: =COUNTIF($J$2:$R$2,"<>") -> 9 | AV523: =COUNTIF($S$2:$X$2,"<>") -> 6 | AW523: =COUNTIF($Y$2:$AG$2,"<>") -> 9 | AY523: Total points | BA523: =COUNTIF($B$2:$AG$2,"<>") -> 32 | BB523: =COUNTIF($B$2:$I$2,"<>") -> 8 | BC523: =COUNTIF($J$2:$R$2,"<>") -> 9 | BD523: =COUNTIF($S$2:$X$2,"<>") -> 6 | BE523: =COUNTIF($Y$2:$AG$2,"<>") -> 9
F524: WET SEASON 1 | H524: 10/1/20 - 3/31/21 | J524: =COUNTIF($B$54:$B$235,"<>") -> 182 | M524: APRIL 1 - SEPTEMBER 30 | S524: Days in run | U524: =COUNTIF($A$3:$A$511,"<>") -> 509 | AA524: Days in run | AC524: =SUM($J$524:$J$525) -> 275 | AE524: Days in run | AG524: =SUM($Q$525:$Q$526) -> 234 | AI524: Days in run | AK524: =COUNTIF($A$3:$A$511,"<>") -> 509 | AL524: =COUNTIF($A$3:$A$511,"<>") -> 509 | AM524: =COUNTIF($A$3:$A$511,"<>") -> 509 | AN524: =COUNTIF($A$3:$A$511,"<>") -> 509 | AO524: =COUNTIF($A$3:$A$511,"<>") -> 509 | AQ524: Days in run | AS524: =SUM($J$524:$J$525) -> 275 | AT524: =SUM($J$524:$J$525) -> 275 | AU524: =SUM($J$524:$J$525) -> 275 | AV524: =SUM($J$524:$J$525) -> 275 | AW524: =SUM($J$524:$J$525) -> 275 | AY524: Days in run | BA524: =SUM($Q$525:$Q$526) -> 234 | BB524: =SUM($Q$525:$Q$526) -> 234 | BC524: =SUM($Q$525:$Q$526) -> 234 | BD524: =SUM($Q$525:$Q$526) -> 234 | BE524: =SUM($Q$525:$Q$526) -> 234
F525: WET SEASON 2 | H525: 10/1/21 - 1/1/22 | J525: =COUNTIF($B$419:$B$511,"<>") -> 93 | M525: DRY SEASON 1 | O525: 8/11/20 - 9/30/20 | Q525: =COUNTIF($B$3:$B$53,"<>") -> 51 | S525: Total measurements | U525: =U524*U523 -> 16288 | V525: DENOMINATOR FOR EXCEEDANCE % | AA525: Total measurements | AC525: =AC524*AC523 -> 8800 | AE525: Total measurements | AG525: =AG523*AG524 -> 7488 | AI525: Total measurements | AK525: =AK524*AK523 -> 16288 | AL525: =AL524*AL523 -> 4072 | AM525: =AM524*AM523 -> 4581 | AN525: =AN524*AN523 -> 3054 | AO525: =AO524*AO523 -> 4581 | AQ525: Total measurements | AS525: =AS524*AS523 -> 8800 | AT525: =AT524*AT523 -> 2200 | AU525: =AU524*AU523 -> 2475 | AV525: =AV524*AV523 -> 1650 | AW525: =AW524*AW523 -> 2475 | AY525: Total measurements | BA525: =BA524*BA523 -> 7488 | BB525: =BB524*BB523 -> 1872 | BC525: =BC524*BC523 -> 2106 | BD525: =BD524*BD523 -> 1404 | BE525: =BE524*BE523 -> 2106
F526: WET SEASON 3 | H526: N/A (outside run period) | J526: =COUNTIF($A$737:$A$798,"<>") -> 0 | M526: DRY SEASON 2 | O526: 4/1/21 - 9/30/21 | Q526: =COUNTIF($B$236:$B$418,"<>") -> 183 | S526: Measurements >= 19C | U526: =SUM(B512:AG512) -> 6781 | V526: NUMERATOR FOR EXCEEDANCE % | AA526: Measurements >= 19C | AC526: =SUM($B$517:$AG$517) -> 778 | AE526: Measurements >= 19C | AG526: =SUM($B$518:$AG$518) -> 6003 | AI526: Measurements >= 19C | AK526: =SUM(B512:AG512) -> 6781 | AL526: =SUM(B512:I512) -> 1545 | AM526: =SUM(J512:R512) -> 2001 | AN526: =SUM(S512:X512) -> 1206 | AO526: =SUM(Y512:AG512) -> 2029 | AQ526: Measurements >= 19C | AS526: =SUM(B517:AG517) -> 778 | AT526: =SUM(B517:I517) -> 187 | AU526: =SUM(J517:R517) -> 270 | AV526: =SUM(S517:X517) -> 62 | AW526: =SUM(Y517:AG517) -> 259 | AY526: Measurements >= 19C | BA526: =SUM($B518:$AG518) -> 6003 | BB526: =SUM(B518:I518) -> 1358 | BC526: =SUM(J518:R518) -> 1731 | BD526: =SUM(S518:X518) -> 1144 | BE526: =SUM(Y518:AG518) -> 1770
S527: % Total Run Exceedances | U527: =$U526/$U525 -> 0.41631876 | AA527: % WET Exceedances | AC527: =AC526/AC525 -> 0.088409091 | AE527: % DRY Exceedances | AG527: =AG526/AG525 -> 0.80168269 | AI527: % Total Run Exceedances | AK527: =AK526/AK525 -> 0.41631876 | AL527: =AL526/AL525 -> 0.37942043 | AM527: =AM526/AM525 -> 0.43680419 | AN527: =AN526/AN525 -> 0.39489194 | AO527: =AO526/AO525 -> 0.44291639 | AQ527: % WET Exceedances | AS527: =AS526/AS525 -> 0.088409091 | AT527: =AT526/AT525 -> 0.085 | AU527: =AU526/AU525 -> 0.10909091 | AV527: =AV526/AV525 -> 0.037575758 | AW527: =AW526/AW525 -> 0.10464646 | AY527: % DRY Exceedances | BA527: =BA526/BA525 -> 0.80168269 | BB527: =BB526/BB525 -> 0.72542735 | BC527: =BC526/BC525 -> 0.82193732 | BD527: =BD526/BD525 -> 0.81481481 | BE527: =BE526/BE525 -> 0.84045584
A529: TOTAL EXCEEDANCES | B529: =COUNTIF(B$3:B$511,">=20") -> 154 | C529: =COUNTIF(C$3:C$511,">=20") -> 173 | D529: =COUNTIF(D$3:D$511,">=20") -> 152 | E529: =COUNTIF(E$3:E$511,">=20") -> 144 | F529: =COUNTIF(F$3:F$511,">=20") -> 160 | G529: =COUNTIF(G$3:G$511,">=20") -> 166 | H529: =COUNTIF(H$3:H$511,">=20") -> 128 | I529: =COUNTIF(I$3:I$511,">=20") -> 104 | ... AG529: =COUNTIF(AG$3:AG$511,">=20") -> 221
A530: WET 1 | B530: =COUNTIF(B$54:B$235,">=20") -> 8 | C530: =COUNTIF(C$54:C$235,">=20") -> 9 | D530: =COUNTIF(D$54:D$235,">=20") -> 9 | E530: =COUNTIF(E$54:E$235,">=20") -> 7 | F530: =COUNTIF(F$54:F$235,">=20") -> 7 | G530: =COUNTIF(G$54:G$235,">=20") -> 8 | H530: =COUNTIF(H$54:H$235,">=20") -> 4 | I530: =COUNTIF(I$54:I$235,">=20") -> 3 | ... AG530: =COUNTIF(AG$54:AG$235,">=20") -> 21 | AH530: OCTOBER 2020 - MARCH 2021
A531: WET 2 | B531: =COUNTIF(B$419:B$511,">=20") -> 0 | C531: =COUNTIF(C$419:C$511,">=20") -> 0 | D531: =COUNTIF(D$419:D$511,">=20") -> 0 | E531: =COUNTIF(E$419:E$511,">=20") -> 0 | F531: =COUNTIF(F$419:F$511,">=20") -> 0 | G531: =COUNTIF(G$419:G$511,">=20") -> 0 | H531: =COUNTIF(H$419:H$511,">=20") -> 0 | I531: =COUNTIF(I$419:I$511,">=20") -> 0 | ... AG531: =COUNTIF(AG$419:AG$511,">=20") -> 6 | AH531: OCTOBER 2021 - JANUARY 2022
A532: DRY 1 | B532: =COUNTIF(B$3:B$53,">=20") -> 51 | C532: =COUNTIF(C$3:C$53,">=20") -> 51 | D532: =COUNTIF(D$3:D$53,">=20") -> 51 | E532: =COUNTIF(E$3:E$53,">=20") -> 51 | F532: =COUNTIF(F$3:F$53,">=20") -> 51 | G532: =COUNTIF(G$3:G$53,">=20") -> 51 | H532: =COUNTIF(H$3:H$53,">=20") -> 45 | I532: =COUNTIF(I$3:I$53,">=20") -> 24 | ... AG532: =COUNTIF(AG$3:AG$53,">=20") -> 51 | AH532: AUGUST 2020 - SEPTEMBER 2020
A533: DRY 2 | B533: =COUNTIF(B$236:B$418,">=20") -> 95 | C533: =COUNTIF(C$236:C$418,">=20") -> 113 | D533: =COUNTIF(D$236:D$418,">=20") -> 92 | E533: =COUNTIF(E$236:E$418,">=20") -> 86 | F533: =COUNTIF(F$236:F$418,">=20") -> 102 | G533: =COUNTIF(G$236:G$418,">=20") -> 107 | H533: =COUNTIF(H$236:H$418,">=20") -> 79 | I533: =COUNTIF(I$236:I$418,">=20") -> 77 | ... AG533: =COUNTIF(AG$236:AG$418,">=20") -> 143 | AH533: APRIL 2021 - SEPTEMBER 2021
A534: ALL WET | B534: =SUM(B530,B531) -> 8 | C534: =SUM(C530,C531) -> 9 | D534: =SUM(D530,D531) -> 9 | E534: =SUM(E530,E531) -> 7 | F534: =SUM(F530,F531) -> 7 | G534: =SUM(G530,G531) -> 8 | H534: =SUM(H530,H531) -> 4 | I534: =SUM(I530,I531) -> 3 | ... AG534: =SUM(AG530,AG531) -> 27
A535: ALL DRY | B535: =SUM(B532,B533) -> 146 | C535: =SUM(C532,C533) -> 164 | D535: =SUM(D532,D533) -> 143 | E535: =SUM(E532,E533) -> 137 | F535: =SUM(F532,F533) -> 153 | G535: =SUM(G532,G533) -> 158 | H535: =SUM(H532,H533) -> 124 | I535: =SUM(I532,I533) -> 101 | ... AG535: =SUM(AG532,AG533) -> 194
D538: Birding 20C | F538: THRESHOLD: 20C | S538: BIRDING | AA538: BIRDING | AE538: BIRDING | AI538: BIRDING | AQ538: BIRDING | AY538: BIRDING
