Workbook

Sheet Overall Acres
A1: OVERALL ACRES — Restoration Scenario Scores (-5 to 5 vs 50% Baseline)
A2: RESTORED ACRES SCORES | G2: Notes: Score = % change in restored acres vs 50% Baseline, rounded to whole %, capped at ±5 (1% = 1 step). Positive = more acres restored. Delta-Wide = Suisun + Central + North + South + Upland. Brannan Island counted in Central; Terminous Tract in South. Upland 50% = midpoint of Upper (100%) and Lower (25%) bounds ('50% Restoration ($)' rows 42–44). North Delta has 0 restored acres at baseline: any gain = +5, none = 0.
B3: REGION | C3: 50% Restoration (Baseline) | D3: 100% Restoration | E3: 25% Restoration
A4: RESTORED ACRES | B4: Delta-Wide | C4: =IF($C14=0,IF(C14>0,5,IF(C14<0,-5,0)),MAX(-5,MIN(5,ROUND((C14-$C14)/$C14*100,0)))) -> 0 | D4: =IF($C14=0,IF(D14>0,5,IF(D14<0,-5,0)),MAX(-5,MIN(5,ROUND((D14-$C14)/$C14*100,0)))) -> 5 | E4: =IF($C14=0,IF(E14>0,5,IF(E14<0,-5,0)),MAX(-5,MIN(5,ROUND((E14-$C14)/$C14*100,0)))) -> -5
B5: Suisun | C5: =IF($C15=0,IF(C15>0,5,IF(C15<0,-5,0)),MAX(-5,MIN(5,ROUND((C15-$C15)/$C15*100,0)))) -> 0 | D5: =IF($C15=0,IF(D15>0,5,IF(D15<0,-5,0)),MAX(-5,MIN(5,ROUND((D15-$C15)/$C15*100,0)))) -> 0 | E5: =IF($C15=0,IF(E15>0,5,IF(E15<0,-5,0)),MAX(-5,MIN(5,ROUND((E15-$C15)/$C15*100,0)))) -> 0
B6: Central | C6: =IF($C16=0,IF(C16>0,5,IF(C16<0,-5,0)),MAX(-5,MIN(5,ROUND((C16-$C16)/$C16*100,0)))) -> 0 | D6: =IF($C16=0,IF(D16>0,5,IF(D16<0,-5,0)),MAX(-5,MIN(5,ROUND((D16-$C16)/$C16*100,0)))) -> 0 | E6: =IF($C16=0,IF(E16>0,5,IF(E16<0,-5,0)),MAX(-5,MIN(5,ROUND((E16-$C16)/$C16*100,0)))) -> -5
B7: North | C7: =IF($C17=0,IF(C17>0,5,IF(C17<0,-5,0)),MAX(-5,MIN(5,ROUND((C17-$C17)/$C17*100,0)))) -> 0 | D7: =IF($C17=0,IF(D17>0,5,IF(D17<0,-5,0)),MAX(-5,MIN(5,ROUND((D17-$C17)/$C17*100,0)))) -> 5 | E7: =IF($C17=0,IF(E17>0,5,IF(E17<0,-5,0)),MAX(-5,MIN(5,ROUND((E17-$C17)/$C17*100,0)))) -> 0
B8: South | C8: =IF($C18=0,IF(C18>0,5,IF(C18<0,-5,0)),MAX(-5,MIN(5,ROUND((C18-$C18)/$C18*100,0)))) -> 0 | D8: =IF($C18=0,IF(D18>0,5,IF(D18<0,-5,0)),MAX(-5,MIN(5,ROUND((D18-$C18)/$C18*100,0)))) -> 5 | E8: =IF($C18=0,IF(E18>0,5,IF(E18<0,-5,0)),MAX(-5,MIN(5,ROUND((E18-$C18)/$C18*100,0)))) -> -5
B9: Upland | C9: =IF($C19=0,IF(C19>0,5,IF(C19<0,-5,0)),MAX(-5,MIN(5,ROUND((C19-$C19)/$C19*100,0)))) -> 0 | D9: =IF($C19=0,IF(D19>0,5,IF(D19<0,-5,0)),MAX(-5,MIN(5,ROUND((D19-$C19)/$C19*100,0)))) -> 5 | E9: =IF($C19=0,IF(E19>0,5,IF(E19<0,-5,0)),MAX(-5,MIN(5,ROUND((E19-$C19)/$C19*100,0)))) -> -5
A12: RESTORED ACRES BY SCENARIO (acres) | B12: Restored Acres
B13: Region | C13: 50% Restoration (Baseline) | D13: 100% Restoration | E13: 25% Restoration
B14: Delta-Wide | C14: =SUM(C15:C19) -> 608339.11 | D14: =SUM(D15:D19) -> 1150076.1 | E14: =SUM(E15:E19) -> 165739.11
B15: Suisun | C15: ='Restoration ($) Combined'!Q51 -> 41914.112 | D15: ='Restoration ($) Combined'!Q4 -> 41914.112 | E15: ='Restoration ($) Combined'!Q94 -> 41914.112
B16: Central | C16: =SUM('Restoration ($) Combined'!Q52:Q58)+'Restoration ($) Combined'!Q67 -> 42274 | D16: =SUM('Restoration ($) Combined'!Q5:Q11)+'Restoration ($) Combined'!Q20 -> 42274 | E16: =SUM('Restoration ($) Combined'!Q95:Q101)+'Restoration ($) Combined'!Q110 -> 29367
B17: North | C17: =SUM('Restoration ($) Combined'!Q59:Q66) -> 0 | D17: =SUM('Restoration ($) Combined'!Q12:Q19) -> 61120 | E17: =SUM('Restoration ($) Combined'!Q102:Q109) -> 0
B18: South | C18: ='Restoration ($) Combined'!Q68+SUM('Restoration ($) Combined'!Q69:Q89) -> 62088 | D18: ='Restoration ($) Combined'!Q21+SUM('Restoration ($) Combined'!Q22:Q42) -> 146801 | E18: ='Restoration ($) Combined'!Q111+SUM('Restoration ($) Combined'!Q112:Q130) -> 28299
B19: Upland | C19: =SUM('50% Restoration ($)'!D42:D44) -> 462063 | D19: =SUM('Restoration ($) Combined'!Q43:Q45) -> 857967 | E19: =SUM('Restoration ($) Combined'!Q131:Q133) -> 66159
A22: RANKINGS — Restored Acres (vs 50% Baseline)
A23: Delta-Wide | E23: Suisun | I23: Central | M23: North | Q23: South | U23: Upland
A24: Results | B24: Ranking | C24: Scale | E24: Results | F24: Ranking | G24: Scale | I24: Results | J24: Ranking | K24: Scale | M24: Results | N24: Ranking | O24: Scale | Q24: Results | R24: Ranking | S24: Scale | U24: Results | V24: Ranking | W24: Scale
A25: =_xlfn.TEXTJOIN(", ",TRUE,IF($C$4=B25,$C$3&" ("&TEXT($C$14,"#,##0")&" ac)",""),IF($D$4=B25,$D$3,""),IF($E$4=B25,$E$3,"")) -> 100% Restoration | B25: 5 | C25: greater than or equal to 5% more acres | E25: =_xlfn.TEXTJOIN(", ",TRUE,IF($C$5=F25,$C$3&" ("&TEXT($C$15,"#,##0")&" ac)",""),IF($D$5=F25,$D$3,""),IF($E$5=F25,$E$3,"")) | F25: 5 | G25: greater than or equal to 5% more acres | I25: =_xlfn.TEXTJOIN(", ",TRUE,IF($C$6=J25,$C$3&" ("&TEXT($C$16,"#,##0")&" ac)",""),IF($D$6=J25,$D$3,""),IF($E$6=J25,$E$3,"")) | J25: 5 | K25: greater than or equal to 5% more acres | M25: =_xlfn.TEXTJOIN(", ",TRUE,IF($C$7=N25,$C$3&" ("&TEXT($C$17,"#,##0")&" ac)",""),IF($D$7=N25,$D$3,""),IF($E$7=N25,$E$3,"")) -> 100% Restoration | N25: 5 | O25: greater than or equal to 5% more acres | Q25: =_xlfn.TEXTJOIN(", ",TRUE,IF($C$8=R25,$C$3&" ("&TEXT($C$18,"#,##0")&" ac)",""),IF($D$8=R25,$D$3,""),IF($E$8=R25,$E$3,"")) -> 100% Restoration | R25: 5 | S25: greater than or equal to 5% more acres | U25: =_xlfn.TEXTJOIN(", ",TRUE,IF($C$9=V25,$C$3&" ("&TEXT($C$19,"#,##0")&" ac)",""),IF($D$9=V25,$D$3,""),IF($E$9=V25,$E$3,"")) -> 100% Restoration | V25: 5 | W25: greater than or equal to 5% more acres
A26: =_xlfn.TEXTJOIN(", ",TRUE,IF($C$4=B26,$C$3&" ("&TEXT($C$14,"#,##0")&" ac)",""),IF($D$4=B26,$D$3,""),IF($E$4=B26,$E$3,"")) | B26: 4 | C26: 4% more | E26: =_xlfn.TEXTJOIN(", ",TRUE,IF($C$5=F26,$C$3&" ("&TEXT($C$15,"#,##0")&" ac)",""),IF($D$5=F26,$D$3,""),IF($E$5=F26,$E$3,"")) | F26: 4 | G26: 4% more | I26: =_xlfn.TEXTJOIN(", ",TRUE,IF($C$6=J26,$C$3&" ("&TEXT($C$16,"#,##0")&" ac)",""),IF($D$6=J26,$D$3,""),IF($E$6=J26,$E$3,"")) | J26: 4 | K26: 4% more | M26: =_xlfn.TEXTJOIN(", ",TRUE,IF($C$7=N26,$C$3&" ("&TEXT($C$17,"#,##0")&" ac)",""),IF($D$7=N26,$D$3,""),IF($E$7=N26,$E$3,"")) | N26: 4 | O26: 4% more | Q26: =_xlfn.TEXTJOIN(", ",TRUE,IF($C$8=R26,$C$3&" ("&TEXT($C$18,"#,##0")&" ac)",""),IF($D$8=R26,$D$3,""),IF($E$8=R26,$E$3,"")) | R26: 4 | S26: 4% more | U26: =_xlfn.TEXTJOIN(", ",TRUE,IF($C$9=V26,$C$3&" ("&TEXT($C$19,"#,##0")&" ac)",""),IF($D$9=V26,$D$3,""),IF($E$9=V26,$E$3,"")) | V26: 4 | W26: 4% more
A27: =_xlfn.TEXTJOIN(", ",TRUE,IF($C$4=B27,$C$3&" ("&TEXT($C$14,"#,##0")&" ac)",""),IF($D$4=B27,$D$3,""),IF($E$4=B27,$E$3,"")) | B27: 3 | C27: 3% more | E27: =_xlfn.TEXTJOIN(", ",TRUE,IF($C$5=F27,$C$3&" ("&TEXT($C$15,"#,##0")&" ac)",""),IF($D$5=F27,$D$3,""),IF($E$5=F27,$E$3,"")) | F27: 3 | G27: 3% more | I27: =_xlfn.TEXTJOIN(", ",TRUE,IF($C$6=J27,$C$3&" ("&TEXT($C$16,"#,##0")&" ac)",""),IF($D$6=J27,$D$3,""),IF($E$6=J27,$E$3,"")) | J27: 3 | K27: 3% more | M27: =_xlfn.TEXTJOIN(", ",TRUE,IF($C$7=N27,$C$3&" ("&TEXT($C$17,"#,##0")&" ac)",""),IF($D$7=N27,$D$3,""),IF($E$7=N27,$E$3,"")) | N27: 3 | O27: 3% more | Q27: =_xlfn.TEXTJOIN(", ",TRUE,IF($C$8=R27,$C$3&" ("&TEXT($C$18,"#,##0")&" ac)",""),IF($D$8=R27,$D$3,""),IF($E$8=R27,$E$3,"")) | R27: 3 | S27: 3% more | U27: =_xlfn.TEXTJOIN(", ",TRUE,IF($C$9=V27,$C$3&" ("&TEXT($C$19,"#,##0")&" ac)",""),IF($D$9=V27,$D$3,""),IF($E$9=V27,$E$3,"")) | V27: 3 | W27: 3% more
A28: =_xlfn.TEXTJOIN(", ",TRUE,IF($C$4=B28,$C$3&" ("&TEXT($C$14,"#,##0")&" ac)",""),IF($D$4=B28,$D$3,""),IF($E$4=B28,$E$3,"")) | B28: 2 | C28: 2% more | E28: =_xlfn.TEXTJOIN(", ",TRUE,IF($C$5=F28,$C$3&" ("&TEXT($C$15,"#,##0")&" ac)",""),IF($D$5=F28,$D$3,""),IF($E$5=F28,$E$3,"")) | F28: 2 | G28: 2% more | I28: =_xlfn.TEXTJOIN(", ",TRUE,IF($C$6=J28,$C$3&" ("&TEXT($C$16,"#,##0")&" ac)",""),IF($D$6=J28,$D$3,""),IF($E$6=J28,$E$3,"")) | J28: 2 | K28: 2% more | M28: =_xlfn.TEXTJOIN(", ",TRUE,IF($C$7=N28,$C$3&" ("&TEXT($C$17,"#,##0")&" ac)",""),IF($D$7=N28,$D$3,""),IF($E$7=N28,$E$3,"")) | N28: 2 | O28: 2% more | Q28: =_xlfn.TEXTJOIN(", ",TRUE,IF($C$8=R28,$C$3&" ("&TEXT($C$18,"#,##0")&" ac)",""),IF($D$8=R28,$D$3,""),IF($E$8=R28,$E$3,"")) | R28: 2 | S28: 2% more | U28: =_xlfn.TEXTJOIN(", ",TRUE,IF($C$9=V28,$C$3&" ("&TEXT($C$19,"#,##0")&" ac)",""),IF($D$9=V28,$D$3,""),IF($E$9=V28,$E$3,"")) | V28: 2 | W28: 2% more
A29: =_xlfn.TEXTJOIN(", ",TRUE,IF($C$4=B29,$C$3&" ("&TEXT($C$14,"#,##0")&" ac)",""),IF($D$4=B29,$D$3,""),IF($E$4=B29,$E$3,"")) | B29: 1 | C29: 1% more than baseline | E29: =_xlfn.TEXTJOIN(", ",TRUE,IF($C$5=F29,$C$3&" ("&TEXT($C$15,"#,##0")&" ac)",""),IF($D$5=F29,$D$3,""),IF($E$5=F29,$E$3,"")) | F29: 1 | G29: 1% more than baseline | I29: =_xlfn.TEXTJOIN(", ",TRUE,IF($C$6=J29,$C$3&" ("&TEXT($C$16,"#,##0")&" ac)",""),IF($D$6=J29,$D$3,""),IF($E$6=J29,$E$3,"")) | J29: 1 | K29: 1% more than baseline | M29: =_xlfn.TEXTJOIN(", ",TRUE,IF($C$7=N29,$C$3&" ("&TEXT($C$17,"#,##0")&" ac)",""),IF($D$7=N29,$D$3,""),IF($E$7=N29,$E$3,"")) | N29: 1 | O29: 1% more than baseline | Q29: =_xlfn.TEXTJOIN(", ",TRUE,IF($C$8=R29,$C$3&" ("&TEXT($C$18,"#,##0")&" ac)",""),IF($D$8=R29,$D$3,""),IF($E$8=R29,$E$3,"")) | R29: 1 | S29: 1% more than baseline | U29: =_xlfn.TEXTJOIN(", ",TRUE,IF($C$9=V29,$C$3&" ("&TEXT($C$19,"#,##0")&" ac)",""),IF($D$9=V29,$D$3,""),IF($E$9=V29,$E$3,"")) | V29: 1 | W29: 1% more than baseline
A30: =_xlfn.TEXTJOIN(", ",TRUE,IF($C$4=B30,$C$3&" ("&TEXT($C$14,"#,##0")&" ac)",""),IF($D$4=B30,$D$3,""),IF($E$4=B30,$E$3,"")) -> 50% Restoration (Baseline) (608,339 ac) | B30: 0 | C30: No change from baseline | E30: =_xlfn.TEXTJOIN(", ",TRUE,IF($C$5=F30,$C$3&" ("&TEXT($C$15,"#,##0")&" ac)",""),IF($D$5=F30,$D$3,""),IF($E$5=F30,$E$3,"")) -> 50% Restoration (Baseline) (41,914 ac), 100% Restoration, 25% Restoration | F30: 0 | G30: No change from baseline | I30: =_xlfn.TEXTJOIN(", ",TRUE,IF($C$6=J30,$C$3&" ("&TEXT($C$16,"#,##0")&" ac)",""),IF($D$6=J30,$D$3,""),IF($E$6=J30,$E$3,"")) -> 50% Restoration (Baseline) (42,274 ac), 100% Restoration | J30: 0 | K30: No change from baseline | M30: =_xlfn.TEXTJOIN(", ",TRUE,IF($C$7=N30,$C$3&" ("&TEXT($C$17,"#,##0")&" ac)",""),IF($D$7=N30,$D$3,""),IF($E$7=N30,$E$3,"")) -> 50% Restoration (Baseline) (0 ac), 25% Restoration | N30: 0 | O30: No change from baseline | Q30: =_xlfn.TEXTJOIN(", ",TRUE,IF($C$8=R30,$C$3&" ("&TEXT($C$18,"#,##0")&" ac)",""),IF($D$8=R30,$D$3,""),IF($E$8=R30,$E$3,"")) -> 50% Restoration (Baseline) (62,088 ac) | R30: 0 | S30: No change from baseline | U30: =_xlfn.TEXTJOIN(", ",TRUE,IF($C$9=V30,$C$3&" ("&TEXT($C$19,"#,##0")&" ac)",""),IF($D$9=V30,$D$3,""),IF($E$9=V30,$E$3,"")) -> 50% Restoration (Baseline) (462,063 ac) | V30: 0 | W30: No change from baseline
A31: =_xlfn.TEXTJOIN(", ",TRUE,IF($C$4=B31,$C$3&" ("&TEXT($C$14,"#,##0")&" ac)",""),IF($D$4=B31,$D$3,""),IF($E$4=B31,$E$3,"")) | B31: -1 | C31: 1% less than baseline | E31: =_xlfn.TEXTJOIN(", ",TRUE,IF($C$5=F31,$C$3&" ("&TEXT($C$15,"#,##0")&" ac)",""),IF($D$5=F31,$D$3,""),IF($E$5=F31,$E$3,"")) | F31: -1 | G31: 1% less than baseline | I31: =_xlfn.TEXTJOIN(", ",TRUE,IF($C$6=J31,$C$3&" ("&TEXT($C$16,"#,##0")&" ac)",""),IF($D$6=J31,$D$3,""),IF($E$6=J31,$E$3,"")) | J31: -1 | K31: 1% less than baseline | M31: =_xlfn.TEXTJOIN(", ",TRUE,IF($C$7=N31,$C$3&" ("&TEXT($C$17,"#,##0")&" ac)",""),IF($D$7=N31,$D$3,""),IF($E$7=N31,$E$3,"")) | N31: -1 | O31: 1% less than baseline | Q31: =_xlfn.TEXTJOIN(", ",TRUE,IF($C$8=R31,$C$3&" ("&TEXT($C$18,"#,##0")&" ac)",""),IF($D$8=R31,$D$3,""),IF($E$8=R31,$E$3,"")) | R31: -1 | S31: 1% less than baseline | U31: =_xlfn.TEXTJOIN(", ",TRUE,IF($C$9=V31,$C$3&" ("&TEXT($C$19,"#,##0")&" ac)",""),IF($D$9=V31,$D$3,""),IF($E$9=V31,$E$3,"")) | V31: -1 | W31: 1% less than baseline
A32: =_xlfn.TEXTJOIN(", ",TRUE,IF($C$4=B32,$C$3&" ("&TEXT($C$14,"#,##0")&" ac)",""),IF($D$4=B32,$D$3,""),IF($E$4=B32,$E$3,"")) | B32: -2 | C32: 2% less | E32: =_xlfn.TEXTJOIN(", ",TRUE,IF($C$5=F32,$C$3&" ("&TEXT($C$15,"#,##0")&" ac)",""),IF($D$5=F32,$D$3,""),IF($E$5=F32,$E$3,"")) | F32: -2 | G32: 2% less | I32: =_xlfn.TEXTJOIN(", ",TRUE,IF($C$6=J32,$C$3&" ("&TEXT($C$16,"#,##0")&" ac)",""),IF($D$6=J32,$D$3,""),IF($E$6=J32,$E$3,"")) | J32: -2 | K32: 2% less | M32: =_xlfn.TEXTJOIN(", ",TRUE,IF($C$7=N32,$C$3&" ("&TEXT($C$17,"#,##0")&" ac)",""),IF($D$7=N32,$D$3,""),IF($E$7=N32,$E$3,"")) | N32: -2 | O32: 2% less | Q32: =_xlfn.TEXTJOIN(", ",TRUE,IF($C$8=R32,$C$3&" ("&TEXT($C$18,"#,##0")&" ac)",""),IF($D$8=R32,$D$3,""),IF($E$8=R32,$E$3,"")) | R32: -2 | S32: 2% less | U32: =_xlfn.TEXTJOIN(", ",TRUE,IF($C$9=V32,$C$3&" ("&TEXT($C$19,"#,##0")&" ac)",""),IF($D$9=V32,$D$3,""),IF($E$9=V32,$E$3,"")) | V32: -2 | W32: 2% less
A33: =_xlfn.TEXTJOIN(", ",TRUE,IF($C$4=B33,$C$3&" ("&TEXT($C$14,"#,##0")&" ac)",""),IF($D$4=B33,$D$3,""),IF($E$4=B33,$E$3,"")) | B33: -3 | C33: 3% less | E33: =_xlfn.TEXTJOIN(", ",TRUE,IF($C$5=F33,$C$3&" ("&TEXT($C$15,"#,##0")&" ac)",""),IF($D$5=F33,$D$3,""),IF($E$5=F33,$E$3,"")) | F33: -3 | G33: 3% less | I33: =_xlfn.TEXTJOIN(", ",TRUE,IF($C$6=J33,$C$3&" ("&TEXT($C$16,"#,##0")&" ac)",""),IF($D$6=J33,$D$3,""),IF($E$6=J33,$E$3,"")) | J33: -3 | K33: 3% less | M33: =_xlfn.TEXTJOIN(", ",TRUE,IF($C$7=N33,$C$3&" ("&TEXT($C$17,"#,##0")&" ac)",""),IF($D$7=N33,$D$3,""),IF($E$7=N33,$E$3,"")) | N33: -3 | O33: 3% less | Q33: =_xlfn.TEXTJOIN(", ",TRUE,IF($C$8=R33,$C$3&" ("&TEXT($C$18,"#,##0")&" ac)",""),IF($D$8=R33,$D$3,""),IF($E$8=R33,$E$3,"")) | R33: -3 | S33: 3% less | U33: =_xlfn.TEXTJOIN(", ",TRUE,IF($C$9=V33,$C$3&" ("&TEXT($C$19,"#,##0")&" ac)",""),IF($D$9=V33,$D$3,""),IF($E$9=V33,$E$3,"")) | V33: -3 | W33: 3% less
A34: =_xlfn.TEXTJOIN(", ",TRUE,IF($C$4=B34,$C$3&" ("&TEXT($C$14,"#,##0")&" ac)",""),IF($D$4=B34,$D$3,""),IF($E$4=B34,$E$3,"")) | B34: -4 | C34: 4% less | E34: =_xlfn.TEXTJOIN(", ",TRUE,IF($C$5=F34,$C$3&" ("&TEXT($C$15,"#,##0")&" ac)",""),IF($D$5=F34,$D$3,""),IF($E$5=F34,$E$3,"")) | F34: -4 | G34: 4% less | I34: =_xlfn.TEXTJOIN(", ",TRUE,IF($C$6=J34,$C$3&" ("&TEXT($C$16,"#,##0")&" ac)",""),IF($D$6=J34,$D$3,""),IF($E$6=J34,$E$3,"")) | J34: -4 | K34: 4% less | M34: =_xlfn.TEXTJOIN(", ",TRUE,IF($C$7=N34,$C$3&" ("&TEXT($C$17,"#,##0")&" ac)",""),IF($D$7=N34,$D$3,""),IF($E$7=N34,$E$3,"")) | N34: -4 | O34: 4% less | Q34: =_xlfn.TEXTJOIN(", ",TRUE,IF($C$8=R34,$C$3&" ("&TEXT($C$18,"#,##0")&" ac)",""),IF($D$8=R34,$D$3,""),IF($E$8=R34,$E$3,"")) | R34: -4 | S34: 4% less | U34: =_xlfn.TEXTJOIN(", ",TRUE,IF($C$9=V34,$C$3&" ("&TEXT($C$19,"#,##0")&" ac)",""),IF($D$9=V34,$D$3,""),IF($E$9=V34,$E$3,"")) | V34: -4 | W34: 4% less
A35: =_xlfn.TEXTJOIN(", ",TRUE,IF($C$4=B35,$C$3&" ("&TEXT($C$14,"#,##0")&" ac)",""),IF($D$4=B35,$D$3,""),IF($E$4=B35,$E$3,"")) -> 25% Restoration | B35: -5 | C35: greater than or equal to 5% less acres | E35: =_xlfn.TEXTJOIN(", ",TRUE,IF($C$5=F35,$C$3&" ("&TEXT($C$15,"#,##0")&" ac)",""),IF($D$5=F35,$D$3,""),IF($E$5=F35,$E$3,"")) | F35: -5 | G35: greater than or equal to 5% less acres | I35: =_xlfn.TEXTJOIN(", ",TRUE,IF($C$6=J35,$C$3&" ("&TEXT($C$16,"#,##0")&" ac)",""),IF($D$6=J35,$D$3,""),IF($E$6=J35,$E$3,"")) -> 25% Restoration | J35: -5 | K35: greater than or equal to 5% less acres | M35: =_xlfn.TEXTJOIN(", ",TRUE,IF($C$7=N35,$C$3&" ("&TEXT($C$17,"#,##0")&" ac)",""),IF($D$7=N35,$D$3,""),IF($E$7=N35,$E$3,"")) | N35: -5 | O35: greater than or equal to 5% less acres | Q35: =_xlfn.TEXTJOIN(", ",TRUE,IF($C$8=R35,$C$3&" ("&TEXT($C$18,"#,##0")&" ac)",""),IF($D$8=R35,$D$3,""),IF($E$8=R35,$E$3,"")) -> 25% Restoration | R35: -5 | S35: greater than or equal to 5% less acres | U35: =_xlfn.TEXTJOIN(", ",TRUE,IF($C$9=V35,$C$3&" ("&TEXT($C$19,"#,##0")&" ac)",""),IF($D$9=V35,$D$3,""),IF($E$9=V35,$E$3,"")) -> 25% Restoration | V35: -5 | W35: greater than or equal to 5% less acres

Sheet Overall $
C2: ECOSYSTEM SERVICE $ SCORES | H2: Notes: 1. BAU baseline is derived from CA Protected Areas Shapefile acres broken down by region (as current available inventory). 25%, 50%, and 100% Restoration measures are measured as differences from BAU (current acreage inventory). Citation: GreenInfo Network. (2026). California Protected Areas Database (CPAD), version 2024 [GIS shapefile]. www.calands.org
C3: REGION | D3: 25% Restoration | E3: 50% Restoration | F3: 100% Restoration | G3: BAU Baseline | M3: RECREATION: ECONOMY SCORE (D) — Restoration Scenarios NGW and ECO
B4: AMENITY/RECREATION (SP Day Use & Boating) | C4: Delta-Wide | D4: =IF($G35=0,IF(F35>0,5,IF(F35<0,-5,0)),MAX(-5,MIN(5,ROUND((F35-$G35)/$G35*100,0)))) -> 5 | E4: =IF($G35=0,IF(D35>0,5,IF(D35<0,-5,0)),MAX(-5,MIN(5,ROUND((D35-$G35)/$G35*100,0)))) -> 5 | F4: =IF($G35=0,IF(E35>0,5,IF(E35<0,-5,0)),MAX(-5,MIN(5,ROUND((E35-$G35)/$G35*100,0)))) -> 5 | G4: =IF($G35=0,IF(G35>0,5,IF(G35<0,-5,0)),MAX(-5,MIN(5,ROUND((G35-$G35)/$G35*100,0)))) -> 0 | M4: Workflow: (1) Each activity = its Delta-Wide ecosystem service $ score (-5 to 5) from the grid at left. No sub-region rows, to avoid double counting. (2) Sum the activity scores. (3) Divide by # of activities = Economy Score (D). Scores are % change in $/yr vs BAU Baseline, rounded, capped at ±5. Final Recreation Score = (A Salinity + B Temperature + C Habitat + D Economy) / 4.
C5: Suisun | D5: =IF($G36=0,IF(F36>0,5,IF(F36<0,-5,0)),MAX(-5,MIN(5,ROUND((F36-$G36)/$G36*100,0)))) -> 5 | E5: =IF($G36=0,IF(D36>0,5,IF(D36<0,-5,0)),MAX(-5,MIN(5,ROUND((D36-$G36)/$G36*100,0)))) -> 5 | F5: =IF($G36=0,IF(E36>0,5,IF(E36<0,-5,0)),MAX(-5,MIN(5,ROUND((E36-$G36)/$G36*100,0)))) -> 5 | G5: =IF($G36=0,IF(G36>0,5,IF(G36<0,-5,0)),MAX(-5,MIN(5,ROUND((G36-$G36)/$G36*100,0)))) -> 0
C6: Central | D6: =IF($G37=0,IF(F37>0,5,IF(F37<0,-5,0)),MAX(-5,MIN(5,ROUND((F37-$G37)/$G37*100,0)))) -> 5 | E6: =IF($G37=0,IF(D37>0,5,IF(D37<0,-5,0)),MAX(-5,MIN(5,ROUND((D37-$G37)/$G37*100,0)))) -> 5 | F6: =IF($G37=0,IF(E37>0,5,IF(E37<0,-5,0)),MAX(-5,MIN(5,ROUND((E37-$G37)/$G37*100,0)))) -> 5 | G6: =IF($G37=0,IF(G37>0,5,IF(G37<0,-5,0)),MAX(-5,MIN(5,ROUND((G37-$G37)/$G37*100,0)))) -> 0 | M6: ACTIVITY | N6: SOURCE | O6: 25% Restoration | P6: 50% Restoration | Q6: 100% Restoration | R6: BAU Baseline
C7: North | D7: =IF($G38=0,IF(F38>0,5,IF(F38<0,-5,0)),MAX(-5,MIN(5,ROUND((F38-$G38)/$G38*100,0)))) -> 0 | E7: =IF($G38=0,IF(D38>0,5,IF(D38<0,-5,0)),MAX(-5,MIN(5,ROUND((D38-$G38)/$G38*100,0)))) -> 0 | F7: =IF($G38=0,IF(E38>0,5,IF(E38<0,-5,0)),MAX(-5,MIN(5,ROUND((E38-$G38)/$G38*100,0)))) -> 5 | G7: =IF($G38=0,IF(G38>0,5,IF(G38<0,-5,0)),MAX(-5,MIN(5,ROUND((G38-$G38)/$G38*100,0)))) -> 0 | M7: Day Use & Boating | N7: Row 4 | O7: =D$4 -> 5 | P7: =E$4 -> 5 | Q7: =F$4 -> 5 | R7: =G$4 -> 0
C8: South | D8: =IF($G39=0,IF(F39>0,5,IF(F39<0,-5,0)),MAX(-5,MIN(5,ROUND((F39-$G39)/$G39*100,0)))) -> 5 | E8: =IF($G39=0,IF(D39>0,5,IF(D39<0,-5,0)),MAX(-5,MIN(5,ROUND((D39-$G39)/$G39*100,0)))) -> 5 | F8: =IF($G39=0,IF(E39>0,5,IF(E39<0,-5,0)),MAX(-5,MIN(5,ROUND((E39-$G39)/$G39*100,0)))) -> 5 | G8: =IF($G39=0,IF(G39>0,5,IF(G39<0,-5,0)),MAX(-5,MIN(5,ROUND((G39-$G39)/$G39*100,0)))) -> 0 | M8: Birding | N8: Row 11 | O8: =D$11 -> 5 | P8: =E$11 -> 5 | Q8: =F$11 -> 5 | R8: =G$11 -> 0
C9: Upland | D9: =IF($G40=0,IF(F40>0,5,IF(F40<0,-5,0)),MAX(-5,MIN(5,ROUND((F40-$G40)/$G40*100,0)))) -> 5 | E9: =IF($G40=0,IF(D40>0,5,IF(D40<0,-5,0)),MAX(-5,MIN(5,ROUND((D40-$G40)/$G40*100,0)))) -> 5 | F9: =IF($G40=0,IF(E40>0,5,IF(E40<0,-5,0)),MAX(-5,MIN(5,ROUND((E40-$G40)/$G40*100,0)))) -> 5 | G9: =IF($G40=0,IF(G40>0,5,IF(G40<0,-5,0)),MAX(-5,MIN(5,ROUND((G40-$G40)/$G40*100,0)))) -> 0 | M9: Waterfowl | N9: Row 18 | O9: =D$18 -> 5 | P9: =E$18 -> 5 | Q9: =F$18 -> 5 | R9: =G$18 -> 0
C10: REGION | D10: 25% Restoration | E10: 50% Restoration | F10: 100% Restoration | G10: BAU Baseline | M10: Angling | N10: Row 25 | O10: =D$25 -> 5 | P10: =E$25 -> 5 | Q10: =F$25 -> 5 | R10: =G$25 -> 0
B11: BIODIVERSITY (Birding) | C11: Delta-Wide | D11: =IF($G43=0,IF(F43>0,5,IF(F43<0,-5,0)),MAX(-5,MIN(5,ROUND((F43-$G43)/$G43*100,0)))) -> 5 | E11: =IF($G43=0,IF(D43>0,5,IF(D43<0,-5,0)),MAX(-5,MIN(5,ROUND((D43-$G43)/$G43*100,0)))) -> 5 | F11: =IF($G43=0,IF(E43>0,5,IF(E43<0,-5,0)),MAX(-5,MIN(5,ROUND((E43-$G43)/$G43*100,0)))) -> 5 | G11: =IF($G43=0,IF(G43>0,5,IF(G43<0,-5,0)),MAX(-5,MIN(5,ROUND((G43-$G43)/$G43*100,0)))) -> 0 | M11: Sum of scores | O11: =SUM(O7:O10) -> 20 | P11: =SUM(P7:P10) -> 20 | Q11: =SUM(Q7:Q10) -> 20 | R11: =SUM(R7:R10) -> 0
C12: Suisun | D12: =IF($G44=0,IF(F44>0,5,IF(F44<0,-5,0)),MAX(-5,MIN(5,ROUND((F44-$G44)/$G44*100,0)))) -> 5 | E12: =IF($G44=0,IF(D44>0,5,IF(D44<0,-5,0)),MAX(-5,MIN(5,ROUND((D44-$G44)/$G44*100,0)))) -> 5 | F12: =IF($G44=0,IF(E44>0,5,IF(E44<0,-5,0)),MAX(-5,MIN(5,ROUND((E44-$G44)/$G44*100,0)))) -> 5 | G12: =IF($G44=0,IF(G44>0,5,IF(G44<0,-5,0)),MAX(-5,MIN(5,ROUND((G44-$G44)/$G44*100,0)))) -> 0 | M12: # of activities | O12: =COUNT(O7:O10) -> 4 | P12: =COUNT(P7:P10) -> 4 | Q12: =COUNT(Q7:Q10) -> 4 | R12: =COUNT(R7:R10) -> 4
C13: Central | D13: =IF($G45=0,IF(F45>0,5,IF(F45<0,-5,0)),MAX(-5,MIN(5,ROUND((F45-$G45)/$G45*100,0)))) -> 5 | E13: =IF($G45=0,IF(D45>0,5,IF(D45<0,-5,0)),MAX(-5,MIN(5,ROUND((D45-$G45)/$G45*100,0)))) -> 5 | F13: =IF($G45=0,IF(E45>0,5,IF(E45<0,-5,0)),MAX(-5,MIN(5,ROUND((E45-$G45)/$G45*100,0)))) -> 5 | G13: =IF($G45=0,IF(G45>0,5,IF(G45<0,-5,0)),MAX(-5,MIN(5,ROUND((G45-$G45)/$G45*100,0)))) -> 0 | M13: ECONOMY SCORE (D) | O13: =IFERROR(O11/O12,0) -> 5 | P13: =IFERROR(P11/P12,0) -> 5 | Q13: =IFERROR(Q11/Q12,0) -> 5 | R13: =IFERROR(R11/R12,0) -> 0
C14: North | D14: =IF($G46=0,IF(F46>0,5,IF(F46<0,-5,0)),MAX(-5,MIN(5,ROUND((F46-$G46)/$G46*100,0)))) -> 0 | E14: =IF($G46=0,IF(D46>0,5,IF(D46<0,-5,0)),MAX(-5,MIN(5,ROUND((D46-$G46)/$G46*100,0)))) -> 0 | F14: =IF($G46=0,IF(E46>0,5,IF(E46<0,-5,0)),MAX(-5,MIN(5,ROUND((E46-$G46)/$G46*100,0)))) -> 5 | G14: =IF($G46=0,IF(G46>0,5,IF(G46<0,-5,0)),MAX(-5,MIN(5,ROUND((G46-$G46)/$G46*100,0)))) -> 0
C15: South | D15: =IF($G47=0,IF(F47>0,5,IF(F47<0,-5,0)),MAX(-5,MIN(5,ROUND((F47-$G47)/$G47*100,0)))) -> 5 | E15: =IF($G47=0,IF(D47>0,5,IF(D47<0,-5,0)),MAX(-5,MIN(5,ROUND((D47-$G47)/$G47*100,0)))) -> 5 | F15: =IF($G47=0,IF(E47>0,5,IF(E47<0,-5,0)),MAX(-5,MIN(5,ROUND((E47-$G47)/$G47*100,0)))) -> 5 | G15: =IF($G47=0,IF(G47>0,5,IF(G47<0,-5,0)),MAX(-5,MIN(5,ROUND((G47-$G47)/$G47*100,0)))) -> 0
C16: Upland | D16: =IF($G48=0,IF(F48>0,5,IF(F48<0,-5,0)),MAX(-5,MIN(5,ROUND((F48-$G48)/$G48*100,0)))) -> 5 | E16: =IF($G48=0,IF(D48>0,5,IF(D48<0,-5,0)),MAX(-5,MIN(5,ROUND((D48-$G48)/$G48*100,0)))) -> 5 | F16: =IF($G48=0,IF(E48>0,5,IF(E48<0,-5,0)),MAX(-5,MIN(5,ROUND((E48-$G48)/$G48*100,0)))) -> 5 | G16: =IF($G48=0,IF(G48>0,5,IF(G48<0,-5,0)),MAX(-5,MIN(5,ROUND((G48-$G48)/$G48*100,0)))) -> 0 | J16: California Protected Areas (Current Inventory) used as BAU | K16: Sum of Acres
C17: REGION | D17: 25% Restoration | E17: 50% Restoration | F17: 100% Restoration | G17: BAU Baseline | J17: Convergence Zone | K17: 23825.864
B18: RECREATIONAL HUNTING (Waterfowl) | C18: Delta-Wide | D18: =IF($G51=0,IF(F51>0,5,IF(F51<0,-5,0)),MAX(-5,MIN(5,ROUND((F51-$G51)/$G51*100,0)))) -> 5 | E18: =IF($G51=0,IF(D51>0,5,IF(D51<0,-5,0)),MAX(-5,MIN(5,ROUND((D51-$G51)/$G51*100,0)))) -> 5 | F18: =IF($G51=0,IF(E51>0,5,IF(E51<0,-5,0)),MAX(-5,MIN(5,ROUND((E51-$G51)/$G51*100,0)))) -> 5 | G18: =IF($G51=0,IF(G51>0,5,IF(G51<0,-5,0)),MAX(-5,MIN(5,ROUND((G51-$G51)/$G51*100,0)))) -> 0 | J18: North Delta | K18: 56014.074
C19: Suisun | D19: =IF($G52=0,IF(F52>0,5,IF(F52<0,-5,0)),MAX(-5,MIN(5,ROUND((F52-$G52)/$G52*100,0)))) -> 5 | E19: =IF($G52=0,IF(D52>0,5,IF(D52<0,-5,0)),MAX(-5,MIN(5,ROUND((D52-$G52)/$G52*100,0)))) -> 5 | F19: =IF($G52=0,IF(E52>0,5,IF(E52<0,-5,0)),MAX(-5,MIN(5,ROUND((E52-$G52)/$G52*100,0)))) -> 5 | G19: =IF($G52=0,IF(G52>0,5,IF(G52<0,-5,0)),MAX(-5,MIN(5,ROUND((G52-$G52)/$G52*100,0)))) -> 0 | J19: South Delta | K19: 10321.817
C20: Central | D20: =IF($G53=0,IF(F53>0,5,IF(F53<0,-5,0)),MAX(-5,MIN(5,ROUND((F53-$G53)/$G53*100,0)))) -> 5 | E20: =IF($G53=0,IF(D53>0,5,IF(D53<0,-5,0)),MAX(-5,MIN(5,ROUND((D53-$G53)/$G53*100,0)))) -> 5 | F20: =IF($G53=0,IF(E53>0,5,IF(E53<0,-5,0)),MAX(-5,MIN(5,ROUND((E53-$G53)/$G53*100,0)))) -> 5 | G20: =IF($G53=0,IF(G53>0,5,IF(G53<0,-5,0)),MAX(-5,MIN(5,ROUND((G53-$G53)/$G53*100,0)))) -> 0 | J20: Suisun Marsh | K20: 18138.948
C21: North | D21: =IF($G54=0,IF(F54>0,5,IF(F54<0,-5,0)),MAX(-5,MIN(5,ROUND((F54-$G54)/$G54*100,0)))) -> 0 | E21: =IF($G54=0,IF(D54>0,5,IF(D54<0,-5,0)),MAX(-5,MIN(5,ROUND((D54-$G54)/$G54*100,0)))) -> 0 | F21: =IF($G54=0,IF(E54>0,5,IF(E54<0,-5,0)),MAX(-5,MIN(5,ROUND((E54-$G54)/$G54*100,0)))) -> 5 | G21: =IF($G54=0,IF(G54>0,5,IF(G54<0,-5,0)),MAX(-5,MIN(5,ROUND((G54-$G54)/$G54*100,0)))) -> 0 | J21: (blank)
C22: South | D22: =IF($G55=0,IF(F55>0,5,IF(F55<0,-5,0)),MAX(-5,MIN(5,ROUND((F55-$G55)/$G55*100,0)))) -> 5 | E22: =IF($G55=0,IF(D55>0,5,IF(D55<0,-5,0)),MAX(-5,MIN(5,ROUND((D55-$G55)/$G55*100,0)))) -> 5 | F22: =IF($G55=0,IF(E55>0,5,IF(E55<0,-5,0)),MAX(-5,MIN(5,ROUND((E55-$G55)/$G55*100,0)))) -> 5 | G22: =IF($G55=0,IF(G55>0,5,IF(G55<0,-5,0)),MAX(-5,MIN(5,ROUND((G55-$G55)/$G55*100,0)))) -> 0 | J22: Grand Total | K22: 108300.7
C23: Upland | D23: =IF($G56=0,IF(F56>0,5,IF(F56<0,-5,0)),MAX(-5,MIN(5,ROUND((F56-$G56)/$G56*100,0)))) -> 5 | E23: =IF($G56=0,IF(D56>0,5,IF(D56<0,-5,0)),MAX(-5,MIN(5,ROUND((D56-$G56)/$G56*100,0)))) -> 5 | F23: =IF($G56=0,IF(E56>0,5,IF(E56<0,-5,0)),MAX(-5,MIN(5,ROUND((E56-$G56)/$G56*100,0)))) -> 5 | G23: =IF($G56=0,IF(G56>0,5,IF(G56<0,-5,0)),MAX(-5,MIN(5,ROUND((G56-$G56)/$G56*100,0)))) -> 0
C24: REGION | D24: 25% Restoration | E24: 50% Restoration | F24: 100% Restoration | G24: BAU Baseline
B25: RECREATIONAL FISHING (Angling) | C25: Delta-Wide | D25: =IF($G59=0,IF(F59>0,5,IF(F59<0,-5,0)),MAX(-5,MIN(5,ROUND((F59-$G59)/$G59*100,0)))) -> 5 | E25: =IF($G59=0,IF(D59>0,5,IF(D59<0,-5,0)),MAX(-5,MIN(5,ROUND((D59-$G59)/$G59*100,0)))) -> 5 | F25: =IF($G59=0,IF(E59>0,5,IF(E59<0,-5,0)),MAX(-5,MIN(5,ROUND((E59-$G59)/$G59*100,0)))) -> 5 | G25: =IF($G59=0,IF(G59>0,5,IF(G59<0,-5,0)),MAX(-5,MIN(5,ROUND((G59-$G59)/$G59*100,0)))) -> 0
C26: Suisun | D26: =IF($G60=0,IF(F60>0,5,IF(F60<0,-5,0)),MAX(-5,MIN(5,ROUND((F60-$G60)/$G60*100,0)))) -> 5 | E26: =IF($G60=0,IF(D60>0,5,IF(D60<0,-5,0)),MAX(-5,MIN(5,ROUND((D60-$G60)/$G60*100,0)))) -> 5 | F26: =IF($G60=0,IF(E60>0,5,IF(E60<0,-5,0)),MAX(-5,MIN(5,ROUND((E60-$G60)/$G60*100,0)))) -> 5 | G26: =IF($G60=0,IF(G60>0,5,IF(G60<0,-5,0)),MAX(-5,MIN(5,ROUND((G60-$G60)/$G60*100,0)))) -> 0
C27: Central | D27: =IF($G61=0,IF(F61>0,5,IF(F61<0,-5,0)),MAX(-5,MIN(5,ROUND((F61-$G61)/$G61*100,0)))) -> 5 | E27: =IF($G61=0,IF(D61>0,5,IF(D61<0,-5,0)),MAX(-5,MIN(5,ROUND((D61-$G61)/$G61*100,0)))) -> 5 | F27: =IF($G61=0,IF(E61>0,5,IF(E61<0,-5,0)),MAX(-5,MIN(5,ROUND((E61-$G61)/$G61*100,0)))) -> 5 | G27: =IF($G61=0,IF(G61>0,5,IF(G61<0,-5,0)),MAX(-5,MIN(5,ROUND((G61-$G61)/$G61*100,0)))) -> 0
C28: North | D28: =IF($G62=0,IF(F62>0,5,IF(F62<0,-5,0)),MAX(-5,MIN(5,ROUND((F62-$G62)/$G62*100,0)))) -> 0 | E28: =IF($G62=0,IF(D62>0,5,IF(D62<0,-5,0)),MAX(-5,MIN(5,ROUND((D62-$G62)/$G62*100,0)))) -> 0 | F28: =IF($G62=0,IF(E62>0,5,IF(E62<0,-5,0)),MAX(-5,MIN(5,ROUND((E62-$G62)/$G62*100,0)))) -> 5 | G28: =IF($G62=0,IF(G62>0,5,IF(G62<0,-5,0)),MAX(-5,MIN(5,ROUND((G62-$G62)/$G62*100,0)))) -> 0
C29: South | D29: =IF($G63=0,IF(F63>0,5,IF(F63<0,-5,0)),MAX(-5,MIN(5,ROUND((F63-$G63)/$G63*100,0)))) -> 5 | E29: =IF($G63=0,IF(D63>0,5,IF(D63<0,-5,0)),MAX(-5,MIN(5,ROUND((D63-$G63)/$G63*100,0)))) -> 5 | F29: =IF($G63=0,IF(E63>0,5,IF(E63<0,-5,0)),MAX(-5,MIN(5,ROUND((E63-$G63)/$G63*100,0)))) -> 5 | G29: =IF($G63=0,IF(G63>0,5,IF(G63<0,-5,0)),MAX(-5,MIN(5,ROUND((G63-$G63)/$G63*100,0)))) -> 0
C30: Upland | D30: =IF($G64=0,IF(F64>0,5,IF(F64<0,-5,0)),MAX(-5,MIN(5,ROUND((F64-$G64)/$G64*100,0)))) -> 5 | E30: =IF($G64=0,IF(D64>0,5,IF(D64<0,-5,0)),MAX(-5,MIN(5,ROUND((D64-$G64)/$G64*100,0)))) -> 5 | F30: =IF($G64=0,IF(E64>0,5,IF(E64<0,-5,0)),MAX(-5,MIN(5,ROUND((E64-$G64)/$G64*100,0)))) -> 5 | G30: =IF($G64=0,IF(G64>0,5,IF(G64<0,-5,0)),MAX(-5,MIN(5,ROUND((G64-$G64)/$G64*100,0)))) -> 0
B33: ECOSYSTEM SERVICE VALUE BY SCENARIO (US$/yr, 2025)
B34: AMENITY/RECREATION (SP Day Use & Boating) | C34: REGION | D34: 50% Restoration | E34: 100% Restoration | F34: 25% Restoration | G34: BAU
C35: Delta-Wide | D35: =SUM(D36:D40) -> 2.4746492e+08 | E35: =SUM(E36:E40) -> 4.2839185e+08 | F35: =SUM(F36:F40) -> 82600844 | G35: =SUM(G36:G40) -> 40340929
C36: Suisun | D36: ='Restoration ($) Combined'!F51 -> 15612588 | E36: ='Restoration ($) Combined'!F4 -> 15612588 | F36: ='Restoration ($) Combined'!F94 -> 15612588 | G36: ='Overall Restoration (Acres)'!$H$19*'Restoration ($) Combined'!$F$2 -> 6756576.7
C37: Central | D37: =SUM('Restoration ($) Combined'!F52:F58)+'Restoration ($) Combined'!F67 -> 15746642 | E37: =SUM('Restoration ($) Combined'!F5:F11)+'Restoration ($) Combined'!F20 -> 15746642 | F37: =SUM('Restoration ($) Combined'!F95:F101)+'Restoration ($) Combined'!F110 -> 10938914 | G37: ='Overall Restoration (Acres)'!$I$19*'Restoration ($) Combined'!$F$2 -> 8874896.1
C38: North | D38: 20864682 | E38: =SUM('Restoration ($) Combined'!F12:F19) -> 22766589 | F38: 20864682 | G38: ='Overall Restoration (Acres)'!$J$19*'Restoration ($) Combined'!$F$2 -> 20864682
C39: South | D39: ='Restoration ($) Combined'!F68+SUM('Restoration ($) Combined'!F69:F89) -> 23127159 | E39: ='Restoration ($) Combined'!F21+SUM('Restoration ($) Combined'!F22:F42) -> 54681904 | F39: ='Restoration ($) Combined'!F111+SUM('Restoration ($) Combined'!F112:F130) -> 10541095 | G39: ='Overall Restoration (Acres)'!$K$19*'Restoration ($) Combined'!$F$2 -> 3844773.6
C40: Upland | D40: =SUM('50% Restoration ($)'!J42:J44) -> 1.7211385e+08 | E40: =SUM('Restoration ($) Combined'!F43:F45) -> 3.1958413e+08 | F40: =SUM('Restoration ($) Combined'!F131:F133) -> 24643566 | G40: ='Overall Restoration (Acres)'!$L$19*'Restoration ($) Combined'!$F$2 -> 0
B42: BIODIVERSITY (Birding) | C42: REGION | D42: 50% Restoration | E42: 100% Restoration | F42: 25% Restoration | G42: BAU
C43: Delta-Wide | D43: =SUM(D44:D48) -> 1.076385e+08 | E43: =SUM(E44:E48) -> 1.8633533e+08 | F43: =SUM(F44:F48) -> 35928451 | G43: =SUM(G44:G48) -> 17546880
C44: Suisun | D44: ='Restoration ($) Combined'!H51 -> 6790924.4 | E44: ='Restoration ($) Combined'!H4 -> 6790924.4 | F44: ='Restoration ($) Combined'!H94 -> 6790924.4 | G44: ='Overall Restoration (Acres)'!$H$19*'Restoration ($) Combined'!$H$2 -> 2938872.4
...

Sheet Overall Restoration (Acres)
A1: Habitat Type | B1: Region_Nam | C1: Region_Code | D1: Regional Acres | F1: Use These for landscape restoration | G1: Habitat / Delta-Wide Total | H1: Suisun | I1: Central | J1: North | K1: South | L1: Upland
A2: Transitional | B2: South Delta | C2: South | D2: 67259.975 | F2: Full Restoration (In-Delta ECO + NGW) (100%) | G2: Transitional | H2: =SUMIFS($D$2:$D$14,$A$2:$A$14,$G2,$C$2:$C$14,H$1) -> 0 | I2: =SUMIFS($D$2:$D$14,$A$2:$A$14,$G2,$C$2:$C$14,I$1) -> 0 | J2: =SUMIFS($D$2:$D$14,$A$2:$A$14,$G2,$C$2:$C$14,J$1) -> 80428.56 | K2: =SUMIFS($D$2:$D$14,$A$2:$A$14,$G2,$C$2:$C$14,K$1) -> 67259.975
A3: Transitional | B3: North Delta | C3: North | D3: 80428.56 | G3: Soil | H3: =SUMIFS($D$2:$D$14,$A$2:$A$14,$G3,$C$2:$C$14,H$1) -> 0 | I3: =SUMIFS($D$2:$D$14,$A$2:$A$14,$G3,$C$2:$C$14,I$1) -> 34255.257 | J3: =SUMIFS($D$2:$D$14,$A$2:$A$14,$G3,$C$2:$C$14,J$1) -> 93152.202 | K3: =SUMIFS($D$2:$D$14,$A$2:$A$14,$G3,$C$2:$C$14,K$1) -> 79914.462
A4: Soil | B4: North Delta | C4: North | D4: 93152.202 | G4: Tidal | H4: =41720 -> 41720 | I4: =SUMIFS($D$2:$D$14,$A$2:$A$14,$G4,$C$2:$C$14,I$1) -> 3324.5082 | J4: =SUMIFS($D$2:$D$14,$A$2:$A$14,$G4,$C$2:$C$14,J$1) -> 25938.422 | K4: =SUMIFS($D$2:$D$14,$A$2:$A$14,$G4,$C$2:$C$14,K$1) -> 0
A5: Soil | B5: South Delta | C5: South | D5: 79914.462 | G5: MW | H5: =SUMIFS($D$2:$D$14,$A$2:$A$14,$G5,$C$2:$C$14,H$1) -> 0 | I5: =SUMIFS($D$2:$D$14,$A$2:$A$14,$G5,$C$2:$C$14,I$1) -> 29367 | J5: =SUMIFS($D$2:$D$14,$A$2:$A$14,$G5,$C$2:$C$14,J$1) -> 84385 | K5: =SUMIFS($D$2:$D$14,$A$2:$A$14,$G5,$C$2:$C$14,K$1) -> 130507 | M5: Franks Tract (ECO) | N5: 1380
A6: Soil | B6: Convergence Zone | C6: Central | D6: 34255.257 | F6: Upland Upper Bound (100%) | G6: Meadows | L6: =SUMIFS($D$2:$D$14,$A$2:$A$14,$G6,$C$2:$C$14,L$1) -> 347591
A7: Tidal | B7: North Delta | C7: North | D7: 25938.422 | G7: Floodplain | L7: =SUMIFS($D$2:$D$14,$A$2:$A$14,$G7,$C$2:$C$14,L$1) -> 303372
A8: Tidal | B8: Convergence Zone | C8: Central | D8: 3324.5082 | G8: Wetland | L8: 207004
A9: Tidal | B9: Suisun Marsh | C9: Suisun | D9: 41914.112 | F9: Upland Middle Bound (50%) | G9: Meadows | L9: =AVERAGE(L6,L12) -> 179588.5
A10: MW | B10: North Delta | C10: North | D10: 84385 | G10: Floodplain | L10: =AVERAGE(L7,L13) -> 154866
A11: MW | B11: Convergence Zone | C11: Central | D11: 29367 | G11: Wetland | L11: =AVERAGE(L8,L14) -> 127608.5
A12: MW | B12: South Delta | C12: South | D12: 130507 | F12: Upland Lower Bound (25%) | G12: Meadows | L12: 11586
A13: Meadows | B13: Non-Delta | C13: Upland | D13: 347591 | G13: Floodplain | L13: 6360 | O13: RESTORED ACRES SCORES (-5 to 5 vs BAU Protected Areas, row 19)
A14: Floodplain | B14: Non-Delta | C14: Upland | D14: 303372 | G14: Wetland | L14: 48213 | O14: SCENARIO | P14: BAU Baseline (Delta-Wide acres) | Q14: Delta-Wide | R14: Suisun | S14: Central | T14: North | U14: South | V14: Upland
A15: Wetlands | B15: Non-Delta | C15: Upland | D15: 207004 | F15: NGW Total (Upper, 100%) | G15: =SUM(H15:L15) -> 1528219.4 | H15: =SUM(H$2:H$5)+SUM(H$6:H$8) -> 41720 | I15: =SUM(I$2:I$5)+SUM(I$6:I$8) -> 66946.765 | J15: =SUM(J$2:J$5)+SUM(J$6:J$8) -> 283904.18 | K15: =SUM(K$2:K$5)+SUM(K$6:K$8) -> 277681.44 | L15: =SUM(L$2:L$5)+SUM(L$6:L$8) -> 857967 | O15: =F15 -> NGW Total (Upper, 100%) | P15: =$G$19 -> 108300.7 | Q15: =IF($P15=0,IF(N($G15)>0,5,0),MAX(-5,MIN(5,ROUND(N($G15)/$P15*100,0)))) -> 5 | R15: =IF(H$19=0,IF(N(H15)>0,5,0),MAX(-5,MIN(5,ROUND(N(H15)/H$19*100,0)))) -> 5 | S15: =IF(I$19=0,IF(N(I15)>0,5,0),MAX(-5,MIN(5,ROUND(N(I15)/I$19*100,0)))) -> 5 | T15: =IF(J$19=0,IF(N(J15)>0,5,0),MAX(-5,MIN(5,ROUND(N(J15)/J$19*100,0)))) -> 5 | U15: =IF(K$19=0,IF(N(K15)>0,5,0),MAX(-5,MIN(5,ROUND(N(K15)/K$19*100,0)))) -> 5 | V15: =IF(L$19=0,IF(N(L15)>0,5,0),MAX(-5,MIN(5,ROUND(N(L15)/L$19*100,0)))) -> 5
F16: NGW Total (Middle, 50%) | G16: =SUM(H16:L16) -> 1132315.4 | H16: =SUM(H$2:H$5)+SUM(H$9:H$11) -> 41720 | I16: =SUM(I$2:I$5)+SUM(I$9:I$11) -> 66946.765 | J16: =SUM(J$2:J$5)+SUM(J$9:J$11) -> 283904.18 | K16: =SUM(K$2:K$5)+SUM(K$9:K$11) -> 277681.44 | L16: =SUM(L$2:L$5)+SUM(L$9:L$11) -> 462063 | O16: =F16 -> NGW Total (Middle, 50%) | P16: =$G$19 -> 108300.7 | Q16: =IF($P16=0,IF(N($G16)>0,5,0),MAX(-5,MIN(5,ROUND(N($G16)/$P16*100,0)))) -> 5 | R16: =IF(H$19=0,IF(N(H16)>0,5,0),MAX(-5,MIN(5,ROUND(N(H16)/H$19*100,0)))) -> 5 | S16: =IF(I$19=0,IF(N(I16)>0,5,0),MAX(-5,MIN(5,ROUND(N(I16)/I$19*100,0)))) -> 5 | T16: =IF(J$19=0,IF(N(J16)>0,5,0),MAX(-5,MIN(5,ROUND(N(J16)/J$19*100,0)))) -> 5 | U16: =IF(K$19=0,IF(N(K16)>0,5,0),MAX(-5,MIN(5,ROUND(N(K16)/K$19*100,0)))) -> 5 | V16: =IF(L$19=0,IF(N(L16)>0,5,0),MAX(-5,MIN(5,ROUND(N(L16)/L$19*100,0)))) -> 5
F17: NGW Total (Lower, 25%) | G17: =SUM(H17:L17) -> 736411.39 | H17: =SUM(H$2:H$5)+SUM(H$12:H$14) -> 41720 | I17: =SUM(I$2:I$5)+SUM(I$12:I$14) -> 66946.765 | J17: =SUM(J$2:J$5)+SUM(J$12:J$14) -> 283904.18 | K17: =SUM(K$2:K$5)+SUM(K$12:K$14) -> 277681.44 | L17: =SUM(L$2:L$5)+SUM(L$12:L$14) -> 66159 | O17: =F17 -> NGW Total (Lower, 25%) | P17: =$G$19 -> 108300.7 | Q17: =IF($P17=0,IF(N($G17)>0,5,0),MAX(-5,MIN(5,ROUND(N($G17)/$P17*100,0)))) -> 5 | R17: =IF(H$19=0,IF(N(H17)>0,5,0),MAX(-5,MIN(5,ROUND(N(H17)/H$19*100,0)))) -> 5 | S17: =IF(I$19=0,IF(N(I17)>0,5,0),MAX(-5,MIN(5,ROUND(N(I17)/I$19*100,0)))) -> 5 | T17: =IF(J$19=0,IF(N(J17)>0,5,0),MAX(-5,MIN(5,ROUND(N(J17)/J$19*100,0)))) -> 5 | U17: =IF(K$19=0,IF(N(K17)>0,5,0),MAX(-5,MIN(5,ROUND(N(K17)/K$19*100,0)))) -> 5 | V17: =IF(L$19=0,IF(N(L17)>0,5,0),MAX(-5,MIN(5,ROUND(N(L17)/L$19*100,0)))) -> 5
C18: =SUM(D2:D12) -> 670446.5 | F18: ECO Total (Only One Scenario) | G18: =SUM(H18:L18) -> 43100 | H18: =SUM(H$2:H$5) -> 41720 | I18: =N5 -> 1380 | J18: NA | K18: NA | L18: NA | O18: =F18 -> ECO Total (Only One Scenario) | P18: =$G$19 -> 108300.7 | Q18: =IF($P18=0,IF(N($G18)>0,5,0),MAX(-5,MIN(5,ROUND(N($G18)/$P18*100,0)))) -> 5 | R18: =IF(H$19=0,IF(N(H18)>0,5,0),MAX(-5,MIN(5,ROUND(N(H18)/H$19*100,0)))) -> 5 | S18: =IF(I$19=0,IF(N(I18)>0,5,0),MAX(-5,MIN(5,ROUND(N(I18)/I$19*100,0)))) -> 5 | T18: =IF(J$19=0,IF(N(J18)>0,5,0),MAX(-5,MIN(5,ROUND(N(J18)/J$19*100,0)))) -> 0 | U18: =IF(K$19=0,IF(N(K18)>0,5,0),MAX(-5,MIN(5,ROUND(N(K18)/K$19*100,0)))) -> 0 | V18: =IF(L$19=0,IF(N(L18)>0,5,0),MAX(-5,MIN(5,ROUND(N(L18)/L$19*100,0)))) -> 0
F19: BAU — Existing Protected Areas (Current Inventory) NOT NEEDED FOR WEBSITE. | G19: =SUM(H19:L19) -> 108300.7 | H19: =SUMIFS($H$57:$H$60,$G$57:$G$60,H$1) -> 18138.948 | I19: =SUMIFS($H$57:$H$60,$G$57:$G$60,I$1) -> 23825.864 | J19: =SUMIFS($H$57:$H$60,$G$57:$G$60,J$1) -> 56014.074 | K19: =SUMIFS($H$57:$H$60,$G$57:$G$60,K$1) -> 10321.817 | L19: =SUMIFS($H$57:$H$60,$G$57:$G$60,L$1) -> 0 | O19: BAU — Existing Protected Areas (Baseline) | P19: =$G$19 -> 108300.7 | Q19: 0 | R19: 0 | S19: 0 | T19: 0 | U19: 0 | V19: 0
F20: NGW = In-Delta + Upland band; ECO = In-Delta only (Upland excluded). Middle Bound = average of Upper and Lower. | O20: Score = % gain over BAU protected acres (row 19), rounded, capped at ±5 (1% = 1 step). Scenario acres are ADDED on top of BAU: (BAU + restored − BAU) / BAU. NA = no restoration in that region, so BAU is unchanged = 0. BAU = 0 (Upland): any gain = +5. BAU row = 0 by definition.
A22: 1. In-Delta Values derive from NGW and Eco Machine in-Delta Acres, and these sheets, used 100% Restoration for this slide 2. Upland (Upper Bound and Lower Bound) restoration values derive from Slide 56 BDSC Presentation Note: only Full Restoration analyzed with In-Delta restoration Objectives (This sheet), while upper and lower bounds are included for upland restoration (Reflected on Restoration ($) Combined sheet 100% and 25% sums Figures here are for Rec Criterion Manuscript and don't serve any other purpose, feel free to map at will for website.
F40: Region_Nam | G40: Region | H40: Habitat Type | I40: Regional Acres
F41: Suisun Marsh | G41: Suisun | H41: Tidal | I41: 41914.112
F42: Convergence Zone | G42: Central | H42: Tidal | I42: 3324.5082
F43: Convergence Zone | H43: Managed Wetland | I43: 29367
F44: Convergence Zone | H44: Soil | I44: 34255.257
F45: North Delta | G45: North | H45: Tidal | I45: 25938.422
F46: North Delta | H46: Managed Wetland | I46: 84385
F47: North Delta | H47: Soil | I47: 93152.202
F48: North Delta | H48: Transitional | I48: 80428.56
F49: South Delta | G49: South | H49: Managed Wetland | I49: 130507
F50: South Delta | H50: Soil | I50: 79914.462
F51: South Delta | H51: Transitional | I51: 67259.975
F52: Non-Delta | G52: Upland | H52: Meadows | I52: 347591
F53: Non-Delta | H53: Floodplain | I53: 303372
F54: Non-Delta | H54: Wetlands | I54: 207004
F56: Region_Nam | G56: Region | H56: Protected Acres (BAU)
F57: Convergence Zone | G57: Central | H57: 23825.864
F58: North Delta | G58: North | H58: 56014.074
F59: South Delta | G59: South | H59: 10321.817
...

Sheet Restoration ($) Combined
C2: $/acre/yr (all islands) | D2: 351.29 | E2: 283.15 | F2: 372.49 | G2: 218.04 | H2: 162.02 | I2: 152.17 | J2: 93.12 | K2: 34.07 | L2: 34.07 | M2: 10.6 | N2: =SUM(D2:M2) -> 1711.02
A3: 100% Restoration | B3: Region | C3: Island | D3: Flood control | E3: Recreational fishing | F3: Amenity/recreation | G3: Water filtering | H3: Biodiversity | I3: Habitat nursery | J3: Recreational hunting | K3: Water supply | L3: Materials | M3: Fuel wood | N3: Sum of all ten | O3: Island acres | P3: Restored (1=yes, 0=no) | Q3: Restored acres
B4: Suisun Marsh | C4: Suisun | D4: =$Q4*D$2 -> 14724008 | E4: =$Q4*E$2 -> 11867981 | F4: =$Q4*F$2 -> 15612588 | G4: =$Q4*G$2 -> 9138953 | H4: =$Q4*H$2 -> 6790924.4 | I4: =$Q4*I$2 -> 6378070.4 | J4: =$Q4*J$2 -> 3903042.1 | K4: =$Q4*K$2 -> 1428013.8 | ... M4: =$Q4*M$2 -> 444289.59 | N4: =SUM(D4:M4) -> 71715884 | O4: ='Overall Restoration (Acres)'!$D$9 -> 41914.112 | P4: 1 | Q4: =O4*P4 -> 41914.112
B5: Central Delta | C5: Bethel Island | D5: =$Q5*D$2 -> 1131153.8 | E5: =$Q5*E$2 -> 911743 | F5: =$Q5*F$2 -> 1199417.8 | G5: =$Q5*G$2 -> 702088.8 | H5: =$Q5*H$2 -> 521704.4 | I5: =$Q5*I$2 -> 489987.4 | J5: =$Q5*J$2 -> 299846.4 | K5: =$Q5*K$2 -> 109705.4 | ... M5: =$Q5*M$2 -> 34132 | N5: =SUM(D5:M5) -> 5509484.4 | O5: =INDEX(References!$C$2:$C$38,MATCH(C5,References!$A$2:$A$38,0)) -> 3220 | P5: 1 | Q5: =O5*P5 -> 3220
C6: Jersey Island | D6: =$Q6*D$2 -> 1215112.1 | E6: =$Q6*E$2 -> 979415.85 | F6: =$Q6*F$2 -> 1288442.9 | G6: =$Q6*G$2 -> 754200.36 | H6: =$Q6*H$2 -> 560427.18 | I6: =$Q6*I$2 -> 526356.03 | J6: =$Q6*J$2 -> 322102.08 | K6: =$Q6*K$2 -> 117848.13 | ... M6: =$Q6*M$2 -> 36665.4 | N6: =SUM(D6:M6) -> 5918418.2 | O6: =INDEX(References!$C$2:$C$38,MATCH(C6,References!$A$2:$A$38,0)) -> 3459 | P6: 1 | Q6: =O6*P6 -> 3459
C7: Webb Tract | D7: =$Q7*D$2 -> 1909612.4 | E7: =$Q7*E$2 -> 1539203.4 | F7: =$Q7*F$2 -> 2024855.6 | G7: =$Q7*G$2 -> 1185265.4 | H7: =$Q7*H$2 -> 880740.72 | I7: =$Q7*I$2 -> 827196.12 | J7: =$Q7*J$2 -> 506200.32 | K7: =$Q7*K$2 -> 185204.52 | ... M7: =$Q7*M$2 -> 57621.6 | N7: =SUM(D7:M7) -> 9301104.7 | O7: =INDEX(References!$C$2:$C$38,MATCH(C7,References!$A$2:$A$38,0)) -> 5436 | P7: 1 | Q7: =O7*P7 -> 5436
C8: Bradford Island | D8: =$Q8*D$2 -> 750004.15 | E8: =$Q8*E$2 -> 604525.25 | F8: =$Q8*F$2 -> 795266.15 | G8: =$Q8*G$2 -> 465515.4 | H8: =$Q8*H$2 -> 345912.7 | I8: =$Q8*I$2 -> 324882.95 | J8: =$Q8*J$2 -> 198811.2 | K8: =$Q8*K$2 -> 72739.45 | ... M8: =$Q8*M$2 -> 22631 | N8: =SUM(D8:M8) -> 3653027.7 | O8: =INDEX(References!$C$2:$C$38,MATCH(C8,References!$A$2:$A$38,0)) -> 2135 | P8: 1 | Q8: =O8*P8 -> 2135
C9: Sherman Island | D9: =$Q9*D$2 -> 3575429.6 | E9: =$Q9*E$2 -> 2881900.7 | F9: =$Q9*F$2 -> 3791203.2 | G9: =$Q9*G$2 -> 2219211.1 | H9: =$Q9*H$2 -> 1649039.6 | I9: =$Q9*I$2 -> 1548786.3 | J9: =$Q9*J$2 -> 947775.36 | K9: =$Q9*K$2 -> 346764.46 | ... M9: =$Q9*M$2 -> 107886.8 | N9: =SUM(D9:M9) -> 17414762 | O9: =INDEX(References!$C$2:$C$38,MATCH(C9,References!$A$2:$A$38,0)) -> 10178 | P9: 1 | Q9: =O9*P9 -> 10178
C10: Franks Tract | D10: =$Q10*D$2 -> 484780.2 | E10: =$Q10*E$2 -> 390747 | F10: =$Q10*F$2 -> 514036.2 | G10: =$Q10*G$2 -> 300895.2 | H10: =$Q10*H$2 -> 223587.6 | I10: =$Q10*I$2 -> 209994.6 | J10: =$Q10*J$2 -> 128505.6 | K10: =$Q10*K$2 -> 47016.6 | ... M10: =$Q10*M$2 -> 14628 | N10: =SUM(D10:M10) -> 2361207.6 | O10: 1380 | P10: 1 | Q10: =O10*P10 -> 1380
C11: Twitchell Island | D11: =$Q11*D$2 -> 1250241.1 | E11: =$Q11*E$2 -> 1007730.8 | F11: =$Q11*F$2 -> 1325691.9 | G11: =$Q11*G$2 -> 776004.36 | H11: =$Q11*H$2 -> 576629.18 | I11: =$Q11*I$2 -> 541573.03 | J11: =$Q11*J$2 -> 331414.08 | K11: =$Q11*K$2 -> 121255.13 | ... M11: =$Q11*M$2 -> 37725.4 | N11: =SUM(D11:M11) -> 6089520.2 | O11: =INDEX(References!$C$2:$C$38,MATCH(C11,References!$A$2:$A$38,0)) -> 3559 | P11: 1 | Q11: =O11*P11 -> 3559
B12: North Delta | C12: Grand Island | D12: =$Q12*D$2 -> 5811390.5 | E12: =$Q12*E$2 -> 4684150.4 | F12: =$Q12*F$2 -> 6162102.1 | G12: =$Q12*G$2 -> 3607035.7 | H12: =$Q12*H$2 -> 2680296.9 | I12: =$Q12*I$2 -> 2517348.3 | J12: =$Q12*J$2 -> 1540484.2 | K12: =$Q12*K$2 -> 563620.01 | ... M12: =$Q12*M$2 -> 175355.8 | N12: =SUM(D12:M12) -> 28305404 | O12: =INDEX(References!$C$2:$C$38,MATCH(C12,References!$A$2:$A$38,0)) -> 16543 | P12: 1 | Q12: =O12*P12 -> 16543
C13: Ryer Island | D13: =$Q13*D$2 -> 4144519.4 | E13: =$Q13*E$2 -> 3340603.7 | F13: =$Q13*F$2 -> 4394637 | G13: =$Q13*G$2 -> 2572435.9 | H13: =$Q13*H$2 -> 1911512 | I13: =$Q13*I$2 -> 1795301.7 | J13: =$Q13*J$2 -> 1098629.8 | K13: =$Q13*K$2 -> 401957.86 | ... M13: =$Q13*M$2 -> 125058.8 | N13: =SUM(D13:M13) -> 20186614 | O13: =INDEX(References!$C$2:$C$38,MATCH(C13,References!$A$2:$A$38,0)) -> 11798 | P13: 1 | Q13: =O13*P13 -> 11798
C14: Tyler Island | D14: =$Q14*D$2 -> 3091000.7 | E14: =$Q14*E$2 -> 2491436.8 | F14: =$Q14*F$2 -> 3277539.5 | G14: =$Q14*G$2 -> 1918534 | H14: =$Q14*H$2 -> 1425614 | I14: =$Q14*I$2 -> 1338943.8 | J14: =$Q14*J$2 -> 819362.88 | K14: =$Q14*K$2 -> 299781.93 | ... M14: =$Q14*M$2 -> 93269.4 | N14: =SUM(D14:M14) -> 15055265 | O14: =INDEX(References!$C$2:$C$38,MATCH(C14,References!$A$2:$A$38,0)) -> 8799 | P14: 1 | Q14: =O14*P14 -> 8799
C15: Staten Island | D15: =$Q15*D$2 -> 3200603.2 | E15: =$Q15*E$2 -> 2579779.6 | F15: =$Q15*F$2 -> 3393756.4 | G15: =$Q15*G$2 -> 1986562.4 | H15: =$Q15*H$2 -> 1476164.2 | I15: =$Q15*I$2 -> 1386420.9 | J15: =$Q15*J$2 -> 848416.32 | K15: =$Q15*K$2 -> 310411.77 | ... M15: =$Q15*M$2 -> 96576.6 | N15: =SUM(D15:M15) -> 15589103 | O15: =INDEX(References!$C$2:$C$38,MATCH(C15,References!$A$2:$A$38,0)) -> 9111 | P15: 1 | Q15: =O15*P15 -> 9111
C16: Dead Horse Island | D16: =$Q16*D$2 -> 73068.32 | E16: =$Q16*E$2 -> 58895.2 | F16: =$Q16*F$2 -> 77477.92 | G16: =$Q16*G$2 -> 45352.32 | H16: =$Q16*H$2 -> 33700.16 | I16: =$Q16*I$2 -> 31651.36 | J16: =$Q16*J$2 -> 19368.96 | K16: =$Q16*K$2 -> 7086.56 | ... M16: =$Q16*M$2 -> 2204.8 | N16: =SUM(D16:M16) -> 355892.16 | O16: =INDEX(References!$C$2:$C$38,MATCH(C16,References!$A$2:$A$38,0)) -> 208 | P16: 1 | Q16: =O16*P16 -> 208
C17: Sutter Island | D17: =$Q17*D$2 -> 883143.06 | E17: =$Q17*E$2 -> 711839.1 | F17: =$Q17*F$2 -> 936439.86 | G17: =$Q17*G$2 -> 548152.56 | H17: =$Q17*H$2 -> 407318.28 | I17: =$Q17*I$2 -> 382555.38 | J17: =$Q17*J$2 -> 234103.68 | K17: =$Q17*K$2 -> 85651.98 | ... M17: =$Q17*M$2 -> 26648.4 | N17: =SUM(D17:M17) -> 4301504.3 | O17: =INDEX(References!$C$2:$C$38,MATCH(C17,References!$A$2:$A$38,0)) -> 2514 | P17: 1 | Q17: =O17*P17 -> 2514
C18: New Hope Tract | D18: =$Q18*D$2 -> 3235732.2 | E18: =$Q18*E$2 -> 2608094.6 | F18: =$Q18*F$2 -> 3431005.4 | G18: =$Q18*G$2 -> 2008366.4 | H18: =$Q18*H$2 -> 1492366.2 | I18: =$Q18*I$2 -> 1401637.9 | J18: =$Q18*J$2 -> 857728.32 | K18: =$Q18*K$2 -> 313818.77 | ... M18: =$Q18*M$2 -> 97636.6 | N18: =SUM(D18:M18) -> 15760205 | O18: =INDEX(References!$C$2:$C$38,MATCH(C18,References!$A$2:$A$38,0)) -> 9211 | P18: 1 | Q18: =O18*P18 -> 9211
C19: Canal Ranch Tract | D19: =$Q19*D$2 -> 1031387.4 | E19: =$Q19*E$2 -> 831328.4 | F19: =$Q19*F$2 -> 1093630.6 | G19: =$Q19*G$2 -> 640165.44 | H19: =$Q19*H$2 -> 475690.72 | I19: =$Q19*I$2 -> 446771.12 | J19: =$Q19*J$2 -> 273400.32 | K19: =$Q19*K$2 -> 100029.52 | ... M19: =$Q19*M$2 -> 31121.6 | N19: =SUM(D19:M19) -> 5023554.7 | O19: =INDEX(References!$C$2:$C$38,MATCH(C19,References!$A$2:$A$38,0)) -> 2936 | P19: 1 | Q19: =O19*P19 -> 2936
B20: North-Central | C20: Brannan Island | D20: =$Q20*D$2 -> 4534100 | E20: =$Q20*E$2 -> 3654617 | F20: =$Q20*F$2 -> 4807728.4 | G20: =$Q20*G$2 -> 2814242.3 | H20: =$Q20*H$2 -> 2091192.1 | I20: =$Q20*I$2 -> 1964058.2 | J20: =$Q20*J$2 -> 1201899.8 | K20: =$Q20*K$2 -> 439741.49 | ... M20: =$Q20*M$2 -> 136814.2 | N20: =SUM(D20:M20) -> 22084135 | O20: =INDEX(References!$C$2:$C$38,MATCH(C20,References!$A$2:$A$38,0)) -> 12907 | P20: 1 | Q20: =O20*P20 -> 12907
B21: North-South | C21: Terminous Tract | D21: =$Q21*D$2 -> 3638661.8 | E21: =$Q21*E$2 -> 2932867.7 | F21: =$Q21*F$2 -> 3858251.4 | G21: =$Q21*G$2 -> 2258458.3 | H21: =$Q21*H$2 -> 1678203.2 | I21: =$Q21*I$2 -> 1576176.9 | J21: =$Q21*J$2 -> 964536.96 | K21: =$Q21*K$2 -> 352897.06 | ... M21: =$Q21*M$2 -> 109794.8 | N21: =SUM(D21:M21) -> 17722745 | O21: =INDEX(References!$C$2:$C$38,MATCH(C21,References!$A$2:$A$38,0)) -> 10358 | P21: 1 | Q21: =O21*P21 -> 10358
B22: South Delta | C22: Bouldin Island | D22: =$Q22*D$2 -> 2085257.4 | E22: =$Q22*E$2 -> 1680778.4 | F22: =$Q22*F$2 -> 2211100.6 | G22: =$Q22*G$2 -> 1294285.4 | H22: =$Q22*H$2 -> 961750.72 | I22: =$Q22*I$2 -> 903281.12 | J22: =$Q22*J$2 -> 552760.32 | K22: =$Q22*K$2 -> 202239.52 | ... M22: =$Q22*M$2 -> 62921.6 | N22: =SUM(D22:M22) -> 10156615 | O22: =INDEX(References!$C$2:$C$38,MATCH(C22,References!$A$2:$A$38,0)) -> 5936 | P22: 1 | Q22: =O22*P22 -> 5936
C23: Venice Island | D23: =$Q23*D$2 -> 1086891.3 | E23: =$Q23*E$2 -> 876066.1 | F23: =$Q23*F$2 -> 1152484.1 | G23: =$Q23*G$2 -> 674615.76 | H23: =$Q23*H$2 -> 501289.88 | I23: =$Q23*I$2 -> 470813.98 | J23: =$Q23*J$2 -> 288113.28 | K23: =$Q23*K$2 -> 105412.58 | ... M23: =$Q23*M$2 -> 32796.4 | N23: =SUM(D23:M23) -> 5293895.9 | O23: =INDEX(References!$C$2:$C$38,MATCH(C23,References!$A$2:$A$38,0)) -> 3094 | P23: 1 | Q23: =O23*P23 -> 3094
C24: Medford Island | D24: =$Q24*D$2 -> 409252.85 | E24: =$Q24*E$2 -> 329869.75 | F24: =$Q24*F$2 -> 433950.85 | G24: =$Q24*G$2 -> 254016.6 | H24: =$Q24*H$2 -> 188753.3 | I24: =$Q24*I$2 -> 177278.05 | J24: =$Q24*J$2 -> 108484.8 | K24: =$Q24*K$2 -> 39691.55 | ... M24: =$Q24*M$2 -> 12349 | N24: =SUM(D24:M24) -> 1993338.3 | O24: =INDEX(References!$C$2:$C$38,MATCH(C24,References!$A$2:$A$38,0)) -> 1165 | P24: 1 | Q24: =O24*P24 -> 1165
C25: Empire Tract | D25: =$Q25*D$2 -> 1273426.2 | E25: =$Q25*E$2 -> 1026418.7 | F25: =$Q25*F$2 -> 1350276.2 | G25: =$Q25*G$2 -> 790395 | H25: =$Q25*H$2 -> 587322.5 | I25: =$Q25*I$2 -> 551616.25 | J25: =$Q25*J$2 -> 337560 | K25: =$Q25*K$2 -> 123503.75 | ... M25: =$Q25*M$2 -> 38425 | N25: =SUM(D25:M25) -> 6202447.5 | O25: =INDEX(References!$C$2:$C$38,MATCH(C25,References!$A$2:$A$38,0)) -> 3625 | P25: 1 | Q25: =O25*P25 -> 3625
C26: King Island | D26: =$Q26*D$2 -> 1129748.6 | E26: =$Q26*E$2 -> 910610.4 | F26: =$Q26*F$2 -> 1197927.8 | G26: =$Q26*G$2 -> 701216.64 | H26: =$Q26*H$2 -> 521056.32 | I26: =$Q26*I$2 -> 489378.72 | J26: =$Q26*J$2 -> 299473.92 | K26: =$Q26*K$2 -> 109569.12 | ... M26: =$Q26*M$2 -> 34089.6 | N26: =SUM(D26:M26) -> 5502640.3 | O26: =INDEX(References!$C$2:$C$38,MATCH(C26,References!$A$2:$A$38,0)) -> 3216 | P26: 1 | Q26: =O26*P26 -> 3216
C27: Rindge Tract | D27: =$Q27*D$2 -> 2368748.5 | E27: =$Q27*E$2 -> 1909280.4 | F27: =$Q27*F$2 -> 2511700.1 | G27: =$Q27*G$2 -> 1470243.7 | H27: =$Q27*H$2 -> 1092500.9 | I27: =$Q27*I$2 -> 1026082.3 | J27: =$Q27*J$2 -> 627908.16 | K27: =$Q27*K$2 -> 229734.01 | ... M27: =$Q27*M$2 -> 71475.8 | N27: =SUM(D27:M27) -> 11537408 | O27: =INDEX(References!$C$2:$C$38,MATCH(C27,References!$A$2:$A$38,0)) -> 6743 | P27: 1 | Q27: =O27*P27 -> 6743
C28: Wright-Elmwood Tract | D28: =$Q28*D$2 -> 739465.45 | E28: =$Q28*E$2 -> 596030.75 | F28: =$Q28*F$2 -> 784091.45 | G28: =$Q28*G$2 -> 458974.2 | H28: =$Q28*H$2 -> 341052.1 | I28: =$Q28*I$2 -> 320317.85 | J28: =$Q28*J$2 -> 196017.6 | K28: =$Q28*K$2 -> 71717.35 | ... M28: =$Q28*M$2 -> 22313 | N28: =SUM(D28:M28) -> 3601697.1 | O28: =INDEX(References!$C$2:$C$38,MATCH(C28,References!$A$2:$A$38,0)) -> 2105 | P28: 1 | Q28: =O28*P28 -> 2105
C29: McDonald Tract | D29: =$Q29*D$2 -> 2128817.4 | E29: =$Q29*E$2 -> 1715889 | F29: =$Q29*F$2 -> 2257289.4 | G29: =$Q29*G$2 -> 1321322.4 | H29: =$Q29*H$2 -> 981841.2 | I29: =$Q29*I$2 -> 922150.2 | J29: =$Q29*J$2 -> 564307.2 | K29: =$Q29*K$2 -> 206464.2 | ... M29: =$Q29*M$2 -> 64236 | N29: =SUM(D29:M29) -> 10368781 | O29: =INDEX(References!$C$2:$C$38,MATCH(C29,References!$A$2:$A$38,0)) -> 6060 | P29: 1 | Q29: =O29*P29 -> 6060
C30: Jones Tract | D30: =$Q30*D$2 -> 4260093.8 | E30: =$Q30*E$2 -> 3433760 | F30: =$Q30*F$2 -> 4517186.2 | G30: =$Q30*G$2 -> 2644171.1 | H30: =$Q30*H$2 -> 1964816.5 | I30: =$Q30*I$2 -> 1845365.6 | J30: =$Q30*J$2 -> 1129266.2 | K30: =$Q30*K$2 -> 413166.89 | ... M30: =$Q30*M$2 -> 128546.2 | N30: =SUM(D30:M30) -> 20749540 | O30: =INDEX(References!$C$2:$C$38,MATCH(C30,References!$A$2:$A$38,0)) -> 12127 | P30: 1 | Q30: =O30*P30 -> 12127
C31: Rough and Ready | D31: =$Q31*D$2 -> 492157.29 | E31: =$Q31*E$2 -> 396693.15 | F31: =$Q31*F$2 -> 521858.49 | G31: =$Q31*G$2 -> 305474.04 | H31: =$Q31*H$2 -> 226990.02 | I31: =$Q31*I$2 -> 213190.17 | J31: =$Q31*J$2 -> 130461.12 | K31: =$Q31*K$2 -> 47732.07 | ... M31: =$Q31*M$2 -> 14850.6 | N31: =SUM(D31:M31) -> 2397139 | O31: =INDEX(References!$C$2:$C$38,MATCH(C31,References!$A$2:$A$38,0)) -> 1401 | P31: 1 | Q31: =O31*P31 -> 1401
C32: Roberts Island | D32: =$Q32*D$2 -> 12528055 | E32: =$Q32*E$2 -> 10097978 | F32: =$Q32*F$2 -> 13284111 | G32: =$Q32*G$2 -> 7775960.5 | H32: =$Q32*H$2 -> 5778119.3 | I32: =$Q32*I$2 -> 5426838.7 | J32: =$Q32*J$2 -> 3320938.6 | K32: =$Q32*K$2 -> 1215038.4 | ... M32: =$Q32*M$2 -> 378027.8 | N32: =SUM(D32:M32) -> 61020106 | O32: =INDEX(References!$C$2:$C$38,MATCH(C32,References!$A$2:$A$38,0)) -> 35663 | P32: 1 | Q32: =O32*P32 -> 35663
C33: Union Island | D33: =$Q33*D$2 -> 8694427.5 | E33: =$Q33*E$2 -> 7007962.5 | F33: =$Q33*F$2 -> 9219127.5 | G33: =$Q33*G$2 -> 5396490 | H33: =$Q33*H$2 -> 4009995 | I33: =$Q33*I$2 -> 3766207.5 | J33: =$Q33*J$2 -> 2304720 | K33: =$Q33*K$2 -> 843232.5 | ... M33: =$Q33*M$2 -> 262350 | N33: =SUM(D33:M33) -> 42347745 | O33: =INDEX(References!$C$2:$C$38,MATCH(C33,References!$A$2:$A$38,0)) -> 24750 | P33: 1 | Q33: =O33*P33 -> 24750
C34: Victoria Island | D34: =$Q34*D$2 -> 2526829 | E34: =$Q34*E$2 -> 2036697.9 | F34: =$Q34*F$2 -> 2679320.6 | G34: =$Q34*G$2 -> 1568361.7 | H34: =$Q34*H$2 -> 1165409.9 | I34: =$Q34*I$2 -> 1094558.8 | J34: =$Q34*J$2 -> 669812.16 | K34: =$Q34*K$2 -> 245065.51 | ... M34: =$Q34*M$2 -> 76245.8 | N34: =SUM(D34:M34) -> 12307367 | O34: =INDEX(References!$C$2:$C$38,MATCH(C34,References!$A$2:$A$38,0)) -> 7193 | P34: 1 | Q34: =O34*P34 -> 7193
... C42: Mandeville Island | D42: =$Q42*D$2 -> 1832679.9 | E42: =$Q42*E$2 -> 1477193.5 | F42: =$Q42*F$2 -> 1943280.3 | G42: =$Q42*G$2 -> 1137514.7 | H42: =$Q42*H$2 -> 845258.34 | I42: =$Q42*I$2 -> 793870.89 | J42: =$Q42*J$2 -> 485807.04 | K42: =$Q42*K$2 -> 177743.19 | ... M42: =$Q42*M$2 -> 55300.2 | N42: =SUM(D42:M42) -> 8926391.3 | O42: =INDEX(References!$C$2:$C$38,MATCH(C42,References!$A$2:$A$38,0)) -> 5217 | P42: 1 | Q42: =O42*P42 -> 5217
B43: Upland | C43: Meadows | D43: =$Q43*D$2 -> 1.2210524e+08 | E43: =$Q43*E$2 -> 98420392 | F43: =$Q43*F$2 -> 1.2947417e+08 | G43: =$Q43*G$2 -> 75788742 | H43: =$Q43*H$2 -> 56316694 | I43: =$Q43*I$2 -> 52892922 | J43: =$Q43*J$2 -> 32367674 | K43: =$Q43*K$2 -> 11842425 | ... N43: =$Q43*N$2 -> 5.9473515e+08 | O43: 347591 | P43: Upland (Upper Bound) | Q43: 347591
C44: Floodplain | D44: =$Q44*D$2 -> 1.0657155e+08 | E44: =$Q44*E$2 -> 85899782 | F44: =$Q44*F$2 -> 1.1300304e+08 | G44: =$Q44*G$2 -> 66147231 | H44: =$Q44*H$2 -> 49152331 | I44: =$Q44*I$2 -> 46164117 | J44: =$Q44*J$2 -> 28250001 | K44: =$Q44*K$2 -> 10335884 | ... N44: =$Q44*N$2 -> 5.1907556e+08 | O44: 303372 | P44: Upland (Upper Bound) | Q44: 303372
C45: Wetland | D45: =$Q45*D$2 -> 72718435 | E45: =$Q45*E$2 -> 58613183 | F45: =$Q45*F$2 -> 77106920 | G45: =$Q45*G$2 -> 45135152 | H45: =$Q45*H$2 -> 33538788 | I45: =$Q45*I$2 -> 31499799 | J45: =$Q45*J$2 -> 19276212 | K45: =$Q45*K$2 -> 7052626.3 | ... N45: =$Q45*N$2 -> 3.5418798e+08 | O45: 207004 | P45: Upland (Upper Bound) | Q45: 207004
C46: Totals summed (ECO + NGW + NGW Upland) | D46: =SUM(D4:D45) -> 4.0401024e+08 | E46: =SUM(E4:E45) -> 3.2564405e+08 | F46: =SUM(F4:F45) -> 4.2839185e+08 | G46: =SUM(G4:G45) -> 2.507626e+08 | H46: =SUM(H4:H45) -> 1.8633533e+08 | I46: =SUM(I4:I45) -> 1.7500708e+08 | J46: =SUM(J4:J45) -> 1.0709509e+08 | K46: =SUM(K4:K45) -> 39183093 | ... O46: =SUM(O4:O45) -> 1150076.1 | Q46: =SUM(Q4:Q45) -> 1150076.1
C47: Totals ECO (Suisun + Franks) Excluding NGW | D47: =D4+D10 -> 15208789 | E47: =E4+E10 -> 12258728 | F47: =F4+F10 -> 16126624 | G47: =G4+G10 -> 9439848.2 | H47: =H4+H10 -> 7014512 | I47: =I4+I10 -> 6588065 | J47: =J4+J10 -> 4031547.7 | K47: =K4+K10 -> 1475030.4 | ... N47: =N4+N10 -> 74077092 | O47: =SUM(O4+O10) -> 43294.112 | Q47: 43294
C48: Totals (ECO + NGW) - NGW Upland | D48: =SUM(D4:D42) -> 1.0261501e+08 | E48: =SUM(E4:E42) -> 82710695 | F48: =SUM(F4:F42) -> 1.0880772e+08 | G48: =SUM(G4:G42) -> 63691471 | H48: =SUM(H4:H42) -> 47327518 | I48: =SUM(I4:I42) -> 44450244 | J48: =SUM(J4:J42) -> 27201201 | K48: =SUM(K4:K42) -> 9952157.4 | ... N48: =SUM(N4:N42) -> 4.9980453e+08 | O48: =SUM(O4:O44) -> 943072.11 | Q48: =SUM(Q4:Q42) -> 292109.11
...

Sheet 100% Restoration ($)
H1: Benefits US$/acre/yr (2025)
A2: Region | B2: Island | C2: ArcGIS object ID | D2: Acres | E2: Elevation (categorical) | F2: Landcover Type (R = Rice; MW = Managed Wetland) | G2: Wetland function | H2: Flood control | I2: Recreational fishing | J2: Amenity/recreation | K2: Water filtering | L2: Biodiversity | M2: Habitat nursery | N2: Recreational hunting | O2: Water supply | P2: Materials | Q2: Fuel wood | R2: Sum of all ten
A3: Suisun Marsh | B3: Suisun | D3: 41914 | F3: Tidal | H3: =IF($F3="Tidal", $D3*$F$52, 0) -> 14723969 | I3: =IF($F3="Tidal", $D3*$F$52, 0) -> 14723969 | J3: =IF($F3="Tidal", $D3*$F$52, 0) -> 14723969 | K3: =IF($F3="Tidal", $D3*$F$52, 0) -> 14723969 | L3: =IF($F3="Tidal", $D3*$F$52, 0) -> 14723969 | M3: =IF($F3="Tidal", $D3*$F$52, 0) -> 14723969 | N3: =IF($F3="Tidal", $D3*$F$52, 0) -> 14723969 | O3: =IF($F3="Tidal", $D3*$F$52, 0) -> 14723969 | ... R3: =IF($F3="Tidal", $D3*$F$52, 0) -> 14723969
A4: North Delta | B4: Grand Island | C4: 80 | D4: 16543 | E4: Mimimal | F4: MW | G4: Grand Island | H4: =IF($F4="MW", $D4*$F$52, 0) -> 5811390.5 | I4: =IF($F4="MW", $D4*$F$53, 0) -> 4684150.4 | J4: =IF($F4="MW", $D4*$F$54, 0) -> 6162102.1 | K4: =IF($F4="MW", $D4*$F$55, 0) -> 3607035.7 | L4: =IF($F4="MW", $D4*$F$56, 0) -> 2680296.9 | M4: =IF($F4="MW", $D4*$F$57, 0) -> 2517348.3 | N4: =IF($F4="MW", $D4*$F$58, 0) -> 1540484.2 | O4: =IF($F4="MW", $D4*$F$59, 0) -> 563620.01 | P4: =IF($F4="MW", $D4*$F$60, 0) -> 563620.01 | Q4: =IF($F4="MW", $D4*$F$61, 0) -> 175355.8 | R4: =IF($F4="MW", $D4*$F$62, 0) -> 28305404
A5: North Delta | B5: Ryer Island | C5: 76 | D5: 11798 | E5: Minimal | F5: MW | G5: Ryer Island | H5: =IF($F5="MW", $D5*$F$52, 0) -> 4144519.4 | I5: =IF($F5="MW", $D5*$F$53, 0) -> 3340603.7 | J5: =IF($F5="MW", $D5*$F$54, 0) -> 4394637 | K5: =IF($F5="MW", $D5*$F$55, 0) -> 2572435.9 | L5: =IF($F5="MW", $D5*$F$56, 0) -> 1911512 | M5: =IF($F5="MW", $D5*$F$57, 0) -> 1795301.7 | N5: =IF($F5="MW", $D5*$F$58, 0) -> 1098629.8 | O5: =IF($F5="MW", $D5*$F$59, 0) -> 401957.86 | P5: =IF($F5="MW", $D5*$F$60, 0) -> 401957.86 | Q5: =IF($F5="MW", $D5*$F$61, 0) -> 125058.8 | R5: =IF($F5="MW", $D5*$F$62, 0) -> 20186614
A6: North Delta | B6: Tyler Island | C6: 62 | D6: 8799 | E6: Minimal | F6: MW | G6: Tyler Island | H6: =IF($F6="MW", $D6*$F$52, 0) -> 3091000.7 | I6: =IF($F6="MW", $D6*$F$53, 0) -> 2491436.8 | J6: =IF($F6="MW", $D6*$F$54, 0) -> 3277539.5 | K6: =IF($F6="MW", $D6*$F$55, 0) -> 1918534 | L6: =IF($F6="MW", $D6*$F$56, 0) -> 1425614 | M6: =IF($F6="MW", $D6*$F$57, 0) -> 1338943.8 | N6: =IF($F6="MW", $D6*$F$58, 0) -> 819362.88 | O6: =IF($F6="MW", $D6*$F$59, 0) -> 299781.93 | P6: =IF($F6="MW", $D6*$F$60, 0) -> 299781.93 | Q6: =IF($F6="MW", $D6*$F$61, 0) -> 93269.4 | R6: =IF($F6="MW", $D6*$F$62, 0) -> 15055265
A7: North Delta | B7: Staten Island | C7: 61 | D7: 9111 | E7: Moderate | F7: MW | G7: Staten Island | H7: =IF($F7="MW", $D7*$F$52, 0) -> 3200603.2 | I7: =IF($F7="MW", $D7*$F$53, 0) -> 2579779.6 | J7: =IF($F7="MW", $D7*$F$54, 0) -> 3393756.4 | K7: =IF($F7="MW", $D7*$F$55, 0) -> 1986562.4 | L7: =IF($F7="MW", $D7*$F$56, 0) -> 1476164.2 | M7: =IF($F7="MW", $D7*$F$57, 0) -> 1386420.9 | N7: =IF($F7="MW", $D7*$F$58, 0) -> 848416.32 | O7: =IF($F7="MW", $D7*$F$59, 0) -> 310411.77 | P7: =IF($F7="MW", $D7*$F$60, 0) -> 310411.77 | Q7: =IF($F7="MW", $D7*$F$61, 0) -> 96576.6 | R7: =IF($F7="MW", $D7*$F$62, 0) -> 15589103
A8: North-Central | B8: Brannan Island | C8: 116 | D8: 12907 | E8: Severe | F8: MW | G8: Brannan Island | H8: =IF($F8="MW", $D8*$F$52, 0) -> 4534100 | I8: =IF($F8="MW", $D8*$F$53, 0) -> 3654617 | J8: =IF($F8="MW", $D8*$F$54, 0) -> 4807728.4 | K8: =IF($F8="MW", $D8*$F$55, 0) -> 2814242.3 | L8: =IF($F8="MW", $D8*$F$56, 0) -> 2091192.1 | M8: =IF($F8="MW", $D8*$F$57, 0) -> 1964058.2 | N8: =IF($F8="MW", $D8*$F$58, 0) -> 1201899.8 | O8: =IF($F8="MW", $D8*$F$59, 0) -> 439741.49 | P8: =IF($F8="MW", $D8*$F$60, 0) -> 439741.49 | Q8: =IF($F8="MW", $D8*$F$61, 0) -> 136814.2 | R8: =IF($F8="MW", $D8*$F$62, 0) -> 22084135
A9: South Delta | B9: Bouldin Island | C9: 57 | D9: 5936 | E9: Severe | F9: MW | G9: Bouldin Island | H9: =IF($F9="MW", $D9*$F$52, 0) -> 2085257.4 | I9: =IF($F9="MW", $D9*$F$53, 0) -> 1680778.4 | J9: =IF($F9="MW", $D9*$F$54, 0) -> 2211100.6 | K9: =IF($F9="MW", $D9*$F$55, 0) -> 1294285.4 | L9: =IF($F9="MW", $D9*$F$56, 0) -> 961750.72 | M9: =IF($F9="MW", $D9*$F$57, 0) -> 903281.12 | N9: =IF($F9="MW", $D9*$F$58, 0) -> 552760.32 | O9: =IF($F9="MW", $D9*$F$59, 0) -> 202239.52 | P9: =IF($F9="MW", $D9*$F$60, 0) -> 202239.52 | Q9: =IF($F9="MW", $D9*$F$61, 0) -> 62921.6 | R9: =IF($F9="MW", $D9*$F$62, 0) -> 10156615
