Workbook

Sheet OVERALL
AH1: Notes: 1. Temperature-based exceedances are spread nearly evenly across Delta regions for the Sea Level Rise Scenario compared to its salinity scenarios, with surprising upswings in increased temperature threshold-crossing exceedances during dry seasons. Under BAU Total Run, each activity stays within about four points across all regions and across each activity's percentages. This is notable but expected, with high exceedances of day-use (<18C) cold-water thresholds across the wet seasons. One notable activity (Waterfowl) threshold, under BAU, sees the highest temperature thresholds (22%) in the Southern Delta, 13% in the Central Delta, 7% in the North, and 5% in Suisun Marsh, and the gap increases during dry seasons; thus if site preference were an objective necessity for waterfowl hunting decisions, the Southern region would face the greatest risks of habitat acidification for that species and activity. 2. For this scenario, it is safe to state that seasonality affects which thresholds get crossed, with most activities crossing their individual thresholds most often during the dry season, with the notable opposite move for cold water. 3. Scenario rankings (-5 to 5 vs BAU) are almost all 0, the few non-zero scores are marginal and only appear in Suisun dry seasons. Overall, dry-season water at Suisun is slightly warmer under ECO and NGW, with more dry-season crossings and fewer cold-sided moves.
C2: TOTAL RUN SCORES | M2: WET SEASON SCORES | W2: DRY SEASON SCORES
D3: REGION | E3: BAU | F3: BAF | G3: ECO | H3: NGW | I3: BAU CS | J3: COR vs CS | K3: TUNNEL VS CS | N3: REGION | O3: BAU | P3: BAF | Q3: ECO | R3: NGW | S3: BAU CS | T3: COR vs CS | U3: TUNNEL VS CS | X3: REGION | Y3: BAU | Z3: BAF | AA3: ECO | AB3: NGW | AC3: BAU CS | AD3: COR vs CS | AE3: TUNNEL VS CS
C4: SP DAY USE & BOATING | D4: Delta-Wide | E4: =-MAX(-5,MIN(5,ROUND((D$43-D$43)*100,0))) -> 0 | F4: =-MAX(-5,MIN(5,ROUND((D$54-D$43)*100,0))) -> 0 | G4: =-MAX(-5,MIN(5,ROUND((D$90-D$43)*100,0))) -> 0 | H4: =-MAX(-5,MIN(5,ROUND((D$99-D$43)*100,0))) -> 0 | I4: =-MAX(-5,MIN(5,ROUND((D$63-D$63)*100,0))) -> 0 | J4: =-MAX(-5,MIN(5,ROUND((D$72-D$63)*100,0))) -> 0 | K4: =-MAX(-5,MIN(5,ROUND((D$81-D$63)*100,0))) -> 0 | M4: SP DAY USE & BOATING | N4: Delta-Wide | O4: =-MAX(-5,MIN(5,ROUND((I$43-I$43)*100,0))) -> 0 | P4: =-MAX(-5,MIN(5,ROUND((I$54-I$43)*100,0))) -> 0 | Q4: =-MAX(-5,MIN(5,ROUND((I$90-I$43)*100,0))) -> 0 | R4: =-MAX(-5,MIN(5,ROUND((I$99-I$43)*100,0))) -> 0 | S4: =-MAX(-5,MIN(5,ROUND((I$63-I$63)*100,0))) -> 0 | T4: =-MAX(-5,MIN(5,ROUND((I$72-I$63)*100,0))) -> 0 | U4: =-MAX(-5,MIN(5,ROUND((I$81-I$63)*100,0))) -> 0 | W4: SP DAY USE & BOATING | X4: Delta-Wide | Y4: =-MAX(-5,MIN(5,ROUND((N$43-N$43)*100,0))) -> 0 | Z4: =-MAX(-5,MIN(5,ROUND((N$54-N$43)*100,0))) -> 0 | AA4: =-MAX(-5,MIN(5,ROUND((N$90-N$43)*100,0))) -> 0 | AB4: =-MAX(-5,MIN(5,ROUND((N$99-N$43)*100,0))) -> 0 | AC4: =-MAX(-5,MIN(5,ROUND((N$63-N$63)*100,0))) -> 0 | AD4: =-MAX(-5,MIN(5,ROUND((N$72-N$63)*100,0))) -> 0 | AE4: =-MAX(-5,MIN(5,ROUND((N$81-N$63)*100,0))) -> 0
D5: Suisun | E5: =-MAX(-5,MIN(5,ROUND((E$43-E$43)*100,0))) -> 0 | F5: =-MAX(-5,MIN(5,ROUND((E$54-E$43)*100,0))) -> 0 | G5: =-MAX(-5,MIN(5,ROUND((E$90-E$43)*100,0))) -> 0 | H5: =-MAX(-5,MIN(5,ROUND((E$99-E$43)*100,0))) -> 0 | I5: =-MAX(-5,MIN(5,ROUND((E$63-E$63)*100,0))) -> 0 | J5: =-MAX(-5,MIN(5,ROUND((E$72-E$63)*100,0))) -> 0 | K5: =-MAX(-5,MIN(5,ROUND((E$81-E$63)*100,0))) -> 0 | N5: Suisun | O5: =-MAX(-5,MIN(5,ROUND((J$43-J$43)*100,0))) -> 0 | P5: =-MAX(-5,MIN(5,ROUND((J$54-J$43)*100,0))) -> 0 | Q5: =-MAX(-5,MIN(5,ROUND((J$90-J$43)*100,0))) -> 0 | R5: =-MAX(-5,MIN(5,ROUND((J$99-J$43)*100,0))) -> 0 | S5: =-MAX(-5,MIN(5,ROUND((J$63-J$63)*100,0))) -> 0 | T5: =-MAX(-5,MIN(5,ROUND((J$72-J$63)*100,0))) -> 0 | U5: =-MAX(-5,MIN(5,ROUND((J$81-J$63)*100,0))) -> 0 | X5: Suisun | Y5: =-MAX(-5,MIN(5,ROUND((O$43-O$43)*100,0))) -> 0 | Z5: =-MAX(-5,MIN(5,ROUND((O$54-O$43)*100,0))) -> 0 | AA5: =-MAX(-5,MIN(5,ROUND((O$90-O$43)*100,0))) -> -1 | AB5: =-MAX(-5,MIN(5,ROUND((O$99-O$43)*100,0))) -> -1 | AC5: =-MAX(-5,MIN(5,ROUND((O$63-O$63)*100,0))) -> 0 | AD5: =-MAX(-5,MIN(5,ROUND((O$72-O$63)*100,0))) -> 0 | AE5: =-MAX(-5,MIN(5,ROUND((O$81-O$63)*100,0))) -> 0
D6: Central | E6: =-MAX(-5,MIN(5,ROUND((F$43-F$43)*100,0))) -> 0 | F6: =-MAX(-5,MIN(5,ROUND((F$54-F$43)*100,0))) -> 0 | G6: =-MAX(-5,MIN(5,ROUND((F$90-F$43)*100,0))) -> 0 | H6: =-MAX(-5,MIN(5,ROUND((F$99-F$43)*100,0))) -> 0 | I6: =-MAX(-5,MIN(5,ROUND((F$63-F$63)*100,0))) -> 0 | J6: =-MAX(-5,MIN(5,ROUND((F$72-F$63)*100,0))) -> 0 | K6: =-MAX(-5,MIN(5,ROUND((F$81-F$63)*100,0))) -> 0 | N6: Central | O6: =-MAX(-5,MIN(5,ROUND((K$43-K$43)*100,0))) -> 0 | P6: =-MAX(-5,MIN(5,ROUND((K$54-K$43)*100,0))) -> 0 | Q6: =-MAX(-5,MIN(5,ROUND((K$90-K$43)*100,0))) -> 0 | R6: =-MAX(-5,MIN(5,ROUND((K$99-K$43)*100,0))) -> 0 | S6: =-MAX(-5,MIN(5,ROUND((K$63-K$63)*100,0))) -> 0 | T6: =-MAX(-5,MIN(5,ROUND((K$72-K$63)*100,0))) -> 0 | U6: =-MAX(-5,MIN(5,ROUND((K$81-K$63)*100,0))) -> 0 | X6: Central | Y6: =-MAX(-5,MIN(5,ROUND((P$43-P$43)*100,0))) -> 0 | Z6: =-MAX(-5,MIN(5,ROUND((P$54-P$43)*100,0))) -> 0 | AA6: =-MAX(-5,MIN(5,ROUND((P$90-P$43)*100,0))) -> 0 | AB6: =-MAX(-5,MIN(5,ROUND((P$99-P$43)*100,0))) -> 0 | AC6: =-MAX(-5,MIN(5,ROUND((P$63-P$63)*100,0))) -> 0 | AD6: =-MAX(-5,MIN(5,ROUND((P$72-P$63)*100,0))) -> 0 | AE6: =-MAX(-5,MIN(5,ROUND((P$81-P$63)*100,0))) -> 0
D7: North | E7: =-MAX(-5,MIN(5,ROUND((G$43-G$43)*100,0))) -> 0 | F7: =-MAX(-5,MIN(5,ROUND((G$54-G$43)*100,0))) -> 0 | G7: =-MAX(-5,MIN(5,ROUND((G$90-G$43)*100,0))) -> 0 | H7: =-MAX(-5,MIN(5,ROUND((G$99-G$43)*100,0))) -> 0 | I7: =-MAX(-5,MIN(5,ROUND((G$63-G$63)*100,0))) -> 0 | J7: =-MAX(-5,MIN(5,ROUND((G$72-G$63)*100,0))) -> 0 | K7: =-MAX(-5,MIN(5,ROUND((G$81-G$63)*100,0))) -> 0 | N7: North | O7: =-MAX(-5,MIN(5,ROUND((L$43-L$43)*100,0))) -> 0 | P7: =-MAX(-5,MIN(5,ROUND((L$54-L$43)*100,0))) -> 0 | Q7: =-MAX(-5,MIN(5,ROUND((L$90-L$43)*100,0))) -> 0 | R7: =-MAX(-5,MIN(5,ROUND((L$99-L$43)*100,0))) -> 0 | S7: =-MAX(-5,MIN(5,ROUND((L$63-L$63)*100,0))) -> 0 | T7: =-MAX(-5,MIN(5,ROUND((L$72-L$63)*100,0))) -> 0 | U7: =-MAX(-5,MIN(5,ROUND((L$81-L$63)*100,0))) -> 0 | X7: North | Y7: =-MAX(-5,MIN(5,ROUND((Q$43-Q$43)*100,0))) -> 0 | Z7: =-MAX(-5,MIN(5,ROUND((Q$54-Q$43)*100,0))) -> 0 | AA7: =-MAX(-5,MIN(5,ROUND((Q$90-Q$43)*100,0))) -> 0 | AB7: =-MAX(-5,MIN(5,ROUND((Q$99-Q$43)*100,0))) -> 0 | AC7: =-MAX(-5,MIN(5,ROUND((Q$63-Q$63)*100,0))) -> 0 | AD7: =-MAX(-5,MIN(5,ROUND((Q$72-Q$63)*100,0))) -> 0 | AE7: =-MAX(-5,MIN(5,ROUND((Q$81-Q$63)*100,0))) -> 0
D8: South | E8: =-MAX(-5,MIN(5,ROUND((H$43-H$43)*100,0))) -> 0 | F8: =-MAX(-5,MIN(5,ROUND((H$54-H$43)*100,0))) -> 0 | G8: =-MAX(-5,MIN(5,ROUND((H$90-H$43)*100,0))) -> 0 | H8: =-MAX(-5,MIN(5,ROUND((H$99-H$43)*100,0))) -> 0 | I8: =-MAX(-5,MIN(5,ROUND((H$63-H$63)*100,0))) -> 0 | J8: =-MAX(-5,MIN(5,ROUND((H$72-H$63)*100,0))) -> 0 | K8: =-MAX(-5,MIN(5,ROUND((H$81-H$63)*100,0))) -> 0 | N8: South | O8: =-MAX(-5,MIN(5,ROUND((M$43-M$43)*100,0))) -> 0 | P8: =-MAX(-5,MIN(5,ROUND((M$54-M$43)*100,0))) -> 0 | Q8: =-MAX(-5,MIN(5,ROUND((M$90-M$43)*100,0))) -> 0 | R8: =-MAX(-5,MIN(5,ROUND((M$99-M$43)*100,0))) -> 0 | S8: =-MAX(-5,MIN(5,ROUND((M$63-M$63)*100,0))) -> 0 | T8: =-MAX(-5,MIN(5,ROUND((M$72-M$63)*100,0))) -> 0 | U8: =-MAX(-5,MIN(5,ROUND((M$81-M$63)*100,0))) -> 0 | X8: South | Y8: =-MAX(-5,MIN(5,ROUND((R$43-R$43)*100,0))) -> 0 | Z8: =-MAX(-5,MIN(5,ROUND((R$54-R$43)*100,0))) -> 0 | AA8: =-MAX(-5,MIN(5,ROUND((R$90-R$43)*100,0))) -> 0 | AB8: =-MAX(-5,MIN(5,ROUND((R$99-R$43)*100,0))) -> 0 | AC8: =-MAX(-5,MIN(5,ROUND((R$63-R$63)*100,0))) -> 0 | AD8: =-MAX(-5,MIN(5,ROUND((R$72-R$63)*100,0))) -> 0 | AE8: =-MAX(-5,MIN(5,ROUND((R$81-R$63)*100,0))) -> 0
D9: REGION | E9: BAU | F9: BAF | G9: ECO | H9: NGW | I9: BAU CS | J9: COR | K9: TUNNEL | N9: REGION | O9: BAU | P9: BAF | Q9: ECO | R9: NGW | S9: BAU CS | T9: COR | U9: TUNNEL | X9: REGION | Y9: BAU | Z9: BAF | AA9: ECO | AB9: NGW | AC9: BAU CS | AD9: COR | AE9: TUNNEL
C10: BIRDING | D10: Delta-Wide | E10: =-MAX(-5,MIN(5,ROUND((D$40-D$40)*100,0))) -> 0 | F10: =-MAX(-5,MIN(5,ROUND((D$51-D$40)*100,0))) -> 0 | G10: =-MAX(-5,MIN(5,ROUND((D$87-D$40)*100,0))) -> 0 | H10: =-MAX(-5,MIN(5,ROUND((D$96-D$40)*100,0))) -> 0 | I10: =-MAX(-5,MIN(5,ROUND((D$60-D$60)*100,0))) -> 0 | J10: =-MAX(-5,MIN(5,ROUND((D$69-D$60)*100,0))) -> 0 | K10: =-MAX(-5,MIN(5,ROUND((D$78-D$60)*100,0))) -> 0 | M10: BIRDING | N10: Delta-Wide | O10: =-MAX(-5,MIN(5,ROUND((I$40-I$40)*100,0))) -> 0 | P10: =-MAX(-5,MIN(5,ROUND((I$51-I$40)*100,0))) -> 0 | Q10: =-MAX(-5,MIN(5,ROUND((I$87-I$40)*100,0))) -> 0 | R10: =-MAX(-5,MIN(5,ROUND((I$96-I$40)*100,0))) -> 0 | S10: =-MAX(-5,MIN(5,ROUND((I$60-I$60)*100,0))) -> 0 | T10: =-MAX(-5,MIN(5,ROUND((I$69-I$60)*100,0))) -> 0 | U10: =-MAX(-5,MIN(5,ROUND((I$78-I$60)*100,0))) -> 0 | W10: BIRDING | X10: Delta-Wide | Y10: =-MAX(-5,MIN(5,ROUND((N$40-N$40)*100,0))) -> 0 | Z10: =-MAX(-5,MIN(5,ROUND((N$51-N$40)*100,0))) -> 0 | AA10: =-MAX(-5,MIN(5,ROUND((N$87-N$40)*100,0))) -> 0 | AB10: =-MAX(-5,MIN(5,ROUND((N$96-N$40)*100,0))) -> 0 | AC10: =-MAX(-5,MIN(5,ROUND((N$60-N$60)*100,0))) -> 0 | AD10: =-MAX(-5,MIN(5,ROUND((N$69-N$60)*100,0))) -> 0 | AE10: =-MAX(-5,MIN(5,ROUND((N$78-N$60)*100,0))) -> 0
D11: Suisun | E11: =-MAX(-5,MIN(5,ROUND((E$40-E$40)*100,0))) -> 0 | F11: =-MAX(-5,MIN(5,ROUND((E$51-E$40)*100,0))) -> 0 | G11: =-MAX(-5,MIN(5,ROUND((E$87-E$40)*100,0))) -> 0 | H11: =-MAX(-5,MIN(5,ROUND((E$96-E$40)*100,0))) -> 0 | I11: =-MAX(-5,MIN(5,ROUND((E$60-E$60)*100,0))) -> 0 | J11: =-MAX(-5,MIN(5,ROUND((E$69-E$60)*100,0))) -> 0 | K11: =-MAX(-5,MIN(5,ROUND((E$78-E$60)*100,0))) -> 0 | N11: Suisun | O11: =-MAX(-5,MIN(5,ROUND((J$40-J$40)*100,0))) -> 0 | P11: =-MAX(-5,MIN(5,ROUND((J$51-J$40)*100,0))) -> 0 | Q11: =-MAX(-5,MIN(5,ROUND((J$87-J$40)*100,0))) -> 0 | R11: =-MAX(-5,MIN(5,ROUND((J$96-J$40)*100,0))) -> 0 | S11: =-MAX(-5,MIN(5,ROUND((J$60-J$60)*100,0))) -> 0 | T11: =-MAX(-5,MIN(5,ROUND((J$69-J$60)*100,0))) -> 0 | U11: =-MAX(-5,MIN(5,ROUND((J$78-J$60)*100,0))) -> 0 | X11: Suisun | Y11: =-MAX(-5,MIN(5,ROUND((O$40-O$40)*100,0))) -> 0 | Z11: =-MAX(-5,MIN(5,ROUND((O$51-O$40)*100,0))) -> 0 | AA11: =-MAX(-5,MIN(5,ROUND((O$87-O$40)*100,0))) -> 0 | AB11: =-MAX(-5,MIN(5,ROUND((O$96-O$40)*100,0))) -> 0 | AC11: =-MAX(-5,MIN(5,ROUND((O$60-O$60)*100,0))) -> 0 | AD11: =-MAX(-5,MIN(5,ROUND((O$69-O$60)*100,0))) -> 0 | AE11: =-MAX(-5,MIN(5,ROUND((O$78-O$60)*100,0))) -> 0
D12: Central | E12: =-MAX(-5,MIN(5,ROUND((F$40-F$40)*100,0))) -> 0 | F12: =-MAX(-5,MIN(5,ROUND((F$51-F$40)*100,0))) -> 0 | G12: =-MAX(-5,MIN(5,ROUND((F$87-F$40)*100,0))) -> 0 | H12: =-MAX(-5,MIN(5,ROUND((F$96-F$40)*100,0))) -> 0 | I12: =-MAX(-5,MIN(5,ROUND((F$60-F$60)*100,0))) -> 0 | J12: =-MAX(-5,MIN(5,ROUND((F$69-F$60)*100,0))) -> 0 | K12: =-MAX(-5,MIN(5,ROUND((F$78-F$60)*100,0))) -> 0 | N12: Central | O12: =-MAX(-5,MIN(5,ROUND((K$40-K$40)*100,0))) -> 0 | P12: =-MAX(-5,MIN(5,ROUND((K$51-K$40)*100,0))) -> 0 | Q12: =-MAX(-5,MIN(5,ROUND((K$87-K$40)*100,0))) -> 0 | R12: =-MAX(-5,MIN(5,ROUND((K$96-K$40)*100,0))) -> 0 | S12: =-MAX(-5,MIN(5,ROUND((K$60-K$60)*100,0))) -> 0 | T12: =-MAX(-5,MIN(5,ROUND((K$69-K$60)*100,0))) -> 0 | U12: =-MAX(-5,MIN(5,ROUND((K$78-K$60)*100,0))) -> 0 | X12: Central | Y12: =-MAX(-5,MIN(5,ROUND((P$40-P$40)*100,0))) -> 0 | Z12: =-MAX(-5,MIN(5,ROUND((P$51-P$40)*100,0))) -> 0 | AA12: =-MAX(-5,MIN(5,ROUND((P$87-P$40)*100,0))) -> 0 | AB12: =-MAX(-5,MIN(5,ROUND((P$96-P$40)*100,0))) -> 0 | AC12: =-MAX(-5,MIN(5,ROUND((P$60-P$60)*100,0))) -> 0 | AD12: =-MAX(-5,MIN(5,ROUND((P$69-P$60)*100,0))) -> 0 | AE12: =-MAX(-5,MIN(5,ROUND((P$78-P$60)*100,0))) -> 0
D13: North | E13: =-MAX(-5,MIN(5,ROUND((G$40-G$40)*100,0))) -> 0 | F13: =-MAX(-5,MIN(5,ROUND((G$51-G$40)*100,0))) -> 0 | G13: =-MAX(-5,MIN(5,ROUND((G$87-G$40)*100,0))) -> 0 | H13: =-MAX(-5,MIN(5,ROUND((G$96-G$40)*100,0))) -> 0 | I13: =-MAX(-5,MIN(5,ROUND((G$60-G$60)*100,0))) -> 0 | J13: =-MAX(-5,MIN(5,ROUND((G$69-G$60)*100,0))) -> 0 | K13: =-MAX(-5,MIN(5,ROUND((G$78-G$60)*100,0))) -> 0 | N13: North | O13: =-MAX(-5,MIN(5,ROUND((L$40-L$40)*100,0))) -> 0 | P13: =-MAX(-5,MIN(5,ROUND((L$51-L$40)*100,0))) -> 0 | Q13: =-MAX(-5,MIN(5,ROUND((L$87-L$40)*100,0))) -> 0 | R13: =-MAX(-5,MIN(5,ROUND((L$96-L$40)*100,0))) -> 0 | S13: =-MAX(-5,MIN(5,ROUND((L$60-L$60)*100,0))) -> 0 | T13: =-MAX(-5,MIN(5,ROUND((L$69-L$60)*100,0))) -> 0 | U13: =-MAX(-5,MIN(5,ROUND((L$78-L$60)*100,0))) -> 0 | X13: North | Y13: =-MAX(-5,MIN(5,ROUND((Q$40-Q$40)*100,0))) -> 0 | Z13: =-MAX(-5,MIN(5,ROUND((Q$51-Q$40)*100,0))) -> 0 | AA13: =-MAX(-5,MIN(5,ROUND((Q$87-Q$40)*100,0))) -> 0 | AB13: =-MAX(-5,MIN(5,ROUND((Q$96-Q$40)*100,0))) -> 0 | AC13: =-MAX(-5,MIN(5,ROUND((Q$60-Q$60)*100,0))) -> 0 | AD13: =-MAX(-5,MIN(5,ROUND((Q$69-Q$60)*100,0))) -> 0 | AE13: =-MAX(-5,MIN(5,ROUND((Q$78-Q$60)*100,0))) -> 0
D14: South | E14: =-MAX(-5,MIN(5,ROUND((H$40-H$40)*100,0))) -> 0 | F14: =-MAX(-5,MIN(5,ROUND((H$51-H$40)*100,0))) -> 0 | G14: =-MAX(-5,MIN(5,ROUND((H$87-H$40)*100,0))) -> 0 | H14: =-MAX(-5,MIN(5,ROUND((H$96-H$40)*100,0))) -> 0 | I14: =-MAX(-5,MIN(5,ROUND((H$60-H$60)*100,0))) -> 0 | J14: =-MAX(-5,MIN(5,ROUND((H$69-H$60)*100,0))) -> 0 | K14: =-MAX(-5,MIN(5,ROUND((H$78-H$60)*100,0))) -> 0 | N14: South | O14: =-MAX(-5,MIN(5,ROUND((M$40-M$40)*100,0))) -> 0 | P14: =-MAX(-5,MIN(5,ROUND((M$51-M$40)*100,0))) -> 0 | Q14: =-MAX(-5,MIN(5,ROUND((M$87-M$40)*100,0))) -> 0 | R14: =-MAX(-5,MIN(5,ROUND((M$96-M$40)*100,0))) -> 0 | S14: =-MAX(-5,MIN(5,ROUND((M$60-M$60)*100,0))) -> 0 | T14: =-MAX(-5,MIN(5,ROUND((M$69-M$60)*100,0))) -> 0 | U14: =-MAX(-5,MIN(5,ROUND((M$78-M$60)*100,0))) -> 0 | X14: South | Y14: =-MAX(-5,MIN(5,ROUND((R$40-R$40)*100,0))) -> 0 | Z14: =-MAX(-5,MIN(5,ROUND((R$51-R$40)*100,0))) -> 0 | AA14: =-MAX(-5,MIN(5,ROUND((R$87-R$40)*100,0))) -> 0 | AB14: =-MAX(-5,MIN(5,ROUND((R$96-R$40)*100,0))) -> 0 | AC14: =-MAX(-5,MIN(5,ROUND((R$60-R$60)*100,0))) -> 0 | AD14: =-MAX(-5,MIN(5,ROUND((R$69-R$60)*100,0))) -> 0 | AE14: =-MAX(-5,MIN(5,ROUND((R$78-R$60)*100,0))) -> 0
D15: REGION | E15: BAU | F15: BAF | G15: ECO | H15: NGW | I15: BAU CS | J15: COR | K15: TUNNEL | N15: REGION | O15: BAU | P15: BAF | Q15: ECO | R15: NGW | S15: BAU CS | T15: COR | U15: TUNNEL | X15: REGION | Y15: BAU | Z15: BAF | AA15: ECO | AB15: NGW | AC15: BAU CS | AD15: COR | AE15: TUNNEL
C16: WATERFOWL | D16: Delta-Wide | E16: =-MAX(-5,MIN(5,ROUND((D$41-D$41)*100,0))) -> 0 | F16: =-MAX(-5,MIN(5,ROUND((D$52-D$41)*100,0))) -> 0 | G16: =-MAX(-5,MIN(5,ROUND((D$88-D$41)*100,0))) -> 0 | H16: =-MAX(-5,MIN(5,ROUND((D$97-D$41)*100,0))) -> 0 | I16: =-MAX(-5,MIN(5,ROUND((D$61-D$61)*100,0))) -> 0 | J16: =-MAX(-5,MIN(5,ROUND((D$70-D$61)*100,0))) -> 0 | K16: =-MAX(-5,MIN(5,ROUND((D$79-D$61)*100,0))) -> 0 | M16: WATERFOWL | N16: Delta-Wide | O16: =-MAX(-5,MIN(5,ROUND((I$41-I$41)*100,0))) -> 0 | P16: =-MAX(-5,MIN(5,ROUND((I$52-I$41)*100,0))) -> 0 | Q16: =-MAX(-5,MIN(5,ROUND((I$88-I$41)*100,0))) -> 0 | R16: =-MAX(-5,MIN(5,ROUND((I$97-I$41)*100,0))) -> 0 | S16: =-MAX(-5,MIN(5,ROUND((I$61-I$61)*100,0))) -> 0 | T16: =-MAX(-5,MIN(5,ROUND((I$70-I$61)*100,0))) -> 0 | U16: =-MAX(-5,MIN(5,ROUND((I$79-I$61)*100,0))) -> 0 | W16: WATERFOWL | X16: Delta-Wide | Y16: =-MAX(-5,MIN(5,ROUND((N$41-N$41)*100,0))) -> 0 | Z16: =-MAX(-5,MIN(5,ROUND((N$52-N$41)*100,0))) -> 0 | AA16: =-MAX(-5,MIN(5,ROUND((N$88-N$41)*100,0))) -> 0 | AB16: =-MAX(-5,MIN(5,ROUND((N$97-N$41)*100,0))) -> 0 | AC16: =-MAX(-5,MIN(5,ROUND((N$61-N$61)*100,0))) -> 0 | AD16: =-MAX(-5,MIN(5,ROUND((N$70-N$61)*100,0))) -> 0 | AE16: =-MAX(-5,MIN(5,ROUND((N$79-N$61)*100,0))) -> -1
D17: Suisun | E17: =-MAX(-5,MIN(5,ROUND((E$41-E$41)*100,0))) -> 0 | F17: =-MAX(-5,MIN(5,ROUND((E$52-E$41)*100,0))) -> 0 | G17: =-MAX(-5,MIN(5,ROUND((E$88-E$41)*100,0))) -> 0 | H17: =-MAX(-5,MIN(5,ROUND((E$97-E$41)*100,0))) -> 0 | I17: =-MAX(-5,MIN(5,ROUND((E$61-E$61)*100,0))) -> 0 | J17: =-MAX(-5,MIN(5,ROUND((E$70-E$61)*100,0))) -> 0 | K17: =-MAX(-5,MIN(5,ROUND((E$79-E$61)*100,0))) -> 0 | N17: Suisun | O17: =-MAX(-5,MIN(5,ROUND((J$41-J$41)*100,0))) -> 0 | P17: =-MAX(-5,MIN(5,ROUND((J$52-J$41)*100,0))) -> 0 | Q17: =-MAX(-5,MIN(5,ROUND((J$88-J$41)*100,0))) -> 0 | R17: =-MAX(-5,MIN(5,ROUND((J$97-J$41)*100,0))) -> 0 | S17: =-MAX(-5,MIN(5,ROUND((J$61-J$61)*100,0))) -> 0 | T17: =-MAX(-5,MIN(5,ROUND((J$70-J$61)*100,0))) -> 0 | U17: =-MAX(-5,MIN(5,ROUND((J$79-J$61)*100,0))) -> 0 | X17: Suisun | Y17: =-MAX(-5,MIN(5,ROUND((O$41-O$41)*100,0))) -> 0 | Z17: =-MAX(-5,MIN(5,ROUND((O$52-O$41)*100,0))) -> 0 | AA17: =-MAX(-5,MIN(5,ROUND((O$88-O$41)*100,0))) -> 0 | AB17: =-MAX(-5,MIN(5,ROUND((O$97-O$41)*100,0))) -> 0 | AC17: =-MAX(-5,MIN(5,ROUND((O$61-O$61)*100,0))) -> 0 | AD17: =-MAX(-5,MIN(5,ROUND((O$70-O$61)*100,0))) -> 0 | AE17: =-MAX(-5,MIN(5,ROUND((O$79-O$61)*100,0))) -> 0
D18: Central | E18: =-MAX(-5,MIN(5,ROUND((F$41-F$41)*100,0))) -> 0 | F18: =-MAX(-5,MIN(5,ROUND((F$52-F$41)*100,0))) -> 0 | G18: =-MAX(-5,MIN(5,ROUND((F$88-F$41)*100,0))) -> 0 | H18: =-MAX(-5,MIN(5,ROUND((F$97-F$41)*100,0))) -> 0 | I18: =-MAX(-5,MIN(5,ROUND((F$61-F$61)*100,0))) -> 0 | J18: =-MAX(-5,MIN(5,ROUND((F$70-F$61)*100,0))) -> 0 | K18: =-MAX(-5,MIN(5,ROUND((F$79-F$61)*100,0))) -> -1 | N18: Central | O18: =-MAX(-5,MIN(5,ROUND((K$41-K$41)*100,0))) -> 0 | P18: =-MAX(-5,MIN(5,ROUND((K$52-K$41)*100,0))) -> 0 | Q18: =-MAX(-5,MIN(5,ROUND((K$88-K$41)*100,0))) -> 0 | R18: =-MAX(-5,MIN(5,ROUND((K$97-K$41)*100,0))) -> 0 | S18: =-MAX(-5,MIN(5,ROUND((K$61-K$61)*100,0))) -> 0 | T18: =-MAX(-5,MIN(5,ROUND((K$70-K$61)*100,0))) -> 0 | U18: =-MAX(-5,MIN(5,ROUND((K$79-K$61)*100,0))) -> 0 | X18: Central | Y18: =-MAX(-5,MIN(5,ROUND((P$41-P$41)*100,0))) -> 0 | Z18: =-MAX(-5,MIN(5,ROUND((P$52-P$41)*100,0))) -> 0 | AA18: =-MAX(-5,MIN(5,ROUND((P$88-P$41)*100,0))) -> 0 | AB18: =-MAX(-5,MIN(5,ROUND((P$97-P$41)*100,0))) -> 0 | AC18: =-MAX(-5,MIN(5,ROUND((P$61-P$61)*100,0))) -> 0 | AD18: =-MAX(-5,MIN(5,ROUND((P$70-P$61)*100,0))) -> 0 | AE18: =-MAX(-5,MIN(5,ROUND((P$79-P$61)*100,0))) -> -2
D19: North | E19: =-MAX(-5,MIN(5,ROUND((G$41-G$41)*100,0))) -> 0 | F19: =-MAX(-5,MIN(5,ROUND((G$52-G$41)*100,0))) -> 0 | G19: =-MAX(-5,MIN(5,ROUND((G$88-G$41)*100,0))) -> 0 | H19: =-MAX(-5,MIN(5,ROUND((G$97-G$41)*100,0))) -> 0 | I19: =-MAX(-5,MIN(5,ROUND((G$61-G$61)*100,0))) -> 0 | J19: =-MAX(-5,MIN(5,ROUND((G$70-G$61)*100,0))) -> 0 | K19: =-MAX(-5,MIN(5,ROUND((G$79-G$61)*100,0))) -> -1 | N19: North | O19: =-MAX(-5,MIN(5,ROUND((L$41-L$41)*100,0))) -> 0 | P19: =-MAX(-5,MIN(5,ROUND((L$52-L$41)*100,0))) -> 0 | Q19: =-MAX(-5,MIN(5,ROUND((L$88-L$41)*100,0))) -> 0 | R19: =-MAX(-5,MIN(5,ROUND((L$97-L$41)*100,0))) -> 0 | S19: =-MAX(-5,MIN(5,ROUND((L$61-L$61)*100,0))) -> 0 | T19: =-MAX(-5,MIN(5,ROUND((L$70-L$61)*100,0))) -> 0 | U19: =-MAX(-5,MIN(5,ROUND((L$79-L$61)*100,0))) -> 0 | X19: North | Y19: =-MAX(-5,MIN(5,ROUND((Q$41-Q$41)*100,0))) -> 0 | Z19: =-MAX(-5,MIN(5,ROUND((Q$52-Q$41)*100,0))) -> 0 | AA19: =-MAX(-5,MIN(5,ROUND((Q$88-Q$41)*100,0))) -> 0 | AB19: =-MAX(-5,MIN(5,ROUND((Q$97-Q$41)*100,0))) -> 0 | AC19: =-MAX(-5,MIN(5,ROUND((Q$61-Q$61)*100,0))) -> 0 | AD19: =-MAX(-5,MIN(5,ROUND((Q$70-Q$61)*100,0))) -> 0 | AE19: =-MAX(-5,MIN(5,ROUND((Q$79-Q$61)*100,0))) -> -2
D20: South | E20: =-MAX(-5,MIN(5,ROUND((H$41-H$41)*100,0))) -> 0 | F20: =-MAX(-5,MIN(5,ROUND((H$52-H$41)*100,0))) -> 0 | G20: =-MAX(-5,MIN(5,ROUND((H$88-H$41)*100,0))) -> 0 | H20: =-MAX(-5,MIN(5,ROUND((H$97-H$41)*100,0))) -> 0 | I20: =-MAX(-5,MIN(5,ROUND((H$61-H$61)*100,0))) -> 0 | J20: =-MAX(-5,MIN(5,ROUND((H$70-H$61)*100,0))) -> 0 | K20: =-MAX(-5,MIN(5,ROUND((H$79-H$61)*100,0))) -> 0 | N20: South | O20: =-MAX(-5,MIN(5,ROUND((M$41-M$41)*100,0))) -> 0 | P20: =-MAX(-5,MIN(5,ROUND((M$52-M$41)*100,0))) -> 0 | Q20: =-MAX(-5,MIN(5,ROUND((M$88-M$41)*100,0))) -> 0 | R20: =-MAX(-5,MIN(5,ROUND((M$97-M$41)*100,0))) -> 0 | S20: =-MAX(-5,MIN(5,ROUND((M$61-M$61)*100,0))) -> 0 | T20: =-MAX(-5,MIN(5,ROUND((M$70-M$61)*100,0))) -> 0 | U20: =-MAX(-5,MIN(5,ROUND((M$79-M$61)*100,0))) -> 0 | X20: South | Y20: =-MAX(-5,MIN(5,ROUND((R$41-R$41)*100,0))) -> 0 | Z20: =-MAX(-5,MIN(5,ROUND((R$52-R$41)*100,0))) -> 0 | AA20: =-MAX(-5,MIN(5,ROUND((R$88-R$41)*100,0))) -> 0 | AB20: =-MAX(-5,MIN(5,ROUND((R$97-R$41)*100,0))) -> 0 | AC20: =-MAX(-5,MIN(5,ROUND((R$61-R$61)*100,0))) -> 0 | AD20: =-MAX(-5,MIN(5,ROUND((R$70-R$61)*100,0))) -> 0 | AE20: =-MAX(-5,MIN(5,ROUND((R$79-R$61)*100,0))) -> -1
D21: REGION | E21: BAU | F21: BAF | G21: ECO | H21: NGW | I21: BAU CS | J21: COR | K21: TUNNEL | N21: REGION | O21: BAU | P21: BAF | Q21: ECO | R21: NGW | S21: BAU CS | T21: COR | U21: TUNNEL | X21: REGION | Y21: BAU | Z21: BAF | AA21: ECO | AB21: NGW | AC21: BAU CS | AD21: COR | AE21: TUNNEL
C22: ANGLING | D22: Delta-Wide | E22: =-MAX(-5,MIN(5,ROUND((D$42-D$42)*100,0))) -> 0 | F22: =-MAX(-5,MIN(5,ROUND((D$53-D$42)*100,0))) -> 0 | G22: =-MAX(-5,MIN(5,ROUND((D$89-D$42)*100,0))) -> 0 | H22: =-MAX(-5,MIN(5,ROUND((D$98-D$42)*100,0))) -> 0 | I22: =-MAX(-5,MIN(5,ROUND((D$62-D$62)*100,0))) -> 0 | J22: =-MAX(-5,MIN(5,ROUND((D$71-D$62)*100,0))) -> 0 | K22: =-MAX(-5,MIN(5,ROUND((D$80-D$62)*100,0))) -> 0 | M22: ANGLING | N22: Delta-Wide | O22: =-MAX(-5,MIN(5,ROUND((I$42-I$42)*100,0))) -> 0 | P22: =-MAX(-5,MIN(5,ROUND((I$53-I$42)*100,0))) -> 0 | Q22: =-MAX(-5,MIN(5,ROUND((I$89-I$42)*100,0))) -> 0 | R22: =-MAX(-5,MIN(5,ROUND((I$98-I$42)*100,0))) -> 0 | S22: =-MAX(-5,MIN(5,ROUND((I$62-I$62)*100,0))) -> 0 | T22: =-MAX(-5,MIN(5,ROUND((I$71-I$62)*100,0))) -> 0 | U22: =-MAX(-5,MIN(5,ROUND((I$80-I$62)*100,0))) -> 0 | W22: ANGLING | X22: Delta-Wide | Y22: =-MAX(-5,MIN(5,ROUND((N$42-N$42)*100,0))) -> 0 | Z22: =-MAX(-5,MIN(5,ROUND((N$53-N$42)*100,0))) -> 0 | AA22: =-MAX(-5,MIN(5,ROUND((N$89-N$42)*100,0))) -> 0 | AB22: =-MAX(-5,MIN(5,ROUND((N$98-N$42)*100,0))) -> 0 | AC22: =-MAX(-5,MIN(5,ROUND((N$62-N$62)*100,0))) -> 0 | AD22: =-MAX(-5,MIN(5,ROUND((N$71-N$62)*100,0))) -> 0 | AE22: =-MAX(-5,MIN(5,ROUND((N$80-N$62)*100,0))) -> 0
D23: Suisun | E23: =-MAX(-5,MIN(5,ROUND((E$42-E$42)*100,0))) -> 0 | F23: =-MAX(-5,MIN(5,ROUND((E$53-E$42)*100,0))) -> 0 | G23: =-MAX(-5,MIN(5,ROUND((E$89-E$42)*100,0))) -> 0 | H23: =-MAX(-5,MIN(5,ROUND((E$98-E$42)*100,0))) -> 0 | I23: =-MAX(-5,MIN(5,ROUND((E$62-E$62)*100,0))) -> 0 | J23: =-MAX(-5,MIN(5,ROUND((E$71-E$62)*100,0))) -> 0 | K23: =-MAX(-5,MIN(5,ROUND((E$80-E$62)*100,0))) -> 0 | N23: Suisun | O23: =-MAX(-5,MIN(5,ROUND((J$42-J$42)*100,0))) -> 0 | P23: =-MAX(-5,MIN(5,ROUND((J$53-J$42)*100,0))) -> 0 | Q23: =-MAX(-5,MIN(5,ROUND((J$89-J$42)*100,0))) -> 0 | R23: =-MAX(-5,MIN(5,ROUND((J$98-J$42)*100,0))) -> 0 | S23: =-MAX(-5,MIN(5,ROUND((J$62-J$62)*100,0))) -> 0 | T23: =-MAX(-5,MIN(5,ROUND((J$71-J$62)*100,0))) -> 0 | U23: =-MAX(-5,MIN(5,ROUND((J$80-J$62)*100,0))) -> 0 | X23: Suisun | Y23: =-MAX(-5,MIN(5,ROUND((O$42-O$42)*100,0))) -> 0 | Z23: =-MAX(-5,MIN(5,ROUND((O$53-O$42)*100,0))) -> 0 | AA23: =-MAX(-5,MIN(5,ROUND((O$89-O$42)*100,0))) -> -1 | AB23: =-MAX(-5,MIN(5,ROUND((O$98-O$42)*100,0))) -> 0 | AC23: =-MAX(-5,MIN(5,ROUND((O$62-O$62)*100,0))) -> 0 | AD23: =-MAX(-5,MIN(5,ROUND((O$71-O$62)*100,0))) -> 0 | AE23: =-MAX(-5,MIN(5,ROUND((O$80-O$62)*100,0))) -> 0
D24: Central | E24: =-MAX(-5,MIN(5,ROUND((F$42-F$42)*100,0))) -> 0 | F24: =-MAX(-5,MIN(5,ROUND((F$53-F$42)*100,0))) -> 0 | G24: =-MAX(-5,MIN(5,ROUND((F$89-F$42)*100,0))) -> 0 | H24: =-MAX(-5,MIN(5,ROUND((F$98-F$42)*100,0))) -> 0 | I24: =-MAX(-5,MIN(5,ROUND((F$62-F$62)*100,0))) -> 0 | J24: =-MAX(-5,MIN(5,ROUND((F$71-F$62)*100,0))) -> 0 | K24: =-MAX(-5,MIN(5,ROUND((F$80-F$62)*100,0))) -> 0 | N24: Central | O24: =-MAX(-5,MIN(5,ROUND((K$42-K$42)*100,0))) -> 0 | P24: =-MAX(-5,MIN(5,ROUND((K$53-K$42)*100,0))) -> 0 | Q24: =-MAX(-5,MIN(5,ROUND((K$89-K$42)*100,0))) -> 0 | R24: =-MAX(-5,MIN(5,ROUND((K$98-K$42)*100,0))) -> 0 | S24: =-MAX(-5,MIN(5,ROUND((K$62-K$62)*100,0))) -> 0 | T24: =-MAX(-5,MIN(5,ROUND((K$71-K$62)*100,0))) -> 0 | U24: =-MAX(-5,MIN(5,ROUND((K$80-K$62)*100,0))) -> 0 | X24: Central | Y24: =-MAX(-5,MIN(5,ROUND((P$42-P$42)*100,0))) -> 0 | Z24: =-MAX(-5,MIN(5,ROUND((P$53-P$42)*100,0))) -> 0 | AA24: =-MAX(-5,MIN(5,ROUND((P$89-P$42)*100,0))) -> 0 | AB24: =-MAX(-5,MIN(5,ROUND((P$98-P$42)*100,0))) -> 0 | AC24: =-MAX(-5,MIN(5,ROUND((P$62-P$62)*100,0))) -> 0 | AD24: =-MAX(-5,MIN(5,ROUND((P$71-P$62)*100,0))) -> 0 | AE24: =-MAX(-5,MIN(5,ROUND((P$80-P$62)*100,0))) -> 0
D25: North | E25: =-MAX(-5,MIN(5,ROUND((G$42-G$42)*100,0))) -> 0 | F25: =-MAX(-5,MIN(5,ROUND((G$53-G$42)*100,0))) -> 0 | G25: =-MAX(-5,MIN(5,ROUND((G$89-G$42)*100,0))) -> 0 | H25: =-MAX(-5,MIN(5,ROUND((G$98-G$42)*100,0))) -> 0 | I25: =-MAX(-5,MIN(5,ROUND((G$62-G$62)*100,0))) -> 0 | J25: =-MAX(-5,MIN(5,ROUND((G$71-G$62)*100,0))) -> 0 | K25: =-MAX(-5,MIN(5,ROUND((G$80-G$62)*100,0))) -> 0 | N25: North | O25: =-MAX(-5,MIN(5,ROUND((L$42-L$42)*100,0))) -> 0 | P25: =-MAX(-5,MIN(5,ROUND((L$53-L$42)*100,0))) -> 0 | Q25: =-MAX(-5,MIN(5,ROUND((L$89-L$42)*100,0))) -> 0 | R25: =-MAX(-5,MIN(5,ROUND((L$98-L$42)*100,0))) -> 0 | S25: =-MAX(-5,MIN(5,ROUND((L$62-L$62)*100,0))) -> 0 | T25: =-MAX(-5,MIN(5,ROUND((L$71-L$62)*100,0))) -> 0 | U25: =-MAX(-5,MIN(5,ROUND((L$80-L$62)*100,0))) -> 0 | X25: North | Y25: =-MAX(-5,MIN(5,ROUND((Q$42-Q$42)*100,0))) -> 0 | Z25: =-MAX(-5,MIN(5,ROUND((Q$53-Q$42)*100,0))) -> 0 | AA25: =-MAX(-5,MIN(5,ROUND((Q$89-Q$42)*100,0))) -> 0 | AB25: =-MAX(-5,MIN(5,ROUND((Q$98-Q$42)*100,0))) -> 0 | AC25: =-MAX(-5,MIN(5,ROUND((Q$62-Q$62)*100,0))) -> 0 | AD25: =-MAX(-5,MIN(5,ROUND((Q$71-Q$62)*100,0))) -> 0 | AE25: =-MAX(-5,MIN(5,ROUND((Q$80-Q$62)*100,0))) -> 0
D26: South | E26: =-MAX(-5,MIN(5,ROUND((H$42-H$42)*100,0))) -> 0 | F26: =-MAX(-5,MIN(5,ROUND((H$53-H$42)*100,0))) -> 0 | G26: =-MAX(-5,MIN(5,ROUND((H$89-H$42)*100,0))) -> 0 | H26: =-MAX(-5,MIN(5,ROUND((H$98-H$42)*100,0))) -> 0 | I26: =-MAX(-5,MIN(5,ROUND((H$62-H$62)*100,0))) -> 0 | J26: =-MAX(-5,MIN(5,ROUND((H$71-H$62)*100,0))) -> 0 | K26: =-MAX(-5,MIN(5,ROUND((H$80-H$62)*100,0))) -> 0 | N26: South | O26: =-MAX(-5,MIN(5,ROUND((M$42-M$42)*100,0))) -> 0 | P26: =-MAX(-5,MIN(5,ROUND((M$53-M$42)*100,0))) -> 0 | Q26: =-MAX(-5,MIN(5,ROUND((M$89-M$42)*100,0))) -> 0 | R26: =-MAX(-5,MIN(5,ROUND((M$98-M$42)*100,0))) -> 0 | S26: =-MAX(-5,MIN(5,ROUND((M$62-M$62)*100,0))) -> 0 | T26: =-MAX(-5,MIN(5,ROUND((M$71-M$62)*100,0))) -> 0 | U26: =-MAX(-5,MIN(5,ROUND((M$80-M$62)*100,0))) -> 0 | X26: South | Y26: =-MAX(-5,MIN(5,ROUND((R$42-R$42)*100,0))) -> 0 | Z26: =-MAX(-5,MIN(5,ROUND((R$53-R$42)*100,0))) -> 0 | AA26: =-MAX(-5,MIN(5,ROUND((R$89-R$42)*100,0))) -> 0 | AB26: =-MAX(-5,MIN(5,ROUND((R$98-R$42)*100,0))) -> 0 | AC26: =-MAX(-5,MIN(5,ROUND((R$62-R$62)*100,0))) -> 0 | AD26: =-MAX(-5,MIN(5,ROUND((R$71-R$62)*100,0))) -> 0 | AE26: =-MAX(-5,MIN(5,ROUND((R$80-R$62)*100,0))) -> 0
D27: REGION | E27: BAU | F27: BAF | G27: ECO | H27: NGW | I27: BAU CS | J27: COR | K27: TUNNEL | N27: REGION | O27: BAU | P27: BAF | Q27: ECO | R27: NGW | S27: BAU CS | T27: COR | U27: TUNNEL | X27: REGION | Y27: BAU | Z27: BAF | AA27: ECO | AB27: NGW | AC27: BAU CS | AD27: COR | AE27: TUNNEL
C28: DAY USE (<18C) | D28: Delta-Wide | E28: =-MAX(-5,MIN(5,ROUND((D$39-D$39)*100,0))) -> 0 | F28: =-MAX(-5,MIN(5,ROUND((D$50-D$39)*100,0))) -> 0 | G28: =-MAX(-5,MIN(5,ROUND((D$86-D$39)*100,0))) -> 0 | H28: =-MAX(-5,MIN(5,ROUND((D$95-D$39)*100,0))) -> 0 | I28: =-MAX(-5,MIN(5,ROUND((D$59-D$59)*100,0))) -> 0 | J28: =-MAX(-5,MIN(5,ROUND((D$68-D$59)*100,0))) -> 0 | K28: =-MAX(-5,MIN(5,ROUND((D$77-D$59)*100,0))) -> 0 | M28: DAY USE (<18C) | N28: Delta-Wide | O28: =-MAX(-5,MIN(5,ROUND((I$39-I$39)*100,0))) -> 0 | P28: =-MAX(-5,MIN(5,ROUND((I$50-I$39)*100,0))) -> 0 | Q28: =-MAX(-5,MIN(5,ROUND((I$86-I$39)*100,0))) -> 0 | R28: =-MAX(-5,MIN(5,ROUND((I$95-I$39)*100,0))) -> 0 | S28: =-MAX(-5,MIN(5,ROUND((I$59-I$59)*100,0))) -> 0 | T28: =-MAX(-5,MIN(5,ROUND((I$68-I$59)*100,0))) -> 0 | U28: =-MAX(-5,MIN(5,ROUND((I$77-I$59)*100,0))) -> 0 | W28: DAY USE (<18C) | X28: Delta-Wide | Y28: =-MAX(-5,MIN(5,ROUND((N$39-N$39)*100,0))) -> 0 | Z28: =-MAX(-5,MIN(5,ROUND((N$50-N$39)*100,0))) -> 0 | AA28: =-MAX(-5,MIN(5,ROUND((N$86-N$39)*100,0))) -> 0 | AB28: =-MAX(-5,MIN(5,ROUND((N$95-N$39)*100,0))) -> 0 | AC28: =-MAX(-5,MIN(5,ROUND((N$59-N$59)*100,0))) -> 0 | AD28: =-MAX(-5,MIN(5,ROUND((N$68-N$59)*100,0))) -> 0 | AE28: =-MAX(-5,MIN(5,ROUND((N$77-N$59)*100,0))) -> 0
D29: Suisun | E29: =-MAX(-5,MIN(5,ROUND((E$39-E$39)*100,0))) -> 0 | F29: =-MAX(-5,MIN(5,ROUND((E$50-E$39)*100,0))) -> 0 | G29: =-MAX(-5,MIN(5,ROUND((E$86-E$39)*100,0))) -> 0 | H29: =-MAX(-5,MIN(5,ROUND((E$95-E$39)*100,0))) -> 0 | I29: =-MAX(-5,MIN(5,ROUND((E$59-E$59)*100,0))) -> 0 | J29: =-MAX(-5,MIN(5,ROUND((E$68-E$59)*100,0))) -> 0 | K29: =-MAX(-5,MIN(5,ROUND((E$77-E$59)*100,0))) -> 0 | N29: Suisun | O29: =-MAX(-5,MIN(5,ROUND((J$39-J$39)*100,0))) -> 0 | P29: =-MAX(-5,MIN(5,ROUND((J$50-J$39)*100,0))) -> 0 | Q29: =-MAX(-5,MIN(5,ROUND((J$86-J$39)*100,0))) -> 0 | R29: =-MAX(-5,MIN(5,ROUND((J$95-J$39)*100,0))) -> 0 | S29: =-MAX(-5,MIN(5,ROUND((J$59-J$59)*100,0))) -> 0 | T29: =-MAX(-5,MIN(5,ROUND((J$68-J$59)*100,0))) -> 0 | U29: =-MAX(-5,MIN(5,ROUND((J$77-J$59)*100,0))) -> 0 | X29: Suisun | Y29: =-MAX(-5,MIN(5,ROUND((O$39-O$39)*100,0))) -> 0 | Z29: =-MAX(-5,MIN(5,ROUND((O$50-O$39)*100,0))) -> 0 | AA29: =-MAX(-5,MIN(5,ROUND((O$86-O$39)*100,0))) -> 1 | AB29: =-MAX(-5,MIN(5,ROUND((O$95-O$39)*100,0))) -> 1 | AC29: =-MAX(-5,MIN(5,ROUND((O$59-O$59)*100,0))) -> 0 | AD29: =-MAX(-5,MIN(5,ROUND((O$68-O$59)*100,0))) -> 0 | AE29: =-MAX(-5,MIN(5,ROUND((O$77-O$59)*100,0))) -> 0
D30: Central | E30: =-MAX(-5,MIN(5,ROUND((F$39-F$39)*100,0))) -> 0 | F30: =-MAX(-5,MIN(5,ROUND((F$50-F$39)*100,0))) -> 0 | G30: =-MAX(-5,MIN(5,ROUND((F$86-F$39)*100,0))) -> 0 | H30: =-MAX(-5,MIN(5,ROUND((F$95-F$39)*100,0))) -> 0 | I30: =-MAX(-5,MIN(5,ROUND((F$59-F$59)*100,0))) -> 0 | J30: =-MAX(-5,MIN(5,ROUND((F$68-F$59)*100,0))) -> 0 | K30: =-MAX(-5,MIN(5,ROUND((F$77-F$59)*100,0))) -> 0 | N30: Central | O30: =-MAX(-5,MIN(5,ROUND((K$39-K$39)*100,0))) -> 0 | P30: =-MAX(-5,MIN(5,ROUND((K$50-K$39)*100,0))) -> 0 | Q30: =-MAX(-5,MIN(5,ROUND((K$86-K$39)*100,0))) -> 0 | R30: =-MAX(-5,MIN(5,ROUND((K$95-K$39)*100,0))) -> 0 | S30: =-MAX(-5,MIN(5,ROUND((K$59-K$59)*100,0))) -> 0 | T30: =-MAX(-5,MIN(5,ROUND((K$68-K$59)*100,0))) -> 0 | U30: =-MAX(-5,MIN(5,ROUND((K$77-K$59)*100,0))) -> 0 | X30: Central | Y30: =-MAX(-5,MIN(5,ROUND((P$39-P$39)*100,0))) -> 0 | Z30: =-MAX(-5,MIN(5,ROUND((P$50-P$39)*100,0))) -> 0 | AA30: =-MAX(-5,MIN(5,ROUND((P$86-P$39)*100,0))) -> 0 | AB30: =-MAX(-5,MIN(5,ROUND((P$95-P$39)*100,0))) -> 0 | AC30: =-MAX(-5,MIN(5,ROUND((P$59-P$59)*100,0))) -> 0 | AD30: =-MAX(-5,MIN(5,ROUND((P$68-P$59)*100,0))) -> 0 | AE30: =-MAX(-5,MIN(5,ROUND((P$77-P$59)*100,0))) -> 0
D31: North | E31: =-MAX(-5,MIN(5,ROUND((G$39-G$39)*100,0))) -> 0 | F31: =-MAX(-5,MIN(5,ROUND((G$50-G$39)*100,0))) -> 0 | G31: =-MAX(-5,MIN(5,ROUND((G$86-G$39)*100,0))) -> 0 | H31: =-MAX(-5,MIN(5,ROUND((G$95-G$39)*100,0))) -> 0 | I31: =-MAX(-5,MIN(5,ROUND((G$59-G$59)*100,0))) -> 0 | J31: =-MAX(-5,MIN(5,ROUND((G$68-G$59)*100,0))) -> 0 | K31: =-MAX(-5,MIN(5,ROUND((G$77-G$59)*100,0))) -> 0 | N31: North | O31: =-MAX(-5,MIN(5,ROUND((L$39-L$39)*100,0))) -> 0 | P31: =-MAX(-5,MIN(5,ROUND((L$50-L$39)*100,0))) -> 0 | Q31: =-MAX(-5,MIN(5,ROUND((L$86-L$39)*100,0))) -> 0 | R31: =-MAX(-5,MIN(5,ROUND((L$95-L$39)*100,0))) -> 0 | S31: =-MAX(-5,MIN(5,ROUND((L$59-L$59)*100,0))) -> 0 | T31: =-MAX(-5,MIN(5,ROUND((L$68-L$59)*100,0))) -> 0 | U31: =-MAX(-5,MIN(5,ROUND((L$77-L$59)*100,0))) -> 0 | X31: North | Y31: =-MAX(-5,MIN(5,ROUND((Q$39-Q$39)*100,0))) -> 0 | Z31: =-MAX(-5,MIN(5,ROUND((Q$50-Q$39)*100,0))) -> 0 | AA31: =-MAX(-5,MIN(5,ROUND((Q$86-Q$39)*100,0))) -> 0 | AB31: =-MAX(-5,MIN(5,ROUND((Q$95-Q$39)*100,0))) -> 0 | AC31: =-MAX(-5,MIN(5,ROUND((Q$59-Q$59)*100,0))) -> 0 | AD31: =-MAX(-5,MIN(5,ROUND((Q$68-Q$59)*100,0))) -> 0 | AE31: =-MAX(-5,MIN(5,ROUND((Q$77-Q$59)*100,0))) -> 0
D32: South | E32: =-MAX(-5,MIN(5,ROUND((H$39-H$39)*100,0))) -> 0 | F32: =-MAX(-5,MIN(5,ROUND((H$50-H$39)*100,0))) -> 0 | G32: =-MAX(-5,MIN(5,ROUND((H$86-H$39)*100,0))) -> 0 | H32: =-MAX(-5,MIN(5,ROUND((H$95-H$39)*100,0))) -> 0 | I32: =-MAX(-5,MIN(5,ROUND((H$59-H$59)*100,0))) -> 0 | J32: =-MAX(-5,MIN(5,ROUND((H$68-H$59)*100,0))) -> 0 | K32: =-MAX(-5,MIN(5,ROUND((H$77-H$59)*100,0))) -> 0 | N32: South | O32: =-MAX(-5,MIN(5,ROUND((M$39-M$39)*100,0))) -> 0 | P32: =-MAX(-5,MIN(5,ROUND((M$50-M$39)*100,0))) -> 0 | Q32: =-MAX(-5,MIN(5,ROUND((M$86-M$39)*100,0))) -> 0 | R32: =-MAX(-5,MIN(5,ROUND((M$95-M$39)*100,0))) -> 0 | S32: =-MAX(-5,MIN(5,ROUND((M$59-M$59)*100,0))) -> 0 | T32: =-MAX(-5,MIN(5,ROUND((M$68-M$59)*100,0))) -> 0 | U32: =-MAX(-5,MIN(5,ROUND((M$77-M$59)*100,0))) -> 0 | X32: South | Y32: =-MAX(-5,MIN(5,ROUND((R$39-R$39)*100,0))) -> 0 | Z32: =-MAX(-5,MIN(5,ROUND((R$50-R$39)*100,0))) -> 0 | AA32: =-MAX(-5,MIN(5,ROUND((R$86-R$39)*100,0))) -> 0 | AB32: =-MAX(-5,MIN(5,ROUND((R$95-R$39)*100,0))) -> 0 | AC32: =-MAX(-5,MIN(5,ROUND((R$59-R$59)*100,0))) -> 0 | AD32: =-MAX(-5,MIN(5,ROUND((R$68-R$59)*100,0))) -> 0 | AE32: =-MAX(-5,MIN(5,ROUND((R$77-R$59)*100,0))) -> 0
C36: BAU % EXCEEDANCES
D37: Total Run | I37: Wet Seasons | N37: Dry Seasons | T37: RECREATION: TEMPERATURE SCORE (B) — RMA SLR Temperature
D38: Delta-Wide | E38: Suisun | F38: Central Delta | G38: North Delta | H38: South Delta | I38: Delta-Wide | J38: Suisun | K38: Central Delta | L38: North Delta | M38: South Delta | N38: Delta-Wide | O38: Suisun | P38: Central Delta | Q38: North Delta | R38: South Delta | T38: Workflow: (1) Each activity = its Delta-Wide, Total Run score (-5 to 5). No Wet/Dry or sub-region rows, to avoid double counting. (2) Sum the activity scores. (3) Divide by # of activities = Temperature Score (B). Unlike salinity, Day Use & Boating are split for temperature: Boating & Day Use uses the warm-water (upper) threshold, while Day Use (<18C) is the cold-water threshold that goes the other way (exceedance = water too cold). Both are scored so more exceedances vs. baseline = lower score. Final Recreation Score = (A Salinity + B Temperature + C Habitat + D Economy) / 4.
C39: Day Use | D39: =BAU!AK876 -> 0.53548222 | E39: =BAU!AL876 -> 0.51812585 | F39: =BAU!AM876 -> 0.52895577 | G39: =BAU!AN876 -> 0.56178751 | H39: =BAU!AO876 -> 0.53989968 | I39: =BAU!AS876 -> 0.91952055 | J39: =BAU!AT876 -> 0.89383562 | K39: =BAU!AU876 -> 0.91841705 | L39: =BAU!AV876 -> 0.97442922 | M39: =BAU!AW876 -> 0.90684932 | N39: =BAU!BA876 -> 0.15249317 | O39: =BAU!BB876 -> 0.14344262 | P39: =BAU!BC876 -> 0.14055859 | Q39: =BAU!BD876 -> 0.15027322 | R39: =BAU!BE876 -> 0.17395264
C40: Birding | D40: =BAU!AK827 -> 0.36892955 | E40: =BAU!AL827 -> 0.36576607 | F40: =BAU!AM827 -> 0.37665299 | G40: =BAU!AN827 -> 0.34131327 | H40: =BAU!AO827 -> 0.38242894 | I40: =BAU!AS827 -> 0.011643836 | J40: =BAU!AT827 -> 0.013013699 | K40: =BAU!AU827 -> 0.0060882801 | L40: =BAU!AV827 -> 0.00091324201 | M40: =BAU!AW827 -> 0.023135464 | N40: =BAU!BA827 -> 0.72523907 | O40: =BAU!BB827 -> 0.71755464 | P40: =BAU!BC827 -> 0.74620522 | Q40: =BAU!BD827 -> 0.68078324 | R40: =BAU!BE827 -> 0.74074074 | T40: ACTIVITY | U40: SOURCE | V40: BAU | W40: BAF | X40: ECO | Y40: NGW | Z40: BAU CS | AA40: COR vs CS | AB40: Tunnel vs CS
C41: Waterfowl | D41: =BAU!AK843 -> 0.12401676 | E41: =BAU!AL843 -> 0.049760602 | F41: =BAU!AM843 -> 0.13391093 | G41: =BAU!AN843 -> 0.06748746 | H41: =BAU!AO843 -> 0.21781426 | I41: =BAU!AS843 -> 0 | J41: =BAU!AT843 -> 0 | K41: =BAU!AU843 -> 0 | L41: =BAU!AV843 -> 0 | M41: =BAU!AW843 -> 0 | N41: =BAU!BA843 -> 0.24769467 | O41: =BAU!BB843 -> 0.099385246 | P41: =BAU!BC843 -> 0.26745598 | Q41: =BAU!BD843 -> 0.13479053 | R41: =BAU!BE843 -> 0.43503339 | T41: Boating & Day Use | U41: Row 4 | V41: =E$4 -> 0 | W41: =F$4 -> 0 | X41: =G$4 -> 0 | Y41: =H$4 -> 0 | Z41: =I$4 -> 0 | AA41: =J$4 -> 0 | AB41: =K$4 -> 0
C42: Angling | D42: =BAU!AK859 -> 0.44699042 | E42: =BAU!AL859 -> 0.46169631 | F42: =BAU!AM859 -> 0.45310838 | G42: =BAU!AN859 -> 0.42065663 | H42: =BAU!AO859 -> 0.44535644 | I42: =BAU!AS859 -> 0.063441781 | J42: =BAU!AT859 -> 0.087328767 | K42: =BAU!AU859 -> 0.061187215 | L42: =BAU!AV859 -> 0.016894977 | M42: =BAU!AW859 -> 0.075494673 | N42: =BAU!BA859 -> 0.82949112 | O42: =BAU!BB859 -> 0.83504098 | P42: =BAU!BC859 -> 0.84395871 | Q42: =BAU!BD859 -> 0.82331512 | R42: =BAU!BE859 -> 0.81420765 | T42: Day Use (<18C, cold) | U42: Row 28 | V42: =E$28 -> 0 | W42: =F$28 -> 0 | X42: =G$28 -> 0 | Y42: =H$28 -> 0 | Z42: =I$28 -> 0 | AA42: =J$28 -> 0 | AB42: =K$28 -> 0
C43: Boating & Day Use | D43: =BAU!AK811 -> 0.41971614 | E43: =BAU!AL811 -> 0.4251026 | F43: =BAU!AM811 -> 0.42878857 | G43: =BAU!AN811 -> 0.39192886 | H43: =BAU!AO811 -> 0.4243806 | I43: =BAU!AS811 -> 0.042808219 | J43: =BAU!AT811 -> 0.057534247 | K43: =BAU!AU811 -> 0.043835616 | L43: =BAU!AV811 -> 0.0068493151 | M43: =BAU!AW811 -> 0.052663623 | N43: =BAU!BA811 -> 0.79559426 | O43: =BAU!BB811 -> 0.79166667 | P43: =BAU!BC811 -> 0.81268974 | Q43: =BAU!BD811 -> 0.77595628 | R43: =BAU!BE811 -> 0.79508197 | T43: Birding | U43: Row 10 | V43: =E$10 -> 0 | W43: =F$10 -> 0 | X43: =G$10 -> 0 | Y43: =H$10 -> 0 | Z43: =I$10 -> 0 | AA43: =J$10 -> 0 | AB43: =K$10 -> 0
...

Sheet BAU
B1: Suisun | J1: Central Delta | S1: North Delta | Y1: South Delta
A2: Date | B2: CHADBOURNE SLOUGH AT SUNRISE DUCK CLUB | C2: MONTEZUMA SLOUGH AT NATIONAL STEEL | D2: MONTEZUMA SLOUGH NEAR BELDENS LANDING | E2: SUISUN SLOUGH 300' SOUTH OF VOLANTI SLOUGH | F2: HONKER BAY | G2: SUISUN BAY AT VAN SICKLE ISLAND | H2: SUISUN BAY WEST REACH | I2: GRIZZLY BAY BUOY | J2: DUTCH SL BELOW JERSEY ISLAND | K2: FALSE RIVER NEAR OAKLEY | L2: OLD RIVER AT FRANKS TRACT | M2: PITTSBURG | N2: SACRAMENTO RIVER AT EMMATON | O2: SAN ANDREAS LANDING | P2: SAN JOAQUIN RIVER AT JERSEY POINT | Q2: SUISUN BAY AT CHANNEL MARKER 5 AT COLLINSVILLE | R2: BRANNAN MARINAS AT SAN JOAQUIN RIVER | S2: LIBERTY CUT AT FIVE POINTS | T2: CACHE SLOUGH ABOVE RYER ISLAND FERRY | U2: DELTA CROSS CHANNEL NEAR WALNUT GROVE | V2: SACRAMENTO RIVER DOWNSTREAM OF ISLETON | W2: COURTLAND AT SACRAMENTO RIVER | X2: VIERAS RESORT AT SACRAMENTO RIVER | Y2: GRANT LINE CANAL NEAR CLIFTON COURT FORE | Z2: LITTLE POTATO SLOUGH AT TERMINOUS | AA2: MIDDLE RIVER AT MILDRED ISLAND | AB2: OLD RIVER AT CLIFTON COURT | AC2: SAN JOAQUIN RIVER AT BRANDT BRIDGE | AD2: SAN JOAQUIN RIVER AT PRISONERS POINT | AE2: SAN JOAQUIN RIVER NEAR VERNALIS | AF2: SAN JOAQUIN RVER AT ROUGH AND READY ISLAND | AG2: VICTORIA CANAL BEFORE CLIFTON COURT FORE
A3: 43374 | B3: 19.621456 | C3: 19.650248 | D3: 19.470547 | E3: 19.27508 | F3: 19.047035 | G3: 19.07571 | H3: 18.865747 | I3: 18.725142 | J3: 20.345684 | K3: 19.976063 | L3: 20.001314 | M3: 19.088718 | N3: 19.449274 | O3: 19.861395 | P3: 19.881754 | Q3: 19.176027 | R3: 20.00821 | S3: 19.436558 | T3: 19.150568 | U3: 18.392368 | V3: 18.967125 | W3: 18.207766 | X3: 18.857056 | Y3: 21.67495 | Z3: 20.477545 | AA3: 20.68192 | AB3: 21.155918 | AC3: 22.314804 | AD3: 19.974895 | AE3: 21.385107 | AF3: 22.507124 | AG3: 21.442987
A4: 43375 | B4: 20.220093 | C4: 20.106773 | D4: 19.890047 | E4: 19.739466 | F4: 19.34155 | G4: 19.244131 | H4: 19.044348 | I4: 19.299963 | J4: 20.658575 | K4: 20.08927 | L4: 20.117836 | M4: 19.258429 | N4: 19.586138 | O4: 19.962988 | P4: 19.993353 | Q4: 19.34041 | R4: 20.078157 | S4: 19.93559 | T4: 19.340757 | U4: 18.444628 | V4: 19.063442 | W4: 18.242056 | X4: 18.89668 | Y4: 21.565435 | Z4: 20.501387 | AA4: 20.6364 | AB4: 21.046179 | AC4: 22.250488 | AD4: 20.05935 | AE4: 21.628126 | AF4: 22.436134 | AG4: 21.294363
A5: 43376 | B5: 20.501528 | C5: 20.349213 | D5: 20.252699 | E5: 20.117355 | F5: 19.508287 | G5: 19.397463 | H5: 19.222723 | I5: 19.66966 | J5: 20.78236 | K5: 20.181566 | L5: 20.154879 | M5: 19.417383 | N5: 19.67796 | O5: 19.961983 | P5: 20.09956 | Q5: 19.483976 | R5: 20.104 | S5: 20.368975 | T5: 19.536505 | U5: 18.445284 | V5: 19.142382 | W5: 18.210623 | X5: 18.949045 | Y5: 21.55558 | Z5: 20.453278 | AA5: 20.704407 | AB5: 21.080248 | AC5: 22.256273 | AD5: 20.121634 | AE5: 21.69896 | AF5: 22.413607 | AG5: 21.309343
A6: 43377 | B6: 20.3778 | C6: 20.304682 | D6: 20.359728 | E6: 20.19246 | F6: 19.480263 | G6: 19.45055 | H6: 19.281939 | I6: 19.660303 | J6: 20.567673 | K6: 20.12165 | L6: 20.058655 | M6: 19.470186 | N6: 19.63094 | O6: 19.845678 | P6: 20.053804 | Q6: 19.525034 | R6: 20.027338 | S6: 20.078283 | T6: 19.479383 | U6: 18.304735 | V6: 18.986786 | W6: 18.072588 | X6: 18.768341 | Y6: 21.4866 | Z6: 20.333994 | AA6: 20.706966 | AB6: 21.081823 | AC6: 22.139097 | AD6: 20.062943 | AE6: 21.5 | AF6: 22.3553 | AG6: 21.192133
A7: 43378 | B7: 19.95881 | C7: 19.896276 | D7: 20.113106 | E7: 19.890882 | F7: 19.280407 | G7: 19.36638 | H7: 19.192842 | I7: 19.246279 | J7: 20.189337 | K7: 19.961796 | L7: 19.90155 | M7: 19.390043 | N7: 19.502638 | O7: 19.608473 | P7: 19.915094 | Q7: 19.422304 | R7: 19.856054 | S7: 19.40171 | T7: 19.15869 | U7: 18.127504 | V7: 18.681326 | W7: 17.923273 | X7: 18.472244 | Y7: 21.328909 | Z7: 20.151472 | AA7: 20.597387 | AB7: 20.952417 | AC7: 21.867636 | AD7: 19.914423 | AE7: 20.830208 | AF7: 22.204615 | AG7: 21.004728
A8: 43379 | B8: 20.163212 | C8: 19.984783 | D8: 20.17353 | E8: 19.984245 | F8: 19.357862 | G8: 19.393276 | H8: 19.210938 | I8: 19.285501 | J8: 20.090975 | K8: 19.897432 | L8: 19.771154 | M8: 19.413134 | N8: 19.46529 | O8: 19.535639 | P8: 19.86006 | Q8: 19.436823 | R8: 19.786098 | S8: 19.460642 | T8: 19.11733 | U8: 18.047483 | V8: 18.723715 | W8: 17.768576 | X8: 18.537003 | Y8: 21.077898 | Z8: 20.022055 | AA8: 20.42726 | AB8: 20.77494 | AC8: 21.537016 | AD8: 19.813938 | AE8: 20.447916 | AF8: 21.998747 | AG8: 20.8129
A9: 43380 | B9: 19.978922 | C9: 19.93667 | D9: 20.113928 | E9: 19.905107 | F9: 19.239012 | G9: 19.347141 | H9: 19.175884 | I9: 19.09558 | J9: 19.411291 | K9: 19.552279 | L9: 19.484356 | M9: 19.37092 | N9: 19.21076 | O9: 19.252466 | P9: 19.556932 | Q9: 19.367235 | R9: 19.512709 | S9: 19.123014 | T9: 18.892683 | U9: 17.56515 | V9: 18.499613 | W9: 17.360651 | X9: 18.29877 | Y9: 20.188492 | Z9: 19.428892 | AA9: 19.85575 | AB9: 19.939226 | AC9: 20.340887 | AD9: 19.531239 | AE9: 19.233334 | AF9: 21.179396 | AG9: 19.8688
A10: 43381 | B10: 20.143581 | C10: 19.932264 | D10: 20.097612 | E10: 19.898766 | F10: 19.296606 | G10: 19.32468 | H10: 19.142183 | I10: 19.129168 | J10: 19.040972 | K10: 19.34875 | L10: 19.278086 | M10: 19.338165 | N10: 19.129124 | O10: 19.114496 | P10: 19.362852 | Q10: 19.337187 | R10: 19.350021 | S10: 18.779058 | T10: 18.641445 | U10: 17.29229 | V10: 18.278868 | W10: 17.150965 | X10: 18.038265 | Y10: 19.668383 | Z10: 19.093134 | AA10: 19.597172 | AB10: 19.492338 | AC10: 19.527126 | AD10: 19.28543 | AE10: 18.642708 | AF10: 20.663006 | AG10: 19.40679
A11: 43382 | B11: 20.21875 | C11: 20.122736 | D11: 20.175146 | E11: 19.952036 | F11: 19.286283 | G11: 19.356115 | H11: 19.155865 | I11: 19.274899 | J11: 19.321405 | K11: 19.401873 | L11: 19.307 | M11: 19.368025 | N11: 19.192564 | O11: 19.165545 | P11: 19.41124 | Q11: 19.378279 | R11: 19.371777 | S11: 18.768917 | T11: 18.536093 | U11: 17.29466 | V11: 18.229555 | W11: 17.121202 | X11: 17.971802 | Y11: 19.742157 | Z11: 19.115519 | AA11: 19.644434 | AB11: 19.627123 | AC11: 19.391441 | AD11: 19.264727 | AE11: 18.9125 | AF11: 20.569994 | AG11: 19.693182
A12: 43383 | B12: 19.531155 | C12: 19.689379 | D12: 19.757711 | E12: 19.45807 | F12: 18.95996 | G12: 19.136284 | H12: 18.92177 | I12: 18.69278 | J12: 19.166277 | K12: 19.270594 | L12: 19.181282 | M12: 19.151772 | N12: 19.042679 | O12: 19.046753 | P12: 19.271955 | Q12: 19.171803 | R12: 19.262901 | S12: 18.338737 | T12: 18.290318 | U12: 17.253702 | V12: 18.007624 | W12: 17.215471 | X12: 17.757542 | Y12: 19.809778 | Z12: 18.932772 | AA12: 19.64345 | AB12: 19.709879 | AC12: 19.341583 | AD12: 19.14191 | AE12: 19.247917 | AF12: 20.49454 | AG12: 19.835222
A13: 43384 | B13: 18.902355 | C13: 19.119143 | D13: 19.239267 | E13: 18.913395 | F13: 18.620363 | G13: 18.86414 | H13: 18.656 | I13: 18.065561 | J13: 18.782532 | K13: 19.03274 | L13: 18.96641 | M13: 18.881117 | N13: 18.784529 | O13: 18.749834 | P13: 19.031704 | Q13: 18.898857 | R13: 19.028051 | S13: 17.746603 | T13: 17.911976 | U13: 17.275244 | V13: 17.656544 | W13: 17.253716 | X13: 17.436365 | Y13: 19.802334 | Z13: 18.650648 | AA13: 19.576641 | AB13: 19.712427 | AC13: 19.325472 | AD13: 18.928318 | AE13: 19.247917 | AF13: 20.347559 | AG13: 19.849632
A14: 43385 | B14: 18.912106 | C14: 18.9784 | D14: 19.053455 | E14: 18.774221 | F14: 18.607014 | G14: 18.760122 | H14: 18.56443 | I14: 18.016962 | J14: 18.692038 | K14: 18.92327 | L14: 18.824945 | M14: 18.772234 | N14: 18.655672 | O14: 18.569838 | P14: 18.920393 | Q14: 18.78651 | R14: 18.862236 | S14: 17.759825 | T14: 17.773855 | U14: 17.3463 | V14: 17.619246 | W14: 17.3301 | X14: 17.495893 | Y14: 19.73516 | Z14: 18.576124 | AA14: 19.456503 | AB14: 19.662706 | AC14: 19.316278 | AD14: 18.783068 | AE14: 19.136457 | AF14: 20.156096 | AG14: 19.801289
... A795: 44166 | B795: 9.695075 | C795: 11.102656 | D795: 10.301434 | E795: 9.814164 | F795: 10.830606 | G795: 11.273779 | H795: 11.295159 | I795: 9.620292 | J795: 10.306324 | K795: 11.145622 | L795: 11.218401 | M795: 11.277278 | N795: 10.979962 | O795: 10.566613 | P795: 11.248478 | Q795: 11.173551 | R795: 11.142659 | S795: 8.916174 | T795: 10.089633 | U795: 10.112248 | V795: 10.000368 | W795: 9.964115 | X795: 9.997412 | Y795: 9.833182 | Z795: 10.405892 | AA795: 10.988554 | AB795: 10.435807 | AC795: 9.685511 | AD795: 11.379086 | AE795: 9.7 | AF795: 10.632603 | AG795: 10.457756
A796: TOTAL EXCEEDANCES | B796: =COUNTIF(B$3:B$733,">=19") -> 327 | C796: =COUNTIF(C$3:C$733,">=19") -> 318 | D796: =COUNTIF(D$3:D$733,">=19") -> 324 | E796: =COUNTIF(E$3:E$733,">=19") -> 318 | F796: =COUNTIF(F$3:F$733,">=19") -> 299 | G796: =COUNTIF(G$3:G$733,">=19") -> 306 | H796: =COUNTIF(H$3:H$733,">=19") -> 295 | I796: =COUNTIF(I$3:I$733,">=19") -> 299 | ... AG796: =COUNTIF(AG$3:AG$733,">=19") -> 342
A797: WET 1 | B797: =COUNTIF(B$3:B$184,">=19") -> 10 | C797: =COUNTIF(C$3:C$184,">=19") -> 12 | D797: =COUNTIF(D$3:D$184,">=19") -> 13 | E797: =COUNTIF(E$3:E$184,">=19") -> 10 | F797: =COUNTIF(F$3:F$184,">=19") -> 9 | G797: =COUNTIF(G$3:G$184,">=19") -> 10 | H797: =COUNTIF(H$3:H$184,">=19") -> 8 | I797: =COUNTIF(I$3:I$184,">=19") -> 8 | ... AG797: =COUNTIF(AG$3:AG$184,">=19") -> 15 | AH797: OCT 2018 - MARCH 2019
A798: WET 2 | B798: =COUNTIF(B$368:B$550,">=19") -> 10 | C798: =COUNTIF(C$368:C$550,">=19") -> 14 | D798: =COUNTIF(D$368:D$550,">=19") -> 12 | E798: =COUNTIF(E$368:E$550,">=19") -> 9 | F798: =COUNTIF(F$368:F$550,">=19") -> 13 | G798: =COUNTIF(G$368:G$550,">=19") -> 10 | H798: =COUNTIF(H$368:H$550,">=19") -> 13 | I798: =COUNTIF(I$368:I$550,">=19") -> 7 | ... AG798: =COUNTIF(AG$368:AG$550,">=19") -> 17 | AH798: OCT 2019 - MARCH 2020
A799: DRY 1 | B799: =COUNTIF(B$185:B$367,">=19") -> 146 | C799: =COUNTIF(C$185:C$367,">=19") -> 133 | D799: =COUNTIF(D$185:D$367,">=19") -> 139 | E799: =COUNTIF(E$185:E$367,">=19") -> 139 | F799: =COUNTIF(F$185:F$367,">=19") -> 126 | G799: =COUNTIF(G$185:G$367,">=19") -> 130 | H799: =COUNTIF(H$185:H$367,">=19") -> 127 | I799: =COUNTIF(I$185:I$367,">=19") -> 134 | ... AG799: =COUNTIF(AG$185:AG$367,">=19") -> 142 | AH799: APRIL 2019 - SEPTEMBER 2019
A800: DRY 2 | B800: =COUNTIF(B$551:B$733,">=19") -> 161 | C800: =COUNTIF(C$551:C$733,">=19") -> 159 | D800: =COUNTIF(D$551:D$733,">=19") -> 160 | E800: =COUNTIF(E$551:E$733,">=19") -> 160 | F800: =COUNTIF(F$551:F$733,">=19") -> 151 | G800: =COUNTIF(G$551:G$733,">=19") -> 156 | H800: =COUNTIF(H$551:H$733,">=19") -> 147 | I800: =COUNTIF(I$551:I$733,">=19") -> 150 | ... AG800: =COUNTIF(AG$551:AG$733,">=19") -> 168 | AH800: APRIL 2020 - SEPTEMBER 2020
A801: ALL WET | B801: =SUM(B$797,B$798) -> 20 | C801: =SUM(C$797,C$798) -> 26 | D801: =SUM(D$797,D$798) -> 25 | E801: =SUM(E$797,E$798) -> 19 | F801: =SUM(F$797,F$798) -> 22 | G801: =SUM(G$797,G$798) -> 20 | H801: =SUM(H$797,H$798) -> 21 | I801: =SUM(I$797,I$798) -> 15 | ... AG801: =SUM(AG$797,AG$798) -> 32
A802: ALL DRY | B802: =SUM(B$799,B$800) -> 307 | C802: =SUM(C$799,C$800) -> 292 | D802: =SUM(D$799,D$800) -> 299 | E802: =SUM(E$799,E$800) -> 299 | F802: =SUM(F$799,F$800) -> 277 | G802: =SUM(G$799,G$800) -> 286 | H802: =SUM(H$799,H$800) -> 274 | I802: =SUM(I$799,I$800) -> 284 | ... AG802: =SUM(AG$799,AG$800) -> 310
D805: Day Use & Boating 19C | F805: THRESHOLD: 19C | S805: SP DAY USE & BOATING | AA805: SP DAY USE & BOATING | AE805: SP DAY USE & BOATING | AI805: SP DAY USE & BOATING | AQ805: SP DAY USE & BOATING | AY805: SP DAY USE & BOATING
F806: WET SEASON | S806: TOTAL RUN | AA806: WET SEASONS | AE806: DRY SEASONS | AI806: TOTAL RUN | AK806: Delta-Wide | AL806: Suisun | AM806: Central Delta | AN806: North Delta | AO806: South Delta | AQ806: WET SEASONS | AS806: Delta-Wide | AT806: Suisun | AU806: Central Delta | AV806: North Delta | AW806: South Delta | AY806: DRY SEASONS | BA806: Delta-Wide | BB806: Suisun | BC806: Central Delta | BD806: North Delta | BE806: South Delta
F807: OCTOBER 1 - MARCH 31 | M807: DRY SEASON | S807: Total points | U807: =COUNTIF($B$2:$AG$2,"<>") -> 32 | AA807: Total points | AC807: =$U$807 -> 32 | AE807: Total points | AG807: =$U$807 -> 32 | AI807: Total points | AK807: =COUNTIF($B$2:$AG$2,"<>") -> 32 | AL807: =COUNTIF($B$2:$I$2,"<>") -> 8 | AM807: =COUNTIF($J$2:$R$2,"<>") -> 9 | AN807: =COUNTIF($S$2:$X$2,"<>") -> 6 | AO807: =COUNTIF($Y$2:$AG$2,"<>") -> 9 | AQ807: Total points | AS807: =COUNTIF($B$2:$AG$2,"<>") -> 32 | AT807: =COUNTIF($B$2:$I$2,"<>") -> 8 | AU807: =COUNTIF($J$2:$R$2,"<>") -> 9 | AV807: =COUNTIF($S$2:$X$2,"<>") -> 6 | AW807: =COUNTIF($Y$2:$AG$2,"<>") -> 9 | AY807: Total points | BA807: =COUNTIF($B$2:$AG$2,"<>") -> 32 | BB807: =COUNTIF($B$2:$I$2,"<>") -> 8 | BC807: =COUNTIF($J$2:$R$2,"<>") -> 9 | BD807: =COUNTIF($S$2:$X$2,"<>") -> 6 | BE807: =COUNTIF($Y$2:$AG$2,"<>") -> 9
F808: WET SEASON 1 | H808: 10/1/18 - 3/31/19 | J808: =COUNTIF($A$3:$A$184,"<>") -> 182 | M808: APRIL 1 - SEPTEMBER 30 | S808: Days in run | U808: =COUNTIF($A$3:$A$733,"<>") -> 731 | AA808: Days in run | AC808: =SUM($J$808:$J$809) -> 365 | AE808: Days in run | AG808: =SUM($Q$809:$Q$810) -> 366 | AI808: Days in run | AK808: =$U$808 -> 731 | AL808: =$U$808 -> 731 | AM808: =$U$808 -> 731 | AN808: =$U$808 -> 731 | AO808: =$U$808 -> 731 | AQ808: Days in run | AS808: =$AC$808 -> 365 | AT808: =$AC$808 -> 365 | AU808: =$AC$808 -> 365 | AV808: =$AC$808 -> 365 | AW808: =$AC$808 -> 365 | AY808: Days in run | BA808: =$AG$808 -> 366 | BB808: =$AG$808 -> 366 | BC808: =$AG$808 -> 366 | BD808: =$AG$808 -> 366 | BE808: =$AG$808 -> 366 | BG808: CHECK days: Total = Wet + Dry | BH808: =AND(U808=AC808+AG808,U808=731,AC808=365,AG808=366) -> TRUE
F809: WET SEASON 2 | H809: 10/1/19 - 3/31/20 | J809: =COUNTIF($A$368:$A$550,"<>") -> 183 | M809: DRY SEASON 1 | O809: 4/1/19 - 9/30/19 | Q809: =COUNTIF($A$185:$A$367,"<>") -> 183 | S809: Total measurements | U809: =U808*U807 -> 23392 | V809: DENOMINATOR FOR EXCEEDANCE % | AA809: Total measurements | AC809: =AC808*AC807 -> 11680 | AE809: Total measurements | AG809: =AG808*AG807 -> 11712 | AI809: Total measurements | AK809: =AK808*AK807 -> 23392 | AL809: =AL808*AL807 -> 5848 | AM809: =AM808*AM807 -> 6579 | AN809: =AN808*AN807 -> 4386 | AO809: =AO808*AO807 -> 6579 | AQ809: Total measurements | AS809: =AS808*AS807 -> 11680 | AT809: =AT808*AT807 -> 2920 | AU809: =AU808*AU807 -> 3285 | AV809: =AV808*AV807 -> 2190 | AW809: =AW808*AW807 -> 3285 | AY809: Total measurements | BA809: =BA808*BA807 -> 11712 | BB809: =BB808*BB807 -> 2928 | BC809: =BC808*BC807 -> 3294 | BD809: =BD808*BD807 -> 2196 | BE809: =BE808*BE807 -> 3294
F810: WET SEASON 3 | H810: 10/1/20 - 12/1/20 | J810: =COUNTIF($A$734:$A$795,"<>") -> 62 | M810: DRY SEASON 2 | O810: 4/1/20 - 9/30/20 | Q810: =COUNTIF($A$551:$A$733,"<>") -> 183 | S810: Measurements >= 19C | U810: =SUM($B$796:$AG$796) -> 9818 | V810: NUMERATOR FOR EXCEEDANCE % | AA810: Measurements >= 19C | AC810: =SUM($B$801:$AG$801) -> 500 | AE810: Measurements >= 19C | AG810: =SUM($B$802:$AG$802) -> 9318 | AI810: Measurements >= 19C | AK810: =SUM(B796:AG796) -> 9818 | AL810: =SUM(B796:I796) -> 2486 | AM810: =SUM(J796:R796) -> 2821 | AN810: =SUM(S796:X796) -> 1719 | AO810: =SUM(Y796:AG796) -> 2792 | AQ810: Measurements >= 19C | AS810: =SUM(B801:AG801) -> 500 | AT810: =SUM(B801:I801) -> 168 | AU810: =SUM(J801:R801) -> 144 | AV810: =SUM(S801:X801) -> 15 | AW810: =SUM(Y801:AG801) -> 173 | AY810: Measurements >= 19C | BA810: =SUM(B802:AG802) -> 9318 | BB810: =SUM(B802:I802) -> 2318 | BC810: =SUM(J802:R802) -> 2677 | BD810: =SUM(S802:X802) -> 1704 | BE810: =SUM(Y802:AG802) -> 2619 | BG810: CHECK counts: Total = Wet + Dry | BH810: =AND(U810=AC810+AG810,AK810=AS810+BA810,AL810=AT810+BB810,AM810=AU810+BC810,AN810=AV810+BD810,AO810=AW810+BE810) -> TRUE
S811: % Total Run Exceedances | U811: =U810/U809 -> 0.41971614 | AA811: % WET Exceedances | AC811: =AC810/AC809 -> 0.042808219 | AE811: % DRY Exceedances | AG811: =AG810/AG809 -> 0.79559426 | AI811: % Total Run Exceedances | AK811: =AK810/AK809 -> 0.41971614 | AL811: =AL810/AL809 -> 0.4251026 | AM811: =AM810/AM809 -> 0.42878857 | AN811: =AN810/AN809 -> 0.39192886 | AO811: =AO810/AO809 -> 0.4243806 | AQ811: % WET Exceedances | AS811: =AS810/AS809 -> 0.042808219 | AT811: =AT810/AT809 -> 0.057534247 | AU811: =AU810/AU809 -> 0.043835616 | AV811: =AV810/AV809 -> 0.0068493151 | AW811: =AW810/AW809 -> 0.052663623 | AY811: % DRY Exceedances | BA811: =BA810/BA809 -> 0.79559426 | BB811: =BB810/BB809 -> 0.79166667 | BC811: =BC810/BC809 -> 0.81268974 | BD811: =BD810/BD809 -> 0.77595628 | BE811: =BE810/BE809 -> 0.79508197
A813: TOTAL EXCEEDANCES | B813: =COUNTIF(B$3:B$733,">=20") -> 294 | C813: =COUNTIF(C$3:C$733,">=20") -> 274 | D813: =COUNTIF(D$3:D$733,">=20") -> 291 | E813: =COUNTIF(E$3:E$733,">=20") -> 277 | F813: =COUNTIF(F$3:F$733,">=20") -> 249 | G813: =COUNTIF(G$3:G$733,">=20") -> 253 | H813: =COUNTIF(H$3:H$733,">=20") -> 246 | I813: =COUNTIF(I$3:I$733,">=20") -> 255 | ... AG813: =COUNTIF(AG$3:AG$733,">=20") -> 305
A814: WET 1 | B814: =COUNTIF(B$3:B$184,">=20") -> 6 | C814: =COUNTIF(C$3:C$184,">=20") -> 4 | D814: =COUNTIF(D$3:D$184,">=20") -> 7 | E814: =COUNTIF(E$3:E$184,">=20") -> 2 | F814: =COUNTIF(F$3:F$184,">=20") -> 0 | G814: =COUNTIF(G$3:G$184,">=20") -> 0 | H814: =COUNTIF(H$3:H$184,">=20") -> 0 | I814: =COUNTIF(I$3:I$184,">=20") -> 0 | ... AG814: =COUNTIF(AG$3:AG$184,">=20") -> 6 | AH814: OCT 2018 - MARCH 2019
A815: WET 2 | B815: =COUNTIF(B$368:B$550,">=20") -> 5 | C815: =COUNTIF(C$368:C$550,">=20") -> 3 | D815: =COUNTIF(D$368:D$550,">=20") -> 6 | E815: =COUNTIF(E$368:E$550,">=20") -> 4 | F815: =COUNTIF(F$368:F$550,">=20") -> 0 | G815: =COUNTIF(G$368:G$550,">=20") -> 0 | H815: =COUNTIF(H$368:H$550,">=20") -> 0 | I815: =COUNTIF(I$368:I$550,">=20") -> 1 | ... AG815: =COUNTIF(AG$368:AG$550,">=20") -> 6 | AH815: OCT 2019 - MARCH 2020
A816: DRY 1 | B816: =COUNTIF(B$185:B$367,">=20") -> 134 | C816: =COUNTIF(C$185:C$367,">=20") -> 119 | D816: =COUNTIF(D$185:D$367,">=20") -> 130 | E816: =COUNTIF(E$185:E$367,">=20") -> 128 | F816: =COUNTIF(F$185:F$367,">=20") -> 118 | G816: =COUNTIF(G$185:G$367,">=20") -> 119 | H816: =COUNTIF(H$185:H$367,">=20") -> 118 | I816: =COUNTIF(I$185:I$367,">=20") -> 121 | ... AG816: =COUNTIF(AG$185:AG$367,">=20") -> 129 | AH816: APRIL 2019 - SEPTEMBER 2019
A817: DRY 2 | B817: =COUNTIF(B$551:B$733,">=20") -> 149 | C817: =COUNTIF(C$551:C$733,">=20") -> 148 | D817: =COUNTIF(D$551:D$733,">=20") -> 148 | E817: =COUNTIF(E$551:E$733,">=20") -> 143 | F817: =COUNTIF(F$551:F$733,">=20") -> 131 | G817: =COUNTIF(G$551:G$733,">=20") -> 134 | H817: =COUNTIF(H$551:H$733,">=20") -> 128 | I817: =COUNTIF(I$551:I$733,">=20") -> 133 | ... AG817: =COUNTIF(AG$551:AG$733,">=20") -> 164 | AH817: APRIL 2020 - SEPTEMBER 2020
A818: ALL WET | B818: =SUM(B$814,B$815) -> 11 | C818: =SUM(C$814,C$815) -> 7 | D818: =SUM(D$814,D$815) -> 13 | E818: =SUM(E$814,E$815) -> 6 | F818: =SUM(F$814,F$815) -> 0 | G818: =SUM(G$814,G$815) -> 0 | H818: =SUM(H$814,H$815) -> 0 | I818: =SUM(I$814,I$815) -> 1 | ... AG818: =SUM(AG$814,AG$815) -> 12
A819: ALL DRY | B819: =SUM(B$816,B$817) -> 283 | C819: =SUM(C$816,C$817) -> 267 | D819: =SUM(D$816,D$817) -> 278 | E819: =SUM(E$816,E$817) -> 271 | F819: =SUM(F$816,F$817) -> 249 | G819: =SUM(G$816,G$817) -> 253 | H819: =SUM(H$816,H$817) -> 246 | I819: =SUM(I$816,I$817) -> 254 | ... AG819: =SUM(AG$816,AG$817) -> 293
D821: Birding 20C | F821: THRESHOLD: 20C | S821: BIRDING | AA821: BIRDING | AE821: BIRDING | AI821: BIRDING | AQ821: BIRDING | AY821: BIRDING
F822: WET SEASON | S822: TOTAL RUN | AA822: WET SEASONS | AE822: DRY SEASONS | AI822: TOTAL RUN | AK822: Delta-Wide | AL822: Suisun | AM822: Central Delta | AN822: North Delta | AO822: South Delta | AQ822: WET SEASONS | AS822: Delta-Wide | AT822: Suisun | AU822: Central Delta | AV822: North Delta | AW822: South Delta | AY822: DRY SEASONS | BA822: Delta-Wide | BB822: Suisun | BC822: Central Delta | BD822: North Delta | BE822: South Delta
F823: OCTOBER 1 - MARCH 31 | M823: DRY SEASON | S823: Total points | U823: =COUNTIF($B$2:$AG$2,"<>") -> 32 | AA823: Total points | AC823: =$U$823 -> 32 | AE823: Total points | AG823: =$U$823 -> 32 | AI823: Total points | AK823: =COUNTIF($B$2:$AG$2,"<>") -> 32 | AL823: =COUNTIF($B$2:$I$2,"<>") -> 8 | AM823: =COUNTIF($J$2:$R$2,"<>") -> 9 | AN823: =COUNTIF($S$2:$X$2,"<>") -> 6 | AO823: =COUNTIF($Y$2:$AG$2,"<>") -> 9 | AQ823: Total points | AS823: =COUNTIF($B$2:$AG$2,"<>") -> 32 | AT823: =COUNTIF($B$2:$I$2,"<>") -> 8 | AU823: =COUNTIF($J$2:$R$2,"<>") -> 9 | AV823: =COUNTIF($S$2:$X$2,"<>") -> 6 | AW823: =COUNTIF($Y$2:$AG$2,"<>") -> 9 | AY823: Total points | BA823: =COUNTIF($B$2:$AG$2,"<>") -> 32 | BB823: =COUNTIF($B$2:$I$2,"<>") -> 8 | BC823: =COUNTIF($J$2:$R$2,"<>") -> 9 | BD823: =COUNTIF($S$2:$X$2,"<>") -> 6 | BE823: =COUNTIF($Y$2:$AG$2,"<>") -> 9
F824: WET SEASON 1 | H824: 10/1/18 - 3/31/19 | J824: =COUNTIF($A$3:$A$184,"<>") -> 182 | M824: APRIL 1 - SEPTEMBER 30 | S824: Days in run | U824: =COUNTIF($A$3:$A$733,"<>") -> 731 | AA824: Days in run | AC824: =SUM($J$824:$J$825) -> 365 | AE824: Days in run | AG824: =SUM($Q$825:$Q$826) -> 366 | AI824: Days in run | AK824: =$U$824 -> 731 | AL824: =$U$824 -> 731 | AM824: =$U$824 -> 731 | AN824: =$U$824 -> 731 | AO824: =$U$824 -> 731 | AQ824: Days in run | AS824: =$AC$824 -> 365 | AT824: =$AC$824 -> 365 | AU824: =$AC$824 -> 365 | AV824: =$AC$824 -> 365 | AW824: =$AC$824 -> 365 | AY824: Days in run | BA824: =$AG$824 -> 366 | BB824: =$AG$824 -> 366 | BC824: =$AG$824 -> 366 | BD824: =$AG$824 -> 366 | BE824: =$AG$824 -> 366 | BG824: CHECK days: Total = Wet + Dry | BH824: =AND(U824=AC824+AG824,U824=731,AC824=365,AG824=366) -> TRUE
...

Sheet B&F
B1: Suisun | J1: Central Delta | S1: North Delta | Y1: South Delta
A2: Date | B2: CHADBOURNE SLOUGH AT SUNRISE DUCK CLUB | C2: MONTEZUMA SLOUGH AT NATIONAL STEEL | D2: MONTEZUMA SLOUGH NEAR BELDENS LANDING | E2: SUISUN SLOUGH 300' SOUTH OF VOLANTI SLOUGH | F2: HONKER BAY | G2: SUISUN BAY AT VAN SICKLE ISLAND | H2: SUISUN BAY WEST REACH | I2: GRIZZLY BAY BUOY | J2: DUTCH SL BELOW JERSEY ISLAND | K2: FALSE RIVER NEAR OAKLEY | L2: OLD RIVER AT FRANKS TRACT | M2: PITTSBURG | N2: SACRAMENTO RIVER AT EMMATON | O2: SAN ANDREAS LANDING | P2: SAN JOAQUIN RIVER AT JERSEY POINT | Q2: SUISUN BAY AT CHANNEL MARKER 5 AT COLLINSVILLE | R2: BRANNAN MARINAS AT SAN JOAQUIN RIVER | S2: LIBERTY CUT AT FIVE POINTS | T2: CACHE SLOUGH ABOVE RYER ISLAND FERRY | U2: DELTA CROSS CHANNEL NEAR WALNUT GROVE | V2: SACRAMENTO RIVER DOWNSTREAM OF ISLETON | W2: COURTLAND AT SACRAMENTO RIVER | X2: VIERAS RESORT AT SACRAMENTO RIVER | Y2: GRANT LINE CANAL NEAR CLIFTON COURT FORE | Z2: LITTLE POTATO SLOUGH AT TERMINOUS | AA2: MIDDLE RIVER AT MILDRED ISLAND | AB2: OLD RIVER AT CLIFTON COURT | AC2: SAN JOAQUIN RIVER AT BRANDT BRIDGE | AD2: SAN JOAQUIN RIVER AT PRISONERS POINT | AE2: SAN JOAQUIN RIVER NEAR VERNALIS | AF2: SAN JOAQUIN RVER AT ROUGH AND READY ISLAND | AG2: VICTORIA CANAL BEFORE CLIFTON COURT FORE
A3: 43374 | B3: 19.61622 | C3: 19.64741 | D3: 19.467564 | E3: 19.274176 | F3: 19.05587 | G3: 19.089382 | H3: 18.870527 | I3: 18.729668 | J3: 20.42826 | K3: 20.104958 | L3: 20.03478 | M3: 19.106619 | N3: 19.442062 | O3: 19.880629 | P3: 19.965002 | Q3: 19.187864 | R3: 20.012558 | S3: 19.437504 | T3: 19.16362 | U3: 18.394327 | V3: 18.994667 | W3: 18.207794 | X3: 18.883308 | Y3: 21.630825 | Z3: 20.352444 | AA3: 20.616661 | AB3: 21.000694 | AC3: 22.367771 | AD3: 19.985447 | AE3: 21.385107 | AF3: 22.497746 | AG3: 21.375547
