Workbook

Sheet OVERALL
AG1: Notes: 1. In overview, most exceedances happen at Suisun Marsh for this Sea Level Rise Salinity model scenario, while the Central Delta sees exceedances to a lesser extent for Total Runs and Winter seasonal thresholds, and by activity-based threshold gradients as well, with angling showing zero threshold crossings at the North and South Delta. Under BAU Total Run, Suisun exceeds 82% of days for Day Use and Boating, 74% for Birding, 70% for Waterfowl, and 42% for angling; the Central Delta follows this gradient to lesser intensities at 38%, 20%, 13%, and 5%. In general, our lower threshold base activities (Day Use and Boating) cross the thresholds most often. 2. Scenario rankings (-5 to 5 vs BAU), similar to our base salinity scenario, show that Bolster and Fortify are very similar to BAU in terms of threshold exceedance. Eco Machine and New Green Watershed follow each other's moves closely, albeit with a few regional differences (Dry Seasons: Birding and Day Use and Boating) in the Central Delta and Suisun Marsh. 3. Surprisingly, threshold exceedances during wet seasons exceed salinity thresholds more often than during dry seasons in every activity (Waterfowl 70% vs 65% in BAF). These unexpected moves are reflected across our NGW and ECO scenarios, both showing -5 scores for birding, waterfowl, and even angling.
C2: TOTAL RUN SCORES | M2: WET SEASON SCORES | W2: DRY SEASON SCORES
D3: REGION | E3: BAU | F3: BAF | G3: ECO | H3: NGW | I3: BAU CS | J3: COR vs CS | K3: TUNNEL VS CS | N3: REGION | O3: BAU | P3: BAF | Q3: ECO | R3: NGW | S3: BAU CS | T3: COR vs CS | U3: TUNNEL VS CS | X3: REGION | Y3: BAU | Z3: BAF | AA3: ECO | AB3: NGW | AC3: BAU CS | AD3: COR vs CS | AE3: TUNNEL VS CS
C4: SP DAY USE & BOATING | D4: Delta-Wide | E4: =-MAX(-5,MIN(5,ROUND((D$33-D$33)*100,0))) -> 0 | F4: =-MAX(-5,MIN(5,ROUND((D$41-D$33)*100,0))) -> 0 | G4: =-MAX(-5,MIN(5,ROUND((D$73-D$33)*100,0))) -> 0 | H4: =-MAX(-5,MIN(5,ROUND((D$81-D$33)*100,0))) -> 0 | I4: =-MAX(-5,MIN(5,ROUND((D$49-D$49)*100,0))) -> 0 | J4: =-MAX(-5,MIN(5,ROUND((D$57-D$49)*100,0))) -> 1 | K4: =-MAX(-5,MIN(5,ROUND((D$65-D$49)*100,0))) -> -1 | M4: SP DAY USE & BOATING | N4: Delta-Wide | O4: =-MAX(-5,MIN(5,ROUND((I$33-I$33)*100,0))) -> 0 | P4: =-MAX(-5,MIN(5,ROUND((I$41-I$33)*100,0))) -> -1 | Q4: =-MAX(-5,MIN(5,ROUND((I$73-I$33)*100,0))) -> 0 | R4: =-MAX(-5,MIN(5,ROUND((I$81-I$33)*100,0))) -> 0 | S4: =-MAX(-5,MIN(5,ROUND((I$49-I$49)*100,0))) -> 0 | T4: =-MAX(-5,MIN(5,ROUND((I$57-I$49)*100,0))) -> 1 | U4: =-MAX(-5,MIN(5,ROUND((I$65-I$49)*100,0))) -> -1 | W4: SP DAY USE & BOATING | X4: Delta-Wide | Y4: =-MAX(-5,MIN(5,ROUND((N$33-N$33)*100,0))) -> 0 | Z4: =-MAX(-5,MIN(5,ROUND((N$41-N$33)*100,0))) -> -1 | AA4: =-MAX(-5,MIN(5,ROUND((N$73-N$33)*100,0))) -> 0 | AB4: =-MAX(-5,MIN(5,ROUND((N$81-N$33)*100,0))) -> 0 | AC4: =-MAX(-5,MIN(5,ROUND((N$49-N$49)*100,0))) -> 0 | AD4: =-MAX(-5,MIN(5,ROUND((N$57-N$49)*100,0))) -> 0 | AE4: =-MAX(-5,MIN(5,ROUND((N$65-N$49)*100,0))) -> -1
D5: Suisun | E5: =-MAX(-5,MIN(5,ROUND((E$33-E$33)*100,0))) -> 0 | F5: =-MAX(-5,MIN(5,ROUND((E$41-E$33)*100,0))) -> 0 | G5: =-MAX(-5,MIN(5,ROUND((E$73-E$33)*100,0))) -> -2 | H5: =-MAX(-5,MIN(5,ROUND((E$81-E$33)*100,0))) -> -2 | I5: =-MAX(-5,MIN(5,ROUND((E$49-E$49)*100,0))) -> 0 | J5: =-MAX(-5,MIN(5,ROUND((E$57-E$49)*100,0))) -> 1 | K5: =-MAX(-5,MIN(5,ROUND((E$65-E$49)*100,0))) -> -1 | N5: Suisun | O5: =-MAX(-5,MIN(5,ROUND((J$33-J$33)*100,0))) -> 0 | P5: =-MAX(-5,MIN(5,ROUND((J$41-J$33)*100,0))) -> 0 | Q5: =-MAX(-5,MIN(5,ROUND((J$73-J$33)*100,0))) -> -3 | R5: =-MAX(-5,MIN(5,ROUND((J$81-J$33)*100,0))) -> -3 | S5: =-MAX(-5,MIN(5,ROUND((J$49-J$49)*100,0))) -> 0 | T5: =-MAX(-5,MIN(5,ROUND((J$57-J$49)*100,0))) -> 2 | U5: =-MAX(-5,MIN(5,ROUND((J$65-J$49)*100,0))) -> -1 | X5: Suisun | Y5: =-MAX(-5,MIN(5,ROUND((O$33-O$33)*100,0))) -> 0 | Z5: =-MAX(-5,MIN(5,ROUND((O$41-O$33)*100,0))) -> 0 | AA5: =-MAX(-5,MIN(5,ROUND((O$73-O$33)*100,0))) -> -1 | AB5: =-MAX(-5,MIN(5,ROUND((O$81-O$33)*100,0))) -> -1 | AC5: =-MAX(-5,MIN(5,ROUND((O$49-O$49)*100,0))) -> 0 | AD5: =-MAX(-5,MIN(5,ROUND((O$57-O$49)*100,0))) -> 0 | AE5: =-MAX(-5,MIN(5,ROUND((O$65-O$49)*100,0))) -> -2
D6: Central | E6: =-MAX(-5,MIN(5,ROUND((F$33-F$33)*100,0))) -> 0 | F6: =-MAX(-5,MIN(5,ROUND((F$41-F$33)*100,0))) -> -3 | G6: =-MAX(-5,MIN(5,ROUND((F$73-F$33)*100,0))) -> 0 | H6: =-MAX(-5,MIN(5,ROUND((F$81-F$33)*100,0))) -> 0 | I6: =-MAX(-5,MIN(5,ROUND((F$49-F$49)*100,0))) -> 0 | J6: =-MAX(-5,MIN(5,ROUND((F$57-F$49)*100,0))) -> 2 | K6: =-MAX(-5,MIN(5,ROUND((F$65-F$49)*100,0))) -> -1 | N6: Central | O6: =-MAX(-5,MIN(5,ROUND((K$33-K$33)*100,0))) -> 0 | P6: =-MAX(-5,MIN(5,ROUND((K$41-K$33)*100,0))) -> -2 | Q6: =-MAX(-5,MIN(5,ROUND((K$73-K$33)*100,0))) -> 1 | R6: =-MAX(-5,MIN(5,ROUND((K$81-K$33)*100,0))) -> 1 | S6: =-MAX(-5,MIN(5,ROUND((K$49-K$49)*100,0))) -> 0 | T6: =-MAX(-5,MIN(5,ROUND((K$57-K$49)*100,0))) -> 3 | U6: =-MAX(-5,MIN(5,ROUND((K$65-K$49)*100,0))) -> -3 | X6: Central | Y6: =-MAX(-5,MIN(5,ROUND((P$33-P$33)*100,0))) -> 0 | Z6: =-MAX(-5,MIN(5,ROUND((P$41-P$33)*100,0))) -> -3 | AA6: =-MAX(-5,MIN(5,ROUND((P$73-P$33)*100,0))) -> 1 | AB6: =-MAX(-5,MIN(5,ROUND((P$81-P$33)*100,0))) -> 0 | AC6: =-MAX(-5,MIN(5,ROUND((P$49-P$49)*100,0))) -> 0 | AD6: =-MAX(-5,MIN(5,ROUND((P$57-P$49)*100,0))) -> 0 | AE6: =-MAX(-5,MIN(5,ROUND((P$65-P$49)*100,0))) -> 0
D7: North | E7: =-MAX(-5,MIN(5,ROUND((G$33-G$33)*100,0))) -> 0 | F7: =-MAX(-5,MIN(5,ROUND((G$41-G$33)*100,0))) -> 0 | G7: =-MAX(-5,MIN(5,ROUND((G$73-G$33)*100,0))) -> 0 | H7: =-MAX(-5,MIN(5,ROUND((G$81-G$33)*100,0))) -> 0 | I7: =-MAX(-5,MIN(5,ROUND((G$49-G$49)*100,0))) -> 0 | J7: =-MAX(-5,MIN(5,ROUND((G$57-G$49)*100,0))) -> 0 | K7: =-MAX(-5,MIN(5,ROUND((G$65-G$49)*100,0))) -> 0 | N7: North | O7: =-MAX(-5,MIN(5,ROUND((L$33-L$33)*100,0))) -> 0 | P7: =-MAX(-5,MIN(5,ROUND((L$41-L$33)*100,0))) -> 0 | Q7: =-MAX(-5,MIN(5,ROUND((L$73-L$33)*100,0))) -> 0 | R7: =-MAX(-5,MIN(5,ROUND((L$81-L$33)*100,0))) -> 0 | S7: =-MAX(-5,MIN(5,ROUND((L$49-L$49)*100,0))) -> 0 | T7: =-MAX(-5,MIN(5,ROUND((L$57-L$49)*100,0))) -> 0 | U7: =-MAX(-5,MIN(5,ROUND((L$65-L$49)*100,0))) -> 0 | X7: North | Y7: =-MAX(-5,MIN(5,ROUND((Q$33-Q$33)*100,0))) -> 0 | Z7: =-MAX(-5,MIN(5,ROUND((Q$41-Q$33)*100,0))) -> 0 | AA7: =-MAX(-5,MIN(5,ROUND((Q$73-Q$33)*100,0))) -> 0 | AB7: =-MAX(-5,MIN(5,ROUND((Q$81-Q$33)*100,0))) -> 0 | AC7: =-MAX(-5,MIN(5,ROUND((Q$49-Q$49)*100,0))) -> 0 | AD7: =-MAX(-5,MIN(5,ROUND((Q$57-Q$49)*100,0))) -> 0 | AE7: =-MAX(-5,MIN(5,ROUND((Q$65-Q$49)*100,0))) -> 0
D8: South | E8: =-MAX(-5,MIN(5,ROUND((H$33-H$33)*100,0))) -> 0 | F8: =-MAX(-5,MIN(5,ROUND((H$41-H$33)*100,0))) -> 1 | G8: =-MAX(-5,MIN(5,ROUND((H$73-H$33)*100,0))) -> 3 | H8: =-MAX(-5,MIN(5,ROUND((H$81-H$33)*100,0))) -> 2 | I8: =-MAX(-5,MIN(5,ROUND((H$49-H$49)*100,0))) -> 0 | J8: =-MAX(-5,MIN(5,ROUND((H$57-H$49)*100,0))) -> 0 | K8: =-MAX(-5,MIN(5,ROUND((H$65-H$49)*100,0))) -> 0 | N8: South | O8: =-MAX(-5,MIN(5,ROUND((M$33-M$33)*100,0))) -> 0 | P8: =-MAX(-5,MIN(5,ROUND((M$41-M$33)*100,0))) -> 0 | Q8: =-MAX(-5,MIN(5,ROUND((M$73-M$33)*100,0))) -> 1 | R8: =-MAX(-5,MIN(5,ROUND((M$81-M$33)*100,0))) -> 2 | S8: =-MAX(-5,MIN(5,ROUND((M$49-M$49)*100,0))) -> 0 | T8: =-MAX(-5,MIN(5,ROUND((M$57-M$49)*100,0))) -> 0 | U8: =-MAX(-5,MIN(5,ROUND((M$65-M$49)*100,0))) -> 0 | X8: South | Y8: =-MAX(-5,MIN(5,ROUND((R$33-R$33)*100,0))) -> 0 | Z8: =-MAX(-5,MIN(5,ROUND((R$41-R$33)*100,0))) -> 1 | AA8: =-MAX(-5,MIN(5,ROUND((R$73-R$33)*100,0))) -> 2 | AB8: =-MAX(-5,MIN(5,ROUND((R$81-R$33)*100,0))) -> 1 | AC8: =-MAX(-5,MIN(5,ROUND((R$49-R$49)*100,0))) -> 0 | AD8: =-MAX(-5,MIN(5,ROUND((R$57-R$49)*100,0))) -> 0 | AE8: =-MAX(-5,MIN(5,ROUND((R$65-R$49)*100,0))) -> 0
D9: REGION | E9: BAU | F9: BAF | G9: ECO | H9: NGW | I9: BAU CS | J9: COR vs CS | K9: TUNNEL VS CS | N9: REGION | O9: BAU | P9: BAF | Q9: ECO | R9: NGW | S9: BAU CS | T9: COR vs CS | U9: TUNNEL VS CS | X9: REGION | Y9: BAU | Z9: BAF | AA9: ECO | AB9: NGW | AC9: BAU CS | AD9: COR vs CS | AE9: TUNNEL VS CS
C10: BIRDING | D10: Delta-Wide | E10: =-MAX(-5,MIN(5,ROUND((D$34-D$34)*100,0))) -> 0 | F10: =-MAX(-5,MIN(5,ROUND((D$42-D$34)*100,0))) -> 0 | G10: =-MAX(-5,MIN(5,ROUND((D$74-D$34)*100,0))) -> 0 | H10: =-MAX(-5,MIN(5,ROUND((D$82-D$34)*100,0))) -> 0 | I10: =-MAX(-5,MIN(5,ROUND((D$50-D$50)*100,0))) -> 0 | J10: =-MAX(-5,MIN(5,ROUND((D$58-D$50)*100,0))) -> 0 | K10: =-MAX(-5,MIN(5,ROUND((D$66-D$50)*100,0))) -> 0 | M10: BIRDING | N10: Delta-Wide | O10: =-MAX(-5,MIN(5,ROUND((I$34-I$34)*100,0))) -> 0 | P10: =-MAX(-5,MIN(5,ROUND((I$42-I$34)*100,0))) -> 0 | Q10: =-MAX(-5,MIN(5,ROUND((I$74-I$34)*100,0))) -> -1 | R10: =-MAX(-5,MIN(5,ROUND((I$82-I$34)*100,0))) -> -1 | S10: =-MAX(-5,MIN(5,ROUND((I$50-I$50)*100,0))) -> 0 | T10: =-MAX(-5,MIN(5,ROUND((I$58-I$50)*100,0))) -> 1 | U10: =-MAX(-5,MIN(5,ROUND((I$66-I$50)*100,0))) -> 0 | W10: BIRDING | X10: Delta-Wide | Y10: =-MAX(-5,MIN(5,ROUND((N$34-N$34)*100,0))) -> 0 | Z10: =-MAX(-5,MIN(5,ROUND((N$42-N$34)*100,0))) -> 0 | AA10: =-MAX(-5,MIN(5,ROUND((N$74-N$34)*100,0))) -> 1 | AB10: =-MAX(-5,MIN(5,ROUND((N$82-N$34)*100,0))) -> 1 | AC10: =-MAX(-5,MIN(5,ROUND((N$50-N$50)*100,0))) -> 0 | AD10: =-MAX(-5,MIN(5,ROUND((N$58-N$50)*100,0))) -> 0 | AE10: =-MAX(-5,MIN(5,ROUND((N$66-N$50)*100,0))) -> 0
D11: Suisun | E11: =-MAX(-5,MIN(5,ROUND((E$34-E$34)*100,0))) -> 0 | F11: =-MAX(-5,MIN(5,ROUND((E$42-E$34)*100,0))) -> 0 | G11: =-MAX(-5,MIN(5,ROUND((E$74-E$34)*100,0))) -> -4 | H11: =-MAX(-5,MIN(5,ROUND((E$82-E$34)*100,0))) -> -4 | I11: =-MAX(-5,MIN(5,ROUND((E$50-E$50)*100,0))) -> 0 | J11: =-MAX(-5,MIN(5,ROUND((E$58-E$50)*100,0))) -> 1 | K11: =-MAX(-5,MIN(5,ROUND((E$66-E$50)*100,0))) -> 0 | N11: Suisun | O11: =-MAX(-5,MIN(5,ROUND((J$34-J$34)*100,0))) -> 0 | P11: =-MAX(-5,MIN(5,ROUND((J$42-J$34)*100,0))) -> 0 | Q11: =-MAX(-5,MIN(5,ROUND((J$74-J$34)*100,0))) -> -5 | R11: =-MAX(-5,MIN(5,ROUND((J$82-J$34)*100,0))) -> -5 | S11: =-MAX(-5,MIN(5,ROUND((J$50-J$50)*100,0))) -> 0 | T11: =-MAX(-5,MIN(5,ROUND((J$58-J$50)*100,0))) -> 2 | U11: =-MAX(-5,MIN(5,ROUND((J$66-J$50)*100,0))) -> -1 | X11: Suisun | Y11: =-MAX(-5,MIN(5,ROUND((O$34-O$34)*100,0))) -> 0 | Z11: =-MAX(-5,MIN(5,ROUND((O$42-O$34)*100,0))) -> 0 | AA11: =-MAX(-5,MIN(5,ROUND((O$74-O$34)*100,0))) -> -1 | AB11: =-MAX(-5,MIN(5,ROUND((O$82-O$34)*100,0))) -> -2 | AC11: =-MAX(-5,MIN(5,ROUND((O$50-O$50)*100,0))) -> 0 | AD11: =-MAX(-5,MIN(5,ROUND((O$58-O$50)*100,0))) -> 0 | AE11: =-MAX(-5,MIN(5,ROUND((O$66-O$50)*100,0))) -> 0
D12: Central | E12: =-MAX(-5,MIN(5,ROUND((F$34-F$34)*100,0))) -> 0 | F12: =-MAX(-5,MIN(5,ROUND((F$42-F$34)*100,0))) -> 0 | G12: =-MAX(-5,MIN(5,ROUND((F$74-F$34)*100,0))) -> 3 | H12: =-MAX(-5,MIN(5,ROUND((F$82-F$34)*100,0))) -> 3 | I12: =-MAX(-5,MIN(5,ROUND((F$50-F$50)*100,0))) -> 0 | J12: =-MAX(-5,MIN(5,ROUND((F$58-F$50)*100,0))) -> 1 | K12: =-MAX(-5,MIN(5,ROUND((F$66-F$50)*100,0))) -> -1 | N12: Central | O12: =-MAX(-5,MIN(5,ROUND((K$34-K$34)*100,0))) -> 0 | P12: =-MAX(-5,MIN(5,ROUND((K$42-K$34)*100,0))) -> 0 | Q12: =-MAX(-5,MIN(5,ROUND((K$74-K$34)*100,0))) -> 2 | R12: =-MAX(-5,MIN(5,ROUND((K$82-K$34)*100,0))) -> 2 | S12: =-MAX(-5,MIN(5,ROUND((K$50-K$50)*100,0))) -> 0 | T12: =-MAX(-5,MIN(5,ROUND((K$58-K$50)*100,0))) -> 2 | U12: =-MAX(-5,MIN(5,ROUND((K$66-K$50)*100,0))) -> -1 | X12: Central | Y12: =-MAX(-5,MIN(5,ROUND((P$34-P$34)*100,0))) -> 0 | Z12: =-MAX(-5,MIN(5,ROUND((P$42-P$34)*100,0))) -> 0 | AA12: =-MAX(-5,MIN(5,ROUND((P$74-P$34)*100,0))) -> 4 | AB12: =-MAX(-5,MIN(5,ROUND((P$82-P$34)*100,0))) -> 3 | AC12: =-MAX(-5,MIN(5,ROUND((P$50-P$50)*100,0))) -> 0 | AD12: =-MAX(-5,MIN(5,ROUND((P$58-P$50)*100,0))) -> 0 | AE12: =-MAX(-5,MIN(5,ROUND((P$66-P$50)*100,0))) -> -1
D13: North | E13: =-MAX(-5,MIN(5,ROUND((G$34-G$34)*100,0))) -> 0 | F13: =-MAX(-5,MIN(5,ROUND((G$42-G$34)*100,0))) -> 0 | G13: =-MAX(-5,MIN(5,ROUND((G$74-G$34)*100,0))) -> 0 | H13: =-MAX(-5,MIN(5,ROUND((G$82-G$34)*100,0))) -> 0 | I13: =-MAX(-5,MIN(5,ROUND((G$50-G$50)*100,0))) -> 0 | J13: =-MAX(-5,MIN(5,ROUND((G$58-G$50)*100,0))) -> 0 | K13: =-MAX(-5,MIN(5,ROUND((G$66-G$50)*100,0))) -> 0 | N13: North | O13: =-MAX(-5,MIN(5,ROUND((L$34-L$34)*100,0))) -> 0 | P13: =-MAX(-5,MIN(5,ROUND((L$42-L$34)*100,0))) -> 0 | Q13: =-MAX(-5,MIN(5,ROUND((L$74-L$34)*100,0))) -> 0 | R13: =-MAX(-5,MIN(5,ROUND((L$82-L$34)*100,0))) -> 0 | S13: =-MAX(-5,MIN(5,ROUND((L$50-L$50)*100,0))) -> 0 | T13: =-MAX(-5,MIN(5,ROUND((L$58-L$50)*100,0))) -> 0 | U13: =-MAX(-5,MIN(5,ROUND((L$66-L$50)*100,0))) -> 0 | X13: North | Y13: =-MAX(-5,MIN(5,ROUND((Q$34-Q$34)*100,0))) -> 0 | Z13: =-MAX(-5,MIN(5,ROUND((Q$42-Q$34)*100,0))) -> 0 | AA13: =-MAX(-5,MIN(5,ROUND((Q$74-Q$34)*100,0))) -> 0 | AB13: =-MAX(-5,MIN(5,ROUND((Q$82-Q$34)*100,0))) -> 0 | AC13: =-MAX(-5,MIN(5,ROUND((Q$50-Q$50)*100,0))) -> 0 | AD13: =-MAX(-5,MIN(5,ROUND((Q$58-Q$50)*100,0))) -> 0 | AE13: =-MAX(-5,MIN(5,ROUND((Q$66-Q$50)*100,0))) -> 0
D14: South | E14: =-MAX(-5,MIN(5,ROUND((H$34-H$34)*100,0))) -> 0 | F14: =-MAX(-5,MIN(5,ROUND((H$42-H$34)*100,0))) -> 0 | G14: =-MAX(-5,MIN(5,ROUND((H$74-H$34)*100,0))) -> 0 | H14: =-MAX(-5,MIN(5,ROUND((H$82-H$34)*100,0))) -> 0 | I14: =-MAX(-5,MIN(5,ROUND((H$50-H$50)*100,0))) -> 0 | J14: =-MAX(-5,MIN(5,ROUND((H$58-H$50)*100,0))) -> 0 | K14: =-MAX(-5,MIN(5,ROUND((H$66-H$50)*100,0))) -> 0 | N14: South | O14: =-MAX(-5,MIN(5,ROUND((M$34-M$34)*100,0))) -> 0 | P14: =-MAX(-5,MIN(5,ROUND((M$42-M$34)*100,0))) -> 0 | Q14: =-MAX(-5,MIN(5,ROUND((M$74-M$34)*100,0))) -> 0 | R14: =-MAX(-5,MIN(5,ROUND((M$82-M$34)*100,0))) -> 0 | S14: =-MAX(-5,MIN(5,ROUND((M$50-M$50)*100,0))) -> 0 | T14: =-MAX(-5,MIN(5,ROUND((M$58-M$50)*100,0))) -> 0 | U14: =-MAX(-5,MIN(5,ROUND((M$66-M$50)*100,0))) -> 0 | X14: South | Y14: =-MAX(-5,MIN(5,ROUND((R$34-R$34)*100,0))) -> 0 | Z14: =-MAX(-5,MIN(5,ROUND((R$42-R$34)*100,0))) -> 0 | AA14: =-MAX(-5,MIN(5,ROUND((R$74-R$34)*100,0))) -> 0 | AB14: =-MAX(-5,MIN(5,ROUND((R$82-R$34)*100,0))) -> 0 | AC14: =-MAX(-5,MIN(5,ROUND((R$50-R$50)*100,0))) -> 0 | AD14: =-MAX(-5,MIN(5,ROUND((R$58-R$50)*100,0))) -> 0 | AE14: =-MAX(-5,MIN(5,ROUND((R$66-R$50)*100,0))) -> 0
D15: REGION | E15: BAU | F15: BAF | G15: ECO | H15: NGW | I15: BAU CS | J15: COR vs CS | K15: TUNNEL VS CS | N15: REGION | O15: BAU | P15: BAF | Q15: ECO | R15: NGW | S15: BAU CS | T15: COR vs CS | U15: TUNNEL VS CS | X15: REGION | Y15: BAU | Z15: BAF | AA15: ECO | AB15: NGW | AC15: BAU CS | AD15: COR vs CS | AE15: TUNNEL VS CS
C16: WATERFOWL | D16: Delta-Wide | E16: =-MAX(-5,MIN(5,ROUND((D$35-D$35)*100,0))) -> 0 | F16: =-MAX(-5,MIN(5,ROUND((D$43-D$35)*100,0))) -> 0 | G16: =-MAX(-5,MIN(5,ROUND((D$75-D$35)*100,0))) -> 0 | H16: =-MAX(-5,MIN(5,ROUND((D$83-D$35)*100,0))) -> 0 | I16: =-MAX(-5,MIN(5,ROUND((D$51-D$51)*100,0))) -> 0 | J16: =-MAX(-5,MIN(5,ROUND((D$59-D$51)*100,0))) -> 0 | K16: =-MAX(-5,MIN(5,ROUND((D$67-D$51)*100,0))) -> 0 | M16: WATERFOWL | N16: Delta-Wide | O16: =-MAX(-5,MIN(5,ROUND((I$35-I$35)*100,0))) -> 0 | P16: =-MAX(-5,MIN(5,ROUND((I$43-I$35)*100,0))) -> 0 | Q16: =-MAX(-5,MIN(5,ROUND((I$75-I$35)*100,0))) -> -1 | R16: =-MAX(-5,MIN(5,ROUND((I$83-I$35)*100,0))) -> -1 | S16: =-MAX(-5,MIN(5,ROUND((I$51-I$51)*100,0))) -> 0 | T16: =-MAX(-5,MIN(5,ROUND((I$59-I$51)*100,0))) -> 0 | U16: =-MAX(-5,MIN(5,ROUND((I$67-I$51)*100,0))) -> 0 | W16: WATERFOWL | X16: Delta-Wide | Y16: =-MAX(-5,MIN(5,ROUND((N$35-N$35)*100,0))) -> 0 | Z16: =-MAX(-5,MIN(5,ROUND((N$43-N$35)*100,0))) -> 0 | AA16: =-MAX(-5,MIN(5,ROUND((N$75-N$35)*100,0))) -> 0 | AB16: =-MAX(-5,MIN(5,ROUND((N$83-N$35)*100,0))) -> 0 | AC16: =-MAX(-5,MIN(5,ROUND((N$51-N$51)*100,0))) -> 0 | AD16: =-MAX(-5,MIN(5,ROUND((N$59-N$51)*100,0))) -> 0 | AE16: =-MAX(-5,MIN(5,ROUND((N$67-N$51)*100,0))) -> 0
D17: Suisun | E17: =-MAX(-5,MIN(5,ROUND((E$35-E$35)*100,0))) -> 0 | F17: =-MAX(-5,MIN(5,ROUND((E$43-E$35)*100,0))) -> 0 | G17: =-MAX(-5,MIN(5,ROUND((E$75-E$35)*100,0))) -> -3 | H17: =-MAX(-5,MIN(5,ROUND((E$83-E$35)*100,0))) -> -3 | I17: =-MAX(-5,MIN(5,ROUND((E$51-E$51)*100,0))) -> 0 | J17: =-MAX(-5,MIN(5,ROUND((E$59-E$51)*100,0))) -> 1 | K17: =-MAX(-5,MIN(5,ROUND((E$67-E$51)*100,0))) -> 0 | N17: Suisun | O17: =-MAX(-5,MIN(5,ROUND((J$35-J$35)*100,0))) -> 0 | P17: =-MAX(-5,MIN(5,ROUND((J$43-J$35)*100,0))) -> 0 | Q17: =-MAX(-5,MIN(5,ROUND((J$75-J$35)*100,0))) -> -5 | R17: =-MAX(-5,MIN(5,ROUND((J$83-J$35)*100,0))) -> -5 | S17: =-MAX(-5,MIN(5,ROUND((J$51-J$51)*100,0))) -> 0 | T17: =-MAX(-5,MIN(5,ROUND((J$59-J$51)*100,0))) -> 1 | U17: =-MAX(-5,MIN(5,ROUND((J$67-J$51)*100,0))) -> -1 | X17: Suisun | Y17: =-MAX(-5,MIN(5,ROUND((O$35-O$35)*100,0))) -> 0 | Z17: =-MAX(-5,MIN(5,ROUND((O$43-O$35)*100,0))) -> 0 | AA17: =-MAX(-5,MIN(5,ROUND((O$75-O$35)*100,0))) -> -1 | AB17: =-MAX(-5,MIN(5,ROUND((O$83-O$35)*100,0))) -> -1 | AC17: =-MAX(-5,MIN(5,ROUND((O$51-O$51)*100,0))) -> 0 | AD17: =-MAX(-5,MIN(5,ROUND((O$59-O$51)*100,0))) -> 0 | AE17: =-MAX(-5,MIN(5,ROUND((O$67-O$51)*100,0))) -> 0
D18: Central | E18: =-MAX(-5,MIN(5,ROUND((F$35-F$35)*100,0))) -> 0 | F18: =-MAX(-5,MIN(5,ROUND((F$43-F$35)*100,0))) -> 0 | G18: =-MAX(-5,MIN(5,ROUND((F$75-F$35)*100,0))) -> 1 | H18: =-MAX(-5,MIN(5,ROUND((F$83-F$35)*100,0))) -> 1 | I18: =-MAX(-5,MIN(5,ROUND((F$51-F$51)*100,0))) -> 0 | J18: =-MAX(-5,MIN(5,ROUND((F$59-F$51)*100,0))) -> 0 | K18: =-MAX(-5,MIN(5,ROUND((F$67-F$51)*100,0))) -> 0 | N18: Central | O18: =-MAX(-5,MIN(5,ROUND((K$35-K$35)*100,0))) -> 0 | P18: =-MAX(-5,MIN(5,ROUND((K$43-K$35)*100,0))) -> 0 | Q18: =-MAX(-5,MIN(5,ROUND((K$75-K$35)*100,0))) -> 1 | R18: =-MAX(-5,MIN(5,ROUND((K$83-K$35)*100,0))) -> 1 | S18: =-MAX(-5,MIN(5,ROUND((K$51-K$51)*100,0))) -> 0 | T18: =-MAX(-5,MIN(5,ROUND((K$59-K$51)*100,0))) -> 0 | U18: =-MAX(-5,MIN(5,ROUND((K$67-K$51)*100,0))) -> -1 | X18: Central | Y18: =-MAX(-5,MIN(5,ROUND((P$35-P$35)*100,0))) -> 0 | Z18: =-MAX(-5,MIN(5,ROUND((P$43-P$35)*100,0))) -> 0 | AA18: =-MAX(-5,MIN(5,ROUND((P$75-P$35)*100,0))) -> 1 | AB18: =-MAX(-5,MIN(5,ROUND((P$83-P$35)*100,0))) -> 1 | AC18: =-MAX(-5,MIN(5,ROUND((P$51-P$51)*100,0))) -> 0 | AD18: =-MAX(-5,MIN(5,ROUND((P$59-P$51)*100,0))) -> 0 | AE18: =-MAX(-5,MIN(5,ROUND((P$67-P$51)*100,0))) -> 1
D19: North | E19: =-MAX(-5,MIN(5,ROUND((G$35-G$35)*100,0))) -> 0 | F19: =-MAX(-5,MIN(5,ROUND((G$43-G$35)*100,0))) -> 0 | G19: =-MAX(-5,MIN(5,ROUND((G$75-G$35)*100,0))) -> 0 | H19: =-MAX(-5,MIN(5,ROUND((G$83-G$35)*100,0))) -> 0 | I19: =-MAX(-5,MIN(5,ROUND((G$51-G$51)*100,0))) -> 0 | J19: =-MAX(-5,MIN(5,ROUND((G$59-G$51)*100,0))) -> 0 | K19: =-MAX(-5,MIN(5,ROUND((G$67-G$51)*100,0))) -> 0 | N19: North | O19: =-MAX(-5,MIN(5,ROUND((L$35-L$35)*100,0))) -> 0 | P19: =-MAX(-5,MIN(5,ROUND((L$43-L$35)*100,0))) -> 0 | Q19: =-MAX(-5,MIN(5,ROUND((L$75-L$35)*100,0))) -> 0 | R19: =-MAX(-5,MIN(5,ROUND((L$83-L$35)*100,0))) -> 0 | S19: =-MAX(-5,MIN(5,ROUND((L$51-L$51)*100,0))) -> 0 | T19: =-MAX(-5,MIN(5,ROUND((L$59-L$51)*100,0))) -> 0 | U19: =-MAX(-5,MIN(5,ROUND((L$67-L$51)*100,0))) -> 0 | X19: North | Y19: =-MAX(-5,MIN(5,ROUND((Q$35-Q$35)*100,0))) -> 0 | Z19: =-MAX(-5,MIN(5,ROUND((Q$43-Q$35)*100,0))) -> 0 | AA19: =-MAX(-5,MIN(5,ROUND((Q$75-Q$35)*100,0))) -> 0 | AB19: =-MAX(-5,MIN(5,ROUND((Q$83-Q$35)*100,0))) -> 0 | AC19: =-MAX(-5,MIN(5,ROUND((Q$51-Q$51)*100,0))) -> 0 | AD19: =-MAX(-5,MIN(5,ROUND((Q$59-Q$51)*100,0))) -> 0 | AE19: =-MAX(-5,MIN(5,ROUND((Q$67-Q$51)*100,0))) -> 0
D20: South | E20: =-MAX(-5,MIN(5,ROUND((H$35-H$35)*100,0))) -> 0 | F20: =-MAX(-5,MIN(5,ROUND((H$43-H$35)*100,0))) -> 0 | G20: =-MAX(-5,MIN(5,ROUND((H$75-H$35)*100,0))) -> 0 | H20: =-MAX(-5,MIN(5,ROUND((H$83-H$35)*100,0))) -> 0 | I20: =-MAX(-5,MIN(5,ROUND((H$51-H$51)*100,0))) -> 0 | J20: =-MAX(-5,MIN(5,ROUND((H$59-H$51)*100,0))) -> 0 | K20: =-MAX(-5,MIN(5,ROUND((H$67-H$51)*100,0))) -> 0 | N20: South | O20: =-MAX(-5,MIN(5,ROUND((M$35-M$35)*100,0))) -> 0 | P20: =-MAX(-5,MIN(5,ROUND((M$43-M$35)*100,0))) -> 0 | Q20: =-MAX(-5,MIN(5,ROUND((M$75-M$35)*100,0))) -> 0 | R20: =-MAX(-5,MIN(5,ROUND((M$83-M$35)*100,0))) -> 0 | S20: =-MAX(-5,MIN(5,ROUND((M$51-M$51)*100,0))) -> 0 | T20: =-MAX(-5,MIN(5,ROUND((M$59-M$51)*100,0))) -> 0 | U20: =-MAX(-5,MIN(5,ROUND((M$67-M$51)*100,0))) -> 0 | X20: South | Y20: =-MAX(-5,MIN(5,ROUND((R$35-R$35)*100,0))) -> 0 | Z20: =-MAX(-5,MIN(5,ROUND((R$43-R$35)*100,0))) -> 0 | AA20: =-MAX(-5,MIN(5,ROUND((R$75-R$35)*100,0))) -> 0 | AB20: =-MAX(-5,MIN(5,ROUND((R$83-R$35)*100,0))) -> 0 | AC20: =-MAX(-5,MIN(5,ROUND((R$51-R$51)*100,0))) -> 0 | AD20: =-MAX(-5,MIN(5,ROUND((R$59-R$51)*100,0))) -> 0 | AE20: =-MAX(-5,MIN(5,ROUND((R$67-R$51)*100,0))) -> 0
D21: REGION | E21: BAU | F21: BAF | G21: ECO | H21: NGW | I21: BAU CS | J21: COR vs CS | K21: TUNNEL VS CS | N21: REGION | O21: BAU | P21: BAF | Q21: ECO | R21: NGW | S21: BAU CS | T21: COR vs CS | U21: TUNNEL VS CS | X21: REGION | Y21: BAU | Z21: BAF | AA21: ECO | AB21: NGW | AC21: BAU CS | AD21: COR vs CS | AE21: TUNNEL VS CS
C22: ANGLING | D22: Delta-Wide | E22: =-MAX(-5,MIN(5,ROUND((D$36-D$36)*100,0))) -> 0 | F22: =-MAX(-5,MIN(5,ROUND((D$44-D$36)*100,0))) -> 0 | G22: =-MAX(-5,MIN(5,ROUND((D$76-D$36)*100,0))) -> -2 | H22: =-MAX(-5,MIN(5,ROUND((D$84-D$36)*100,0))) -> -2 | I22: =-MAX(-5,MIN(5,ROUND((D$52-D$52)*100,0))) -> 0 | J22: =-MAX(-5,MIN(5,ROUND((D$60-D$52)*100,0))) -> 0 | K22: =-MAX(-5,MIN(5,ROUND((D$68-D$52)*100,0))) -> 0 | M22: ANGLING | N22: Delta-Wide | O22: =-MAX(-5,MIN(5,ROUND((I$36-I$36)*100,0))) -> 0 | P22: =-MAX(-5,MIN(5,ROUND((I$44-I$36)*100,0))) -> 0 | Q22: =-MAX(-5,MIN(5,ROUND((I$76-I$36)*100,0))) -> -3 | R22: =-MAX(-5,MIN(5,ROUND((I$84-I$36)*100,0))) -> -3 | S22: =-MAX(-5,MIN(5,ROUND((I$52-I$52)*100,0))) -> 0 | T22: =-MAX(-5,MIN(5,ROUND((I$60-I$52)*100,0))) -> 1 | U22: =-MAX(-5,MIN(5,ROUND((I$68-I$52)*100,0))) -> -1 | W22: ANGLING | X22: Delta-Wide | Y22: =-MAX(-5,MIN(5,ROUND((N$36-N$36)*100,0))) -> 0 | Z22: =-MAX(-5,MIN(5,ROUND((N$44-N$36)*100,0))) -> 0 | AA22: =-MAX(-5,MIN(5,ROUND((N$76-N$36)*100,0))) -> -2 | AB22: =-MAX(-5,MIN(5,ROUND((N$84-N$36)*100,0))) -> -2 | AC22: =-MAX(-5,MIN(5,ROUND((N$52-N$52)*100,0))) -> 0 | AD22: =-MAX(-5,MIN(5,ROUND((N$60-N$52)*100,0))) -> 0 | AE22: =-MAX(-5,MIN(5,ROUND((N$68-N$52)*100,0))) -> 0
D23: Suisun | E23: =-MAX(-5,MIN(5,ROUND((E$36-E$36)*100,0))) -> 0 | F23: =-MAX(-5,MIN(5,ROUND((E$44-E$36)*100,0))) -> 0 | G23: =-MAX(-5,MIN(5,ROUND((E$76-E$36)*100,0))) -> -5 | H23: =-MAX(-5,MIN(5,ROUND((E$84-E$36)*100,0))) -> -5 | I23: =-MAX(-5,MIN(5,ROUND((E$52-E$52)*100,0))) -> 0 | J23: =-MAX(-5,MIN(5,ROUND((E$60-E$52)*100,0))) -> 1 | K23: =-MAX(-5,MIN(5,ROUND((E$68-E$52)*100,0))) -> 0 | N23: Suisun | O23: =-MAX(-5,MIN(5,ROUND((J$36-J$36)*100,0))) -> 0 | P23: =-MAX(-5,MIN(5,ROUND((J$44-J$36)*100,0))) -> 0 | Q23: =-MAX(-5,MIN(5,ROUND((J$76-J$36)*100,0))) -> -5 | R23: =-MAX(-5,MIN(5,ROUND((J$84-J$36)*100,0))) -> -5 | S23: =-MAX(-5,MIN(5,ROUND((J$52-J$52)*100,0))) -> 0 | T23: =-MAX(-5,MIN(5,ROUND((J$60-J$52)*100,0))) -> 2 | U23: =-MAX(-5,MIN(5,ROUND((J$68-J$52)*100,0))) -> -2 | X23: Suisun | Y23: =-MAX(-5,MIN(5,ROUND((O$36-O$36)*100,0))) -> 0 | Z23: =-MAX(-5,MIN(5,ROUND((O$44-O$36)*100,0))) -> 0 | AA23: =-MAX(-5,MIN(5,ROUND((O$76-O$36)*100,0))) -> -5 | AB23: =-MAX(-5,MIN(5,ROUND((O$84-O$36)*100,0))) -> -5 | AC23: =-MAX(-5,MIN(5,ROUND((O$52-O$52)*100,0))) -> 0 | AD23: =-MAX(-5,MIN(5,ROUND((O$60-O$52)*100,0))) -> 0 | AE23: =-MAX(-5,MIN(5,ROUND((O$68-O$52)*100,0))) -> 3
D24: Central | E24: =-MAX(-5,MIN(5,ROUND((F$36-F$36)*100,0))) -> 0 | F24: =-MAX(-5,MIN(5,ROUND((F$44-F$36)*100,0))) -> 0 | G24: =-MAX(-5,MIN(5,ROUND((F$76-F$36)*100,0))) -> 1 | H24: =-MAX(-5,MIN(5,ROUND((F$84-F$36)*100,0))) -> 1 | I24: =-MAX(-5,MIN(5,ROUND((F$52-F$52)*100,0))) -> 0 | J24: =-MAX(-5,MIN(5,ROUND((F$60-F$52)*100,0))) -> 0 | K24: =-MAX(-5,MIN(5,ROUND((F$68-F$52)*100,0))) -> -1 | N24: Central | O24: =-MAX(-5,MIN(5,ROUND((K$36-K$36)*100,0))) -> 0 | P24: =-MAX(-5,MIN(5,ROUND((K$44-K$36)*100,0))) -> 0 | Q24: =-MAX(-5,MIN(5,ROUND((K$76-K$36)*100,0))) -> 1 | R24: =-MAX(-5,MIN(5,ROUND((K$84-K$36)*100,0))) -> 1 | S24: =-MAX(-5,MIN(5,ROUND((K$52-K$52)*100,0))) -> 0 | T24: =-MAX(-5,MIN(5,ROUND((K$60-K$52)*100,0))) -> 0 | U24: =-MAX(-5,MIN(5,ROUND((K$68-K$52)*100,0))) -> 0 | X24: Central | Y24: =-MAX(-5,MIN(5,ROUND((P$36-P$36)*100,0))) -> 0 | Z24: =-MAX(-5,MIN(5,ROUND((P$44-P$36)*100,0))) -> 0 | AA24: =-MAX(-5,MIN(5,ROUND((P$76-P$36)*100,0))) -> 1 | AB24: =-MAX(-5,MIN(5,ROUND((P$84-P$36)*100,0))) -> 1 | AC24: =-MAX(-5,MIN(5,ROUND((P$52-P$52)*100,0))) -> 0 | AD24: =-MAX(-5,MIN(5,ROUND((P$60-P$52)*100,0))) -> 0 | AE24: =-MAX(-5,MIN(5,ROUND((P$68-P$52)*100,0))) -> -1
D25: North | E25: =-MAX(-5,MIN(5,ROUND((G$36-G$36)*100,0))) -> 0 | F25: =-MAX(-5,MIN(5,ROUND((G$44-G$36)*100,0))) -> 0 | G25: =-MAX(-5,MIN(5,ROUND((G$76-G$36)*100,0))) -> 0 | H25: =-MAX(-5,MIN(5,ROUND((G$84-G$36)*100,0))) -> 0 | I25: =-MAX(-5,MIN(5,ROUND((G$52-G$52)*100,0))) -> 0 | J25: =-MAX(-5,MIN(5,ROUND((G$60-G$52)*100,0))) -> 0 | K25: =-MAX(-5,MIN(5,ROUND((G$68-G$52)*100,0))) -> 0 | N25: North | O25: =-MAX(-5,MIN(5,ROUND((L$36-L$36)*100,0))) -> 0 | P25: =-MAX(-5,MIN(5,ROUND((L$44-L$36)*100,0))) -> 0 | Q25: =-MAX(-5,MIN(5,ROUND((L$76-L$36)*100,0))) -> 0 | R25: =-MAX(-5,MIN(5,ROUND((L$84-L$36)*100,0))) -> 0 | S25: =-MAX(-5,MIN(5,ROUND((L$52-L$52)*100,0))) -> 0 | T25: =-MAX(-5,MIN(5,ROUND((L$60-L$52)*100,0))) -> 0 | U25: =-MAX(-5,MIN(5,ROUND((L$68-L$52)*100,0))) -> 0 | X25: North | Y25: =-MAX(-5,MIN(5,ROUND((Q$36-Q$36)*100,0))) -> 0 | Z25: =-MAX(-5,MIN(5,ROUND((Q$44-Q$36)*100,0))) -> 0 | AA25: =-MAX(-5,MIN(5,ROUND((Q$76-Q$36)*100,0))) -> 0 | AB25: =-MAX(-5,MIN(5,ROUND((Q$84-Q$36)*100,0))) -> 0 | AC25: =-MAX(-5,MIN(5,ROUND((Q$52-Q$52)*100,0))) -> 0 | AD25: =-MAX(-5,MIN(5,ROUND((Q$60-Q$52)*100,0))) -> 0 | AE25: =-MAX(-5,MIN(5,ROUND((Q$68-Q$52)*100,0))) -> 0
D26: South | E26: =-MAX(-5,MIN(5,ROUND((H$36-H$36)*100,0))) -> 0 | F26: =-MAX(-5,MIN(5,ROUND((H$44-H$36)*100,0))) -> 0 | G26: =-MAX(-5,MIN(5,ROUND((H$76-H$36)*100,0))) -> 0 | H26: =-MAX(-5,MIN(5,ROUND((H$84-H$36)*100,0))) -> 0 | I26: =-MAX(-5,MIN(5,ROUND((H$52-H$52)*100,0))) -> 0 | J26: =-MAX(-5,MIN(5,ROUND((H$60-H$52)*100,0))) -> 0 | K26: =-MAX(-5,MIN(5,ROUND((H$68-H$52)*100,0))) -> 0 | N26: South | O26: =-MAX(-5,MIN(5,ROUND((M$36-M$36)*100,0))) -> 0 | P26: =-MAX(-5,MIN(5,ROUND((M$44-M$36)*100,0))) -> 0 | Q26: =-MAX(-5,MIN(5,ROUND((M$76-M$36)*100,0))) -> 0 | R26: =-MAX(-5,MIN(5,ROUND((M$84-M$36)*100,0))) -> 0 | S26: =-MAX(-5,MIN(5,ROUND((M$52-M$52)*100,0))) -> 0 | T26: =-MAX(-5,MIN(5,ROUND((M$60-M$52)*100,0))) -> 0 | U26: =-MAX(-5,MIN(5,ROUND((M$68-M$52)*100,0))) -> 0 | X26: South | Y26: =-MAX(-5,MIN(5,ROUND((R$36-R$36)*100,0))) -> 0 | Z26: =-MAX(-5,MIN(5,ROUND((R$44-R$36)*100,0))) -> 0 | AA26: =-MAX(-5,MIN(5,ROUND((R$76-R$36)*100,0))) -> 0 | AB26: =-MAX(-5,MIN(5,ROUND((R$84-R$36)*100,0))) -> 0 | AC26: =-MAX(-5,MIN(5,ROUND((R$52-R$52)*100,0))) -> 0 | AD26: =-MAX(-5,MIN(5,ROUND((R$60-R$52)*100,0))) -> 0 | AE26: =-MAX(-5,MIN(5,ROUND((R$68-R$52)*100,0))) -> 0
C30: BAU % EXCEEDANCES
D31: Total Run | I31: Wet Seasons | N31: Dry Seasons | T31: RECREATION: SALINITY SCORE (A) — RMA SLR Salinity
D32: Delta-Wide | E32: Suisun | F32: Central Delta | G32: North Delta | H32: South Delta | I32: Delta-Wide | J32: Suisun | K32: Central Delta | L32: North Delta | M32: South Delta | N32: Delta-Wide | O32: Suisun | P32: Central Delta | Q32: North Delta | R32: South Delta | T32: Workflow: (1) Each activity = its Delta-Wide, Total Run score (-5 to 5). No Wet/Dry or sub-region rows, to avoid double counting. (2) Sum the activity scores. (3) Divide by # of activities = Salinity Score (A). Day Use & Boating share one salinity threshold (1,000 µS/cm), so they're one combined activity here (will split for temperature). Final Recreation Score = (A Salinity + B Temperature + C Habitat + D Economy) / 4. B–D come from the other workbooks.
C33: Day Use & Boating | D33: =BAU!AK811 -> 0.32183953 | E33: =BAU!AL811 -> 0.82061791 | F33: =BAU!AM811 -> 0.37845033 | G33: =BAU!AN811 -> 0 | H33: =BAU!AO811 -> 0.036429872 | I33: =BAU!AS811 -> 0.32037671 | J33: =BAU!AT811 -> 0.85034247 | K33: =BAU!AU811 -> 0.36194825 | L33: =BAU!AV811 -> 0 | M33: =BAU!AW811 -> 0.02130898 | N33: =BAU!BA811 -> 0.27817623 | O33: =BAU!BB811 -> 0.76058743 | P33: =BAU!BC811 -> 0.2962963 | Q33: =BAU!BD811 -> 0 | R33: =BAU!BE811 -> 0.016697025
C34: Birding | D34: =BAU!AK827 -> 0.24062106 | E34: =BAU!AL827 -> 0.73644388 | F34: =BAU!AM827 -> 0.20092476 | G34: =BAU!AN827 -> 0 | H34: =BAU!AO827 -> 0 | I34: =BAU!AS827 -> 0.2322774 | J34: =BAU!AT827 -> 0.74520548 | K34: =BAU!AU827 -> 0.16347032 | L34: =BAU!AV827 -> 0 | M34: =BAU!AW827 -> 0 | N34: =BAU!BA827 -> 0.21653005 | O34: =BAU!BB827 -> 0.68306011 | P34: =BAU!BC827 -> 0.1627201 | Q34: =BAU!BD827 -> 0 | R34: =BAU!BE827 -> 0 | T34: ACTIVITY | U34: SOURCE | V34: BAU | W34: BAF | X34: ECO | Y34: NGW | Z34: BAU CS | AA34: COR vs CS | AB34: Tunnel vs CS
C35: Waterfowl | D35: =BAU!AK843 -> 0.21071091 | E35: =BAU!AL843 -> 0.69955864 | F35: =BAU!AM843 -> 0.12736444 | G35: =BAU!AN843 -> 0 | H35: =BAU!AO843 -> 0 | I35: =BAU!AS843 -> 0.20847603 | J35: =BAU!AT843 -> 0.70308219 | K35: =BAU!AU843 -> 0.11628615 | L35: =BAU!AV843 -> 0 | M35: =BAU!AW843 -> 0 | N35: =BAU!BA843 -> 0.19031762 | O35: =BAU!BB843 -> 0.64515027 | P35: =BAU!BC843 -> 0.10321797 | Q35: =BAU!BD843 -> 0 | R35: =BAU!BE843 -> 0 | T35: Day Use/Boating | U35: Row 4 | V35: =E$4 -> 0 | W35: =F$4 -> 0 | X35: =G$4 -> 0 | Y35: =H$4 -> 0 | Z35: =I$4 -> 0 | AA35: =J$4 -> 1 | AB35: =K$4 -> -1
C36: Angling | D36: =BAU!AK859 -> 0.11834016 | E36: =BAU!AL859 -> 0.4175599 | F36: =BAU!AM859 -> 0.049600673 | G36: =BAU!AN859 -> 0 | H36: =BAU!AO859 -> 0 | I36: =BAU!AS859 -> 0.10496575 | J36: =BAU!AT859 -> 0.37773973 | K36: =BAU!AU859 -> 0.037442922 | L36: =BAU!AV859 -> 0 | M36: =BAU!AW859 -> 0 | N36: =BAU!BA859 -> 0.099385246 | O36: =BAU!BB859 -> 0.35928962 | P36: =BAU!BC859 -> 0.034001214 | Q36: =BAU!BD859 -> 0 | R36: =BAU!BE859 -> 0 | T36: Birding | U36: Row 10 | V36: =E$10 -> 0 | W36: =F$10 -> 0 | X36: =G$10 -> 0 | Y36: =H$10 -> 0 | Z36: =I$10 -> 0 | AA36: =J$10 -> 0 | AB36: =K$10 -> 0
T37: Waterfowl | U37: Row 16 | V37: =E$16 -> 0 | W37: =F$16 -> 0 | X37: =G$16 -> 0 | Y37: =H$16 -> 0 | Z37: =I$16 -> 0 | AA37: =J$16 -> 0 | AB37: =K$16 -> 0
C38: BAF % EXCEEDANCES | T38: Angling | U38: Row 22 | V38: =E$22 -> 0 | W38: =F$22 -> 0 | X38: =G$22 -> -2 | Y38: =H$22 -> -2 | Z38: =I$22 -> 0 | AA38: =J$22 -> 0 | AB38: =K$22 -> 0
D39: Total Run | I39: Wet Seasons | N39: Dry Seasons | T39: Sum of scores | V39: =SUM(V35:V38) -> 0 | W39: =SUM(W35:W38) -> 0 | X39: =SUM(X35:X38) -> -2 | Y39: =SUM(Y35:Y38) -> -2 | Z39: =SUM(Z35:Z38) -> 0 | AA39: =SUM(AA35:AA38) -> 1 | AB39: =SUM(AB35:AB38) -> -1
D40: Delta-Wide | E40: Suisun | F40: Central Delta | G40: North Delta | H40: South Delta | I40: Delta-Wide | J40: Suisun | K40: Central Delta | L40: North Delta | M40: South Delta | N40: Delta-Wide | O40: Suisun | P40: Central Delta | Q40: North Delta | R40: South Delta | T40: # of activities | V40: =COUNT(V35:V38) -> 4 | W40: =COUNT(W35:W38) -> 4 | X40: =COUNT(X35:X38) -> 4 | Y40: =COUNT(Y35:Y38) -> 4 | Z40: =COUNT(Z35:Z38) -> 4 | AA40: =COUNT(AA35:AA38) -> 4 | AB40: =COUNT(AB35:AB38) -> 4
C41: Day Use & Boating | D41: =BAF!AK811 -> 0.32550441 | E41: =BAF!AL811 -> 0.82093317 | F41: =BAF!AM811 -> 0.40423147 | G41: =BAF!AN811 -> 0 | H41: =BAF!AO811 -> 0.023399187 | I41: =BAF!AS811 -> 0.32842466 | J41: =BAF!AT811 -> 0.85068493 | K41: =BAF!AU811 -> 0.38599696 | L41: =BAF!AV811 -> 0 | M41: =BAF!AW811 -> 0.025570776 | N41: =BAF!BA811 -> 0.28329918 | O41: =BAF!BB811 -> 0.76092896 | P41: =BAF!BC811 -> 0.32210079 | Q41: =BAF!BD811 -> 0 | R41: =BAF!BE811 -> 0.0088038859 | T41: SALINITY SCORE (A) | V41: =IFERROR(V39/V40,0) -> 0 | W41: =IFERROR(W39/W40,0) -> 0 | X41: =IFERROR(X39/X40,0) -> -0.5 | Y41: =IFERROR(Y39/Y40,0) -> -0.5 | Z41: =IFERROR(Z39/Z40,0) -> 0 | AA41: =IFERROR(AA39/AA40,0) -> 0.25 | AB41: =IFERROR(AB39/AB40,0) -> -0.25
C42: Birding | D42: =BAF!AK827 -> 0.24101513 | E42: =BAF!AL827 -> 0.73660151 | F42: =BAF!AM827 -> 0.20218579 | G42: =BAF!AN827 -> 0 | H42: =BAF!AO827 -> 0 | I42: =BAF!AS827 -> 0.23287671 | J42: =BAF!AT827 -> 0.74554795 | K42: =BAF!AU827 -> 0.1652968 | L42: =BAF!AV827 -> 0 | M42: =BAF!AW827 -> 0 | N42: =BAF!BA827 -> 0.21610314 | O42: =BAF!BB827 -> 0.68306011 | P42: =BAF!BC827 -> 0.16120219 | Q42: =BAF!BD827 -> 0 | R42: =BAF!BE827 -> 0
C43: Waterfowl | D43: =BAF!AK843 -> 0.21169609 | E43: =BAF!AL843 -> 0.69955864 | F43: =BAF!AM843 -> 0.13086731 | G43: =BAF!AN843 -> 0 | H43: =BAF!AO843 -> 0 | I43: =BAF!AS843 -> 0.20864726 | J43: =BAF!AT843 -> 0.70308219 | K43: =BAF!AU843 -> 0.11689498 | L43: =BAF!AV843 -> 0 | M43: =BAF!AW843 -> 0 | N43: =BAF!BA843 -> 0.19134221 | O43: =BAF!BB843 -> 0.64515027 | P43: =BAF!BC843 -> 0.10686096 | Q43: =BAF!BD843 -> 0 | R43: =BAF!BE843 -> 0
...

Sheet BAU
B1: Suisun | J1: Central Delta | S1: North Delta | Y1: South Delta
A2: Date | B2: CHADBOURNE SLOUGH AT SUNRISE DUCK CLUB | C2: MONTEZUMA SLOUGH AT NATIONAL STEEL | D2: MONTEZUMA SLOUGH NEAR BELDENS LANDING | E2: SUISUN SLOUGH 300' SOUTH OF VOLANTI SLOUGH | F2: HONKER BAY | G2: SUISUN BAY AT VAN SICKLE ISLAND | H2: SUISUN BAY WEST REACH | I2: GRIZZLY BAY BUOY | J2: DUTCH SL BELOW JERSEY ISLAND | K2: FALSE RIVER NEAR OAKLEY | L2: OLD RIVER AT FRANKS TRACT | M2: PITTSBURG | N2: SACRAMENTO RIVER AT EMMATON | O2: SAN ANDREAS LANDING | P2: SAN JOAQUIN RIVER AT JERSEY POINT | Q2: SUISUN BAY AT CHANNEL MARKER 5 AT COLLINSVILLE | R2: BRANNAN MARINAS AT SAN JOAQUIN RIVER | S2: LIBERTY CUT AT FIVE POINTS | T2: CACHE SLOUGH ABOVE RYER ISLAND FERRY | U2: DELTA CROSS CHANNEL NEAR WALNUT GROVE | V2: SACRAMENTO RIVER DOWNSTREAM OF ISLETON | W2: COURTLAND AT SACRAMENTO RIVER | X2: VIERAS RESORT AT SACRAMENTO RIVER | Y2: GRANT LINE CANAL NEAR CLIFTON COURT FORE | Z2: LITTLE POTATO SLOUGH AT TERMINOUS | AA2: MIDDLE RIVER AT MILDRED ISLAND | AB2: OLD RIVER AT CLIFTON COURT | AC2: SAN JOAQUIN RIVER AT BRANDT BRIDGE | AD2: SAN JOAQUIN RIVER AT PRISONERS POINT | AE2: SAN JOAQUIN RIVER NEAR VERNALIS | AF2: SAN JOAQUIN RVER AT ROUGH AND READY ISLAND | AG2: VICTORIA CANAL BEFORE CLIFTON COURT FORE
A3: 43374 | B3: 15491.159 | C3: 6308.7646 | D3: 13535.573 | E3: 15645.412 | F3: 12701.988 | G3: 10018.657 | H3: 17600.361 | I3: 17035.219 | J3: 1804.9523 | K3: 1800.4069 | L3: 633.9048 | M3: 9800.864 | N3: 1656.0243 | O3: 701.0631 | P3: 2061.692 | Q3: 6861.0527 | R3: 967.8121 | S3: 281.35776 | T3: 141.81566 | U3: 109.16977 | V3: 127.44006 | W3: 110.73523 | X3: 116.47016 | Y3: 510.4771 | Z3: 134.32439 | AA3: 540.99786 | AB3: 844.1023 | AC3: 413.43805 | AD3: 519.06055 | AE3: 448.86038 | AF3: 432.15237 | AG3: 501.21756
A4: 43375 | B4: 15628.714 | C4: 6314.8164 | D4: 13675.848 | E4: 15795.319 | F4: 12925.177 | G4: 10250.212 | H4: 17812.51 | I4: 17097.164 | J4: 1807.7274 | K4: 1855.0044 | L4: 664.76654 | M4: 10011.478 | N4: 1778.7666 | O4: 735.2354 | P4: 2125.9001 | Q4: 7042.7305 | R4: 1003.751 | S4: 271.1294 | T4: 142.51825 | U4: 109.85611 | V4: 126.36919 | W4: 109.1926 | X4: 113.6285 | Y4: 528.98083 | Z4: 133.85085 | AA4: 532.02924 | AB4: 840.81805 | AC4: 421.00937 | AD4: 532.86273 | AE4: 480.7754 | AF4: 430.20584 | AG4: 493.03613
A5: 43376 | B5: 15784.017 | C5: 6326.136 | D5: 13720.399 | E5: 15864.098 | F5: 12945.628 | G5: 10066.431 | H5: 17536.271 | I5: 17140.06 | J5: 1811.8735 | K5: 1829.9349 | L5: 684.4926 | M5: 9715.1045 | N5: 1697.3256 | O5: 717.60114 | P5: 2094.966 | Q5: 6928.606 | R5: 1007.5832 | S5: 267.7271 | T5: 140.20715 | U5: 109.28668 | V5: 124.68064 | W5: 109.15531 | X5: 114.66095 | Y5: 556.2249 | Z5: 134.37726 | AA5: 529.31195 | AB5: 830.65204 | AC5: 425.41116 | AD5: 534.3498 | AE5: 498.2621 | AF5: 429.21036 | AG5: 486.88452
A6: 43377 | B6: 15929.47 | C6: 6371.511 | D6: 13753.684 | E6: 15919.953 | F6: 12829.897 | G6: 9821.697 | H6: 17290.623 | I6: 17211.385 | J6: 1817.355 | K6: 1796.2954 | L6: 680.9484 | M6: 9419.462 | N6: 1594.6631 | O6: 690.41846 | P6: 2056.2478 | Q6: 6730.9766 | R6: 990.21576 | S6: 262.87625 | T6: 137.66876 | U6: 109.47163 | V6: 122.56097 | W6: 109.27136 | X6: 113.57633 | Y6: 581.43884 | Z6: 134.7112 | AA6: 527.6747 | AB6: 831.52563 | AC6: 431.5326 | AD6: 533.3575 | AE6: 445.90475 | AF6: 429.6155 | AG6: 484.4795
A7: 43378 | B7: 16025.042 | C7: 6395.506 | D7: 13758.41 | E7: 15934.409 | F7: 12477.003 | G7: 9427.751 | H7: 16849.662 | I7: 17293.373 | J7: 1814.0844 | K7: 1760.5182 | L7: 668.32336 | M7: 9020.22 | N7: 1476.2706 | O7: 643.3658 | P7: 2002.164 | Q7: 6385.9004 | R7: 939.22723 | S7: 258.4514 | T7: 137.436 | U7: 106.461 | V7: 123.13013 | W7: 104.41894 | X7: 113.89976 | Y7: 593.0991 | Z7: 133.82335 | AA7: 526.5951 | AB7: 819.3792 | AC7: 444.1726 | AD7: 524.5575 | AE7: 449.29773 | AF7: 432.6993 | AG7: 481.7496
A8: 43379 | B8: 16139.038 | C8: 6379.818 | D8: 13981.695 | E8: 16102.738 | F8: 12504.282 | G8: 9752.153 | H8: 17296.555 | I8: 17324.088 | J8: 1814.0449 | K8: 1789.1063 | L8: 645.4565 | M8: 9324.1 | N8: 1618.6466 | O8: 675.44635 | P8: 2028.3373 | Q8: 6671.765 | R8: 967.0866 | S8: 245.15758 | T8: 138.9693 | U8: 108.4718 | V8: 125.48579 | W8: 119.01929 | X8: 114.44297 | Y8: 629.4232 | Z8: 133.35463 | AA8: 527.7196 | AB8: 829.82697 | AC8: 449.17514 | AD8: 509.88736 | AE8: 465.14456 | AF8: 436.3206 | AG8: 480.95535
A9: 43380 | B9: 16213.547 | C9: 6414.484 | D9: 14113.452 | E9: 16157.297 | F9: 12434.333 | G9: 9626.361 | H9: 17024.848 | I9: 17393.44 | J9: 1800.3862 | K9: 1714.8766 | L9: 678.8112 | M9: 9066.809 | N9: 1560.602 | O9: 683.269 | P9: 1968.9644 | Q9: 6549.5957 | R9: 975.2723 | S9: 237.44969 | T9: 137.62161 | U9: 120.7485 | V9: 123.70077 | W9: 116.67078 | X9: 113.10145 | Y9: 628.39044 | Z9: 131.65007 | AA9: 537.8468 | AB9: 851.9878 | AC9: 453.2247 | AD9: 488.7992 | AE9: 457.11743 | AF9: 440.7236 | AG9: 481.55295
A10: 43381 | B10: 16351.664 | C10: 6433.0234 | D10: 14457.797 | E10: 16409.19 | F10: 12520.798 | G10: 10091.606 | H10: 17838.346 | I10: 17368.9 | J10: 1790.2352 | K10: 1770.9076 | L10: 613.2471 | M10: 9664.404 | N10: 1755.5431 | O10: 711.32745 | P10: 2010.7153 | Q10: 6944.734 | R10: 996.38983 | S10: 228.73466 | T10: 141.10022 | U10: 113.43459 | V10: 135.75447 | W10: 112.69254 | X10: 124.03192 | Y10: 664.1046 | Z10: 134.94781 | AA10: 542.4827 | AB10: 858.94244 | AC10: 463.65332 | AD10: 497.09436 | AE10: 433.6356 | AF10: 445.30676 | AG10: 488.51187
A11: 43382 | B11: 16580.504 | C11: 6522.0312 | D11: 14904.528 | E11: 16751.498 | F11: 13625.317 | G11: 11495.128 | H11: 19409.23 | I11: 17479.201 | J11: 1800.8092 | K11: 1915.9418 | L11: 656.1298 | M11: 11001.917 | N11: 2426.1294 | O11: 827.39777 | P11: 2185.312 | Q11: 8178.18 | R11: 1097.7218 | S11: 218.18878 | T11: 154.62697 | U11: 114.61978 | V11: 152.49052 | W11: 113.93241 | X11: 130.38358 | Y11: 667.49554 | Z11: 138.33662 | AA11: 524.3593 | AB11: 828.85425 | AC11: 454.26352 | AD11: 539.7493 | AE11: 425.36978 | AF11: 447.8353 | AG11: 489.3623
A12: 43383 | B12: 16836.43 | C12: 6799.3613 | D12: 15278.405 | E12: 17107.246 | F12: 14993.138 | G12: 12632.75 | H12: 20465.03 | I12: 17750.064 | J12: 1838.2262 | K12: 2067.6375 | L12: 730.28217 | M12: 12117 | N12: 3118.1416 | O12: 914.6653 | P12: 2391.4373 | Q12: 9291.098 | R12: 1183.3077 | S12: 210.49083 | T12: 173.54814 | U12: 119.69137 | V12: 169.93062 | W12: 129.0721 | X12: 134.76627 | Y12: 674.2861 | Z12: 141.65431 | AA12: 514.80725 | AB12: 827.5925 | AC12: 442.2037 | AD12: 594.0948 | AE12: 448.22903 | AF12: 449.5117 | AG12: 484.9631
A13: 43384 | B13: 17027.547 | C13: 7224.397 | D13: 15420.257 | E13: 17307.22 | F13: 15356.38 | G13: 12651.667 | H13: 20381.203 | I13: 18040.488 | J13: 1871.1812 | K13: 2074.735 | L13: 767.13434 | M13: 12143.359 | N13: 3162.9226 | O13: 867.4963 | P13: 2410.743 | Q13: 9397.998 | R13: 1157.8599 | S13: 208.87328 | T13: 175.85661 | U13: 122.24628 | V13: 168.82115 | W13: 120.17617 | X13: 133.60481 | Y13: 678.21655 | Z13: 141.998 | AA13: 516.01886 | AB13: 823.8372 | AC13: 433.40854 | AD13: 604.2972 | AE13: 473.5988 | AF13: 451.2698 | AG13: 479.74167
A14: 43385 | B14: 17190.596 | C14: 7624.363 | D14: 15494.915 | E14: 17431.541 | F14: 15127.646 | G14: 12227.93 | H14: 19885.877 | I14: 18401.03 | J14: 1887.4946 | K14: 2042.5132 | L14: 740.85114 | M14: 11774.723 | N14: 2886.1204 | O14: 802.1387 | P14: 2364.453 | Q14: 8998.3955 | R14: 1101.4172 | S14: 206.11229 | T14: 169.37712 | U14: 119.61243 | V14: 162.70386 | W14: 117.31164 | X14: 136.95842 | Y14: 667.7361 | Z14: 141.34251 | AA14: 525.20953 | AB14: 820.4673 | AC14: 446.62772 | AD14: 587.8101 | AE14: 482.0358 | AF14: 450.83554 | AG14: 478.0601
... A795: 44166 | B795: 16243.354 | C795: 10367.393 | D795: 10005.476 | E795: 15210.817 | F795: 17692.969 | G795: 9145.906 | H795: 14908.921 | I795: 21075.797 | J795: 2709.668 | K795: 2464.8035 | L795: 1655.2594 | M795: 8729.155 | N795: 2620.5312 | O795: 500.32718 | P795: 2517.744 | Q795: 5465.22 | R795: 1063.6771 | S795: 199.93715 | T795: 199.63115 | U795: 142.56554 | V795: 148.14203 | W795: 144.44926 | X795: 146.44826 | Y795: 958.5978 | Z795: 187.3148 | AA795: 1015.0657 | AB795: 1397.3455 | AC795: 646.164 | AD795: 941.91504 | AE795: 799.69885 | AF795: 475.55237 | AG795: 1002.4056
A796: TOTAL EXCEEDANCES | B796: =COUNTIF(B$3:B$795,">=1000") -> 678 | C796: =COUNTIF(C$3:C$795,">=1000") -> 589 | D796: =COUNTIF(D$3:D$795,">=1000") -> 656 | E796: =COUNTIF(E$3:E$795,">=1000") -> 678 | F796: =COUNTIF(F$3:F$795,">=1000") -> 636 | G796: =COUNTIF(G$3:G$795,">=1000") -> 631 | H796: =COUNTIF(H$3:H$795,">=1000") -> 669 | I796: =COUNTIF(I$3:I$795,">=1000") -> 669 | ... AG796: =COUNTIF(AG$3:AG$795,">=1000") -> 19
A797: WET 1 | B797: =COUNTIF(B$3:B$184,">=1000") -> 152 | C797: =COUNTIF(C$3:C$184,">=1000") -> 105 | D797: =COUNTIF(D$3:D$184,">=1000") -> 136 | E797: =COUNTIF(E$3:E$184,">=1000") -> 147 | F797: =COUNTIF(F$3:F$184,">=1000") -> 116 | G797: =COUNTIF(G$3:G$184,">=1000") -> 112 | H797: =COUNTIF(H$3:H$184,">=1000") -> 130 | I797: =COUNTIF(I$3:I$184,">=1000") -> 138 | ... AG797: =COUNTIF(AG$3:AG$184,">=1000") -> 0 | AH797: OCT 2018 - MARCH 2019
A798: WET 2 | B798: =COUNTIF(B$368:B$550,">=1000") -> 183 | C798: =COUNTIF(C$368:C$550,">=1000") -> 166 | D798: =COUNTIF(D$368:D$550,">=1000") -> 183 | E798: =COUNTIF(E$368:E$550,">=1000") -> 183 | F798: =COUNTIF(F$368:F$550,">=1000") -> 183 | G798: =COUNTIF(G$368:G$550,">=1000") -> 183 | H798: =COUNTIF(H$368:H$550,">=1000") -> 183 | I798: =COUNTIF(I$368:I$550,">=1000") -> 183 | ... AG798: =COUNTIF(AG$368:AG$550,">=1000") -> 0 | AH798: OCT 2019 - MARCH 2020
A799: DRY 1 | B799: =COUNTIF(B$185:B$367,">=1000") -> 98 | C799: =COUNTIF(C$185:C$367,">=1000") -> 73 | D799: =COUNTIF(D$185:D$367,">=1000") -> 92 | E799: =COUNTIF(E$185:E$367,">=1000") -> 103 | F799: =COUNTIF(F$185:F$367,">=1000") -> 92 | G799: =COUNTIF(G$185:G$367,">=1000") -> 91 | H799: =COUNTIF(H$185:H$367,">=1000") -> 111 | I799: =COUNTIF(I$185:I$367,">=1000") -> 103 | ... AG799: =COUNTIF(AG$185:AG$367,">=1000") -> 0 | AH799: APRIL 2019 - SEPTEMBER 2019
A800: DRY 2 | B800: =COUNTIF(B$551:B$733,">=1000") -> 183 | C800: =COUNTIF(C$551:C$733,">=1000") -> 183 | D800: =COUNTIF(D$551:D$733,">=1000") -> 183 | E800: =COUNTIF(E$551:E$733,">=1000") -> 183 | F800: =COUNTIF(F$551:F$733,">=1000") -> 183 | G800: =COUNTIF(G$551:G$733,">=1000") -> 183 | H800: =COUNTIF(H$551:H$733,">=1000") -> 183 | I800: =COUNTIF(I$551:I$733,">=1000") -> 183 | ... AG800: =COUNTIF(AG$551:AG$733,">=1000") -> 0 | AH800: APRIL 2020 - SEPTEMBER 2020
A801: ALL WET | B801: =SUM(B$797,B$798) -> 335 | C801: =SUM(C$797,C$798) -> 271 | D801: =SUM(D$797,D$798) -> 319 | E801: =SUM(E$797,E$798) -> 330 | F801: =SUM(F$797,F$798) -> 299 | G801: =SUM(G$797,G$798) -> 295 | H801: =SUM(H$797,H$798) -> 313 | I801: =SUM(I$797,I$798) -> 321 | ... AG801: =SUM(AG$797,AG$798) -> 0
A802: ALL DRY | B802: =SUM(B$799,B$800) -> 281 | C802: =SUM(C$799,C$800) -> 256 | D802: =SUM(D$799,D$800) -> 275 | E802: =SUM(E$799,E$800) -> 286 | F802: =SUM(F$799,F$800) -> 275 | G802: =SUM(G$799,G$800) -> 274 | H802: =SUM(H$799,H$800) -> 294 | I802: =SUM(I$799,I$800) -> 286 | ... AG802: =SUM(AG$799,AG$800) -> 0
D805: Day Use & Boating | F805: THRESHOLD: 1,000 MICROSIEMENS/CM (EC) | S805: SP DAY USE & BOATING | AA805: SP DAY USE & BOATING | AE805: SP DAY USE & BOATING | AI805: SP DAY USE & BOATING | AQ805: SP DAY USE & BOATING | AY805: SP DAY USE & BOATING
F806: WET SEASON | S806: TOTAL RUN | AA806: WET SEASONS | AE806: DRY SEASONS | AI806: TOTAL RUN | AK806: Delta-Wide | AL806: Suisun | AM806: Central Delta | AN806: North Delta | AO806: South Delta | AQ806: WET SEASONS | AS806: Delta-Wide | AT806: Suisun | AU806: Central Delta | AV806: North Delta | AW806: South Delta | AY806: DRY SEASONS | BA806: Delta-Wide | BB806: Suisun | BC806: Central Delta | BD806: North Delta | BE806: South Delta
F807: OCTOBER 1 - MARCH 31 | M807: DRY SEASON | S807: Total points | U807: =COUNTIF($B$2:$AG$2,"<>") -> 32 | AA807: Total points | AC807: =$U$807 -> 32 | AE807: Total points | AG807: =$U$807 -> 32 | AI807: Total points | AK807: =COUNTIF($B$2:$AG$2,"<>") -> 32 | AL807: =COUNTIF($B$2:$I$2,"<>") -> 8 | AM807: =COUNTIF($J$2:$R$2,"<>") -> 9 | AN807: =COUNTIF($S$2:$X$2,"<>") -> 6 | AO807: =COUNTIF($Y$2:$AG$2,"<>") -> 9 | AQ807: Total points | AS807: =COUNTIF($B$2:$AG$2,"<>") -> 32 | AT807: =COUNTIF($B$2:$I$2,"<>") -> 8 | AU807: =COUNTIF($J$2:$R$2,"<>") -> 9 | AV807: =COUNTIF($S$2:$X$2,"<>") -> 6 | AW807: =COUNTIF($Y$2:$AG$2,"<>") -> 9 | AY807: Total points | BA807: =COUNTIF($B$2:$AG$2,"<>") -> 32 | BB807: =COUNTIF($B$2:$I$2,"<>") -> 8 | BC807: =COUNTIF($J$2:$R$2,"<>") -> 9 | BD807: =COUNTIF($S$2:$X$2,"<>") -> 6 | BE807: =COUNTIF($Y$2:$AG$2,"<>") -> 9
F808: WET SEASON 1 | H808: 10/1/18 - 3/31/19 | J808: =COUNTIF($A$3:$A$184,"<>") -> 182 | M808: APRIL 1 - SEPTEMBER 30 | S808: Days in run | U808: =COUNTIF($A$3:$A$795,"<>") -> 793 | AA808: Days in run | AC808: =SUM($J$808:$J$809) -> 365 | AE808: Days in run | AG808: =SUM($Q$809:$Q$810) -> 366 | AI808: Days in run | AK808: =COUNTIF($A$3:$A$795,"<>") -> 793 | AL808: =COUNTIF($A$3:$A$795,"<>") -> 793 | AM808: =COUNTIF($A$3:$A$795,"<>") -> 793 | AN808: =COUNTIF($A$3:$A$795,"<>") -> 793 | AO808: =COUNTIF($A$3:$A$795,"<>") -> 793 | AQ808: Days in run | AS808: =SUM($J$808:$J$809) -> 365 | AT808: =SUM($J$808:$J$809) -> 365 | AU808: =SUM($J$808:$J$809) -> 365 | AV808: =SUM($J$808:$J$809) -> 365 | AW808: =SUM($J$808:$J$809) -> 365 | AY808: Days in run | BA808: =SUM($Q$809:$Q$810) -> 366 | BB808: =SUM($Q$809:$Q$810) -> 366 | BC808: =SUM($Q$809:$Q$810) -> 366 | BD808: =SUM($Q$809:$Q$810) -> 366 | BE808: =SUM($Q$809:$Q$810) -> 366
F809: WET SEASON 2 | H809: 10/1/19 - 3/31/20 | J809: =COUNTIF($A$368:$A$550,"<>") -> 183 | M809: DRY SEASON 1 | O809: 4/1/19 - 9/30/19 | Q809: =COUNTIF($A$185:$A$367,"<>") -> 183 | S809: Total measurements | U809: =U808*U807 -> 25376 | V809: DENOMINATOR FOR EXCEEDANCE % | AA809: Total measurements | AC809: =AC808*AC807 -> 11680 | AE809: Total measurements | AG809: =$AG$808*$AG$807 -> 11712 | AI809: Total measurements | AK809: =AK808*AK807 -> 25376 | AL809: =AL808*AL807 -> 6344 | AM809: =AM808*AM807 -> 7137 | AN809: =AN808*AN807 -> 4758 | AO809: =AO808*AO807 -> 7137 | AQ809: Total measurements | AS809: =AS808*AS807 -> 11680 | AT809: =AT808*AT807 -> 2920 | AU809: =AU808*AU807 -> 3285 | AV809: =AV808*AV807 -> 2190 | AW809: =AW808*AW807 -> 3285 | AY809: Total measurements | BA809: =BA808*BA807 -> 11712 | BB809: =BB808*BB807 -> 2928 | BC809: =BC808*BC807 -> 3294 | BD809: =BD808*BD807 -> 2196 | BE809: =BE808*BE807 -> 3294
F810: WET SEASON 3 | H810: 10/1/20 - 12/1/20 | J810: =COUNTIF($A$734:$A$795,"<>") -> 62 | M810: DRY SEASON 2 | O810: 4/1/20 - 9/30/20 | Q810: =COUNTIF($A$551:$A$733,"<>") -> 183 | S810: Measurements >= 1000 | U810: =SUM(B796:AG796) -> 8167 | V810: NUMERATOR FOR EXCEEDANCE % | AA810: Measurements >= 1000 | AC810: =SUM($B$801:$AG$801) -> 3742 | AE810: Measurements >= 1000 | AG810: =SUM($B$802:$AG$802) -> 3258 | AI810: Measurements >= 1000 | AK810: =SUM(B796:AG796) -> 8167 | AL810: =SUM(B796:I796) -> 5206 | AM810: =SUM(J796:R796) -> 2701 | AN810: =SUM(S796:X796) -> 0 | AO810: =SUM(Y796:AG796) -> 260 | AQ810: Measurements >= 1000 | AS810: =SUM($B$801:$AG$801) -> 3742 | AT810: =SUM(B801:I801) -> 2483 | AU810: =SUM(J801:R801) -> 1189 | AV810: =SUM(S801:X801) -> 0 | AW810: =SUM(Y801:AG801) -> 70 | AY810: Measurements >= 1000 | BA810: =SUM($B$802:$AG$802) -> 3258 | BB810: =SUM(B802:I802) -> 2227 | BC810: =SUM(J802:R802) -> 976 | BD810: =SUM(S802:X802) -> 0 | BE810: =SUM(Y802:AG802) -> 55
S811: % Total Run Exceedances | U811: =$U810/$U809 -> 0.32183953 | AA811: % WET Exceedances | AC811: =AC810/AC809 -> 0.32037671 | AE811: % DRY Exceedances | AG811: =AG810/AG809 -> 0.27817623 | AI811: % Total Run Exceedances | AK811: =AK810/AK809 -> 0.32183953 | AL811: =AL810/AL809 -> 0.82061791 | AM811: =AM810/AM809 -> 0.37845033 | AN811: =AN810/AN809 -> 0 | AO811: =AO810/AO809 -> 0.036429872 | AQ811: % WET Exceedances | AS811: =AS810/AS809 -> 0.32037671 | AT811: =AT810/AT809 -> 0.85034247 | AU811: =AU810/AU809 -> 0.36194825 | AV811: =AV810/AV809 -> 0 | AW811: =AW810/AW809 -> 0.02130898 | AY811: % DRY Exceedances | BA811: =BA810/BA809 -> 0.27817623 | BB811: =BB810/BB809 -> 0.76058743 | BC811: =BC810/BC809 -> 0.2962963 | BD811: =BD810/BD809 -> 0 | BE811: =BE810/BE809 -> 0.016697025
A813: TOTAL EXCEEDANCES | B813: =COUNTIF(B$3:B$795,">=2640") -> 642 | C813: =COUNTIF(C$3:C$795,">=2640") -> 356 | D813: =COUNTIF(D$3:D$795,">=2640") -> 561 | E813: =COUNTIF(E$3:E$795,">=2640") -> 645 | F813: =COUNTIF(F$3:F$795,">=2640") -> 623 | G813: =COUNTIF(G$3:G$795,">=2640") -> 572 | H813: =COUNTIF(H$3:H$795,">=2640") -> 637 | I813: =COUNTIF(I$3:I$795,">=2640") -> 636 | ... AG813: =COUNTIF(AG$3:AG$795,">=2640") -> 0
A814: WET 1 | B814: =COUNTIF(B$3:B$184,">=2640") -> 130 | C814: =COUNTIF(C$3:C$184,">=2640") -> 102 | D814: =COUNTIF(D$3:D$184,">=2640") -> 109 | E814: =COUNTIF(E$3:E$184,">=2640") -> 130 | F814: =COUNTIF(F$3:F$184,">=2640") -> 110 | G814: =COUNTIF(G$3:G$184,">=2640") -> 105 | H814: =COUNTIF(H$3:H$184,">=2640") -> 116 | I814: =COUNTIF(I$3:I$184,">=2640") -> 119 | ... AG814: =COUNTIF(AG$3:AG$184,">=2640") -> 0 | AH814: OCT 2018 - MARCH 2019
A815: WET 2 | B815: =COUNTIF(B$368:B$550,">=2640") -> 183 | C815: =COUNTIF(C$368:C$550,">=2640") -> 44 | D815: =COUNTIF(D$368:D$550,">=2640") -> 138 | E815: =COUNTIF(E$368:E$550,">=2640") -> 183 | F815: =COUNTIF(F$368:F$550,">=2640") -> 183 | G815: =COUNTIF(G$368:G$550,">=2640") -> 158 | H815: =COUNTIF(H$368:H$550,">=2640") -> 183 | I815: =COUNTIF(I$368:I$550,">=2640") -> 183 | ... AG815: =COUNTIF(AG$368:AG$550,">=2640") -> 0 | AH815: OCT 2019 - MARCH 2020
A816: DRY 1 | B816: =COUNTIF(B$185:B$367,">=2640") -> 84 | C816: =COUNTIF(C$185:C$367,">=2640") -> 0 | D816: =COUNTIF(D$185:D$367,">=2640") -> 80 | E816: =COUNTIF(E$185:E$367,">=2640") -> 87 | F816: =COUNTIF(F$185:F$367,">=2640") -> 85 | G816: =COUNTIF(G$185:G$367,">=2640") -> 64 | H816: =COUNTIF(H$185:H$367,">=2640") -> 93 | I816: =COUNTIF(I$185:I$367,">=2640") -> 89 | ... AG816: =COUNTIF(AG$185:AG$367,">=2640") -> 0 | AH816: APRIL 2019 - SEPTEMBER 2019
A817: DRY 2 | B817: =COUNTIF(B$551:B$733,">=2640") -> 183 | C817: =COUNTIF(C$551:C$733,">=2640") -> 148 | D817: =COUNTIF(D$551:D$733,">=2640") -> 172 | E817: =COUNTIF(E$551:E$733,">=2640") -> 183 | F817: =COUNTIF(F$551:F$733,">=2640") -> 183 | G817: =COUNTIF(G$551:G$733,">=2640") -> 183 | H817: =COUNTIF(H$551:H$733,">=2640") -> 183 | I817: =COUNTIF(I$551:I$733,">=2640") -> 183 | ... AG817: =COUNTIF(AG$551:AG$733,">=2640") -> 0 | AH817: APRIL 2020 - SEPTEMBER 2020
A818: ALL WET | B818: =SUM(B814,B815) -> 313 | C818: =SUM(C814,C815) -> 146 | D818: =SUM(D814,D815) -> 247 | E818: =SUM(E814,E815) -> 313 | F818: =SUM(F814,F815) -> 293 | G818: =SUM(G814,G815) -> 263 | H818: =SUM(H814,H815) -> 299 | I818: =SUM(I814,I815) -> 302 | ... AG818: =SUM(AG814,AG815) -> 0
A819: ALL DRY | B819: =SUM(B816,B817) -> 267 | C819: =SUM(C816,C817) -> 148 | D819: =SUM(D816,D817) -> 252 | E819: =SUM(E816,E817) -> 270 | F819: =SUM(F816,F817) -> 268 | G819: =SUM(G816,G817) -> 247 | H819: =SUM(H816,H817) -> 276 | I819: =SUM(I816,I817) -> 272 | ... AG819: =SUM(AG816,AG817) -> 0
D821: Birding | F821: THRESHOLD: 2,640 MICROSIEMENS/CM (EC) | S821: BIRDING | AA821: BIRDING | AE821: BIRDING | AI821: BIRDING | AQ821: BIRDING | AY821: BIRDING
F822: WET SEASON | S822: TOTAL RUN | AA822: WET SEASONS | AE822: DRY SEASONS | AI822: TOTAL RUN | AK822: Delta-Wide | AL822: Suisun | AM822: Central Delta | AN822: North Delta | AO822: South Delta | AQ822: WET SEASONS | AS822: Delta-Wide | AT822: Suisun | AU822: Central Delta | AV822: North Delta | AW822: South Delta | AY822: DRY SEASONS | BA822: Delta-Wide | BB822: Suisun | BC822: Central Delta | BD822: North Delta | BE822: South Delta
F823: OCTOBER 1 - MARCH 31 | M823: DRY SEASON | S823: Total points | U823: =COUNTIF($B$2:$AG$2,"<>") -> 32 | AA823: Total points | AC823: =$U$807 -> 32 | AE823: Total points | AG823: =$U$807 -> 32 | AI823: Total points | AK823: =COUNTIF($B$2:$AG$2,"<>") -> 32 | AL823: =COUNTIF($B$2:$I$2,"<>") -> 8 | AM823: =COUNTIF($J$2:$R$2,"<>") -> 9 | AN823: =COUNTIF($S$2:$X$2,"<>") -> 6 | AO823: =COUNTIF($Y$2:$AG$2,"<>") -> 9 | AQ823: Total points | AS823: =COUNTIF($B$2:$AG$2,"<>") -> 32 | AT823: =COUNTIF($B$2:$I$2,"<>") -> 8 | AU823: =COUNTIF($J$2:$R$2,"<>") -> 9 | AV823: =COUNTIF($S$2:$X$2,"<>") -> 6 | AW823: =COUNTIF($Y$2:$AG$2,"<>") -> 9 | AY823: Total points | BA823: =COUNTIF($B$2:$AG$2,"<>") -> 32 | BB823: =COUNTIF($B$2:$I$2,"<>") -> 8 | BC823: =COUNTIF($J$2:$R$2,"<>") -> 9 | BD823: =COUNTIF($S$2:$X$2,"<>") -> 6 | BE823: =COUNTIF($Y$2:$AG$2,"<>") -> 9
F824: WET SEASON 1 | H824: 10/1/18 - 3/31/19 | J824: =COUNTIF($A$3:$A$184,"<>") -> 182 | M824: APRIL 1 - SEPTEMBER 30 | S824: Days in run | U824: =COUNTIF($A$3:$A$795,"<>") -> 793 | AA824: Days in run | AC824: =SUM($J$808:$J$809) -> 365 | AE824: Days in run | AG824: =SUM($Q$809:$Q$810) -> 366 | AI824: Days in run | AK824: =COUNTIF($A$3:$A$795,"<>") -> 793 | AL824: =COUNTIF($A$3:$A$795,"<>") -> 793 | AM824: =COUNTIF($A$3:$A$795,"<>") -> 793 | AN824: =COUNTIF($A$3:$A$795,"<>") -> 793 | AO824: =COUNTIF($A$3:$A$795,"<>") -> 793 | AQ824: Days in run | AS824: =SUM($J$808:$J$809) -> 365 | AT824: =SUM($J$808:$J$809) -> 365 | AU824: =SUM($J$808:$J$809) -> 365 | AV824: =SUM($J$808:$J$809) -> 365 | AW824: =SUM($J$808:$J$809) -> 365 | AY824: Days in run | BA824: =SUM($Q$809:$Q$810) -> 366 | BB824: =SUM($Q$809:$Q$810) -> 366 | BC824: =SUM($Q$809:$Q$810) -> 366 | BD824: =SUM($Q$809:$Q$810) -> 366 | BE824: =SUM($Q$809:$Q$810) -> 366
...

Sheet BAF
B1: Suisun | J1: Central Delta | S1: North Delta | Y1: South Delta
A2: Date | B2: CHADBOURNE SLOUGH AT SUNRISE DUCK CLUB | C2: MONTEZUMA SLOUGH AT NATIONAL STEEL | D2: MONTEZUMA SLOUGH NEAR BELDENS LANDING | E2: SUISUN SLOUGH 300' SOUTH OF VOLANTI SLOUGH | F2: HONKER BAY | G2: SUISUN BAY AT VAN SICKLE ISLAND | H2: SUISUN BAY WEST REACH | I2: GRIZZLY BAY BUOY | J2: DUTCH SL BELOW JERSEY ISLAND | K2: FALSE RIVER NEAR OAKLEY | L2: OLD RIVER AT FRANKS TRACT | M2: PITTSBURG | N2: SACRAMENTO RIVER AT EMMATON | O2: SAN ANDREAS LANDING | P2: SAN JOAQUIN RIVER AT JERSEY POINT | Q2: SUISUN BAY AT CHANNEL MARKER 5 AT COLLINSVILLE | R2: BRANNAN MARINAS AT SAN JOAQUIN RIVER | S2: LIBERTY CUT AT FIVE POINTS | T2: CACHE SLOUGH ABOVE RYER ISLAND FERRY | U2: DELTA CROSS CHANNEL NEAR WALNUT GROVE | V2: SACRAMENTO RIVER DOWNSTREAM OF ISLETON | W2: COURTLAND AT SACRAMENTO RIVER | X2: VIERAS RESORT AT SACRAMENTO RIVER | Y2: GRANT LINE CANAL NEAR CLIFTON COURT FORE | Z2: LITTLE POTATO SLOUGH AT TERMINOUS | AA2: MIDDLE RIVER AT MILDRED ISLAND | AB2: OLD RIVER AT CLIFTON COURT | AC2: SAN JOAQUIN RIVER AT BRANDT BRIDGE | AD2: SAN JOAQUIN RIVER AT PRISONERS POINT | AE2: SAN JOAQUIN RIVER NEAR VERNALIS | AF2: SAN JOAQUIN RVER AT ROUGH AND READY ISLAND | AG2: VICTORIA CANAL BEFORE CLIFTON COURT FORE
A3: 43374 | B3: 15635.199 | C3: 6344.161 | D3: 13715.155 | E3: 15796.606 | F3: 12710.851 | G3: 10022.274 | H3: 17674.936 | I3: 17087.264 | J3: 1698.1898 | K3: 1682.9191 | L3: 827.5831 | M3: 9772.137 | N3: 1784.9921 | O3: 879.9628 | P3: 1977.4282 | Q3: 6910.837 | R3: 1140.7704 | S3: 279.35333 | T3: 145.29579 | U3: 109.188 | V3: 132.61646 | W3: 110.72922 | X3: 118.62231 | Y3: 467.4685 | Z3: 130.66962 | AA3: 603.42865 | AB3: 673.3455 | AC3: 430.99652 | AD3: 718.24915 | AE3: 448.86038 | AF3: 447.91327 | AG3: 586.7396
A4: 43375 | B4: 15775.989 | C4: 6350.1895 | D4: 13845.36 | E4: 15944.465 | F4: 12930.038 | G4: 10259.771 | H4: 17889.96 | I4: 17148.357 | J4: 1705.2533 | K4: 1723.472 | L4: 857.87256 | M4: 9990.733 | N4: 1909.6285 | O4: 913.9516 | P4: 2046.0773 | Q4: 7093.2383 | R4: 1180.5901 | S4: 269.14822 | T4: 146.678 | U4: 109.79845 | V4: 132.589 | W4: 109.19177 | X4: 115.97275 | Y4: 486.38443 | Z4: 131.06882 | AA4: 596.0474 | AB4: 667.7829 | AC4: 438.35757 | AD4: 739.71826 | AE4: 480.7754 | AF4: 446.77148 | AG4: 579.7093
A5: 43376 | B5: 15930.887 | C5: 6359.1562 | D5: 13884.356 | E5: 16012.286 | F5: 12958.418 | G5: 10084.919 | H5: 17625.135 | I5: 17192.438 | J5: 1711.9146 | K5: 1725.1576 | L5: 865.98486 | M5: 9704.296 | N5: 1828.127 | O5: 895.2339 | P5: 2030.1176 | Q5: 6982.92 | R5: 1185.5195 | S5: 265.61404 | T5: 144.29668 | U5: 109.29227 | V5: 129.81743 | W5: 109.1555 | X5: 116.4706 | Y5: 504.30994 | Z5: 131.9033 | AA5: 590.22504 | AB5: 660.8297 | AC5: 442.00272 | AD5: 741.9152 | AE5: 498.2621 | AF5: 446.36365 | AG5: 575.9025
A6: 43377 | B6: 16073.606 | C6: 6400.49 | D6: 13916.515 | E6: 16068.734 | F6: 12849.759 | G6: 9843.151 | H6: 17380.955 | I6: 17267.328 | J6: 1718.7819 | K6: 1709.3223 | L6: 858.56635 | M6: 9405.652 | N6: 1716.0231 | O6: 867.1563 | P6: 2005.5034 | Q6: 6793.485 | R6: 1170.9719 | S6: 260.7006 | T6: 141.37544 | U6: 109.48865 | V6: 127.75253 | W6: 109.2709 | X6: 115.48505 | Y6: 527.9218 | Z6: 131.69185 | AA6: 587.69183 | AB6: 658.5133 | AC6: 445.99088 | AD6: 739.2524 | AE6: 445.90475 | AF6: 447.14145 | AG6: 573.74146
A7: 43378 | B7: 16167.808 | C7: 6426.066 | D7: 13926.083 | E7: 16085.735 | F7: 12501.483 | G7: 9447.387 | H7: 16933.387 | I7: 17351.965 | J7: 1718.1459 | K7: 1698.3883 | L7: 836.51416 | M7: 8992.038 | N7: 1592.2062 | O7: 814.4519 | P7: 1972.9103 | Q7: 6458.7876 | R7: 1121.0774 | S7: 256.20645 | T7: 141.1584 | U7: 106.54459 | V7: 128.44868 | W7: 104.41192 | X7: 115.82851 | Y7: 544.64105 | Z7: 130.38667 | AA7: 589.6793 | AB7: 653.4377 | AC7: 453.88147 | AD7: 721.6661 | AE7: 449.29773 | AF7: 450.41882 | AG7: 569.12384
A8: 43379 | B8: 16281.281 | C8: 6415.707 | D8: 14154.274 | E8: 16255.113 | F8: 12529.567 | G8: 9760.786 | H8: 17374.328 | I8: 17383.33 | J8: 1729.0426 | K8: 1725.5643 | L8: 824.2329 | M8: 9284.958 | N8: 1744.0631 | O8: 846.0738 | P8: 2000.1195 | Q8: 6745.22 | R8: 1151.1202 | S8: 243.15535 | T8: 143.50563 | U8: 108.48242 | V8: 131.85808 | W8: 119.0418 | X8: 116.98917 | Y8: 571.31305 | Z8: 130.08736 | AA8: 593.7822 | AB8: 656.5371 | AC8: 453.04477 | AD8: 710.90594 | AE8: 465.14456 | AF8: 453.66702 | AG8: 566.8241
A9: 43380 | B9: 16357.125 | C9: 6449.4966 | D9: 14292.778 | E9: 16312.481 | F9: 12466.918 | G9: 9640.563 | H9: 17103.951 | I9: 17459.1 | J9: 1741.0503 | K9: 1710.526 | L9: 800.37067 | M9: 9015.176 | N9: 1688.5482 | O9: 824.61346 | P9: 1979.068 | Q9: 6633.404 | R9: 1125.0132 | S9: 235.65263 | T9: 141.8191 | U9: 120.75433 | V9: 129.48991 | W9: 116.664 | X9: 115.28321 | Y9: 569.4433 | Z9: 129.52243 | AA9: 593.5119 | AB9: 663.16437 | AC9: 453.92636 | AD9: 679.2082 | AE9: 457.11743 | AF9: 456.59305 | AG9: 567.1627
A10: 43381 | B10: 16497.406 | C10: 6475.15 | D10: 14641.97 | E10: 16565.467 | F10: 12545.652 | G10: 10087.763 | H10: 17910.836 | I10: 17436.186 | J10: 1744.7148 | K10: 1737.9244 | L10: 776.58057 | M10: 9606.726 | N10: 1900.0181 | O10: 862.03973 | P10: 1997.3834 | Q10: 7015.1196 | R10: 1161.9999 | S10: 227.05717 | T10: 146.25212 | U10: 113.50354 | V10: 143.19324 | W10: 112.70921 | X10: 126.51276 | Y10: 582.6145 | Z10: 132.45937 | AA10: 584.3589 | AB10: 663.77655 | AC10: 464.08252 | AD10: 680.6694 | AE10: 433.6356 | AF10: 458.69034 | AG10: 572.10803
A11: 43382 | B11: 16727.861 | C11: 6564.1484 | D11: 15092.493 | E11: 16907.99 | F11: 13644.698 | G11: 11484.521 | H11: 19481.246 | I11: 17548.48 | J11: 1764.0458 | K11: 1809.7676 | L11: 853.4207 | M11: 10938.378 | N11: 2620.7756 | O11: 1014.6155 | P11: 2119.7478 | Q11: 8239.785 | R11: 1301.8389 | S11: 216.76997 | T11: 162.48073 | U11: 114.64352 | V11: 164.85283 | W11: 113.9473 | X11: 135.95668 | Y11: 588.99176 | Z11: 135.28099 | AA11: 571.3808 | AB11: 660.412 | AC11: 454.15756 | AD11: 746.2139 | AE11: 425.36978 | AF11: 459.78943 | AG11: 571.04285
