Workbook

Sheet OVERALL
V1: Notes: 1. Most exceedances happen in Suisun, in line with wider observations, followed by Central Delta exceedances, and thresholds also follow activity-specific gradients. As a result, angling, the activity with the highest activity threshold, shows zero exceedances in both the North and South Delta, alongside birding and waterfowl. Boating, meanwhile, is the only activity that crosses the threshold in the North and South, at a rate of about 2%. Historic baseine, and -10% outflows show exceedances at similar rates. 2. Scenario rankings (-5 to 5 vs Historical Baseline) show deviations from each other vs baselin.e, with +30% added flows and -10% flows. Positive moves on the scale are most pronounced in the Central Delta, which shows the largest positive moves across activities. 3. Under seasonality analysis, dry seasons exceed thresholds more often than wet seasons for every activity. in contrastn the Ither handn the opposOite side, extra outflow helps Suisun during wet periods.
C2: TOTAL RUN SCORES | I2: WET SEASON SCORES | O2: DRY SEASON SCORES
D3: REGION | E3: Historical Baseline | F3: +30% Outflow | G3: -10% Outflow | J3: REGION | K3: Historical Baseline | L3: +30% Outflow | M3: -10% Outflow | P3: REGION | Q3: Historical Baseline | R3: +30% Outflow | S3: -10% Outflow
C4: SP DAY USE & BOATING | D4: Delta-Wide | E4: =-MAX(-5,MIN(5,ROUND((D$39-D$39)*100,0))) -> 0 | F4: =-MAX(-5,MIN(5,ROUND((D$47-D$39)*100,0))) -> 5 | G4: =-MAX(-5,MIN(5,ROUND((D$55-D$39)*100,0))) -> -5 | I4: SP DAY USE & BOATING | J4: Delta-Wide | K4: =-MAX(-5,MIN(5,ROUND((I$39-I$39)*100,0))) -> 0 | L4: =-MAX(-5,MIN(5,ROUND((I$47-I$39)*100,0))) -> 5 | M4: =-MAX(-5,MIN(5,ROUND((I$55-I$39)*100,0))) -> -5 | O4: SP DAY USE & BOATING | P4: Delta-Wide | Q4: =-MAX(-5,MIN(5,ROUND((N$39-N$39)*100,0))) -> 0 | R4: =-MAX(-5,MIN(5,ROUND((N$47-N$39)*100,0))) -> 5 | S4: =-MAX(-5,MIN(5,ROUND((N$55-N$39)*100,0))) -> -5
D5: Suisun | E5: =-MAX(-5,MIN(5,ROUND((E$39-E$39)*100,0))) -> 0 | F5: =-MAX(-5,MIN(5,ROUND((E$47-E$39)*100,0))) -> 1 | G5: =-MAX(-5,MIN(5,ROUND((E$55-E$39)*100,0))) -> 0 | J5: Suisun | K5: =-MAX(-5,MIN(5,ROUND((J$39-J$39)*100,0))) -> 0 | L5: =-MAX(-5,MIN(5,ROUND((J$47-J$39)*100,0))) -> 2 | M5: =-MAX(-5,MIN(5,ROUND((J$55-J$39)*100,0))) -> 0 | P5: Suisun | Q5: =-MAX(-5,MIN(5,ROUND((O$39-O$39)*100,0))) -> 0 | R5: =-MAX(-5,MIN(5,ROUND((O$47-O$39)*100,0))) -> 0 | S5: =-MAX(-5,MIN(5,ROUND((O$55-O$39)*100,0))) -> 0
D6: Central | E6: =-MAX(-5,MIN(5,ROUND((F$39-F$39)*100,0))) -> 0 | F6: =-MAX(-5,MIN(5,ROUND((F$47-F$39)*100,0))) -> 5 | G6: =-MAX(-5,MIN(5,ROUND((F$55-F$39)*100,0))) -> -5 | J6: Central | K6: =-MAX(-5,MIN(5,ROUND((K$39-K$39)*100,0))) -> 0 | L6: =-MAX(-5,MIN(5,ROUND((K$47-K$39)*100,0))) -> 5 | M6: =-MAX(-5,MIN(5,ROUND((K$55-K$39)*100,0))) -> -5 | P6: Central | Q6: =-MAX(-5,MIN(5,ROUND((P$39-P$39)*100,0))) -> 0 | R6: =-MAX(-5,MIN(5,ROUND((P$47-P$39)*100,0))) -> 5 | S6: =-MAX(-5,MIN(5,ROUND((P$55-P$39)*100,0))) -> -5
D7: North | E7: =-MAX(-5,MIN(5,ROUND((G$39-G$39)*100,0))) -> 0 | F7: =-MAX(-5,MIN(5,ROUND((G$47-G$39)*100,0))) -> 2 | G7: =-MAX(-5,MIN(5,ROUND((G$55-G$39)*100,0))) -> -3 | J7: North | K7: =-MAX(-5,MIN(5,ROUND((L$39-L$39)*100,0))) -> 0 | L7: =-MAX(-5,MIN(5,ROUND((L$47-L$39)*100,0))) -> 0 | M7: =-MAX(-5,MIN(5,ROUND((L$55-L$39)*100,0))) -> -2 | P7: North | Q7: =-MAX(-5,MIN(5,ROUND((Q$39-Q$39)*100,0))) -> 0 | R7: =-MAX(-5,MIN(5,ROUND((Q$47-Q$39)*100,0))) -> 4 | S7: =-MAX(-5,MIN(5,ROUND((Q$55-Q$39)*100,0))) -> -5
D8: South | E8: =-MAX(-5,MIN(5,ROUND((H$39-H$39)*100,0))) -> 0 | F8: =-MAX(-5,MIN(5,ROUND((H$47-H$39)*100,0))) -> 2 | G8: =-MAX(-5,MIN(5,ROUND((H$55-H$39)*100,0))) -> -5 | J8: South | K8: =-MAX(-5,MIN(5,ROUND((M$39-M$39)*100,0))) -> 0 | L8: =-MAX(-5,MIN(5,ROUND((M$47-M$39)*100,0))) -> 2 | M8: =-MAX(-5,MIN(5,ROUND((M$55-M$39)*100,0))) -> -5 | P8: South | Q8: =-MAX(-5,MIN(5,ROUND((R$39-R$39)*100,0))) -> 0 | R8: =-MAX(-5,MIN(5,ROUND((R$47-R$39)*100,0))) -> 2 | S8: =-MAX(-5,MIN(5,ROUND((R$55-R$39)*100,0))) -> -5
D9: REGION | E9: Historical Baseline | F9: +30% Outflow | G9: -10% Outflow | J9: REGION | K9: Historical Baseline | L9: +30% Outflow | M9: -10% Outflow | P9: REGION | Q9: Historical Baseline | R9: +30% Outflow | S9: -10% Outflow
C10: BIRDING | D10: Delta-Wide | E10: =-MAX(-5,MIN(5,ROUND((D$40-D$40)*100,0))) -> 0 | F10: =-MAX(-5,MIN(5,ROUND((D$48-D$40)*100,0))) -> 4 | G10: =-MAX(-5,MIN(5,ROUND((D$56-D$40)*100,0))) -> -3 | I10: BIRDING | J10: Delta-Wide | K10: =-MAX(-5,MIN(5,ROUND((I$40-I$40)*100,0))) -> 0 | L10: =-MAX(-5,MIN(5,ROUND((I$48-I$40)*100,0))) -> 5 | M10: =-MAX(-5,MIN(5,ROUND((I$56-I$40)*100,0))) -> -3 | O10: BIRDING | P10: Delta-Wide | Q10: =-MAX(-5,MIN(5,ROUND((N$40-N$40)*100,0))) -> 0 | R10: =-MAX(-5,MIN(5,ROUND((N$48-N$40)*100,0))) -> 3 | S10: =-MAX(-5,MIN(5,ROUND((N$56-N$40)*100,0))) -> -3
D11: Suisun | E11: =-MAX(-5,MIN(5,ROUND((E$40-E$40)*100,0))) -> 0 | F11: =-MAX(-5,MIN(5,ROUND((E$48-E$40)*100,0))) -> 3 | G11: =-MAX(-5,MIN(5,ROUND((E$56-E$40)*100,0))) -> 0 | J11: Suisun | K11: =-MAX(-5,MIN(5,ROUND((J$40-J$40)*100,0))) -> 0 | L11: =-MAX(-5,MIN(5,ROUND((J$48-J$40)*100,0))) -> 5 | M11: =-MAX(-5,MIN(5,ROUND((J$56-J$40)*100,0))) -> 0 | P11: Suisun | Q11: =-MAX(-5,MIN(5,ROUND((O$40-O$40)*100,0))) -> 0 | R11: =-MAX(-5,MIN(5,ROUND((O$48-O$40)*100,0))) -> 0 | S11: =-MAX(-5,MIN(5,ROUND((O$56-O$40)*100,0))) -> 0
D12: Central | E12: =-MAX(-5,MIN(5,ROUND((F$40-F$40)*100,0))) -> 0 | F12: =-MAX(-5,MIN(5,ROUND((F$48-F$40)*100,0))) -> 5 | G12: =-MAX(-5,MIN(5,ROUND((F$56-F$40)*100,0))) -> -5 | J12: Central | K12: =-MAX(-5,MIN(5,ROUND((K$40-K$40)*100,0))) -> 0 | L12: =-MAX(-5,MIN(5,ROUND((K$48-K$40)*100,0))) -> 5 | M12: =-MAX(-5,MIN(5,ROUND((K$56-K$40)*100,0))) -> -5 | P12: Central | Q12: =-MAX(-5,MIN(5,ROUND((P$40-P$40)*100,0))) -> 0 | R12: =-MAX(-5,MIN(5,ROUND((P$48-P$40)*100,0))) -> 5 | S12: =-MAX(-5,MIN(5,ROUND((P$56-P$40)*100,0))) -> -5
D13: North | E13: =-MAX(-5,MIN(5,ROUND((G$40-G$40)*100,0))) -> 0 | F13: =-MAX(-5,MIN(5,ROUND((G$48-G$40)*100,0))) -> 0 | G13: =-MAX(-5,MIN(5,ROUND((G$56-G$40)*100,0))) -> 0 | J13: North | K13: =-MAX(-5,MIN(5,ROUND((L$40-L$40)*100,0))) -> 0 | L13: =-MAX(-5,MIN(5,ROUND((L$48-L$40)*100,0))) -> 0 | M13: =-MAX(-5,MIN(5,ROUND((L$56-L$40)*100,0))) -> 0 | P13: North | Q13: =-MAX(-5,MIN(5,ROUND((Q$40-Q$40)*100,0))) -> 0 | R13: =-MAX(-5,MIN(5,ROUND((Q$48-Q$40)*100,0))) -> 0 | S13: =-MAX(-5,MIN(5,ROUND((Q$56-Q$40)*100,0))) -> 0
D14: South | E14: =-MAX(-5,MIN(5,ROUND((H$40-H$40)*100,0))) -> 0 | F14: =-MAX(-5,MIN(5,ROUND((H$48-H$40)*100,0))) -> 0 | G14: =-MAX(-5,MIN(5,ROUND((H$56-H$40)*100,0))) -> 0 | J14: South | K14: =-MAX(-5,MIN(5,ROUND((M$40-M$40)*100,0))) -> 0 | L14: =-MAX(-5,MIN(5,ROUND((M$48-M$40)*100,0))) -> 0 | M14: =-MAX(-5,MIN(5,ROUND((M$56-M$40)*100,0))) -> 0 | P14: South | Q14: =-MAX(-5,MIN(5,ROUND((R$40-R$40)*100,0))) -> 0 | R14: =-MAX(-5,MIN(5,ROUND((R$48-R$40)*100,0))) -> 0 | S14: =-MAX(-5,MIN(5,ROUND((R$56-R$40)*100,0))) -> 0
D15: REGION | E15: Historical Baseline | F15: +30% Outflow | G15: -10% Outflow | J15: REGION | K15: Historical Baseline | L15: +30% Outflow | M15: -10% Outflow | P15: REGION | Q15: Historical Baseline | R15: +30% Outflow | S15: -10% Outflow
C16: WATERFOWL | D16: Delta-Wide | E16: =-MAX(-5,MIN(5,ROUND((D$41-D$41)*100,0))) -> 0 | F16: =-MAX(-5,MIN(5,ROUND((D$49-D$41)*100,0))) -> 4 | G16: =-MAX(-5,MIN(5,ROUND((D$57-D$41)*100,0))) -> -1 | I16: WATERFOWL | J16: Delta-Wide | K16: =-MAX(-5,MIN(5,ROUND((I$41-I$41)*100,0))) -> 0 | L16: =-MAX(-5,MIN(5,ROUND((I$49-I$41)*100,0))) -> 5 | M16: =-MAX(-5,MIN(5,ROUND((I$57-I$41)*100,0))) -> -1 | O16: WATERFOWL | P16: Delta-Wide | Q16: =-MAX(-5,MIN(5,ROUND((N$41-N$41)*100,0))) -> 0 | R16: =-MAX(-5,MIN(5,ROUND((N$49-N$41)*100,0))) -> 3 | S16: =-MAX(-5,MIN(5,ROUND((N$57-N$41)*100,0))) -> -1
D17: Suisun | E17: =-MAX(-5,MIN(5,ROUND((E$41-E$41)*100,0))) -> 0 | F17: =-MAX(-5,MIN(5,ROUND((E$49-E$41)*100,0))) -> 5 | G17: =-MAX(-5,MIN(5,ROUND((E$57-E$41)*100,0))) -> 0 | J17: Suisun | K17: =-MAX(-5,MIN(5,ROUND((J$41-J$41)*100,0))) -> 0 | L17: =-MAX(-5,MIN(5,ROUND((J$49-J$41)*100,0))) -> 5 | M17: =-MAX(-5,MIN(5,ROUND((J$57-J$41)*100,0))) -> -1 | P17: Suisun | Q17: =-MAX(-5,MIN(5,ROUND((O$41-O$41)*100,0))) -> 0 | R17: =-MAX(-5,MIN(5,ROUND((O$49-O$41)*100,0))) -> 2 | S17: =-MAX(-5,MIN(5,ROUND((O$57-O$41)*100,0))) -> 0
D18: Central | E18: =-MAX(-5,MIN(5,ROUND((F$41-F$41)*100,0))) -> 0 | F18: =-MAX(-5,MIN(5,ROUND((F$49-F$41)*100,0))) -> 5 | G18: =-MAX(-5,MIN(5,ROUND((F$57-F$41)*100,0))) -> -4 | J18: Central | K18: =-MAX(-5,MIN(5,ROUND((K$41-K$41)*100,0))) -> 0 | L18: =-MAX(-5,MIN(5,ROUND((K$49-K$41)*100,0))) -> 5 | M18: =-MAX(-5,MIN(5,ROUND((K$57-K$41)*100,0))) -> -4 | P18: Central | Q18: =-MAX(-5,MIN(5,ROUND((P$41-P$41)*100,0))) -> 0 | R18: =-MAX(-5,MIN(5,ROUND((P$49-P$41)*100,0))) -> 5 | S18: =-MAX(-5,MIN(5,ROUND((P$57-P$41)*100,0))) -> -3
D19: North | E19: =-MAX(-5,MIN(5,ROUND((G$41-G$41)*100,0))) -> 0 | F19: =-MAX(-5,MIN(5,ROUND((G$49-G$41)*100,0))) -> 0 | G19: =-MAX(-5,MIN(5,ROUND((G$57-G$41)*100,0))) -> 0 | J19: North | K19: =-MAX(-5,MIN(5,ROUND((L$41-L$41)*100,0))) -> 0 | L19: =-MAX(-5,MIN(5,ROUND((L$49-L$41)*100,0))) -> 0 | M19: =-MAX(-5,MIN(5,ROUND((L$57-L$41)*100,0))) -> 0 | P19: North | Q19: =-MAX(-5,MIN(5,ROUND((Q$41-Q$41)*100,0))) -> 0 | R19: =-MAX(-5,MIN(5,ROUND((Q$49-Q$41)*100,0))) -> 0 | S19: =-MAX(-5,MIN(5,ROUND((Q$57-Q$41)*100,0))) -> 0
D20: South | E20: =-MAX(-5,MIN(5,ROUND((H$41-H$41)*100,0))) -> 0 | F20: =-MAX(-5,MIN(5,ROUND((H$49-H$41)*100,0))) -> 0 | G20: =-MAX(-5,MIN(5,ROUND((H$57-H$41)*100,0))) -> 0 | J20: South | K20: =-MAX(-5,MIN(5,ROUND((M$41-M$41)*100,0))) -> 0 | L20: =-MAX(-5,MIN(5,ROUND((M$49-M$41)*100,0))) -> 0 | M20: =-MAX(-5,MIN(5,ROUND((M$57-M$41)*100,0))) -> 0 | P20: South | Q20: =-MAX(-5,MIN(5,ROUND((R$41-R$41)*100,0))) -> 0 | R20: =-MAX(-5,MIN(5,ROUND((R$49-R$41)*100,0))) -> 0 | S20: =-MAX(-5,MIN(5,ROUND((R$57-R$41)*100,0))) -> 0
D21: REGION | E21: Historical Baseline | F21: +30% Outflow | G21: -10% Outflow | J21: REGION | K21: Historical Baseline | L21: +30% Outflow | M21: -10% Outflow | P21: REGION | Q21: Historical Baseline | R21: +30% Outflow | S21: -10% Outflow
C22: ANGLING | D22: Delta-Wide | E22: =-MAX(-5,MIN(5,ROUND((D$42-D$42)*100,0))) -> 0 | F22: =-MAX(-5,MIN(5,ROUND((D$50-D$42)*100,0))) -> 5 | G22: =-MAX(-5,MIN(5,ROUND((D$58-D$42)*100,0))) -> -1 | I22: ANGLING | J22: Delta-Wide | K22: =-MAX(-5,MIN(5,ROUND((I$42-I$42)*100,0))) -> 0 | L22: =-MAX(-5,MIN(5,ROUND((I$50-I$42)*100,0))) -> 5 | M22: =-MAX(-5,MIN(5,ROUND((I$58-I$42)*100,0))) -> -1 | O22: ANGLING | P22: Delta-Wide | Q22: =-MAX(-5,MIN(5,ROUND((N$42-N$42)*100,0))) -> 0 | R22: =-MAX(-5,MIN(5,ROUND((N$50-N$42)*100,0))) -> 5 | S22: =-MAX(-5,MIN(5,ROUND((N$58-N$42)*100,0))) -> 0
D23: Suisun | E23: =-MAX(-5,MIN(5,ROUND((E$42-E$42)*100,0))) -> 0 | F23: =-MAX(-5,MIN(5,ROUND((E$50-E$42)*100,0))) -> 5 | G23: =-MAX(-5,MIN(5,ROUND((E$58-E$42)*100,0))) -> -2 | J23: Suisun | K23: =-MAX(-5,MIN(5,ROUND((J$42-J$42)*100,0))) -> 0 | L23: =-MAX(-5,MIN(5,ROUND((J$50-J$42)*100,0))) -> 5 | M23: =-MAX(-5,MIN(5,ROUND((J$58-J$42)*100,0))) -> -3 | P23: Suisun | Q23: =-MAX(-5,MIN(5,ROUND((O$42-O$42)*100,0))) -> 0 | R23: =-MAX(-5,MIN(5,ROUND((O$50-O$42)*100,0))) -> 5 | S23: =-MAX(-5,MIN(5,ROUND((O$58-O$42)*100,0))) -> 0
D24: Central | E24: =-MAX(-5,MIN(5,ROUND((F$42-F$42)*100,0))) -> 0 | F24: =-MAX(-5,MIN(5,ROUND((F$50-F$42)*100,0))) -> 5 | G24: =-MAX(-5,MIN(5,ROUND((F$58-F$42)*100,0))) -> 0 | J24: Central | K24: =-MAX(-5,MIN(5,ROUND((K$42-K$42)*100,0))) -> 0 | L24: =-MAX(-5,MIN(5,ROUND((K$50-K$42)*100,0))) -> 5 | M24: =-MAX(-5,MIN(5,ROUND((K$58-K$42)*100,0))) -> -1 | P24: Central | Q24: =-MAX(-5,MIN(5,ROUND((P$42-P$42)*100,0))) -> 0 | R24: =-MAX(-5,MIN(5,ROUND((P$50-P$42)*100,0))) -> 5 | S24: =-MAX(-5,MIN(5,ROUND((P$58-P$42)*100,0))) -> 0
D25: North | E25: =-MAX(-5,MIN(5,ROUND((G$42-G$42)*100,0))) -> 0 | F25: =-MAX(-5,MIN(5,ROUND((G$50-G$42)*100,0))) -> 0 | G25: =-MAX(-5,MIN(5,ROUND((G$58-G$42)*100,0))) -> 0 | J25: North | K25: =-MAX(-5,MIN(5,ROUND((L$42-L$42)*100,0))) -> 0 | L25: =-MAX(-5,MIN(5,ROUND((L$50-L$42)*100,0))) -> 0 | M25: =-MAX(-5,MIN(5,ROUND((L$58-L$42)*100,0))) -> 0 | P25: North | Q25: =-MAX(-5,MIN(5,ROUND((Q$42-Q$42)*100,0))) -> 0 | R25: =-MAX(-5,MIN(5,ROUND((Q$50-Q$42)*100,0))) -> 0 | S25: =-MAX(-5,MIN(5,ROUND((Q$58-Q$42)*100,0))) -> 0
D26: South | E26: =-MAX(-5,MIN(5,ROUND((H$42-H$42)*100,0))) -> 0 | F26: =-MAX(-5,MIN(5,ROUND((H$50-H$42)*100,0))) -> 0 | G26: =-MAX(-5,MIN(5,ROUND((H$58-H$42)*100,0))) -> 0 | J26: South | K26: =-MAX(-5,MIN(5,ROUND((M$42-M$42)*100,0))) -> 0 | L26: =-MAX(-5,MIN(5,ROUND((M$50-M$42)*100,0))) -> 0 | M26: =-MAX(-5,MIN(5,ROUND((M$58-M$42)*100,0))) -> 0 | P26: South | Q26: =-MAX(-5,MIN(5,ROUND((R$42-R$42)*100,0))) -> 0 | R26: =-MAX(-5,MIN(5,ROUND((R$50-R$42)*100,0))) -> 0 | S26: =-MAX(-5,MIN(5,ROUND((R$58-R$42)*100,0))) -> 0
C36: RUN 15 % EXCEEDANCES
C37: Tiered Outflows | D37: Total Run | I37: Wet Seasons | N37: Dry Seasons | AB37: Tiered Outflows | AD37: Wet Seasons | AI37: Dry Seasons
D38: Delta-Wide | E38: Suisun | F38: Central Delta | G38: North Delta | H38: South Delta | I38: Delta-Wide | J38: Suisun | K38: Central Delta | L38: North Delta | M38: South Delta | N38: Delta-Wide | O38: Suisun | P38: Central Delta | Q38: North Delta | R38: South Delta | T38: Tiered Outflows | V38: Delta-Wide | W38: Suisun | X38: Central Delta | Y38: North Delta | Z38: South Delta | AD38: Delta-Wide | AE38: Suisun | AF38: Central Delta | AG38: North Delta | AH38: South Delta | AI38: Delta-Wide | AJ38: Suisun | AK38: Central Delta | AL38: North Delta | AM38: South Delta
C39: Day Use & Boating | D39: ='Run 15'!AK527 -> 0.46138261 | E39: ='Run 15'!AL527 -> 0.99803536 | F39: ='Run 15'!AM527 -> 0.71556429 | G39: ='Run 15'!AN527 -> 0.021283563 | H39: ='Run 15'!AO527 -> 0.023575639 | I39: ='Run 15'!AS527 -> 0.44363636 | J39: ='Run 15'!AT527 -> 0.99636364 | K39: ='Run 15'!AU527 -> 0.66424242 | L39: ='Run 15'!AV527 -> 0.0018181818 | M39: ='Run 15'!AW527 -> 0.026262626 | N39: ='Run 15'!BA527 -> 0.48223825 | O39: ='Run 15'!BB527 -> 1 | P39: ='Run 15'!BC527 -> 0.77587844 | Q39: ='Run 15'!BD527 -> 0.044159544 | R39: ='Run 15'!BE527 -> 0.020417854 | T39: Historical Baseline | U39: Day Use & Boating | V39: 0.46138261 | W39: 0.99803536 | X39: 0.71556429 | Y39: 0.021283563 | Z39: 0.023575639 | AB39: Historical Baseline | AC39: Day Use & Boating | AD39: 0.44363636 | AE39: 0.99636364 | AF39: 0.66424242 | AG39: 0.0018181818 | AH39: 0.026262626 | AI39: 0.48223825 | AJ39: 1 | AK39: 0.77587844 | AL39: 0.044159544 | AM39: 0.020417854
C40: Birding | D40: ='Run 15'!AK544 -> 0.34381139 | E40: ='Run 15'!AL544 -> 0.99189587 | F40: ='Run 15'!AM544 -> 0.34075529 | G40: ='Run 15'!AN544 -> 0 | H40: ='Run 15'!AO544 -> 0 | I40: ='Run 15'!AS544 -> 0.33602273 | J40: ='Run 15'!AT544 -> 0.985 | K40: ='Run 15'!AU544 -> 0.31919192 | L40: ='Run 15'!AV544 -> 0 | M40: ='Run 15'!AW544 -> 0 | N40: ='Run 15'!BA544 -> 0.35296474 | O40: ='Run 15'!BB544 -> 1 | P40: ='Run 15'!BC544 -> 0.36609687 | Q40: ='Run 15'!BD544 -> 0 | R40: ='Run 15'!BE544 -> 0 | U40: Birding | V40: 0.34381139 | W40: 0.99189587 | X40: 0.34075529 | Y40: 0 | Z40: 0 | AC40: Birding | AD40: 0.33602273 | AE40: 0.985 | AF40: 0.31919192 | AG40: 0 | AH40: 0 | AI40: 0.35296474 | AJ40: 1 | AK40: 0.36609687 | AL40: 0 | AM40: 0
C41: Waterfowl | D41: ='Run 15'!AK561 -> 0.32680501 | E41: ='Run 15'!AL561 -> 0.98870334 | F41: ='Run 15'!AM561 -> 0.28312596 | G41: ='Run 15'!AN561 -> 0 | H41: ='Run 15'!AO561 -> 0 | I41: ='Run 15'!AS561 -> 0.31795455 | J41: ='Run 15'!AT561 -> 0.97909091 | K41: ='Run 15'!AU561 -> 0.26020202 | L41: ='Run 15'!AV561 -> 0 | M41: ='Run 15'!AW561 -> 0 | N41: ='Run 15'!BA561 -> 0.3372062 | O41: ='Run 15'!BB561 -> 1 | P41: ='Run 15'!BC561 -> 0.31006648 | Q41: ='Run 15'!BD561 -> 0 | R41: ='Run 15'!BE561 -> 0 | U41: Waterfowl | V41: 0.32680501 | W41: 0.98870334 | X41: 0.28312596 | Y41: 0 | Z41: 0 | AC41: Waterfowl | AD41: 0.31795455 | AE41: 0.97909091 | AF41: 0.26020202 | AG41: 0 | AH41: 0 | AI41: 0.3372062 | AJ41: 1 | AK41: 0.31006648 | AL41: 0 | AM41: 0
C42: Angling | D42: ='Run 15'!AK578 -> 0.25994597 | E42: ='Run 15'!AL578 -> 0.85019646 | F42: ='Run 15'!AM578 -> 0.16852216 | G42: ='Run 15'!AN578 -> 0 | H42: ='Run 15'!AO578 -> 0 | I42: ='Run 15'!AS578 -> 0.23852273 | J42: ='Run 15'!AT578 -> 0.79136364 | K42: ='Run 15'!AU578 -> 0.14464646 | L42: ='Run 15'!AV578 -> 0 | M42: ='Run 15'!AW578 -> 0 | N42: ='Run 15'!BA578 -> 0.28512286 | O42: ='Run 15'!BB578 -> 0.91933761 | P42: ='Run 15'!BC578 -> 0.1965812 | Q42: ='Run 15'!BD578 -> 0 | R42: ='Run 15'!BE578 -> 0 | U42: Angling | V42: 0.25994597 | W42: 0.85019646 | X42: 0.16852216 | Y42: 0 | Z42: 0 | AC42: Angling | AD42: 0.23852273 | AE42: 0.79136364 | AF42: 0.14464646 | AG42: 0 | AH42: 0 | AI42: 0.28512286 | AJ42: 0.91933761 | AK42: 0.1965812 | AL42: 0 | AM42: 0
T43: +30% Flow | U43: Day Use & Boating | V43: 0.35768664 | W43: 0.98968566 | X43: 0.38746998 | Y43: 0 | Z43: 0.0045841519 | AB43: +30% Flow | AC43: Day Use & Boating | AD43: 0.34647727 | AE43: 0.98090909 | AF43: 0.35151515 | AG43: 0 | AH43: 0.0084848485 | AI43: 0.37086004 | AJ43: 1 | AK43: 0.4297246 | AL43: 0 | AM43: 0
C44: RUN 16 % EXCEEDANCES | U44: Birding | V44: 0.30279961 | W44: 0.95849705 | X44: 0.22462344 | Y44: 0 | Z44: 0 | AC44: Birding | AD44: 0.28625 | AE44: 0.925 | AF44: 0.19555556 | AG44: 0 | AH44: 0 | AI44: 0.32224893 | AJ44: 0.99786325 | AK44: 0.25878443 | AL44: 0 | AM44: 0
D45: Total Run | I45: Wet Seasons | N45: Dry Seasons | U45: Waterfowl | V45: 0.28554764 | W45: 0.92264244 | X45: 0.1951539 | Y45: 0 | Z45: 0 | AC45: Waterfowl | AD45: 0.26659091 | AE45: 0.87590909 | AF45: 0.16929293 | AG45: 0 | AH45: 0 | AI45: 0.30782585 | AJ45: 0.9775641 | AK45: 0.22554606 | AL45: 0 | AM45: 0
D46: Delta-Wide | E46: Suisun | F46: Central Delta | G46: North Delta | H46: South Delta | I46: Delta-Wide | J46: Suisun | K46: Central Delta | L46: North Delta | M46: South Delta | N46: Delta-Wide | O46: Suisun | P46: Central Delta | Q46: North Delta | R46: South Delta | U46: Angling | V46: 0.15913556 | W46: 0.57637525 | X46: 0.053481773 | Y46: 0 | Z46: 0 | AC46: Angling | AD46: 0.12977273 | AE46: 0.46181818 | AF46: 0.050909091 | AG46: 0 | AH46: 0 | AI46: 0.19364316 | AJ46: 0.71100427 | AK46: 0.056505223 | AL46: 0 | AM46: 0
C47: Day Use & Boating | D47: ='Run 16'!AK527 -> 0.35768664 | E47: ='Run 16'!AL527 -> 0.98968566 | F47: ='Run 16'!AM527 -> 0.38746998 | G47: ='Run 16'!AN527 -> 0 | H47: ='Run 16'!AO527 -> 0.0045841519 | I47: ='Run 16'!AS527 -> 0.34647727 | J47: ='Run 16'!AT527 -> 0.98090909 | K47: ='Run 16'!AU527 -> 0.35151515 | L47: ='Run 16'!AV527 -> 0 | M47: ='Run 16'!AW527 -> 0.0084848485 | N47: ='Run 16'!BA527 -> 0.37086004 | O47: ='Run 16'!BB527 -> 1 | P47: ='Run 16'!BC527 -> 0.4297246 | Q47: ='Run 16'!BD527 -> 0 | R47: ='Run 16'!BE527 -> 0 | T47: -10% Flows | U47: Day Use & Boating | V47: 0.52897839 | W47: 0.9987721 | X47: 0.84173761 | Y47: 0.053045187 | Z47: 0.11591356 | AB47: -10% Flows | AC47: Day Use & Boating | AD47: 0.52613636 | AE47: 0.99772727 | AF47: 0.83393939 | AG47: 0.017575758 | AH47: 0.13818182 | AI47: 0.53231838 | AJ47: 1 | AK47: 0.85090218 | AL47: 0.094729345 | AM47: 0.08974359
C48: Birding | D48: ='Run 16'!AK544 -> 0.30279961 | E48: ='Run 16'!AL544 -> 0.95849705 | F48: ='Run 16'!AM544 -> 0.22462344 | G48: ='Run 16'!AN544 -> 0 | H48: ='Run 16'!AO544 -> 0 | I48: ='Run 16'!AS544 -> 0.28625 | J48: ='Run 16'!AT544 -> 0.925 | K48: ='Run 16'!AU544 -> 0.19555556 | L48: ='Run 16'!AV544 -> 0 | M48: ='Run 16'!AW544 -> 0 | N48: ='Run 16'!BA544 -> 0.32224893 | O48: ='Run 16'!BB544 -> 0.99786325 | P48: ='Run 16'!BC544 -> 0.25878443 | Q48: ='Run 16'!BD544 -> 0 | R48: ='Run 16'!BE544 -> 0 | U48: Birding | V48: 0.37604371 | W48: 0.99410609 | X48: 0.45339446 | Y48: 0 | Z48: 0 | AC48: Birding | AD48: 0.36738636 | AE48: 0.98909091 | AF48: 0.42707071 | AG48: 0 | AH48: 0 | AI48: 0.38621795 | AJ48: 1 | AK48: 0.48433048 | AL48: 0 | AM48: 0
C49: Waterfowl | D49: ='Run 16'!AK561 -> 0.28554764 | E49: ='Run 16'!AL561 -> 0.92264244 | F49: ='Run 16'!AM561 -> 0.1951539 | G49: ='Run 16'!AN561 -> 0 | H49: ='Run 16'!AO561 -> 0 | I49: ='Run 16'!AS561 -> 0.26659091 | J49: ='Run 16'!AT561 -> 0.87590909 | K49: ='Run 16'!AU561 -> 0.16929293 | L49: ='Run 16'!AV561 -> 0 | M49: ='Run 16'!AW561 -> 0 | N49: ='Run 16'!BA561 -> 0.30782585 | O49: ='Run 16'!BB561 -> 0.9775641 | P49: ='Run 16'!BC561 -> 0.22554606 | Q49: ='Run 16'!BD561 -> 0 | R49: ='Run 16'!BE561 -> 0 | U49: Waterfowl | V49: 0.33761051 | W49: 0.99165029 | X49: 0.318926 | Y49: 0 | Z49: 0 | AC49: Waterfowl | AD49: 0.33159091 | AE49: 0.98454545 | AF49: 0.30383838 | AG49: 0 | AH49: 0 | AI49: 0.34468483 | AJ49: 1 | AK49: 0.33665717 | AL49: 0 | AM49: 0
...

Sheet Run 15
B1: Suisun | J1: Central Delta | S1: North Delta | Y1: South Delta
A2: Date | B2: CHADBOURNE SLOUGH AT SUNRISE DUCK CLUB | C2: MONTEZUMA SLOUGH AT NATIONAL STEEL | D2: MONTEZUMA SLOUGH NEAR BELDENS LANDING | E2: SUISUN SLOUGH 300' SOUTH OF VOLANTI SLOUGH | F2: HONKER BAY | G2: SUISUN BAY AT VAN SICKLE ISLAND | H2: SUISUN BAY WEST REACH | I2: GRIZZLY BAY BUOY | J2: DUTCH SL BELOW JERSEY ISLAND | K2: FALSE RIVER NEAR OAKLEY | L2: OLD RIVER AT FRANKS TRACT | M2: PITTSBURG | N2: SACRAMENTO RIVER AT EMMATON | O2: SAN ANDREAS LANDING | P2: SAN JOAQUIN RIVER AT JERSEY POINT | Q2: SUISUN BAY AT CHANNEL MARKER 5 AT COLLINSVILLE | R2: BRANNAN MARINAS AT SAN JOAQUIN RIVER | S2: LIBERTY CUT AT FIVE POINTS | T2: CACHE SLOUGH ABOVE RYER ISLAND FERRY | U2: DELTA CROSS CHANNEL NEAR WALNUT GROVE | V2: SACRAMENTO RIVER DOWNSTREAM OF ISLETON | W2: COURTLAND AT SACRAMENTO RIVER | X2: VIERAS RESORT AT SACRAMENTO RIVER | Y2: GRANT LINE CANAL NEAR CLIFTON COURT FORE | Z2: LITTLE POTATO SLOUGH AT TERMINOUS | AA2: MIDDLE RIVER AT MILDRED ISLAND | AB2: OLD RIVER AT CLIFTON COURT | AC2: SAN JOAQUIN RIVER AT BRANDT BRIDGE | AD2: SAN JOAQUIN RIVER AT PRISONERS POINT | AE2: SAN JOAQUIN RIVER NEAR VERNALIS | AF2: SAN JOAQUIN RVER AT ROUGH AND READY ISLAND | AG2: VICTORIA CANAL BEFORE CLIFTON COURT FORE
A3: 44054 | B3: 15899.1 | C3: 10968.696 | D3: 13592.969 | E3: 15099.631 | F3: 16166.13 | G3: 14494.415 | H3: 34112.811 | I3: 17920.062 | J3: 1119.1519 | K3: 1820.7731 | L3: 334.39722 | M3: 13718.39 | N3: 3678.327 | O3: 462.36336 | P3: 2090.2879 | Q3: 11316.092 | R3: 731.357 | S3: 156.52555 | T3: 323.73683 | U3: 156.61155 | V3: 325.6662 | W3: 159.03711 | X3: 188.69112 | Y3: 319.83121 | Z3: 324.69912 | AA3: 315.48717 | AB3: 336.88674 | AC3: 422.06969 | AD3: 302.82665 | AE3: 521.87002 | AF3: 369.90787 | AG3: 286.13633
A4: 44055 | B4: 15708.115 | C4: 10516.738 | D4: 13803.551 | E4: 14909.273 | F4: 17038.926 | G4: 16435.544 | H4: 33613.145 | I4: 17840.264 | J4: 1201.4687 | K4: 1938.8663 | L4: 376.59269 | M4: 14506.483 | N4: 4180.2317 | O4: 603.78098 | P4: 2403.502 | Q4: 12304.192 | R4: 839.6368 | S4: 157.11955 | T4: 342.80275 | U4: 158.53607 | V4: 317.04367 | W4: 159.89819 | X4: 193.99036 | Y4: 319.55719 | Z4: 308.17162 | AA4: 320.69074 | AB4: 316.38315 | AC4: 429.26083 | AD4: 327.92953 | AE4: 522.89222 | AF4: 362.63006 | AG4: 285.14101
A5: 44056 | B5: 15344.253 | C5: 10659.41 | D5: 13918.228 | E5: 14991.807 | F5: 17408.482 | G5: 16804.671 | H5: 32270.143 | I5: 18268.105 | J5: 1233.4415 | K5: 2095.962 | L5: 484.72391 | M5: 14850.357 | N5: 4271.8672 | O5: 618.55281 | P5: 2657.5987 | Q5: 12751.776 | R5: 856.40217 | S5: 157.48799 | T5: 295.94561 | U5: 158.35481 | V5: 262.09231 | W5: 151.51947 | X5: 167.12924 | Y5: 328.27486 | Z5: 286.08761 | AA5: 316.58383 | AB5: 346.14846 | AC5: 437.81138 | AD5: 375.59073 | AE5: 587.1325 | AF5: 360.37968 | AG5: 335.6695
A6: 44057 | B6: 15028.47 | C6: 11600.363 | D6: 14077.664 | E6: 15180.733 | F6: 17505.036 | G6: 16929.433 | H6: 31322.411 | I6: 19157.381 | J6: 1278.4359 | K6: 2223.6015 | L6: 571.5682 | M6: 14957.817 | N6: 4345.6224 | O6: 611.54024 | P6: 2797.5714 | Q6: 12911.263 | R6: 867.75483 | S6: 157.55253 | T6: 280.2772 | U6: 145.28652 | V6: 263.75561 | W6: 136.35398 | X6: 170.19302 | Y6: 364.24248 | Z6: 250.17232 | AA6: 315.75888 | AB6: 387.45463 | AC6: 446.68634 | AD6: 433.39671 | AE6: 591.26947 | AF6: 358.06849 | AG6: 344.9071
A7: 44058 | B7: 14981.492 | C7: 12245.549 | D7: 14260.873 | E7: 15551.029 | F7: 17855.775 | G7: 17633.081 | H7: 31360.156 | I7: 19861.486 | J7: 1371.4148 | K7: 2429.6009 | L7: 653.62797 | M7: 15565.516 | N7: 4812.7326 | O7: 668.85512 | P7: 3043.6023 | Q7: 13554.567 | R7: 930.95251 | S7: 157.47487 | T7: 314.71059 | U7: 137.43603 | V7: 297.14334 | W7: 132.67305 | X7: 180.09856 | Y7: 384.10358 | Z7: 213.11127 | AA7: 316.85409 | AB7: 398.44038 | AC7: 452.57166 | AD7: 501.55646 | AE7: 560.60174 | AF7: 352.04274 | AG7: 344.64841
A8: 44059 | B8: 15086.931 | C8: 12809.974 | D8: 14449.579 | E8: 15876.806 | F8: 18297.633 | G8: 17923.356 | H8: 30991.51 | I8: 20590.71 | J8: 1480.3402 | K8: 2568.7327 | L8: 714.12102 | M8: 15868 | N8: 5054.4119 | O8: 712.05924 | P8: 3153.7243 | Q8: 13836.245 | R8: 977.99142 | S8: 157.53278 | T8: 355.95379 | U8: 133.594 | V8: 319.72958 | W8: 131.80037 | X8: 182.38788 | Y8: 394.04177 | Z8: 178.30566 | AA8: 316.68068 | AB8: 404.88387 | AC8: 457.93322 | AD8: 554.24667 | AE8: 567.06967 | AF8: 346.41605 | AG8: 341.2175
A9: 44060 | B9: 15214.732 | C9: 13335.048 | D9: 14605.881 | E9: 16111.114 | F9: 18262.912 | G9: 17556.775 | H9: 30040.763 | I9: 21214.008 | J9: 1563.3028 | K9: 2564.7196 | L9: 747.18351 | M9: 15497.589 | N9: 4943 | O9: 699.74655 | P9: 3148.2558 | Q9: 13497.635 | R9: 970.8192 | S9: 157.8494 | T9: 359.35346 | U9: 135.21124 | V9: 323.98142 | W9: 135.56626 | X9: 181.67215 | Y9: 404.7132 | Z9: 165.71542 | AA9: 318.52756 | AB9: 416.28126 | AC9: 465.63081 | AD9: 578.71661 | AE9: 553.35759 | AF9: 346.13955 | AG9: 335.52005
A10: 44061 | B10: 15447.22 | C10: 13718.645 | D10: 14844.29 | E10: 16443.433 | F10: 18085.665 | G10: 17348.906 | H10: 29629.891 | I10: 21356.375 | J10: 1661.3233 | K10: 2571.6479 | L10: 771.09015 | M10: 15284.421 | N10: 4929.7036 | O10: 695.1591 | P10: 3130.5152 | Q10: 13295.262 | R10: 974.80368 | S10: 158.44211 | T10: 355.12284 | U10: 139.29232 | V10: 327.17757 | W10: 138.33592 | X10: 182.89294 | Y10: 420.64542 | Z10: 157.71424 | AA10: 324.88844 | AB10: 426.51211 | AC10: 473.01482 | AD10: 597.67918 | AE10: 521.47268 | AF10: 348.19851 | AG10: 332.10736
A11: 44062 | B11: 15798.987 | C11: 13960.664 | D11: 15166.876 | E11: 16855.71 | F11: 18079.288 | G11: 17537.77 | H11: 29695.668 | I11: 21385.707 | J11: 1771.1356 | K11: 2633.4693 | L11: 812.20726 | M11: 15471.575 | N11: 5092.8236 | O11: 730.35182 | P11: 3168.5017 | Q11: 13474.519 | R11: 1020.0887 | S11: 159.74252 | T11: 380.10549 | U11: 137.31252 | V11: 353.08361 | W11: 139.41971 | X11: 195.59604 | Y11: 437.28009 | Z11: 149.28073 | AA11: 333.12757 | AB11: 458.23226 | AC11: 477.92996 | AD11: 630.14645 | AE11: 553.0779 | AF11: 346.38141 | AG11: 334.27134
A12: 44063 | B12: 16175.768 | C12: 14148.088 | D12: 15509.436 | E12: 17241.839 | F12: 18141.936 | G12: 17671.703 | H12: 29603.728 | I12: 21470.823 | J12: 1874.9318 | K12: 2651.1274 | L12: 856.01824 | M12: 15706.373 | N12: 5231.741 | O12: 761.23902 | P12: 3200.3281 | Q12: 13628.875 | R12: 1068.7137 | S12: 161.7001 | T12: 384.76756 | U12: 137.69593 | V12: 340.78345 | W12: 139.079 | X12: 185.82869 | Y12: 465.88037 | Z12: 143.13208 | AA12: 342.82414 | AB12: 481.25937 | AC12: 480.41754 | AD12: 661.33798 | AE12: 517.11356 | AF12: 344.05501 | AG12: 343.2359
A13: 44064 | B13: 16535.328 | C13: 14217.303 | D13: 15884.53 | E13: 17583.383 | F13: 18236.455 | G13: 17782.581 | H13: 29516.697 | I13: 21547.483 | J13: 1952.8898 | K13: 2735.9371 | L13: 911.54874 | M13: 15905.153 | N13: 5281.8318 | O13: 765.61375 | P13: 3308.1354 | Q13: 13796.345 | R13: 1099.2707 | S13: 163.79944 | T13: 359.84806 | U13: 138.577 | V13: 311.65183 | W13: 139.65935 | X13: 171.48414 | Y13: 500.36313 | Z13: 141.54884 | AA13: 355.74946 | AB13: 505.67744 | AC13: 482.49204 | AD13: 696.93683 | AE13: 558.83804 | AF13: 341.56379 | AG13: 358.96214
A14: 44065 | B14: 16744.704 | C14: 14320.403 | D14: 16018.899 | E14: 17647.352 | F14: 17998.344 | G14: 17437.711 | H14: 28959.896 | I14: 21566.885 | J14: 2005.9053 | K14: 2730.8404 | L14: 931.06995 | M14: 15530.671 | N14: 4687.9909 | O14: 731.75073 | P14: 3295.6767 | Q14: 13467.843 | R14: 1086.8217 | S14: 165.5242 | T14: 287.56234 | U14: 141.00233 | V14: 251.34713 | W14: 141.13079 | X14: 157.92112 | Y14: 526.11499 | Z14: 142.33038 | AA14: 370.34434 | AB14: 542.46992 | AC14: 484.11681 | AD14: 709.5458 | AE14: 498.43761 | AF14: 341.19612 | AG14: 381.35518
... A511: 44562 | B511: 7364.3016 | C511: 432.95499 | D511: 4232.6148 | E511: 5802.8582 | F511: 1130.2778 | G511: 880.93638 | H511: 9813.2277 | I511: 3862.3893 | J511: 830.18394 | K511: 830.53188 | L511: 408.4949 | M511: 709.55105 | N511: 190.36536 | O511: 297.35075 | P511: 454.36102 | Q511: 399.4987 | R511: 367.09243 | S511: 508.39622 | T511: 176.56455 | U511: 297.23912 | V511: 127.44862 | W511: 128.79564 | X511: 127.52446 | Y511: 636.60301 | Z511: 184.94764 | AA511: 690.89458 | AB511: 738.52436 | AC511: 475.4895 | AD511: 387.21735 | AE511: 302.70968 | AF511: 496.67089 | AG511: 800.29691
A512: TOTAL EXCEEDANCES | B512: =COUNTIF(B$3:B$511,">=1000") -> 509 | C512: =COUNTIF(C$3:C$511,">=1000") -> 505 | D512: =COUNTIF(D$3:D$511,">=1000") -> 509 | E512: =COUNTIF(E$3:E$511,">=1000") -> 509 | F512: =COUNTIF(F$3:F$511,">=1000") -> 509 | G512: =COUNTIF(G$3:G$511,">=1000") -> 505 | H512: =COUNTIF(H$3:H$511,">=1000") -> 509 | I512: =COUNTIF(I$3:I$511,">=1000") -> 509 | ... AG512: =COUNTIF(AG$3:AG$511,">=1000") -> 0
A513: WET 1 | B513: =COUNTIF(B$54:B$235,">=1000") -> 182 | C513: =COUNTIF(C$54:C$235,">=1000") -> 182 | D513: =COUNTIF(D$54:D$235,">=1000") -> 182 | E513: =COUNTIF(E$54:E$235,">=1000") -> 182 | F513: =COUNTIF(F$54:F$235,">=1000") -> 182 | G513: =COUNTIF(G$54:G$235,">=1000") -> 182 | H513: =COUNTIF(H$54:H$235,">=1000") -> 182 | I513: =COUNTIF(I$54:I$235,">=1000") -> 182 | ... AG513: =COUNTIF(AG$54:AG$235,">=1000") -> 0 | AH513: OCT 1, 2020 - MAR 31, 2021
A514: WET 2 | B514: =COUNTIF(B$419:B$511,">=1000") -> 93 | C514: =COUNTIF(C$419:C$511,">=1000") -> 89 | D514: =COUNTIF(D$419:D$511,">=1000") -> 93 | E514: =COUNTIF(E$419:E$511,">=1000") -> 93 | F514: =COUNTIF(F$419:F$511,">=1000") -> 93 | G514: =COUNTIF(G$419:G$511,">=1000") -> 89 | H514: =COUNTIF(H$419:H$511,">=1000") -> 93 | I514: =COUNTIF(I$419:I$511,">=1000") -> 93 | ... AG514: =COUNTIF(AG$419:AG$511,">=1000") -> 0 | AH514: OCT 1, 2021 - JAN 1, 2022
A515: DRY 1 | B515: =COUNTIF(B$3:B$53,">=1000") -> 51 | C515: =COUNTIF(C$3:C$53,">=1000") -> 51 | D515: =COUNTIF(D$3:D$53,">=1000") -> 51 | E515: =COUNTIF(E$3:E$53,">=1000") -> 51 | F515: =COUNTIF(F$3:F$53,">=1000") -> 51 | G515: =COUNTIF(G$3:G$53,">=1000") -> 51 | H515: =COUNTIF(H$3:H$53,">=1000") -> 51 | I515: =COUNTIF(I$3:I$53,">=1000") -> 51 | ... AG515: =COUNTIF(AG$3:AG$53,">=1000") -> 0 | AH515: AUG 11, 2020 - SEP 30, 2020
A516: DRY 2 | B516: =COUNTIF(B$236:B$418,">=1000") -> 183 | C516: =COUNTIF(C$236:C$418,">=1000") -> 183 | D516: =COUNTIF(D$236:D$418,">=1000") -> 183 | E516: =COUNTIF(E$236:E$418,">=1000") -> 183 | F516: =COUNTIF(F$236:F$418,">=1000") -> 183 | G516: =COUNTIF(G$236:G$418,">=1000") -> 183 | H516: =COUNTIF(H$236:H$418,">=1000") -> 183 | I516: =COUNTIF(I$236:I$418,">=1000") -> 183 | ... AG516: =COUNTIF(AG$236:AG$418,">=1000") -> 0 | AH516: APR 1, 2021 - SEP 30, 2021
A517: ALL WET | B517: =SUM(B$513,B$514) -> 275 | C517: =SUM(C$513,C$514) -> 271 | D517: =SUM(D$513,D$514) -> 275 | E517: =SUM(E$513,E$514) -> 275 | F517: =SUM(F$513,F$514) -> 275 | G517: =SUM(G$513,G$514) -> 271 | H517: =SUM(H$513,H$514) -> 275 | I517: =SUM(I$513,I$514) -> 275 | ... AG517: =SUM(AG$513,AG$514) -> 0
A518: ALL DRY | B518: =SUM(B$515,B$516) -> 234 | C518: =SUM(C$515,C$516) -> 234 | D518: =SUM(D$515,D$516) -> 234 | E518: =SUM(E$515,E$516) -> 234 | F518: =SUM(F$515,F$516) -> 234 | G518: =SUM(G$515,G$516) -> 234 | H518: =SUM(H$515,H$516) -> 234 | I518: =SUM(I$515,I$516) -> 234 | ... AG518: =SUM(AG$515,AG$516) -> 0
D521: Day Use & Boating | F521: THRESHOLD: 1,000 MICROSIEMENS/CM (EC) | S521: SP DAY USE & BOATING | AA521: SP DAY USE & BOATING | AE521: SP DAY USE & BOATING | AI521: SP DAY USE & BOATING | AQ521: SP DAY USE & BOATING | AY521: SP DAY USE & BOATING
F522: WET SEASON | S522: TOTAL RUN | AA522: WET SEASONS | AE522: DRY SEASONS | AI522: TOTAL RUN | AK522: Delta-Wide | AL522: Suisun | AM522: Central Delta | AN522: North Delta | AO522: South Delta | AQ522: WET SEASONS | AS522: Delta-Wide | AT522: Suisun | AU522: Central Delta | AV522: North Delta | AW522: South Delta | AY522: DRY SEASONS | BA522: Delta-Wide | BB522: Suisun | BC522: Central Delta | BD522: North Delta | BE522: South Delta
F523: OCTOBER 1 - MARCH 31 | M523: DRY SEASON | S523: Total points | U523: =COUNTIF(B2:AG2,"<>") -> 32 | AA523: Total points | AC523: =COUNTIF(B2:AG2,"<>") -> 32 | AE523: Total points | AG523: =COUNTIF(B2:AG2,"<>") -> 32 | AI523: Total points | AK523: =COUNTIF($B$2:$AG$2,"<>") -> 32 | AL523: =COUNTIF($B$2:$I$2,"<>") -> 8 | AM523: =COUNTIF($J$2:$R$2,"<>") -> 9 | AN523: =COUNTIF($S$2:$X$2,"<>") -> 6 | AO523: =COUNTIF($Y$2:$AG$2,"<>") -> 9 | AQ523: Total points | AS523: =COUNTIF($B$2:$AG$2,"<>") -> 32 | AT523: =COUNTIF($B$2:$I$2,"<>") -> 8 | AU523: =COUNTIF($J$2:$R$2,"<>") -> 9 | AV523: =COUNTIF($S$2:$X$2,"<>") -> 6 | AW523: =COUNTIF($Y$2:$AG$2,"<>") -> 9 | AY523: Total points | BA523: =COUNTIF($B$2:$AG$2,"<>") -> 32 | BB523: =COUNTIF($B$2:$I$2,"<>") -> 8 | BC523: =COUNTIF($J$2:$R$2,"<>") -> 9 | BD523: =COUNTIF($S$2:$X$2,"<>") -> 6 | BE523: =COUNTIF($Y$2:$AG$2,"<>") -> 9
F524: WET SEASON 1 | H524: 10/1/20 - 3/31/21 | J524: =COUNTIF($B$54:$B$235,"<>") -> 182 | M524: APRIL 1 - SEPTEMBER 30 | S524: Days in run | U524: =COUNTIF($A$3:$A$511,"<>") -> 509 | AA524: Days in run | AC524: =SUM($J$524:$J$525) -> 275 | AE524: Days in run | AG524: =SUM($Q$525:$Q$526) -> 234 | AI524: Days in run | AK524: =COUNTIF($A$3:$A$511,"<>") -> 509 | AL524: =COUNTIF($A$3:$A$511,"<>") -> 509 | AM524: =COUNTIF($A$3:$A$511,"<>") -> 509 | AN524: =COUNTIF($A$3:$A$511,"<>") -> 509 | AO524: =COUNTIF($A$3:$A$511,"<>") -> 509 | AQ524: Days in run | AS524: =SUM($J$524:$J$525) -> 275 | AT524: =SUM($J$524:$J$525) -> 275 | AU524: =SUM($J$524:$J$525) -> 275 | AV524: =SUM($J$524:$J$525) -> 275 | AW524: =SUM($J$524:$J$525) -> 275 | AY524: Days in run | BA524: =SUM($Q$525:$Q$526) -> 234 | BB524: =SUM($Q$525:$Q$526) -> 234 | BC524: =SUM($Q$525:$Q$526) -> 234 | BD524: =SUM($Q$525:$Q$526) -> 234 | BE524: =SUM($Q$525:$Q$526) -> 234
F525: WET SEASON 2 | H525: 10/1/21 - 1/1/22 | J525: =COUNTIF($B$419:$B$511,"<>") -> 93 | M525: DRY SEASON 1 | O525: 8/11/20 - 9/30/20 | Q525: =COUNTIF($B$3:$B$53,"<>") -> 51 | S525: Total measurements | U525: =U524*U523 -> 16288 | V525: DENOMINATOR FOR EXCEEDANCE % | AA525: Total measurements | AC525: =AC524*AC523 -> 8800 | AE525: Total measurements | AG525: =AG523*AG524 -> 7488 | AI525: Total measurements | AK525: =AK524*AK523 -> 16288 | AL525: =AL524*AL523 -> 4072 | AM525: =AM524*AM523 -> 4581 | AN525: =AN524*AN523 -> 3054 | AO525: =AO524*AO523 -> 4581 | AQ525: Total measurements | AS525: =AS524*AS523 -> 8800 | AT525: =AT524*AT523 -> 2200 | AU525: =AU524*AU523 -> 2475 | AV525: =AV524*AV523 -> 1650 | AW525: =AW524*AW523 -> 2475 | AY525: Total measurements | BA525: =BA524*BA523 -> 7488 | BB525: =BB524*BB523 -> 1872 | BC525: =BC524*BC523 -> 2106 | BD525: =BD524*BD523 -> 1404 | BE525: =BE524*BE523 -> 2106
M526: DRY SEASON 2 | O526: 4/1/21 - 9/30/21 | Q526: =COUNTIF($B$236:$B$418,"<>") -> 183 | S526: Measurements >= 1,000 | U526: =SUM(B512:AG512) -> 7515 | V526: NUMERATOR FOR EXCEEDANCE % | AA526: Measurements >= 1,000 | AC526: =SUM($B$517:$AG$517) -> 3904 | AE526: Measurements >= 1,000 | AG526: =SUM($B$518:$AG$518) -> 3611 | AI526: Measurements >= 1,000 | AK526: =SUM(B512:AG512) -> 7515 | AL526: =SUM(B512:I512) -> 4064 | AM526: =SUM(J512:R512) -> 3278 | AN526: =SUM(S512:X512) -> 65 | AO526: =SUM(Y512:AG512) -> 108 | AQ526: Measurements >= 1,000 | AS526: =SUM(B517:AG517) -> 3904 | AT526: =SUM(B517:I517) -> 2192 | AU526: =SUM(J517:R517) -> 1644 | AV526: =SUM(S517:X517) -> 3 | AW526: =SUM(Y517:AG517) -> 65 | AY526: Measurements >= 1,000 | BA526: =SUM($B518:$AG518) -> 3611 | BB526: =SUM(B518:I518) -> 1872 | BC526: =SUM(J518:R518) -> 1634 | BD526: =SUM(S518:X518) -> 62 | BE526: =SUM(Y518:AG518) -> 43
S527: % Total Run Exceedances | U527: =$U526/$U525 -> 0.46138261 | AA527: % WET Exceedances | AC527: =AC526/AC525 -> 0.44363636 | AE527: % DRY Exceedances | AG527: =AG526/AG525 -> 0.48223825 | AI527: % Total Run Exceedances | AK527: =AK526/AK525 -> 0.46138261 | AL527: =AL526/AL525 -> 0.99803536 | AM527: =AM526/AM525 -> 0.71556429 | AN527: =AN526/AN525 -> 0.021283563 | AO527: =AO526/AO525 -> 0.023575639 | AQ527: % WET Exceedances | AS527: =AS526/AS525 -> 0.44363636 | AT527: =AT526/AT525 -> 0.99636364 | AU527: =AU526/AU525 -> 0.66424242 | AV527: =AV526/AV525 -> 0.0018181818 | AW527: =AW526/AW525 -> 0.026262626 | AY527: % DRY Exceedances | BA527: =BA526/BA525 -> 0.48223825 | BB527: =BB526/BB525 -> 1 | BC527: =BC526/BC525 -> 0.77587844 | BD527: =BD526/BD525 -> 0.044159544 | BE527: =BE526/BE525 -> 0.020417854
A529: TOTAL EXCEEDANCES | B529: =COUNTIF(B$3:B$511,">=2640") -> 509 | C529: =COUNTIF(C$3:C$511,">=2640") -> 488 | D529: =COUNTIF(D$3:D$511,">=2640") -> 509 | E529: =COUNTIF(E$3:E$511,">=2640") -> 509 | F529: =COUNTIF(F$3:F$511,">=2640") -> 504 | G529: =COUNTIF(G$3:G$511,">=2640") -> 502 | H529: =COUNTIF(H$3:H$511,">=2640") -> 509 | I529: =COUNTIF(I$3:I$511,">=2640") -> 509 | ... AG529: =COUNTIF(AG$3:AG$511,">=2640") -> 0
A530: WET 1 | B530: =COUNTIF(B$54:B$235,">=2640") -> 182 | C530: =COUNTIF(C$54:C$235,">=2640") -> 182 | D530: =COUNTIF(D$54:D$235,">=2640") -> 182 | E530: =COUNTIF(E$54:E$235,">=2640") -> 182 | F530: =COUNTIF(F$54:F$235,">=2640") -> 182 | G530: =COUNTIF(G$54:G$235,">=2640") -> 182 | H530: =COUNTIF(H$54:H$235,">=2640") -> 182 | I530: =COUNTIF(I$54:I$235,">=2640") -> 182 | ... AG530: =COUNTIF(AG$54:AG$235,">=2640") -> 0 | AH530: OCT 1, 2020 - MAR 31, 2021
A531: WET 2 | B531: =COUNTIF(B$419:B$511,">=2640") -> 93 | C531: =COUNTIF(C$419:C$511,">=2640") -> 72 | D531: =COUNTIF(D$419:D$511,">=2640") -> 93 | E531: =COUNTIF(E$419:E$511,">=2640") -> 93 | F531: =COUNTIF(F$419:F$511,">=2640") -> 88 | G531: =COUNTIF(G$419:G$511,">=2640") -> 86 | H531: =COUNTIF(H$419:H$511,">=2640") -> 93 | I531: =COUNTIF(I$419:I$511,">=2640") -> 93 | ... AG531: =COUNTIF(AG$419:AG$511,">=2640") -> 0 | AH531: OCT 1, 2021 - JAN 1, 2022
A532: DRY 1 | B532: =COUNTIF(B$3:B$53,">=2640") -> 51 | C532: =COUNTIF(C$3:C$53,">=2640") -> 51 | D532: =COUNTIF(D$3:D$53,">=2640") -> 51 | E532: =COUNTIF(E$3:E$53,">=2640") -> 51 | F532: =COUNTIF(F$3:F$53,">=2640") -> 51 | G532: =COUNTIF(G$3:G$53,">=2640") -> 51 | H532: =COUNTIF(H$3:H$53,">=2640") -> 51 | I532: =COUNTIF(I$3:I$53,">=2640") -> 51 | ... AG532: =COUNTIF(AG$3:AG$53,">=2640") -> 0 | AH532: AUG 11, 2020 - SEP 30, 2020
A533: DRY 2 | B533: =COUNTIF(B$236:B$418,">=2640") -> 183 | C533: =COUNTIF(C$236:C$418,">=2640") -> 183 | D533: =COUNTIF(D$236:D$418,">=2640") -> 183 | E533: =COUNTIF(E$236:E$418,">=2640") -> 183 | F533: =COUNTIF(F$236:F$418,">=2640") -> 183 | G533: =COUNTIF(G$236:G$418,">=2640") -> 183 | H533: =COUNTIF(H$236:H$418,">=2640") -> 183 | I533: =COUNTIF(I$236:I$418,">=2640") -> 183 | ... AG533: =COUNTIF(AG$236:AG$418,">=2640") -> 0 | AH533: APR 1, 2021 - SEP 30, 2021
A534: ALL WET | B534: =SUM(B530,B531) -> 275 | C534: =SUM(C530,C531) -> 254 | D534: =SUM(D530,D531) -> 275 | E534: =SUM(E530,E531) -> 275 | F534: =SUM(F530,F531) -> 270 | G534: =SUM(G530,G531) -> 268 | H534: =SUM(H530,H531) -> 275 | I534: =SUM(I530,I531) -> 275 | ... AG534: =SUM(AG530,AG531) -> 0
A535: ALL DRY | B535: =SUM(B532,B533) -> 234 | C535: =SUM(C532,C533) -> 234 | D535: =SUM(D532,D533) -> 234 | E535: =SUM(E532,E533) -> 234 | F535: =SUM(F532,F533) -> 234 | G535: =SUM(G532,G533) -> 234 | H535: =SUM(H532,H533) -> 234 | I535: =SUM(I532,I533) -> 234 | ... AG535: =SUM(AG532,AG533) -> 0
D538: Birding | F538: THRESHOLD: 2,640 MICROSIEMENS/CM (EC) | S538: BIRDING | AA538: BIRDING | AE538: BIRDING | AI538: BIRDING | AQ538: BIRDING | AY538: BIRDING
F539: WET SEASON | S539: TOTAL RUN | AA539: WET SEASONS | AE539: DRY SEASONS | AI539: TOTAL RUN | AK539: Delta-Wide | AL539: Suisun | AM539: Central Delta | AN539: North Delta | AO539: South Delta | AQ539: WET SEASONS | AS539: Delta-Wide | AT539: Suisun | AU539: Central Delta | AV539: North Delta | AW539: South Delta | AY539: DRY SEASONS | BA539: Delta-Wide | BB539: Suisun | BC539: Central Delta | BD539: North Delta | BE539: South Delta
F540: OCTOBER 1 - MARCH 31 | M540: DRY SEASON | S540: Total points | U540: =COUNTIF(B18:AG18,"<>") -> 32 | AA540: Total points | AC540: =COUNTIF(B18:AG18,"<>") -> 32 | AE540: Total points | AG540: =COUNTIF(B18:AG18,"<>") -> 32 | AI540: Total points | AK540: =COUNTIF($B$2:$AG$2,"<>") -> 32 | AL540: =COUNTIF($B$2:$I$2,"<>") -> 8 | AM540: =COUNTIF($J$2:$R$2,"<>") -> 9 | AN540: =COUNTIF($S$2:$X$2,"<>") -> 6 | AO540: =COUNTIF($Y$2:$AG$2,"<>") -> 9 | AQ540: Total points | AS540: =COUNTIF($B$2:$AG$2,"<>") -> 32 | AT540: =COUNTIF($B$2:$I$2,"<>") -> 8 | AU540: =COUNTIF($J$2:$R$2,"<>") -> 9 | AV540: =COUNTIF($S$2:$X$2,"<>") -> 6 | AW540: =COUNTIF($Y$2:$AG$2,"<>") -> 9 | AY540: Total points | BA540: =COUNTIF($B$2:$AG$2,"<>") -> 32 | BB540: =COUNTIF($B$2:$I$2,"<>") -> 8 | BC540: =COUNTIF($J$2:$R$2,"<>") -> 9 | BD540: =COUNTIF($S$2:$X$2,"<>") -> 6 | BE540: =COUNTIF($Y$2:$AG$2,"<>") -> 9
F541: WET SEASON 1 | H541: 10/1/20 - 3/31/21 | J541: =COUNTIF($B$54:$B$235,"<>") -> 182 | M541: APRIL 1 - SEPTEMBER 30 | S541: Days in run | U541: =COUNTIF($A$3:$A$511,"<>") -> 509 | AA541: Days in run | AC541: =SUM($J$524:$J$525) -> 275 | AE541: Days in run | AG541: =SUM($Q$525:$Q$526) -> 234 | AI541: Days in run | AK541: =COUNTIF($A$3:$A$511,"<>") -> 509 | AL541: =COUNTIF($A$3:$A$511,"<>") -> 509 | AM541: =COUNTIF($A$3:$A$511,"<>") -> 509 | AN541: =COUNTIF($A$3:$A$511,"<>") -> 509 | AO541: =COUNTIF($A$3:$A$511,"<>") -> 509 | AQ541: Days in run | AS541: =SUM($J$524:$J$525) -> 275 | AT541: =SUM($J$524:$J$525) -> 275 | AU541: =SUM($J$524:$J$525) -> 275 | AV541: =SUM($J$524:$J$525) -> 275 | AW541: =SUM($J$524:$J$525) -> 275 | AY541: Days in run | BA541: =SUM($Q$525:$Q$526) -> 234 | BB541: =SUM($Q$525:$Q$526) -> 234 | BC541: =SUM($Q$525:$Q$526) -> 234 | BD541: =SUM($Q$525:$Q$526) -> 234 | BE541: =SUM($Q$525:$Q$526) -> 234
...

Sheet Run 16
B1: Suisun | J1: Central Delta | S1: North Delta | Y1: South Delta
A2: Date | B2: CHADBOURNE SLOUGH AT SUNRISE DUCK CLUB | C2: MONTEZUMA SLOUGH AT NATIONAL STEEL | D2: MONTEZUMA SLOUGH NEAR BELDENS LANDING | E2: SUISUN SLOUGH 300' SOUTH OF VOLANTI SLOUGH | F2: HONKER BAY | G2: SUISUN BAY AT VAN SICKLE ISLAND | H2: SUISUN BAY WEST REACH | I2: GRIZZLY BAY BUOY | J2: DUTCH SL BELOW JERSEY ISLAND | K2: FALSE RIVER NEAR OAKLEY | L2: OLD RIVER AT FRANKS TRACT | M2: PITTSBURG | N2: SACRAMENTO RIVER AT EMMATON | O2: SAN ANDREAS LANDING | P2: SAN JOAQUIN RIVER AT JERSEY POINT | Q2: SUISUN BAY AT CHANNEL MARKER 5 AT COLLINSVILLE | R2: BRANNAN MARINAS AT SAN JOAQUIN RIVER | S2: LIBERTY CUT AT FIVE POINTS | T2: CACHE SLOUGH ABOVE RYER ISLAND FERRY | U2: DELTA CROSS CHANNEL NEAR WALNUT GROVE | V2: SACRAMENTO RIVER DOWNSTREAM OF ISLETON | W2: COURTLAND AT SACRAMENTO RIVER | X2: VIERAS RESORT AT SACRAMENTO RIVER | Y2: GRANT LINE CANAL NEAR CLIFTON COURT FORE | Z2: LITTLE POTATO SLOUGH AT TERMINOUS | AA2: MIDDLE RIVER AT MILDRED ISLAND | AB2: OLD RIVER AT CLIFTON COURT | AC2: SAN JOAQUIN RIVER AT BRANDT BRIDGE | AD2: SAN JOAQUIN RIVER AT PRISONERS POINT | AE2: SAN JOAQUIN RIVER NEAR VERNALIS | AF2: SAN JOAQUIN RVER AT ROUGH AND READY ISLAND | AG2: VICTORIA CANAL BEFORE CLIFTON COURT FORE
A3: 44054 | B3: 15899.115 | C3: 10966.803 | D3: 13592.777 | E3: 15099.82 | F3: 16164.775 | G3: 14490.316 | H3: 34111.724 | I3: 17920.188 | J3: 1119.1522 | K3: 1819.3014 | L3: 334.51777 | M3: 13714.741 | N3: 3669.5726 | O3: 461.62282 | P3: 2088.4199 | Q3: 11310.359 | R3: 730.79448 | S3: 156.52519 | T3: 321.01941 | U3: 156.71875 | V3: 315.56616 | W3: 159.40387 | X3: 182.18285 | Y3: 319.84797 | Z3: 324.96045 | AA3: 315.4881 | AB3: 336.87608 | AC3: 422.08469 | AD3: 302.81018 | AE3: 521.86996 | AF3: 369.8625 | AG3: 286.1282
A4: 44055 | B4: 15708.099 | C4: 10493.312 | D4: 13800.773 | E4: 14910.954 | F4: 16991.558 | G4: 16321.618 | H4: 33498.072 | I4: 17840.271 | J4: 1199.2372 | K4: 1917.3044 | L4: 375.63619 | M4: 14395.225 | N4: 4018.7209 | O4: 589.07273 | P4: 2369.1605 | Q4: 12182.168 | R4: 827.21222 | S4: 157.1197 | T4: 320.74375 | U4: 158.0329 | V4: 276.55762 | W4: 159.62759 | X4: 172.43258 | Y4: 319.56646 | Z4: 304.06588 | AA4: 320.52824 | AB4: 316.39398 | AC4: 429.0938 | AD4: 325.64339 | AE4: 522.89191 | AF4: 362.30112 | AG4: 285.30623
A5: 44056 | B5: 15345.056 | C5: 10710.192 | D5: 13910.211 | E5: 14989.332 | F5: 17186.164 | G5: 16445.995 | H5: 31952.837 | I5: 18251.29 | J5: 1224.823 | K5: 2025.6898 | L5: 474.04443 | M5: 14503.693 | N5: 3839.5761 | O5: 569.78276 | P5: 2553.4229 | Q5: 12355.655 | R5: 817.20208 | S5: 157.48226 | T5: 259.35402 | U5: 154.22898 | V5: 215.3993 | W5: 147.61168 | X5: 158.40168 | Y5: 328.31307 | Z5: 265.22965 | AA5: 315.96794 | AB5: 346.27251 | AC5: 437.51966 | AD5: 365.43801 | AE5: 587.13156 | AF5: 359.75252 | AG5: 335.77657
A6: 44057 | B6: 15028.894 | C6: 11696.435 | D6: 14057.565 | E6: 15163.452 | F6: 17041.61 | G6: 16278.835 | H6: 30831.81 | I6: 19053.876 | J6: 1258.4432 | K6: 2090.3523 | L6: 541.97363 | M6: 14326.531 | N6: 3685.2692 | O6: 536.81318 | P6: 2614.2158 | Q6: 12216.481 | R6: 799.1703 | S6: 157.54185 | T6: 234.117 | U6: 137.65234 | V6: 210.13542 | W6: 136.29202 | X6: 159.48267 | Y6: 364.24305 | Z6: 219.35278 | AA6: 315.12337 | AB6: 387.37394 | AC6: 446.20835 | AD6: 410.56563 | AE6: 591.26931 | AF6: 357.29884 | AG6: 344.6806
A7: 44058 | B7: 14975.611 | C7: 12230.758 | D7: 14215.87 | E7: 15504.301 | F7: 17126.579 | G7: 16699.074 | H7: 30695.03 | I7: 19618.576 | J7: 1330.676 | K7: 2212.8271 | L7: 603.07999 | M7: 14645.559 | N7: 3925.3673 | O7: 574.2812 | P7: 2759.2152 | Q7: 12568.487 | R7: 834.77617 | S7: 157.45317 | T7: 244.56517 | U7: 132.19321 | V7: 216.71218 | W7: 131.48471 | X7: 149.52708 | Y7: 383.84998 | Z7: 182.99311 | AA7: 316.46509 | AB7: 398.00162 | AC7: 452.32036 | AD7: 462.47149 | AE7: 560.60182 | AF7: 351.14828 | AG7: 344.10661
A8: 44059 | B8: 15065.139 | C8: 12631.565 | D8: 14367.634 | E8: 15786.753 | F8: 17308.719 | G8: 16727.34 | H8: 30170.542 | I8: 20135.783 | J8: 1411.7524 | K8: 2264.8686 | L8: 644.73431 | M8: 14666.301 | N8: 3986.709 | O8: 591.3122 | P8: 2763.3626 | Q8: 12568.466 | R8: 851.87313 | S8: 157.45622 | T8: 259.47428 | U8: 132.02729 | V8: 225.10291 | W8: 133.44815 | X8: 147.63105 | Y8: 393.47069 | Z8: 164.15372 | AA8: 316.59057 | AB8: 403.90824 | AC8: 457.93752 | AD8: 500.07821 | AE8: 567.06938 | AF8: 345.40316 | AG8: 340.5803
A9: 44060 | B9: 15172.836 | C9: 12943.233 | D9: 14484.894 | E9: 15981.191 | F9: 17022.572 | G9: 16104.613 | H9: 29040.028 | I9: 20508.307 | J9: 1464.0857 | K9: 2191.2319 | L9: 658.15976 | M9: 14041.588 | N9: 3779.6482 | O9: 563.04015 | P9: 2671.5073 | Q9: 11978.55 | R9: 819.7411 | S9: 157.65001 | T9: 250.81877 | U9: 135.17715 | V9: 223.52458 | W9: 140.656 | X9: 145.0292 | Y9: 403.54922 | Z9: 155.58672 | AA9: 318.43547 | AB9: 413.99277 | AC9: 465.16644 | AD9: 511.34745 | AE9: 553.35812 | AF9: 344.96521 | AG9: 334.9566
A10: 44061 | B10: 15377.21 | C10: 13102.938 | D10: 14669.206 | E10: 16244.524 | F10: 16610.843 | G10: 15654.192 | H10: 28451.699 | I10: 20442.623 | J10: 1517.8549 | K10: 2128.3722 | L10: 662.17942 | M10: 13596.247 | N10: 3649.7626 | O10: 543.91789 | P10: 2571.7146 | Q10: 11550.299 | R10: 798.11136 | S10: 157.98044 | T10: 239.93894 | U10: 138.47115 | V10: 219.0079 | W10: 138.31875 | X10: 147.34228 | Y10: 418.24977 | Z10: 145.57381 | AA10: 323.99753 | AB10: 422.8603 | AC10: 472.01139 | AD10: 516.31008 | AE10: 521.4727 | AF10: 346.7649 | AG10: 331.46305
A11: 44062 | B11: 15679.514 | C11: 13104.213 | D11: 14923.231 | E11: 16559.186 | F11: 16368.321 | G11: 15617.907 | H11: 28351.448 | I11: 20288.836 | J11: 1578.7909 | K11: 2105.6485 | L11: 677.35855 | M11: 13559.721 | N11: 3656.2146 | O11: 557.64398 | P11: 2516.5525 | Q11: 11505.411 | R11: 810.35702 | S11: 158.7065 | T11: 244.73343 | U11: 139.8237 | V11: 226.90489 | W11: 138.87126 | X11: 151.89816 | Y11: 433.06793 | Z11: 139.81268 | AA11: 330.38181 | AB11: 452.63432 | AC11: 476.72744 | AD11: 529.62356 | AE11: 553.07792 | AF11: 344.77831 | AG11: 332.93649
A12: 44063 | B12: 15994.776 | C12: 12988.738 | D12: 15189.809 | E12: 16832.971 | F12: 16197.13 | G12: 15524.596 | H12: 28065.852 | I12: 20211.872 | J12: 1631.7533 | K12: 2046.1657 | L12: 688.42585 | M12: 13564.642 | N12: 3600.4039 | O12: 566.53584 | P12: 2451.9302 | Q12: 11424.416 | R12: 823.8348 | S12: 159.70461 | T12: 238.89992 | U12: 139.63446 | V12: 212.82439 | W12: 138.1363 | X12: 150.02815 | Y12: 459.20852 | Z12: 140.07746 | AA12: 336.9794 | AB12: 470.68807 | AC12: 479.34011 | AD12: 539.12663 | AE12: 517.11344 | AF12: 342.41316 | AG12: 339.70714
A13: 44064 | B13: 16270.211 | C13: 12848.585 | D13: 15472.161 | E13: 17052.305 | F13: 16043.755 | G13: 15387.667 | H13: 27789.286 | I13: 20118.339 | J13: 1660.6868 | K13: 2033.1117 | L13: 700.91934 | M13: 13511.252 | N13: 3465.9036 | O13: 556.34872 | P13: 2445.6972 | Q13: 11325.756 | R13: 820.91808 | S13: 160.5077 | T13: 220.51582 | U13: 140.20492 | V13: 190.56452 | W13: 140.0576 | X13: 145.5161 | Y13: 487.85406 | Z13: 142.35614 | AA13: 344.65009 | AB13: 488.85418 | AC13: 481.48762 | AD13: 546.63373 | AE13: 558.83782 | AF13: 339.85912 | AG13: 351.0298
A14: 44065 | B14: 16402.715 | C14: 12666.941 | D14: 15532.317 | E14: 17041.39 | F14: 15536.721 | G14: 14772.338 | H14: 27006.671 | I14: 19949.198 | J14: 1671.6803 | K14: 1958.2056 | L14: 681.84974 | M14: 12865.489 | N14: 2840.5494 | O14: 526.72504 | P14: 2354.5882 | Q14: 10731.762 | R14: 790.31383 | S14: 161.06797 | T14: 188.56132 | U14: 141.53175 | V14: 163.83883 | W14: 141.72962 | X14: 141.52932 | Y14: 509.40262 | Z14: 142.70933 | AA14: 351.60427 | AB14: 513.10972 | AC14: 483.03243 | AD14: 535.1535 | AE14: 498.43751 | AF14: 339.34604 | AG14: 366.13531
... A511: 44562 | B511: 4355.6167 | C511: 187.52444 | D511: 1840.4141 | E511: 3140.184 | F511: 401.97167 | G511: 331.89512 | H511: 5767.5188 | I511: 1708.906 | J511: 442.84388 | K511: 414.40746 | L511: 259.52903 | M511: 325.2005 | N511: 158.3642 | O511: 201.54522 | P511: 268.13921 | Q511: 201.68872 | R511: 234.85764 | S511: 505.61152 | T511: 167.10575 | U511: 301.46051 | V511: 128.4182 | W511: 128.90149 | X511: 128.41579 | Y511: 528.03073 | Z511: 179.40005 | AA511: 489.45731 | AB511: 570.75389 | AC511: 495.0597 | AD511: 260.31632 | AE511: 302.70978 | AF511: 517.69317 | AG511: 559.2191
A512: TOTAL EXCEEDANCES | B512: =COUNTIF(B$3:B$511,">=1000") -> 509 | C512: =COUNTIF(C$3:C$511,">=1000") -> 485 | D512: =COUNTIF(D$3:D$511,">=1000") -> 509 | E512: =COUNTIF(E$3:E$511,">=1000") -> 509 | F512: =COUNTIF(F$3:F$511,">=1000") -> 503 | G512: =COUNTIF(G$3:G$511,">=1000") -> 497 | H512: =COUNTIF(H$3:H$511,">=1000") -> 509 | I512: =COUNTIF(I$3:I$511,">=1000") -> 509 | ... AG512: =COUNTIF(AG$3:AG$511,">=1000") -> 0
A513: WET 1 | B513: =COUNTIF(B$54:B$235,">=1000") -> 182 | C513: =COUNTIF(C$54:C$235,">=1000") -> 179 | D513: =COUNTIF(D$54:D$235,">=1000") -> 182 | E513: =COUNTIF(E$54:E$235,">=1000") -> 182 | F513: =COUNTIF(F$54:F$235,">=1000") -> 182 | G513: =COUNTIF(G$54:G$235,">=1000") -> 182 | H513: =COUNTIF(H$54:H$235,">=1000") -> 182 | I513: =COUNTIF(I$54:I$235,">=1000") -> 182 | ... AG513: =COUNTIF(AG$54:AG$235,">=1000") -> 0 | AH513: OCT 1, 2020 - MAR 31, 2021
A514: WET 2 | B514: =COUNTIF(B$419:B$511,">=1000") -> 93 | C514: =COUNTIF(C$419:C$511,">=1000") -> 72 | D514: =COUNTIF(D$419:D$511,">=1000") -> 93 | E514: =COUNTIF(E$419:E$511,">=1000") -> 93 | F514: =COUNTIF(F$419:F$511,">=1000") -> 87 | G514: =COUNTIF(G$419:G$511,">=1000") -> 81 | H514: =COUNTIF(H$419:H$511,">=1000") -> 93 | I514: =COUNTIF(I$419:I$511,">=1000") -> 93 | ... AG514: =COUNTIF(AG$419:AG$511,">=1000") -> 0 | AH514: OCT 1, 2021 - JAN 1, 2022
A515: DRY 1 | B515: =COUNTIF(B$3:B$53,">=1000") -> 51 | C515: =COUNTIF(C$3:C$53,">=1000") -> 51 | D515: =COUNTIF(D$3:D$53,">=1000") -> 51 | E515: =COUNTIF(E$3:E$53,">=1000") -> 51 | F515: =COUNTIF(F$3:F$53,">=1000") -> 51 | G515: =COUNTIF(G$3:G$53,">=1000") -> 51 | H515: =COUNTIF(H$3:H$53,">=1000") -> 51 | I515: =COUNTIF(I$3:I$53,">=1000") -> 51 | ... AG515: =COUNTIF(AG$3:AG$53,">=1000") -> 0 | AH515: AUG 11, 2020 - SEP 30, 2020
A516: DRY 2 | B516: =COUNTIF(B$236:B$418,">=1000") -> 183 | C516: =COUNTIF(C$236:C$418,">=1000") -> 183 | D516: =COUNTIF(D$236:D$418,">=1000") -> 183 | E516: =COUNTIF(E$236:E$418,">=1000") -> 183 | F516: =COUNTIF(F$236:F$418,">=1000") -> 183 | G516: =COUNTIF(G$236:G$418,">=1000") -> 183 | H516: =COUNTIF(H$236:H$418,">=1000") -> 183 | I516: =COUNTIF(I$236:I$418,">=1000") -> 183 | ... AG516: =COUNTIF(AG$236:AG$418,">=1000") -> 0 | AH516: APR 1, 2021 - SEP 30, 2021
A517: ALL WET | B517: =SUM(B$513,B$514) -> 275 | C517: =SUM(C$513,C$514) -> 251 | D517: =SUM(D$513,D$514) -> 275 | E517: =SUM(E$513,E$514) -> 275 | F517: =SUM(F$513,F$514) -> 269 | G517: =SUM(G$513,G$514) -> 263 | H517: =SUM(H$513,H$514) -> 275 | I517: =SUM(I$513,I$514) -> 275 | ... AG517: =SUM(AG$513,AG$514) -> 0
A518: ALL DRY | B518: =SUM(B$515,B$516) -> 234 | C518: =SUM(C$515,C$516) -> 234 | D518: =SUM(D$515,D$516) -> 234 | E518: =SUM(E$515,E$516) -> 234 | F518: =SUM(F$515,F$516) -> 234 | G518: =SUM(G$515,G$516) -> 234 | H518: =SUM(H$515,H$516) -> 234 | I518: =SUM(I$515,I$516) -> 234 | ... AG518: =SUM(AG$515,AG$516) -> 0
D521: Day Use & Boating | F521: THRESHOLD: 1,000 MICROSIEMENS/CM (EC) | S521: SP DAY USE & BOATING | AA521: SP DAY USE & BOATING | AE521: SP DAY USE & BOATING | AI521: SP DAY USE & BOATING | AQ521: SP DAY USE & BOATING | AY521: SP DAY USE & BOATING
F522: WET SEASON | S522: TOTAL RUN | AA522: WET SEASONS | AE522: DRY SEASONS | AI522: TOTAL RUN | AK522: Delta-Wide | AL522: Suisun | AM522: Central Delta | AN522: North Delta | AO522: South Delta | AQ522: WET SEASONS | AS522: Delta-Wide | AT522: Suisun | AU522: Central Delta | AV522: North Delta | AW522: South Delta | AY522: DRY SEASONS | BA522: Delta-Wide | BB522: Suisun | BC522: Central Delta | BD522: North Delta | BE522: South Delta
F523: OCTOBER 1 - MARCH 31 | M523: DRY SEASON | S523: Total points | U523: =COUNTIF(B2:AG2,"<>") -> 32 | AA523: Total points | AC523: =COUNTIF(B2:AG2,"<>") -> 32 | AE523: Total points | AG523: =COUNTIF(B2:AG2,"<>") -> 32 | AI523: Total points | AK523: =COUNTIF($B$2:$AG$2,"<>") -> 32 | AL523: =COUNTIF($B$2:$I$2,"<>") -> 8 | AM523: =COUNTIF($J$2:$R$2,"<>") -> 9 | AN523: =COUNTIF($S$2:$X$2,"<>") -> 6 | AO523: =COUNTIF($Y$2:$AG$2,"<>") -> 9 | AQ523: Total points | AS523: =COUNTIF($B$2:$AG$2,"<>") -> 32 | AT523: =COUNTIF($B$2:$I$2,"<>") -> 8 | AU523: =COUNTIF($J$2:$R$2,"<>") -> 9 | AV523: =COUNTIF($S$2:$X$2,"<>") -> 6 | AW523: =COUNTIF($Y$2:$AG$2,"<>") -> 9 | AY523: Total points | BA523: =COUNTIF($B$2:$AG$2,"<>") -> 32 | BB523: =COUNTIF($B$2:$I$2,"<>") -> 8 | BC523: =COUNTIF($J$2:$R$2,"<>") -> 9 | BD523: =COUNTIF($S$2:$X$2,"<>") -> 6 | BE523: =COUNTIF($Y$2:$AG$2,"<>") -> 9
F524: WET SEASON 1 | H524: 10/1/20 - 3/31/21 | J524: =COUNTIF($B$54:$B$235,"<>") -> 182 | M524: APRIL 1 - SEPTEMBER 30 | S524: Days in run | U524: =COUNTIF($A$3:$A$511,"<>") -> 509 | AA524: Days in run | AC524: =SUM($J$524:$J$525) -> 275 | AE524: Days in run | AG524: =SUM($Q$525:$Q$526) -> 234 | AI524: Days in run | AK524: =COUNTIF($A$3:$A$511,"<>") -> 509 | AL524: =COUNTIF($A$3:$A$511,"<>") -> 509 | AM524: =COUNTIF($A$3:$A$511,"<>") -> 509 | AN524: =COUNTIF($A$3:$A$511,"<>") -> 509 | AO524: =COUNTIF($A$3:$A$511,"<>") -> 509 | AQ524: Days in run | AS524: =SUM($J$524:$J$525) -> 275 | AT524: =SUM($J$524:$J$525) -> 275 | AU524: =SUM($J$524:$J$525) -> 275 | AV524: =SUM($J$524:$J$525) -> 275 | AW524: =SUM($J$524:$J$525) -> 275 | AY524: Days in run | BA524: =SUM($Q$525:$Q$526) -> 234 | BB524: =SUM($Q$525:$Q$526) -> 234 | BC524: =SUM($Q$525:$Q$526) -> 234 | BD524: =SUM($Q$525:$Q$526) -> 234 | BE524: =SUM($Q$525:$Q$526) -> 234
F525: WET SEASON 2 | H525: 10/1/21 - 1/1/22 | J525: =COUNTIF($B$419:$B$511,"<>") -> 93 | M525: DRY SEASON 1 | O525: 8/11/20 - 9/30/20 | Q525: =COUNTIF($B$3:$B$53,"<>") -> 51 | S525: Total measurements | U525: =U524*U523 -> 16288 | V525: DENOMINATOR FOR EXCEEDANCE % | AA525: Total measurements | AC525: =AC524*AC523 -> 8800 | AE525: Total measurements | AG525: =AG523*AG524 -> 7488 | AI525: Total measurements | AK525: =AK524*AK523 -> 16288 | AL525: =AL524*AL523 -> 4072 | AM525: =AM524*AM523 -> 4581 | AN525: =AN524*AN523 -> 3054 | AO525: =AO524*AO523 -> 4581 | AQ525: Total measurements | AS525: =AS524*AS523 -> 8800 | AT525: =AT524*AT523 -> 2200 | AU525: =AU524*AU523 -> 2475 | AV525: =AV524*AV523 -> 1650 | AW525: =AW524*AW523 -> 2475 | AY525: Total measurements | BA525: =BA524*BA523 -> 7488 | BB525: =BB524*BB523 -> 1872 | BC525: =BC524*BC523 -> 2106 | BD525: =BD524*BD523 -> 1404 | BE525: =BE524*BE523 -> 2106
M526: DRY SEASON 2 | O526: 4/1/21 - 9/30/21 | Q526: =COUNTIF($B$236:$B$418,"<>") -> 183 | S526: Measurements >= 1,000 | U526: =SUM(B512:AG512) -> 5826 | V526: NUMERATOR FOR EXCEEDANCE % | AA526: Measurements >= 1,000 | AC526: =SUM($B$517:$AG$517) -> 3049 | AE526: Measurements >= 1,000 | AG526: =SUM($B$518:$AG$518) -> 2777 | AI526: Measurements >= 1,000 | AK526: =SUM(B512:AG512) -> 5826 | AL526: =SUM(B512:I512) -> 4030 | AM526: =SUM(J512:R512) -> 1775 | AN526: =SUM(S512:X512) -> 0 | AO526: =SUM(Y512:AG512) -> 21 | AQ526: Measurements >= 1,000 | AS526: =SUM(B517:AG517) -> 3049 | AT526: =SUM(B517:I517) -> 2158 | AU526: =SUM(J517:R517) -> 870 | AV526: =SUM(S517:X517) -> 0 | AW526: =SUM(Y517:AG517) -> 21 | AY526: Measurements >= 1,000 | BA526: =SUM($B518:$AG518) -> 2777 | BB526: =SUM(B518:I518) -> 1872 | BC526: =SUM(J518:R518) -> 905 | BD526: =SUM(S518:X518) -> 0 | BE526: =SUM(Y518:AG518) -> 0
S527: % Total Run Exceedances | U527: =$U526/$U525 -> 0.35768664 | AA527: % WET Exceedances | AC527: =AC526/AC525 -> 0.34647727 | AE527: % DRY Exceedances | AG527: =AG526/AG525 -> 0.37086004 | AI527: % Total Run Exceedances | AK527: =AK526/AK525 -> 0.35768664 | AL527: =AL526/AL525 -> 0.98968566 | AM527: =AM526/AM525 -> 0.38746998 | AN527: =AN526/AN525 -> 0 | AO527: =AO526/AO525 -> 0.0045841519 | AQ527: % WET Exceedances | AS527: =AS526/AS525 -> 0.34647727 | AT527: =AT526/AT525 -> 0.98090909 | AU527: =AU526/AU525 -> 0.35151515 | AV527: =AV526/AV525 -> 0 | AW527: =AW526/AW525 -> 0.0084848485 | AY527: % DRY Exceedances | BA527: =BA526/BA525 -> 0.37086004 | BB527: =BB526/BB525 -> 1 | BC527: =BC526/BC525 -> 0.4297246 | BD527: =BD526/BD525 -> 0 | BE527: =BE526/BE525 -> 0
A529: TOTAL EXCEEDANCES | B529: =COUNTIF(B$3:B$511,">=2640") -> 509 | C529: =COUNTIF(C$3:C$511,">=2640") -> 438 | D529: =COUNTIF(D$3:D$511,">=2640") -> 452 | E529: =COUNTIF(E$3:E$511,">=2640") -> 509 | F529: =COUNTIF(F$3:F$511,">=2640") -> 496 | G529: =COUNTIF(G$3:G$511,">=2640") -> 483 | H529: =COUNTIF(H$3:H$511,">=2640") -> 509 | I529: =COUNTIF(I$3:I$511,">=2640") -> 507 | ... AG529: =COUNTIF(AG$3:AG$511,">=2640") -> 0
A530: WET 1 | B530: =COUNTIF(B$54:B$235,">=2640") -> 182 | C530: =COUNTIF(C$54:C$235,">=2640") -> 141 | D530: =COUNTIF(D$54:D$235,">=2640") -> 146 | E530: =COUNTIF(E$54:E$235,">=2640") -> 182 | F530: =COUNTIF(F$54:F$235,">=2640") -> 182 | G530: =COUNTIF(G$54:G$235,">=2640") -> 177 | H530: =COUNTIF(H$54:H$235,">=2640") -> 182 | I530: =COUNTIF(I$54:I$235,">=2640") -> 182 | ... AG530: =COUNTIF(AG$54:AG$235,">=2640") -> 0 | AH530: OCT 1, 2020 - MAR 31, 2021
A531: WET 2 | B531: =COUNTIF(B$419:B$511,">=2640") -> 93 | C531: =COUNTIF(C$419:C$511,">=2640") -> 64 | D531: =COUNTIF(D$419:D$511,">=2640") -> 75 | E531: =COUNTIF(E$419:E$511,">=2640") -> 93 | F531: =COUNTIF(F$419:F$511,">=2640") -> 80 | G531: =COUNTIF(G$419:G$511,">=2640") -> 72 | H531: =COUNTIF(H$419:H$511,">=2640") -> 93 | I531: =COUNTIF(I$419:I$511,">=2640") -> 91 | ... AG531: =COUNTIF(AG$419:AG$511,">=2640") -> 0 | AH531: OCT 1, 2021 - JAN 1, 2022
