Workbook

Sheet Habitat Restoration (Acres)
A1: Habitat Type | B1: Region_Nam | C1: Region_Code | D1: Regional Acres | F1: Use These for landscape restoration | H1: Suisun | I1: Central | J1: North | K1: South | L1: Upland
A2: Transitional | B2: South Delta | C2: South | D2: 67259.975 | F2: Full Restoration (In-Delta ECO + NGW) (100%) | G2: Transitional | H2: =SUMIFS($D$2:$D$14,$A$2:$A$14,$G2,$C$2:$C$14,H$1) -> 0 | I2: =SUMIFS($D$2:$D$14,$A$2:$A$14,$G2,$C$2:$C$14,I$1) -> 0 | J2: =SUMIFS($D$2:$D$14,$A$2:$A$14,$G2,$C$2:$C$14,J$1) -> 80428.56 | K2: =SUMIFS($D$2:$D$14,$A$2:$A$14,$G2,$C$2:$C$14,K$1) -> 67259.975
A3: Transitional | B3: North Delta | C3: North | D3: 80428.56 | G3: Soil | H3: =SUMIFS($D$2:$D$14,$A$2:$A$14,$G3,$C$2:$C$14,H$1) -> 0 | I3: =SUMIFS($D$2:$D$14,$A$2:$A$14,$G3,$C$2:$C$14,I$1) -> 34255.257 | J3: =SUMIFS($D$2:$D$14,$A$2:$A$14,$G3,$C$2:$C$14,J$1) -> 93152.202 | K3: =SUMIFS($D$2:$D$14,$A$2:$A$14,$G3,$C$2:$C$14,K$1) -> 79914.462
A4: Soil | B4: North Delta | C4: North | D4: 93152.202 | G4: Tidal | H4: =SUMIFS($D$2:$D$14,$A$2:$A$14,$G4,$C$2:$C$14,H$1) -> 41914.112 | I4: =SUMIFS($D$2:$D$14,$A$2:$A$14,$G4,$C$2:$C$14,I$1) -> 3324.5082 | J4: =SUMIFS($D$2:$D$14,$A$2:$A$14,$G4,$C$2:$C$14,J$1) -> 25938.422 | K4: =SUMIFS($D$2:$D$14,$A$2:$A$14,$G4,$C$2:$C$14,K$1) -> 0
A5: Soil | B5: South Delta | C5: South | D5: 79914.462 | G5: MW | H5: =SUMIFS($D$2:$D$14,$A$2:$A$14,$G5,$C$2:$C$14,H$1) -> 0 | I5: =SUMIFS($D$2:$D$14,$A$2:$A$14,$G5,$C$2:$C$14,I$1) -> 29367 | J5: =SUMIFS($D$2:$D$14,$A$2:$A$14,$G5,$C$2:$C$14,J$1) -> 84385 | K5: =SUMIFS($D$2:$D$14,$A$2:$A$14,$G5,$C$2:$C$14,K$1) -> 130507
A6: Soil | B6: Convergence Zone | C6: Central | D6: 34255.257 | F6: Upland Upper Bound (100%) | G6: Meadows | L6: =SUMIFS($D$2:$D$14,$A$2:$A$14,$G6,$C$2:$C$14,L$1) -> 347591
A7: Tidal | B7: North Delta | C7: North | D7: 25938.422 | G7: Floodplain | L7: =SUMIFS($D$2:$D$14,$A$2:$A$14,$G7,$C$2:$C$14,L$1) -> 303372
A8: Tidal | B8: Convergence Zone | C8: Central | D8: 3324.5082 | G8: Wetland | L8: 207004
A9: Tidal | B9: Suisun Marsh | C9: Suisun | D9: 41914.112 | F9: Upland Lower Bound (25%) | G9: Meadows | L9: 11586
A10: MW | B10: North Delta | C10: North | D10: 84385 | G10: Floodplain | L10: 6360
A11: MW | B11: Convergence Zone | C11: Central | D11: 29367 | G11: Wetland | L11: 48213
A12: MW | B12: South Delta | C12: South | D12: 130507 | F12: Total (In-Delta + Lower Upland) | G12: =SUM(H4,I3,I4,I5,J5,J4,J3,J2,K2,K3,K5,L9,L10,L11) -> 736605.5 | H12: =SUM(H2:H5:H9:H11) -> 41914.112 | I12: =SUM(I2:I5:I9:I11) -> 66946.765 | J12: =SUM(J2:J5:J9:J11) -> 283904.18 | K12: =SUM(K2:K5:K9:K11) -> 277681.44 | L12: =SUM(L2:L5:L9:L11) -> 924126
A13: Meadows | B13: Non-Delta | C13: Upland | D13: 347591 | F13: Total (In-Delta + Upper Bound) | G13: =SUM(H4,I3,I4,I5,J5,J4,J3,J2,K2,K3,K5,L6,L7,L8) -> 1528413.5 | H13: =SUM(H2:H5:H6:H8) -> 41914.112 | I13: =SUM(I2:I5:I6:I8) -> 66946.765 | J13: =SUM(J2:J5:J6:J8) -> 283904.18 | K13: =SUM(K2:K5:K6:K8) -> 277681.44 | L13: =SUM(L2:L5:L6:L8) -> 857967
A14: Floodplain | B14: Non-Delta | C14: Upland | D14: 303372 | F14: Total (In-Delta Only) | G14: =SUM(H2:K5) -> 670446.5 | H14: =SUM(H2:H5) -> 41914.112 | I14: =SUM(I2:I5) -> 66946.765 | J14: =SUM(J2:J5) -> 283904.18 | K14: =SUM(K2:K5) -> 277681.44 | L14: =SUM(L2:L5) -> 0
A21: 1. In-Delta Values derive from NGW and Eco Machine in-Delta Acres, and these sheets, used 100% Restoration for this slide 2. Upland (Upper Bound and Lower Bound) restoration values derive from Slide 56 BDSC Presentation Note: only Full Restoration analyzed with In-Delta restoration Objectives (This sheet), while upper and lower bounds are included for upland restoration (Reflected on Restoration ($) Combined sheet 100% and 25% sums Figures here are for Rec Criterion Manuscript and don't serve any other purpose, feel free to map at will for website.

Sheet Restoration ($) Combined
C2: $/acre/yr (all islands) | D2: 351.29 | E2: 283.15 | F2: 372.49 | G2: 218.04 | H2: 162.02 | I2: 152.17 | J2: 93.12 | K2: 34.07 | L2: 34.07 | M2: 10.6 | N2: =SUM(D2:M2) -> 1711.02
A3: 100% Restoration | B3: Region | C3: Island | D3: Flood control | E3: Recreational fishing | F3: Amenity/recreation | G3: Water filtering | H3: Biodiversity | I3: Habitat nursery | J3: Recreational hunting | K3: Water supply | L3: Materials | M3: Fuel wood | N3: Sum of all ten | O3: Island acres | P3: Restored (1=yes, 0=no) | Q3: Restored acres
B4: Suisun Marsh | C4: Suisun | D4: =$Q4*D$2 -> 14724008 | E4: =$Q4*E$2 -> 11867981 | F4: =$Q4*F$2 -> 15612588 | G4: =$Q4*G$2 -> 9138953 | H4: =$Q4*H$2 -> 6790924.4 | I4: =$Q4*I$2 -> 6378070.4 | J4: =$Q4*J$2 -> 3903042.1 | K4: =$Q4*K$2 -> 1428013.8 | ... M4: =$Q4*M$2 -> 444289.59 | N4: =SUM(D4:M4) -> 71715884 | O4: ='Habitat Restoration (Acres)'!$D$9 -> 41914.112 | P4: 1 | Q4: =O4*P4 -> 41914.112
B5: Central Delta | C5: Bethel Island | D5: =$Q5*D$2 -> 1131153.8 | E5: =$Q5*E$2 -> 911743 | F5: =$Q5*F$2 -> 1199417.8 | G5: =$Q5*G$2 -> 702088.8 | H5: =$Q5*H$2 -> 521704.4 | I5: =$Q5*I$2 -> 489987.4 | J5: =$Q5*J$2 -> 299846.4 | K5: =$Q5*K$2 -> 109705.4 | ... M5: =$Q5*M$2 -> 34132 | N5: =SUM(D5:M5) -> 5509484.4 | O5: =INDEX(References!$C$2:$C$38,MATCH(C5,References!$A$2:$A$38,0)) -> 3220 | P5: 1 | Q5: =O5*P5 -> 3220
C6: Jersey Island | D6: =$Q6*D$2 -> 1215112.1 | E6: =$Q6*E$2 -> 979415.85 | F6: =$Q6*F$2 -> 1288442.9 | G6: =$Q6*G$2 -> 754200.36 | H6: =$Q6*H$2 -> 560427.18 | I6: =$Q6*I$2 -> 526356.03 | J6: =$Q6*J$2 -> 322102.08 | K6: =$Q6*K$2 -> 117848.13 | ... M6: =$Q6*M$2 -> 36665.4 | N6: =SUM(D6:M6) -> 5918418.2 | O6: =INDEX(References!$C$2:$C$38,MATCH(C6,References!$A$2:$A$38,0)) -> 3459 | P6: 1 | Q6: =O6*P6 -> 3459
C7: Webb Tract | D7: =$Q7*D$2 -> 1909612.4 | E7: =$Q7*E$2 -> 1539203.4 | F7: =$Q7*F$2 -> 2024855.6 | G7: =$Q7*G$2 -> 1185265.4 | H7: =$Q7*H$2 -> 880740.72 | I7: =$Q7*I$2 -> 827196.12 | J7: =$Q7*J$2 -> 506200.32 | K7: =$Q7*K$2 -> 185204.52 | ... M7: =$Q7*M$2 -> 57621.6 | N7: =SUM(D7:M7) -> 9301104.7 | O7: =INDEX(References!$C$2:$C$38,MATCH(C7,References!$A$2:$A$38,0)) -> 5436 | P7: 1 | Q7: =O7*P7 -> 5436
C8: Bradford Island | D8: =$Q8*D$2 -> 750004.15 | E8: =$Q8*E$2 -> 604525.25 | F8: =$Q8*F$2 -> 795266.15 | G8: =$Q8*G$2 -> 465515.4 | H8: =$Q8*H$2 -> 345912.7 | I8: =$Q8*I$2 -> 324882.95 | J8: =$Q8*J$2 -> 198811.2 | K8: =$Q8*K$2 -> 72739.45 | ... M8: =$Q8*M$2 -> 22631 | N8: =SUM(D8:M8) -> 3653027.7 | O8: =INDEX(References!$C$2:$C$38,MATCH(C8,References!$A$2:$A$38,0)) -> 2135 | P8: 1 | Q8: =O8*P8 -> 2135
C9: Sherman Island | D9: =$Q9*D$2 -> 3575429.6 | E9: =$Q9*E$2 -> 2881900.7 | F9: =$Q9*F$2 -> 3791203.2 | G9: =$Q9*G$2 -> 2219211.1 | H9: =$Q9*H$2 -> 1649039.6 | I9: =$Q9*I$2 -> 1548786.3 | J9: =$Q9*J$2 -> 947775.36 | K9: =$Q9*K$2 -> 346764.46 | ... M9: =$Q9*M$2 -> 107886.8 | N9: =SUM(D9:M9) -> 17414762 | O9: =INDEX(References!$C$2:$C$38,MATCH(C9,References!$A$2:$A$38,0)) -> 10178 | P9: 1 | Q9: =O9*P9 -> 10178
C10: Franks Tract | D10: =$Q10*D$2 -> 484780.2 | E10: =$Q10*E$2 -> 390747 | F10: =$Q10*F$2 -> 514036.2 | G10: =$Q10*G$2 -> 300895.2 | H10: =$Q10*H$2 -> 223587.6 | I10: =$Q10*I$2 -> 209994.6 | J10: =$Q10*J$2 -> 128505.6 | K10: =$Q10*K$2 -> 47016.6 | ... M10: =$Q10*M$2 -> 14628 | N10: =SUM(D10:M10) -> 2361207.6 | O10: 1380 | P10: 1 | Q10: =O10*P10 -> 1380
C11: Twitchell Island | D11: =$Q11*D$2 -> 1250241.1 | E11: =$Q11*E$2 -> 1007730.8 | F11: =$Q11*F$2 -> 1325691.9 | G11: =$Q11*G$2 -> 776004.36 | H11: =$Q11*H$2 -> 576629.18 | I11: =$Q11*I$2 -> 541573.03 | J11: =$Q11*J$2 -> 331414.08 | K11: =$Q11*K$2 -> 121255.13 | ... M11: =$Q11*M$2 -> 37725.4 | N11: =SUM(D11:M11) -> 6089520.2 | O11: =INDEX(References!$C$2:$C$38,MATCH(C11,References!$A$2:$A$38,0)) -> 3559 | P11: 1 | Q11: =O11*P11 -> 3559
B12: North Delta | C12: Grand Island | D12: =$Q12*D$2 -> 5811390.5 | E12: =$Q12*E$2 -> 4684150.4 | F12: =$Q12*F$2 -> 6162102.1 | G12: =$Q12*G$2 -> 3607035.7 | H12: =$Q12*H$2 -> 2680296.9 | I12: =$Q12*I$2 -> 2517348.3 | J12: =$Q12*J$2 -> 1540484.2 | K12: =$Q12*K$2 -> 563620.01 | ... M12: =$Q12*M$2 -> 175355.8 | N12: =SUM(D12:M12) -> 28305404 | O12: =INDEX(References!$C$2:$C$38,MATCH(C12,References!$A$2:$A$38,0)) -> 16543 | P12: 1 | Q12: =O12*P12 -> 16543
C13: Ryer Island | D13: =$Q13*D$2 -> 4144519.4 | E13: =$Q13*E$2 -> 3340603.7 | F13: =$Q13*F$2 -> 4394637 | G13: =$Q13*G$2 -> 2572435.9 | H13: =$Q13*H$2 -> 1911512 | I13: =$Q13*I$2 -> 1795301.7 | J13: =$Q13*J$2 -> 1098629.8 | K13: =$Q13*K$2 -> 401957.86 | ... M13: =$Q13*M$2 -> 125058.8 | N13: =SUM(D13:M13) -> 20186614 | O13: =INDEX(References!$C$2:$C$38,MATCH(C13,References!$A$2:$A$38,0)) -> 11798 | P13: 1 | Q13: =O13*P13 -> 11798
C14: Tyler Island | D14: =$Q14*D$2 -> 3091000.7 | E14: =$Q14*E$2 -> 2491436.8 | F14: =$Q14*F$2 -> 3277539.5 | G14: =$Q14*G$2 -> 1918534 | H14: =$Q14*H$2 -> 1425614 | I14: =$Q14*I$2 -> 1338943.8 | J14: =$Q14*J$2 -> 819362.88 | K14: =$Q14*K$2 -> 299781.93 | ... M14: =$Q14*M$2 -> 93269.4 | N14: =SUM(D14:M14) -> 15055265 | O14: =INDEX(References!$C$2:$C$38,MATCH(C14,References!$A$2:$A$38,0)) -> 8799 | P14: 1 | Q14: =O14*P14 -> 8799
C15: Staten Island | D15: =$Q15*D$2 -> 3200603.2 | E15: =$Q15*E$2 -> 2579779.6 | F15: =$Q15*F$2 -> 3393756.4 | G15: =$Q15*G$2 -> 1986562.4 | H15: =$Q15*H$2 -> 1476164.2 | I15: =$Q15*I$2 -> 1386420.9 | J15: =$Q15*J$2 -> 848416.32 | K15: =$Q15*K$2 -> 310411.77 | ... M15: =$Q15*M$2 -> 96576.6 | N15: =SUM(D15:M15) -> 15589103 | O15: =INDEX(References!$C$2:$C$38,MATCH(C15,References!$A$2:$A$38,0)) -> 9111 | P15: 1 | Q15: =O15*P15 -> 9111
C16: Dead Horse Island | D16: =$Q16*D$2 -> 73068.32 | E16: =$Q16*E$2 -> 58895.2 | F16: =$Q16*F$2 -> 77477.92 | G16: =$Q16*G$2 -> 45352.32 | H16: =$Q16*H$2 -> 33700.16 | I16: =$Q16*I$2 -> 31651.36 | J16: =$Q16*J$2 -> 19368.96 | K16: =$Q16*K$2 -> 7086.56 | ... M16: =$Q16*M$2 -> 2204.8 | N16: =SUM(D16:M16) -> 355892.16 | O16: =INDEX(References!$C$2:$C$38,MATCH(C16,References!$A$2:$A$38,0)) -> 208 | P16: 1 | Q16: =O16*P16 -> 208
C17: Sutter Island | D17: =$Q17*D$2 -> 883143.06 | E17: =$Q17*E$2 -> 711839.1 | F17: =$Q17*F$2 -> 936439.86 | G17: =$Q17*G$2 -> 548152.56 | H17: =$Q17*H$2 -> 407318.28 | I17: =$Q17*I$2 -> 382555.38 | J17: =$Q17*J$2 -> 234103.68 | K17: =$Q17*K$2 -> 85651.98 | ... M17: =$Q17*M$2 -> 26648.4 | N17: =SUM(D17:M17) -> 4301504.3 | O17: =INDEX(References!$C$2:$C$38,MATCH(C17,References!$A$2:$A$38,0)) -> 2514 | P17: 1 | Q17: =O17*P17 -> 2514
C18: New Hope Tract | D18: =$Q18*D$2 -> 3235732.2 | E18: =$Q18*E$2 -> 2608094.6 | F18: =$Q18*F$2 -> 3431005.4 | G18: =$Q18*G$2 -> 2008366.4 | H18: =$Q18*H$2 -> 1492366.2 | I18: =$Q18*I$2 -> 1401637.9 | J18: =$Q18*J$2 -> 857728.32 | K18: =$Q18*K$2 -> 313818.77 | ... M18: =$Q18*M$2 -> 97636.6 | N18: =SUM(D18:M18) -> 15760205 | O18: =INDEX(References!$C$2:$C$38,MATCH(C18,References!$A$2:$A$38,0)) -> 9211 | P18: 1 | Q18: =O18*P18 -> 9211
C19: Canal Ranch Tract | D19: =$Q19*D$2 -> 1031387.4 | E19: =$Q19*E$2 -> 831328.4 | F19: =$Q19*F$2 -> 1093630.6 | G19: =$Q19*G$2 -> 640165.44 | H19: =$Q19*H$2 -> 475690.72 | I19: =$Q19*I$2 -> 446771.12 | J19: =$Q19*J$2 -> 273400.32 | K19: =$Q19*K$2 -> 100029.52 | ... M19: =$Q19*M$2 -> 31121.6 | N19: =SUM(D19:M19) -> 5023554.7 | O19: =INDEX(References!$C$2:$C$38,MATCH(C19,References!$A$2:$A$38,0)) -> 2936 | P19: 1 | Q19: =O19*P19 -> 2936
B20: North-Central | C20: Brannan Island | D20: =$Q20*D$2 -> 4534100 | E20: =$Q20*E$2 -> 3654617 | F20: =$Q20*F$2 -> 4807728.4 | G20: =$Q20*G$2 -> 2814242.3 | H20: =$Q20*H$2 -> 2091192.1 | I20: =$Q20*I$2 -> 1964058.2 | J20: =$Q20*J$2 -> 1201899.8 | K20: =$Q20*K$2 -> 439741.49 | ... M20: =$Q20*M$2 -> 136814.2 | N20: =SUM(D20:M20) -> 22084135 | O20: =INDEX(References!$C$2:$C$38,MATCH(C20,References!$A$2:$A$38,0)) -> 12907 | P20: 1 | Q20: =O20*P20 -> 12907
B21: North-South | C21: Terminous Tract | D21: =$Q21*D$2 -> 3638661.8 | E21: =$Q21*E$2 -> 2932867.7 | F21: =$Q21*F$2 -> 3858251.4 | G21: =$Q21*G$2 -> 2258458.3 | H21: =$Q21*H$2 -> 1678203.2 | I21: =$Q21*I$2 -> 1576176.9 | J21: =$Q21*J$2 -> 964536.96 | K21: =$Q21*K$2 -> 352897.06 | ... M21: =$Q21*M$2 -> 109794.8 | N21: =SUM(D21:M21) -> 17722745 | O21: =INDEX(References!$C$2:$C$38,MATCH(C21,References!$A$2:$A$38,0)) -> 10358 | P21: 1 | Q21: =O21*P21 -> 10358
B22: South Delta | C22: Bouldin Island | D22: =$Q22*D$2 -> 2085257.4 | E22: =$Q22*E$2 -> 1680778.4 | F22: =$Q22*F$2 -> 2211100.6 | G22: =$Q22*G$2 -> 1294285.4 | H22: =$Q22*H$2 -> 961750.72 | I22: =$Q22*I$2 -> 903281.12 | J22: =$Q22*J$2 -> 552760.32 | K22: =$Q22*K$2 -> 202239.52 | ... M22: =$Q22*M$2 -> 62921.6 | N22: =SUM(D22:M22) -> 10156615 | O22: =INDEX(References!$C$2:$C$38,MATCH(C22,References!$A$2:$A$38,0)) -> 5936 | P22: 1 | Q22: =O22*P22 -> 5936
C23: Venice Island | D23: =$Q23*D$2 -> 1086891.3 | E23: =$Q23*E$2 -> 876066.1 | F23: =$Q23*F$2 -> 1152484.1 | G23: =$Q23*G$2 -> 674615.76 | H23: =$Q23*H$2 -> 501289.88 | I23: =$Q23*I$2 -> 470813.98 | J23: =$Q23*J$2 -> 288113.28 | K23: =$Q23*K$2 -> 105412.58 | ... M23: =$Q23*M$2 -> 32796.4 | N23: =SUM(D23:M23) -> 5293895.9 | O23: =INDEX(References!$C$2:$C$38,MATCH(C23,References!$A$2:$A$38,0)) -> 3094 | P23: 1 | Q23: =O23*P23 -> 3094
C24: Medford Island | D24: =$Q24*D$2 -> 409252.85 | E24: =$Q24*E$2 -> 329869.75 | F24: =$Q24*F$2 -> 433950.85 | G24: =$Q24*G$2 -> 254016.6 | H24: =$Q24*H$2 -> 188753.3 | I24: =$Q24*I$2 -> 177278.05 | J24: =$Q24*J$2 -> 108484.8 | K24: =$Q24*K$2 -> 39691.55 | ... M24: =$Q24*M$2 -> 12349 | N24: =SUM(D24:M24) -> 1993338.3 | O24: =INDEX(References!$C$2:$C$38,MATCH(C24,References!$A$2:$A$38,0)) -> 1165 | P24: 1 | Q24: =O24*P24 -> 1165
C25: Empire Tract | D25: =$Q25*D$2 -> 1273426.2 | E25: =$Q25*E$2 -> 1026418.7 | F25: =$Q25*F$2 -> 1350276.2 | G25: =$Q25*G$2 -> 790395 | H25: =$Q25*H$2 -> 587322.5 | I25: =$Q25*I$2 -> 551616.25 | J25: =$Q25*J$2 -> 337560 | K25: =$Q25*K$2 -> 123503.75 | ... M25: =$Q25*M$2 -> 38425 | N25: =SUM(D25:M25) -> 6202447.5 | O25: =INDEX(References!$C$2:$C$38,MATCH(C25,References!$A$2:$A$38,0)) -> 3625 | P25: 1 | Q25: =O25*P25 -> 3625
C26: King Island | D26: =$Q26*D$2 -> 1129748.6 | E26: =$Q26*E$2 -> 910610.4 | F26: =$Q26*F$2 -> 1197927.8 | G26: =$Q26*G$2 -> 701216.64 | H26: =$Q26*H$2 -> 521056.32 | I26: =$Q26*I$2 -> 489378.72 | J26: =$Q26*J$2 -> 299473.92 | K26: =$Q26*K$2 -> 109569.12 | ... M26: =$Q26*M$2 -> 34089.6 | N26: =SUM(D26:M26) -> 5502640.3 | O26: =INDEX(References!$C$2:$C$38,MATCH(C26,References!$A$2:$A$38,0)) -> 3216 | P26: 1 | Q26: =O26*P26 -> 3216
C27: Rindge Tract | D27: =$Q27*D$2 -> 2368748.5 | E27: =$Q27*E$2 -> 1909280.4 | F27: =$Q27*F$2 -> 2511700.1 | G27: =$Q27*G$2 -> 1470243.7 | H27: =$Q27*H$2 -> 1092500.9 | I27: =$Q27*I$2 -> 1026082.3 | J27: =$Q27*J$2 -> 627908.16 | K27: =$Q27*K$2 -> 229734.01 | ... M27: =$Q27*M$2 -> 71475.8 | N27: =SUM(D27:M27) -> 11537408 | O27: =INDEX(References!$C$2:$C$38,MATCH(C27,References!$A$2:$A$38,0)) -> 6743 | P27: 1 | Q27: =O27*P27 -> 6743
C28: Wright-Elmwood Tract | D28: =$Q28*D$2 -> 739465.45 | E28: =$Q28*E$2 -> 596030.75 | F28: =$Q28*F$2 -> 784091.45 | G28: =$Q28*G$2 -> 458974.2 | H28: =$Q28*H$2 -> 341052.1 | I28: =$Q28*I$2 -> 320317.85 | J28: =$Q28*J$2 -> 196017.6 | K28: =$Q28*K$2 -> 71717.35 | ... M28: =$Q28*M$2 -> 22313 | N28: =SUM(D28:M28) -> 3601697.1 | O28: =INDEX(References!$C$2:$C$38,MATCH(C28,References!$A$2:$A$38,0)) -> 2105 | P28: 1 | Q28: =O28*P28 -> 2105
C29: McDonald Tract | D29: =$Q29*D$2 -> 2128817.4 | E29: =$Q29*E$2 -> 1715889 | F29: =$Q29*F$2 -> 2257289.4 | G29: =$Q29*G$2 -> 1321322.4 | H29: =$Q29*H$2 -> 981841.2 | I29: =$Q29*I$2 -> 922150.2 | J29: =$Q29*J$2 -> 564307.2 | K29: =$Q29*K$2 -> 206464.2 | ... M29: =$Q29*M$2 -> 64236 | N29: =SUM(D29:M29) -> 10368781 | O29: =INDEX(References!$C$2:$C$38,MATCH(C29,References!$A$2:$A$38,0)) -> 6060 | P29: 1 | Q29: =O29*P29 -> 6060
C30: Jones Tract | D30: =$Q30*D$2 -> 4260093.8 | E30: =$Q30*E$2 -> 3433760 | F30: =$Q30*F$2 -> 4517186.2 | G30: =$Q30*G$2 -> 2644171.1 | H30: =$Q30*H$2 -> 1964816.5 | I30: =$Q30*I$2 -> 1845365.6 | J30: =$Q30*J$2 -> 1129266.2 | K30: =$Q30*K$2 -> 413166.89 | ... M30: =$Q30*M$2 -> 128546.2 | N30: =SUM(D30:M30) -> 20749540 | O30: =INDEX(References!$C$2:$C$38,MATCH(C30,References!$A$2:$A$38,0)) -> 12127 | P30: 1 | Q30: =O30*P30 -> 12127
C31: Rough and Ready | D31: =$Q31*D$2 -> 492157.29 | E31: =$Q31*E$2 -> 396693.15 | F31: =$Q31*F$2 -> 521858.49 | G31: =$Q31*G$2 -> 305474.04 | H31: =$Q31*H$2 -> 226990.02 | I31: =$Q31*I$2 -> 213190.17 | J31: =$Q31*J$2 -> 130461.12 | K31: =$Q31*K$2 -> 47732.07 | ... M31: =$Q31*M$2 -> 14850.6 | N31: =SUM(D31:M31) -> 2397139 | O31: =INDEX(References!$C$2:$C$38,MATCH(C31,References!$A$2:$A$38,0)) -> 1401 | P31: 1 | Q31: =O31*P31 -> 1401
C32: Roberts Island | D32: =$Q32*D$2 -> 12528055 | E32: =$Q32*E$2 -> 10097978 | F32: =$Q32*F$2 -> 13284111 | G32: =$Q32*G$2 -> 7775960.5 | H32: =$Q32*H$2 -> 5778119.3 | I32: =$Q32*I$2 -> 5426838.7 | J32: =$Q32*J$2 -> 3320938.6 | K32: =$Q32*K$2 -> 1215038.4 | ... M32: =$Q32*M$2 -> 378027.8 | N32: =SUM(D32:M32) -> 61020106 | O32: =INDEX(References!$C$2:$C$38,MATCH(C32,References!$A$2:$A$38,0)) -> 35663 | P32: 1 | Q32: =O32*P32 -> 35663
C33: Union Island | D33: =$Q33*D$2 -> 8694427.5 | E33: =$Q33*E$2 -> 7007962.5 | F33: =$Q33*F$2 -> 9219127.5 | G33: =$Q33*G$2 -> 5396490 | H33: =$Q33*H$2 -> 4009995 | I33: =$Q33*I$2 -> 3766207.5 | J33: =$Q33*J$2 -> 2304720 | K33: =$Q33*K$2 -> 843232.5 | ... M33: =$Q33*M$2 -> 262350 | N33: =SUM(D33:M33) -> 42347745 | O33: =INDEX(References!$C$2:$C$38,MATCH(C33,References!$A$2:$A$38,0)) -> 24750 | P33: 1 | Q33: =O33*P33 -> 24750
C34: Victoria Island | D34: =$Q34*D$2 -> 2526829 | E34: =$Q34*E$2 -> 2036697.9 | F34: =$Q34*F$2 -> 2679320.6 | G34: =$Q34*G$2 -> 1568361.7 | H34: =$Q34*H$2 -> 1165409.9 | I34: =$Q34*I$2 -> 1094558.8 | J34: =$Q34*J$2 -> 669812.16 | K34: =$Q34*K$2 -> 245065.51 | ... M34: =$Q34*M$2 -> 76245.8 | N34: =SUM(D34:M34) -> 12307367 | O34: =INDEX(References!$C$2:$C$38,MATCH(C34,References!$A$2:$A$38,0)) -> 7193 | P34: 1 | Q34: =O34*P34 -> 7193
... C42: Mandeville Island | D42: =$Q42*D$2 -> 1832679.9 | E42: =$Q42*E$2 -> 1477193.5 | F42: =$Q42*F$2 -> 1943280.3 | G42: =$Q42*G$2 -> 1137514.7 | H42: =$Q42*H$2 -> 845258.34 | I42: =$Q42*I$2 -> 793870.89 | J42: =$Q42*J$2 -> 485807.04 | K42: =$Q42*K$2 -> 177743.19 | ... M42: =$Q42*M$2 -> 55300.2 | N42: =SUM(D42:M42) -> 8926391.3 | O42: =INDEX(References!$C$2:$C$38,MATCH(C42,References!$A$2:$A$38,0)) -> 5217 | P42: 1 | Q42: =O42*P42 -> 5217
B43: Upland | C43: Meadows | D43: =$Q43*D$2 -> 1.2210524e+08 | E43: =$Q43*E$2 -> 98420392 | F43: =$Q43*F$2 -> 1.2947417e+08 | G43: =$Q43*G$2 -> 75788742 | H43: =$Q43*H$2 -> 56316694 | I43: =$Q43*I$2 -> 52892922 | J43: =$Q43*J$2 -> 32367674 | K43: =$Q43*K$2 -> 11842425 | ... N43: =$Q43*N$2 -> 5.9473515e+08 | O43: 347591 | P43: Upland (Upper Bound) | Q43: 347591
C44: Floodplain | D44: =$Q44*D$2 -> 1.0657155e+08 | E44: =$Q44*E$2 -> 85899782 | F44: =$Q44*F$2 -> 1.1300304e+08 | G44: =$Q44*G$2 -> 66147231 | H44: =$Q44*H$2 -> 49152331 | I44: =$Q44*I$2 -> 46164117 | J44: =$Q44*J$2 -> 28250001 | K44: =$Q44*K$2 -> 10335884 | ... N44: =$Q44*N$2 -> 5.1907556e+08 | O44: 303372 | P44: Upland (Upper Bound) | Q44: 303372
C45: Wetland | D45: =$Q45*D$2 -> 72718435 | E45: =$Q45*E$2 -> 58613183 | F45: =$Q45*F$2 -> 77106920 | G45: =$Q45*G$2 -> 45135152 | H45: =$Q45*H$2 -> 33538788 | I45: =$Q45*I$2 -> 31499799 | J45: =$Q45*J$2 -> 19276212 | K45: =$Q45*K$2 -> 7052626.3 | ... N45: =$Q45*N$2 -> 3.5418798e+08 | O45: 207004 | P45: Upland (Upper Bound) | Q45: 207004
C46: Totals summed (ECO + NGW + NGW Upland) | D46: =SUM(D4:D45) -> 4.0401024e+08 | E46: =SUM(E4:E45) -> 3.2564405e+08 | F46: =SUM(F4:F45) -> 4.2839185e+08 | G46: =SUM(G4:G45) -> 2.507626e+08 | H46: =SUM(H4:H45) -> 1.8633533e+08 | I46: =SUM(I4:I45) -> 1.7500708e+08 | J46: =SUM(J4:J45) -> 1.0709509e+08 | K46: =SUM(K4:K45) -> 39183093 | ... O46: =SUM(O4:O45) -> 1150076.1 | Q46: =SUM(Q4:Q45) -> 1150076.1
C47: Totals ECO (Suisun + Franks) Excluding NGW | D47: =D4+D10 -> 15208789 | E47: =E4+E10 -> 12258728 | F47: =F4+F10 -> 16126624 | G47: =G4+G10 -> 9439848.2 | H47: =H4+H10 -> 7014512 | I47: =I4+I10 -> 6588065 | J47: =J4+J10 -> 4031547.7 | K47: =K4+K10 -> 1475030.4 | ... N47: =N4+N10 -> 74077092 | O47: =SUM(O4+O10) -> 43294.112 | Q47: 43294
C48: Totals (ECO + NGW) - NGW Upland | D48: =SUM(D4:D42) -> 1.0261501e+08 | E48: =SUM(E4:E42) -> 82710695 | F48: =SUM(F4:F42) -> 1.0880772e+08 | G48: =SUM(G4:G42) -> 63691471 | H48: =SUM(H4:H42) -> 47327518 | I48: =SUM(I4:I42) -> 44450244 | J48: =SUM(J4:J42) -> 27201201 | K48: =SUM(K4:K42) -> 9952157.4 | ... N48: =SUM(N4:N42) -> 4.9980453e+08 | O48: =SUM(O4:O44) -> 943072.11 | Q48: =SUM(Q4:Q42) -> 292109.11
...

Sheet 100% Restoration ($)
H1: Benefits US$/acre/yr (2025)
A2: Region | B2: Island | C2: ArcGIS object ID | D2: Acres | E2: Elevation (categorical) | F2: Landcover Type (R = Rice; MW = Managed Wetland) | G2: Wetland function | H2: Flood control | I2: Recreational fishing | J2: Amenity/recreation | K2: Water filtering | L2: Biodiversity | M2: Habitat nursery | N2: Recreational hunting | O2: Water supply | P2: Materials | Q2: Fuel wood | R2: Sum of all ten
A3: Suisun Marsh | B3: Suisun | D3: 41914 | F3: Tidal | H3: =IF($F3="Tidal", $D3*$F$52, 0) -> 14723969 | I3: =IF($F3="Tidal", $D3*$F$52, 0) -> 14723969 | J3: =IF($F3="Tidal", $D3*$F$52, 0) -> 14723969 | K3: =IF($F3="Tidal", $D3*$F$52, 0) -> 14723969 | L3: =IF($F3="Tidal", $D3*$F$52, 0) -> 14723969 | M3: =IF($F3="Tidal", $D3*$F$52, 0) -> 14723969 | N3: =IF($F3="Tidal", $D3*$F$52, 0) -> 14723969 | O3: =IF($F3="Tidal", $D3*$F$52, 0) -> 14723969 | ... R3: =IF($F3="Tidal", $D3*$F$52, 0) -> 14723969
A4: North Delta | B4: Grand Island | C4: 80 | D4: 16543 | E4: Mimimal | F4: MW | G4: Grand Island | H4: =IF($F4="MW", $D4*$F$52, 0) -> 5811390.5 | I4: =IF($F4="MW", $D4*$F$53, 0) -> 4684150.4 | J4: =IF($F4="MW", $D4*$F$54, 0) -> 6162102.1 | K4: =IF($F4="MW", $D4*$F$55, 0) -> 3607035.7 | L4: =IF($F4="MW", $D4*$F$56, 0) -> 2680296.9 | M4: =IF($F4="MW", $D4*$F$57, 0) -> 2517348.3 | N4: =IF($F4="MW", $D4*$F$58, 0) -> 1540484.2 | O4: =IF($F4="MW", $D4*$F$59, 0) -> 563620.01 | P4: =IF($F4="MW", $D4*$F$60, 0) -> 563620.01 | Q4: =IF($F4="MW", $D4*$F$61, 0) -> 175355.8 | R4: =IF($F4="MW", $D4*$F$62, 0) -> 28305404
A5: North Delta | B5: Ryer Island | C5: 76 | D5: 11798 | E5: Minimal | F5: MW | G5: Ryer Island | H5: =IF($F5="MW", $D5*$F$52, 0) -> 4144519.4 | I5: =IF($F5="MW", $D5*$F$53, 0) -> 3340603.7 | J5: =IF($F5="MW", $D5*$F$54, 0) -> 4394637 | K5: =IF($F5="MW", $D5*$F$55, 0) -> 2572435.9 | L5: =IF($F5="MW", $D5*$F$56, 0) -> 1911512 | M5: =IF($F5="MW", $D5*$F$57, 0) -> 1795301.7 | N5: =IF($F5="MW", $D5*$F$58, 0) -> 1098629.8 | O5: =IF($F5="MW", $D5*$F$59, 0) -> 401957.86 | P5: =IF($F5="MW", $D5*$F$60, 0) -> 401957.86 | Q5: =IF($F5="MW", $D5*$F$61, 0) -> 125058.8 | R5: =IF($F5="MW", $D5*$F$62, 0) -> 20186614
A6: North Delta | B6: Tyler Island | C6: 62 | D6: 8799 | E6: Minimal | F6: MW | G6: Tyler Island | H6: =IF($F6="MW", $D6*$F$52, 0) -> 3091000.7 | I6: =IF($F6="MW", $D6*$F$53, 0) -> 2491436.8 | J6: =IF($F6="MW", $D6*$F$54, 0) -> 3277539.5 | K6: =IF($F6="MW", $D6*$F$55, 0) -> 1918534 | L6: =IF($F6="MW", $D6*$F$56, 0) -> 1425614 | M6: =IF($F6="MW", $D6*$F$57, 0) -> 1338943.8 | N6: =IF($F6="MW", $D6*$F$58, 0) -> 819362.88 | O6: =IF($F6="MW", $D6*$F$59, 0) -> 299781.93 | P6: =IF($F6="MW", $D6*$F$60, 0) -> 299781.93 | Q6: =IF($F6="MW", $D6*$F$61, 0) -> 93269.4 | R6: =IF($F6="MW", $D6*$F$62, 0) -> 15055265
A7: North Delta | B7: Staten Island | C7: 61 | D7: 9111 | E7: Moderate | F7: MW | G7: Staten Island | H7: =IF($F7="MW", $D7*$F$52, 0) -> 3200603.2 | I7: =IF($F7="MW", $D7*$F$53, 0) -> 2579779.6 | J7: =IF($F7="MW", $D7*$F$54, 0) -> 3393756.4 | K7: =IF($F7="MW", $D7*$F$55, 0) -> 1986562.4 | L7: =IF($F7="MW", $D7*$F$56, 0) -> 1476164.2 | M7: =IF($F7="MW", $D7*$F$57, 0) -> 1386420.9 | N7: =IF($F7="MW", $D7*$F$58, 0) -> 848416.32 | O7: =IF($F7="MW", $D7*$F$59, 0) -> 310411.77 | P7: =IF($F7="MW", $D7*$F$60, 0) -> 310411.77 | Q7: =IF($F7="MW", $D7*$F$61, 0) -> 96576.6 | R7: =IF($F7="MW", $D7*$F$62, 0) -> 15589103
A8: North-Central | B8: Brannan Island | C8: 116 | D8: 12907 | E8: Severe | F8: MW | G8: Brannan Island | H8: =IF($F8="MW", $D8*$F$52, 0) -> 4534100 | I8: =IF($F8="MW", $D8*$F$53, 0) -> 3654617 | J8: =IF($F8="MW", $D8*$F$54, 0) -> 4807728.4 | K8: =IF($F8="MW", $D8*$F$55, 0) -> 2814242.3 | L8: =IF($F8="MW", $D8*$F$56, 0) -> 2091192.1 | M8: =IF($F8="MW", $D8*$F$57, 0) -> 1964058.2 | N8: =IF($F8="MW", $D8*$F$58, 0) -> 1201899.8 | O8: =IF($F8="MW", $D8*$F$59, 0) -> 439741.49 | P8: =IF($F8="MW", $D8*$F$60, 0) -> 439741.49 | Q8: =IF($F8="MW", $D8*$F$61, 0) -> 136814.2 | R8: =IF($F8="MW", $D8*$F$62, 0) -> 22084135
A9: South Delta | B9: Bouldin Island | C9: 57 | D9: 5936 | E9: Severe | F9: MW | G9: Bouldin Island | H9: =IF($F9="MW", $D9*$F$52, 0) -> 2085257.4 | I9: =IF($F9="MW", $D9*$F$53, 0) -> 1680778.4 | J9: =IF($F9="MW", $D9*$F$54, 0) -> 2211100.6 | K9: =IF($F9="MW", $D9*$F$55, 0) -> 1294285.4 | L9: =IF($F9="MW", $D9*$F$56, 0) -> 961750.72 | M9: =IF($F9="MW", $D9*$F$57, 0) -> 903281.12 | N9: =IF($F9="MW", $D9*$F$58, 0) -> 552760.32 | O9: =IF($F9="MW", $D9*$F$59, 0) -> 202239.52 | P9: =IF($F9="MW", $D9*$F$60, 0) -> 202239.52 | Q9: =IF($F9="MW", $D9*$F$61, 0) -> 62921.6 | R9: =IF($F9="MW", $D9*$F$62, 0) -> 10156615
A10: South Delta | B10: Venice Island | C10: 49 | D10: 3094 | E10: Severe | F10: MW | G10: Venice Island | H10: =IF($F10="MW", $D10*$F$52, 0) -> 1086891.3 | I10: =IF($F10="MW", $D10*$F$53, 0) -> 876066.1 | J10: =IF($F10="MW", $D10*$F$54, 0) -> 1152484.1 | K10: =IF($F10="MW", $D10*$F$55, 0) -> 674615.76 | L10: =IF($F10="MW", $D10*$F$56, 0) -> 501289.88 | M10: =IF($F10="MW", $D10*$F$57, 0) -> 470813.98 | N10: =IF($F10="MW", $D10*$F$58, 0) -> 288113.28 | O10: =IF($F10="MW", $D10*$F$59, 0) -> 105412.58 | P10: =IF($F10="MW", $D10*$F$60, 0) -> 105412.58 | Q10: =IF($F10="MW", $D10*$F$61, 0) -> 32796.4 | R10: =IF($F10="MW", $D10*$F$62, 0) -> 5293895.9
A11: South Delta | B11: Medford Island | C11: 41 | D11: 1165 | E11: Moderate | F11: MW | G11: Medford Island | H11: =IF($F11="MW", $D11*$F$52, 0) -> 409252.85 | I11: =IF($F11="MW", $D11*$F$53, 0) -> 329869.75 | J11: =IF($F11="MW", $D11*$F$54, 0) -> 433950.85 | K11: =IF($F11="MW", $D11*$F$55, 0) -> 254016.6 | L11: =IF($F11="MW", $D11*$F$56, 0) -> 188753.3 | M11: =IF($F11="MW", $D11*$F$57, 0) -> 177278.05 | N11: =IF($F11="MW", $D11*$F$58, 0) -> 108484.8 | O11: =IF($F11="MW", $D11*$F$59, 0) -> 39691.55 | P11: =IF($F11="MW", $D11*$F$60, 0) -> 39691.55 | Q11: =IF($F11="MW", $D11*$F$61, 0) -> 12349 | R11: =IF($F11="MW", $D11*$F$62, 0) -> 1993338.3
A12: South Delta | B12: Empire Tract | C12: 50 | D12: 3625 | E12: Moderate | F12: MW | G12: Empire Tract | H12: =IF($F12="MW", $D12*$F$52, 0) -> 1273426.2 | I12: =IF($F12="MW", $D12*$F$53, 0) -> 1026418.7 | J12: =IF($F12="MW", $D12*$F$54, 0) -> 1350276.2 | K12: =IF($F12="MW", $D12*$F$55, 0) -> 790395 | L12: =IF($F12="MW", $D12*$F$56, 0) -> 587322.5 | M12: =IF($F12="MW", $D12*$F$57, 0) -> 551616.25 | N12: =IF($F12="MW", $D12*$F$58, 0) -> 337560 | O12: =IF($F12="MW", $D12*$F$59, 0) -> 123503.75 | P12: =IF($F12="MW", $D12*$F$60, 0) -> 123503.75 | Q12: =IF($F12="MW", $D12*$F$61, 0) -> 38425 | R12: =IF($F12="MW", $D12*$F$62, 0) -> 6202447.5
A13: South Delta | B13: King Island | C13: 46 | D13: 3216 | E13: Minimal | F13: MW | G13: King Island | H13: =IF($F13="MW", $D13*$F$52, 0) -> 1129748.6 | I13: =IF($F13="MW", $D13*$F$53, 0) -> 910610.4 | J13: =IF($F13="MW", $D13*$F$54, 0) -> 1197927.8 | K13: =IF($F13="MW", $D13*$F$55, 0) -> 701216.64 | L13: =IF($F13="MW", $D13*$F$56, 0) -> 521056.32 | M13: =IF($F13="MW", $D13*$F$57, 0) -> 489378.72 | N13: =IF($F13="MW", $D13*$F$58, 0) -> 299473.92 | O13: =IF($F13="MW", $D13*$F$59, 0) -> 109569.12 | P13: =IF($F13="MW", $D13*$F$60, 0) -> 109569.12 | Q13: =IF($F13="MW", $D13*$F$61, 0) -> 34089.6 | R13: =IF($F13="MW", $D13*$F$62, 0) -> 5502640.3
A14: North-South | B14: Terminous Tract | C14: 58 | D14: 10358 | E14: Minimal | F14: MW | G14: Terminous Tract | H14: =IF($F14="MW", $D14*$F$52, 0) -> 3638661.8 | I14: =IF($F14="MW", $D14*$F$53, 0) -> 2932867.7 | J14: =IF($F14="MW", $D14*$F$54, 0) -> 3858251.4 | K14: =IF($F14="MW", $D14*$F$55, 0) -> 2258458.3 | L14: =IF($F14="MW", $D14*$F$56, 0) -> 1678203.2 | M14: =IF($F14="MW", $D14*$F$57, 0) -> 1576176.9 | N14: =IF($F14="MW", $D14*$F$58, 0) -> 964536.96 | O14: =IF($F14="MW", $D14*$F$59, 0) -> 352897.06 | P14: =IF($F14="MW", $D14*$F$60, 0) -> 352897.06 | Q14: =IF($F14="MW", $D14*$F$61, 0) -> 109794.8 | R14: =IF($F14="MW", $D14*$F$62, 0) -> 17722745
A15: South Delta | B15: Rindge Tract | C15: 40 | D15: 6743 | E15: Moderate | F15: MW | G15: Rindge Tract | H15: =IF($F15="MW", $D15*$F$52, 0) -> 2368748.5 | I15: =IF($F15="MW", $D15*$F$53, 0) -> 1909280.4 | J15: =IF($F15="MW", $D15*$F$54, 0) -> 2511700.1 | K15: =IF($F15="MW", $D15*$F$55, 0) -> 1470243.7 | L15: =IF($F15="MW", $D15*$F$56, 0) -> 1092500.9 | M15: =IF($F15="MW", $D15*$F$57, 0) -> 1026082.3 | N15: =IF($F15="MW", $D15*$F$58, 0) -> 627908.16 | O15: =IF($F15="MW", $D15*$F$59, 0) -> 229734.01 | P15: =IF($F15="MW", $D15*$F$60, 0) -> 229734.01 | Q15: =IF($F15="MW", $D15*$F$61, 0) -> 71475.8 | R15: =IF($F15="MW", $D15*$F$62, 0) -> 11537408
... A19: South Delta | B19: Rough and Ready | C19: 25 | D19: 1401 | E19: Minimal | F19: MW | G19: Rough and Ready | H19: =IF($F19="MW", $D19*$F$52, 0) -> 492157.29 | I19: =IF($F19="MW", $D19*$F$53, 0) -> 396693.15 | J19: =IF($F19="MW", $D19*$F$54, 0) -> 521858.49 | K19: =IF($F19="MW", $D19*$F$55, 0) -> 305474.04 | L19: =IF($F19="MW", $D19*$F$56, 0) -> 226990.02 | M19: =IF($F19="MW", $D19*$F$57, 0) -> 213190.17 | N19: =IF($F19="MW", $D19*$F$58, 0) -> 130461.12 | O19: =IF($F19="MW", $D19*$F$59, 0) -> 47732.07 | P19: =IF($F19="MW", $D19*$F$60, 0) -> 47732.07 | Q19: =IF($F19="MW", $D19*$F$61, 0) -> 14850.6 | R19: =IF($F19="MW", $D19*$F$62, 0) -> 2397139
A20: South Delta | B20: Roberts Island | C20: 31 + 22 + 12+23+ 8 | D20: 35663 | E20: Minimal | F20: MW | G20: Roberts Island | H20: =IF($F20="MW", $D20*$F$52, 0) -> 12528055 | I20: =IF($F20="MW", $D20*$F$53, 0) -> 10097978 | J20: =IF($F20="MW", $D20*$F$54, 0) -> 13284111 | K20: =IF($F20="MW", $D20*$F$55, 0) -> 7775960.5 | L20: =IF($F20="MW", $D20*$F$56, 0) -> 5778119.3 | M20: =IF($F20="MW", $D20*$F$57, 0) -> 5426838.7 | N20: =IF($F20="MW", $D20*$F$58, 0) -> 3320938.6 | O20: =IF($F20="MW", $D20*$F$59, 0) -> 1215038.4 | P20: =IF($F20="MW", $D20*$F$60, 0) -> 1215038.4 | Q20: =IF($F20="MW", $D20*$F$61, 0) -> 378027.8 | R20: =IF($F20="MW", $D20*$F$62, 0) -> 61020106
A21: South Delta | B21: Union Island | C21: 9 | D21: 24750 | E21: Minimal | F21: MW | G21: Union Island | H21: =IF($F21="MW", $D21*$F$52, 0) -> 8694427.5 | I21: =IF($F21="MW", $D21*$F$53, 0) -> 7007962.5 | J21: =IF($F21="MW", $D21*$F$54, 0) -> 9219127.5 | K21: =IF($F21="MW", $D21*$F$55, 0) -> 5396490 | L21: =IF($F21="MW", $D21*$F$56, 0) -> 4009995 | M21: =IF($F21="MW", $D21*$F$57, 0) -> 3766207.5 | N21: =IF($F21="MW", $D21*$F$58, 0) -> 2304720 | O21: =IF($F21="MW", $D21*$F$59, 0) -> 843232.5 | P21: =IF($F21="MW", $D21*$F$60, 0) -> 843232.5 | Q21: =IF($F21="MW", $D21*$F$61, 0) -> 262350 | R21: =IF($F21="MW", $D21*$F$62, 0) -> 42347745
A22: South Delta | B22: Victoria Island | C22: 10 | D22: 7193 | E22: Minimal | F22: MW | G22: Victoria Island | H22: =IF($F22="MW", $D22*$F$52, 0) -> 2526829 | I22: =IF($F22="MW", $D22*$F$53, 0) -> 2036697.9 | J22: =IF($F22="MW", $D22*$F$54, 0) -> 2679320.6 | K22: =IF($F22="MW", $D22*$F$55, 0) -> 1568361.7 | L22: =IF($F22="MW", $D22*$F$56, 0) -> 1165409.9 | M22: =IF($F22="MW", $D22*$F$57, 0) -> 1094558.8 | N22: =IF($F22="MW", $D22*$F$58, 0) -> 669812.16 | O22: =IF($F22="MW", $D22*$F$59, 0) -> 245065.51 | P22: =IF($F22="MW", $D22*$F$60, 0) -> 245065.51 | Q22: =IF($F22="MW", $D22*$F$61, 0) -> 76245.8 | R22: =IF($F22="MW", $D22*$F$62, 0) -> 12307367
A23: South Delta | B23: Woodward Island | C23: 18 | D23: 1809 | E23: Minimal | F23: MW | G23: Woodward Island | H23: =IF($F23="MW", $D23*$F$52, 0) -> 635483.61 | I23: =IF($F23="MW", $D23*$F$53, 0) -> 512218.35 | J23: =IF($F23="MW", $D23*$F$54, 0) -> 673834.41 | K23: =IF($F23="MW", $D23*$F$55, 0) -> 394434.36 | L23: =IF($F23="MW", $D23*$F$56, 0) -> 293094.18 | M23: =IF($F23="MW", $D23*$F$57, 0) -> 275275.53 | N23: =IF($F23="MW", $D23*$F$58, 0) -> 168454.08 | O23: =IF($F23="MW", $D23*$F$59, 0) -> 61632.63 | P23: =IF($F23="MW", $D23*$F$60, 0) -> 61632.63 | Q23: =IF($F23="MW", $D23*$F$61, 0) -> 19175.4 | R23: =IF($F23="MW", $D23*$F$62, 0) -> 3095235.2
A24: South Delta | B24: Coney Island | C24: 6 | D24: 965 | E24: Minimal | F24: MW | G24: Coney Island | H24: =IF($F24="MW", $D24*$F$52, 0) -> 338994.85 | I24: =IF($F24="MW", $D24*$F$53, 0) -> 273239.75 | J24: =IF($F24="MW", $D24*$F$54, 0) -> 359452.85 | K24: =IF($F24="MW", $D24*$F$55, 0) -> 210408.6 | L24: =IF($F24="MW", $D24*$F$56, 0) -> 156349.3 | M24: =IF($F24="MW", $D24*$F$57, 0) -> 146844.05 | N24: =IF($F24="MW", $D24*$F$58, 0) -> 89860.8 | O24: =IF($F24="MW", $D24*$F$59, 0) -> 32877.55 | P24: =IF($F24="MW", $D24*$F$60, 0) -> 32877.55 | Q24: =IF($F24="MW", $D24*$F$61, 0) -> 10229 | R24: =IF($F24="MW", $D24*$F$62, 0) -> 1651134.3
A25: South Delta | B25: Orowood Tract | C25: 20 | D25: 2383 | E25: Minimal | F25: MW | G25: Orowood Tract | H25: =IF($F25="MW", $D25*$F$52, 0) -> 837124.07 | I25: =IF($F25="MW", $D25*$F$53, 0) -> 674746.45 | J25: =IF($F25="MW", $D25*$F$54, 0) -> 887643.67 | K25: =IF($F25="MW", $D25*$F$55, 0) -> 519589.32 | L25: =IF($F25="MW", $D25*$F$56, 0) -> 386093.66 | M25: =IF($F25="MW", $D25*$F$57, 0) -> 362621.11 | N25: =IF($F25="MW", $D25*$F$58, 0) -> 221904.96 | O25: =IF($F25="MW", $D25*$F$59, 0) -> 81188.81 | P25: =IF($F25="MW", $D25*$F$60, 0) -> 81188.81 | Q25: =IF($F25="MW", $D25*$F$61, 0) -> 25259.8 | R25: =IF($F25="MW", $D25*$F$62, 0) -> 4077360.7
A26: South Delta | B26: Palm Tract | C26: 27 | D26: 2470 | E26: Minimal | F26: MW | G26: Palm Tract | H26: =IF($F26="MW", $D26*$F$52, 0) -> 867686.3 | I26: =IF($F26="MW", $D26*$F$53, 0) -> 699380.5 | J26: =IF($F26="MW", $D26*$F$54, 0) -> 920050.3 | K26: =IF($F26="MW", $D26*$F$55, 0) -> 538558.8 | L26: =IF($F26="MW", $D26*$F$56, 0) -> 400189.4 | M26: =IF($F26="MW", $D26*$F$57, 0) -> 375859.9 | N26: =IF($F26="MW", $D26*$F$58, 0) -> 230006.4 | O26: =IF($F26="MW", $D26*$F$59, 0) -> 84152.9 | P26: =IF($F26="MW", $D26*$F$60, 0) -> 84152.9 | Q26: =IF($F26="MW", $D26*$F$61, 0) -> 26182 | R26: =IF($F26="MW", $D26*$F$62, 0) -> 4226219.4
A27: South Delta | B27: Bacon Island | C27: 32 | D27: 5533 | E27: Severe | F27: MW | G27: Bacon Island | H27: =IF($F27="MW", $D27*$F$52, 0) -> 1943687.6 | I27: =IF($F27="MW", $D27*$F$53, 0) -> 1566668.9 | J27: =IF($F27="MW", $D27*$F$54, 0) -> 2060987.2 | K27: =IF($F27="MW", $D27*$F$55, 0) -> 1206415.3 | L27: =IF($F27="MW", $D27*$F$56, 0) -> 896456.66 | M27: =IF($F27="MW", $D27*$F$57, 0) -> 841956.61 | N27: =IF($F27="MW", $D27*$F$58, 0) -> 515232.96 | O27: =IF($F27="MW", $D27*$F$59, 0) -> 188509.31 | P27: =IF($F27="MW", $D27*$F$60, 0) -> 188509.31 | Q27: =IF($F27="MW", $D27*$F$61, 0) -> 58649.8 | R27: =IF($F27="MW", $D27*$F$62, 0) -> 9467073.7
A28: South Delta | B28: Holland Tract | C28: 35 | D28: 4214 | E28: Minimal | F28: MW | G28: Holland Tract | H28: =IF($F28="MW", $D28*$F$52, 0) -> 1480336.1 | I28: =IF($F28="MW", $D28*$F$53, 0) -> 1193194.1 | J28: =IF($F28="MW", $D28*$F$54, 0) -> 1569672.9 | K28: =IF($F28="MW", $D28*$F$55, 0) -> 918820.56 | L28: =IF($F28="MW", $D28*$F$56, 0) -> 682752.28 | M28: =IF($F28="MW", $D28*$F$57, 0) -> 641244.38 | N28: =IF($F28="MW", $D28*$F$58, 0) -> 392407.68 | O28: =IF($F28="MW", $D28*$F$59, 0) -> 143570.98 | P28: =IF($F28="MW", $D28*$F$60, 0) -> 143570.98 | Q28: =IF($F28="MW", $D28*$F$61, 0) -> 44668.4 | R28: =IF($F28="MW", $D28*$F$62, 0) -> 7210238.3
A29: South Delta | B29: Quinby Island | C29: 36 | D29: 774 | E29: Moderate | F29: MW | G29: Quinby Island | H29: =IF($F29="MW", $D29*$F$52, 0) -> 271898.46 | I29: =IF($F29="MW", $D29*$F$53, 0) -> 219158.1 | J29: =IF($F29="MW", $D29*$F$54, 0) -> 288307.26 | K29: =IF($F29="MW", $D29*$F$55, 0) -> 168762.96 | L29: =IF($F29="MW", $D29*$F$56, 0) -> 125403.48 | M29: =IF($F29="MW", $D29*$F$57, 0) -> 117779.58 | N29: =IF($F29="MW", $D29*$F$58, 0) -> 72074.88 | O29: =IF($F29="MW", $D29*$F$59, 0) -> 26370.18 | P29: =IF($F29="MW", $D29*$F$60, 0) -> 26370.18 | Q29: =IF($F29="MW", $D29*$F$61, 0) -> 8204.4 | R29: =IF($F29="MW", $D29*$F$62, 0) -> 1324329.5
A30: South Delta | B30: Mandeville Island | C30: 44 | D30: 5217 | E30: Severe | F30: MW | G30: Mandeville Island | H30: =IF($F30="MW", $D30*$F$52, 0) -> 1832679.9 | I30: =IF($F30="MW", $D30*$F$53, 0) -> 1477193.5 | J30: =IF($F30="MW", $D30*$F$54, 0) -> 1943280.3 | K30: =IF($F30="MW", $D30*$F$55, 0) -> 1137514.7 | L30: =IF($F30="MW", $D30*$F$56, 0) -> 845258.34 | M30: =IF($F30="MW", $D30*$F$57, 0) -> 793870.89 | N30: =IF($F30="MW", $D30*$F$58, 0) -> 485807.04 | O30: =IF($F30="MW", $D30*$F$59, 0) -> 177743.19 | P30: =IF($F30="MW", $D30*$F$60, 0) -> 177743.19 | Q30: =IF($F30="MW", $D30*$F$61, 0) -> 55300.2 | R30: =IF($F30="MW", $D30*$F$62, 0) -> 8926391.3
A31: Central Delta | B31: Franks Tract | D31: 1380 | E31: Flooded | F31: MW | G31: Franks Tract | H31: =IF($F31="MW", $D31*$F$52, 0) -> 484780.2 | I31: =IF($F31="MW", $D31*$F$53, 0) -> 390747 | J31: =IF($F31="MW", $D31*$F$54, 0) -> 514036.2 | K31: =IF($F31="MW", $D31*$F$55, 0) -> 300895.2 | L31: =IF($F31="MW", $D31*$F$56, 0) -> 223587.6 | M31: =IF($F31="MW", $D31*$F$57, 0) -> 209994.6 | N31: =IF($F31="MW", $D31*$F$58, 0) -> 128505.6 | O31: =IF($F31="MW", $D31*$F$59, 0) -> 47016.6 | P31: =IF($F31="MW", $D31*$F$60, 0) -> 47016.6 | Q31: =IF($F31="MW", $D31*$F$61, 0) -> 14628 | R31: =IF($F31="MW", $D31*$F$62, 0) -> 2361207.6
A32: Central Delta | B32: Bethel Island | C32: 39 | D32: 3220 | E32: Minimal | F32: MW | G32: Bethel Island | H32: =IF($F32="MW", $D32*$F$52, 0) -> 1131153.8 | I32: =IF($F32="MW", $D32*$F$53, 0) -> 911743 | J32: =IF($F32="MW", $D32*$F$54, 0) -> 1199417.8 | K32: =IF($F32="MW", $D32*$F$55, 0) -> 702088.8 | L32: =IF($F32="MW", $D32*$F$56, 0) -> 521704.4 | M32: =IF($F32="MW", $D32*$F$57, 0) -> 489987.4 | N32: =IF($F32="MW", $D32*$F$58, 0) -> 299846.4 | O32: =IF($F32="MW", $D32*$F$59, 0) -> 109705.4 | P32: =IF($F32="MW", $D32*$F$60, 0) -> 109705.4 | Q32: =IF($F32="MW", $D32*$F$61, 0) -> 34132 | R32: =IF($F32="MW", $D32*$F$62, 0) -> 5509484.4
A33: Central Delta | B33: Jersey Island | C33: 43 | D33: 3459 | E33: Moderate | F33: MW | G33: Jersey Island | H33: =IF($F33="MW", $D33*$F$52, 0) -> 1215112.1 | I33: =IF($F33="MW", $D33*$F$53, 0) -> 979415.85 | J33: =IF($F33="MW", $D33*$F$54, 0) -> 1288442.9 | K33: =IF($F33="MW", $D33*$F$55, 0) -> 754200.36 | L33: =IF($F33="MW", $D33*$F$56, 0) -> 560427.18 | M33: =IF($F33="MW", $D33*$F$57, 0) -> 526356.03 | N33: =IF($F33="MW", $D33*$F$58, 0) -> 322102.08 | O33: =IF($F33="MW", $D33*$F$59, 0) -> 117848.13 | P33: =IF($F33="MW", $D33*$F$60, 0) -> 117848.13 | Q33: =IF($F33="MW", $D33*$F$61, 0) -> 36665.4 | R33: =IF($F33="MW", $D33*$F$62, 0) -> 5918418.2
A34: Central Delta | B34: Webb Tract | C34: 53 | D34: 5436 | E34: Severe | F34: MW | G34: Webb Tract | H34: =IF($F34="MW", $D34*$F$52, 0) -> 1909612.4 | I34: =IF($F34="MW", $D34*$F$53, 0) -> 1539203.4 | J34: =IF($F34="MW", $D34*$F$54, 0) -> 2024855.6 | K34: =IF($F34="MW", $D34*$F$55, 0) -> 1185265.4 | L34: =IF($F34="MW", $D34*$F$56, 0) -> 880740.72 | M34: =IF($F34="MW", $D34*$F$57, 0) -> 827196.12 | N34: =IF($F34="MW", $D34*$F$58, 0) -> 506200.32 | O34: =IF($F34="MW", $D34*$F$59, 0) -> 185204.52 | P34: =IF($F34="MW", $D34*$F$60, 0) -> 185204.52 | Q34: =IF($F34="MW", $D34*$F$61, 0) -> 57621.6 | R34: =IF($F34="MW", $D34*$F$62, 0) -> 9301104.7
A35: Central Delta | B35: Bradford Island | C35: 52 | D35: 2135 | E35: Severe | F35: MW | G35: Bradford Island | H35: =IF($F35="MW", $D35*$F$52, 0) -> 750004.15 | I35: =IF($F35="MW", $D35*$F$53, 0) -> 604525.25 | J35: =IF($F35="MW", $D35*$F$54, 0) -> 795266.15 | K35: =IF($F35="MW", $D35*$F$55, 0) -> 465515.4 | L35: =IF($F35="MW", $D35*$F$56, 0) -> 345912.7 | M35: =IF($F35="MW", $D35*$F$57, 0) -> 324882.95 | N35: =IF($F35="MW", $D35*$F$58, 0) -> 198811.2 | O35: =IF($F35="MW", $D35*$F$59, 0) -> 72739.45 | P35: =IF($F35="MW", $D35*$F$60, 0) -> 72739.45 | Q35: =IF($F35="MW", $D35*$F$61, 0) -> 22631 | R35: =IF($F35="MW", $D35*$F$62, 0) -> 3653027.7
A36: Central Delta | B36: Sherman Island | C36: 54 | D36: 10178 | E36: Severe | F36: MW | G36: Sherman Island | H36: =IF($F36="MW", $D36*$F$52, 0) -> 3575429.6 | I36: =IF($F36="MW", $D36*$F$53, 0) -> 2881900.7 | J36: =IF($F36="MW", $D36*$F$54, 0) -> 3791203.2 | K36: =IF($F36="MW", $D36*$F$55, 0) -> 2219211.1 | L36: =IF($F36="MW", $D36*$F$56, 0) -> 1649039.6 | M36: =IF($F36="MW", $D36*$F$57, 0) -> 1548786.3 | N36: =IF($F36="MW", $D36*$F$58, 0) -> 947775.36 | O36: =IF($F36="MW", $D36*$F$59, 0) -> 346764.46 | P36: =IF($F36="MW", $D36*$F$60, 0) -> 346764.46 | Q36: =IF($F36="MW", $D36*$F$61, 0) -> 107886.8 | R36: =IF($F36="MW", $D36*$F$62, 0) -> 17414762
A37: Central Delta | B37: Twitchell Island | C37: 55 | D37: 3559 | E37: Severe | F37: MW | G37: Twitchell Island | H37: =IF($F37="MW", $D37*$F$52, 0) -> 1250241.1 | I37: =IF($F37="MW", $D37*$F$53, 0) -> 1007730.8 | J37: =IF($F37="MW", $D37*$F$54, 0) -> 1325691.9 | K37: =IF($F37="MW", $D37*$F$55, 0) -> 776004.36 | L37: =IF($F37="MW", $D37*$F$56, 0) -> 576629.18 | M37: =IF($F37="MW", $D37*$F$57, 0) -> 541573.03 | N37: =IF($F37="MW", $D37*$F$58, 0) -> 331414.08 | O37: =IF($F37="MW", $D37*$F$59, 0) -> 121255.13 | P37: =IF($F37="MW", $D37*$F$60, 0) -> 121255.13 | Q37: =IF($F37="MW", $D37*$F$61, 0) -> 37725.4 | R37: =IF($F37="MW", $D37*$F$62, 0) -> 6089520.2
A38: North Delta | B38: Dead Horse Island | C38: 63 | D38: 208 | E38: Minimal | F38: MW | G38: Dead Horse Island | H38: =IF($F38="MW", $D38*$F$52, 0) -> 73068.32 | I38: =IF($F38="MW", $D38*$F$53, 0) -> 58895.2 | J38: =IF($F38="MW", $D38*$F$54, 0) -> 77477.92 | K38: =IF($F38="MW", $D38*$F$55, 0) -> 45352.32 | L38: =IF($F38="MW", $D38*$F$56, 0) -> 33700.16 | M38: =IF($F38="MW", $D38*$F$57, 0) -> 31651.36 | N38: =IF($F38="MW", $D38*$F$58, 0) -> 19368.96 | O38: =IF($F38="MW", $D38*$F$59, 0) -> 7086.56 | P38: =IF($F38="MW", $D38*$F$60, 0) -> 7086.56 | Q38: =IF($F38="MW", $D38*$F$61, 0) -> 2204.8 | R38: =IF($F38="MW", $D38*$F$62, 0) -> 355892.16
A39: North Delta | B39: Sutter Island | C39: 87 | D39: 2514 | E39: Minimal | F39: MW | G39: Sutter Island | H39: =IF($F39="MW", $D39*$F$52, 0) -> 883143.06 | I39: =IF($F39="MW", $D39*$F$53, 0) -> 711839.1 | J39: =IF($F39="MW", $D39*$F$54, 0) -> 936439.86 | K39: =IF($F39="MW", $D39*$F$55, 0) -> 548152.56 | L39: =IF($F39="MW", $D39*$F$56, 0) -> 407318.28 | M39: =IF($F39="MW", $D39*$F$57, 0) -> 382555.38 | N39: =IF($F39="MW", $D39*$F$58, 0) -> 234103.68 | O39: =IF($F39="MW", $D39*$F$59, 0) -> 85651.98 | P39: =IF($F39="MW", $D39*$F$60, 0) -> 85651.98 | Q39: =IF($F39="MW", $D39*$F$61, 0) -> 26648.4 | R39: =IF($F39="MW", $D39*$F$62, 0) -> 4301504.3
A40: North Delta | B40: New Hope Tract | C40: 89 | D40: 9211 | E40: Minimal | F40: MW | G40: New Hope Tract | H40: =IF($F40="MW", $D40*$F$52, 0) -> 3235732.2 | I40: =IF($F40="MW", $D40*$F$53, 0) -> 2608094.6 | J40: =IF($F40="MW", $D40*$F$54, 0) -> 3431005.4 | K40: =IF($F40="MW", $D40*$F$55, 0) -> 2008366.4 | L40: =IF($F40="MW", $D40*$F$56, 0) -> 1492366.2 | M40: =IF($F40="MW", $D40*$F$57, 0) -> 1401637.9 | N40: =IF($F40="MW", $D40*$F$58, 0) -> 857728.32 | O40: =IF($F40="MW", $D40*$F$59, 0) -> 313818.77 | P40: =IF($F40="MW", $D40*$F$60, 0) -> 313818.77 | Q40: =IF($F40="MW", $D40*$F$61, 0) -> 97636.6 | R40: =IF($F40="MW", $D40*$F$62, 0) -> 15760205
A41: North Delta | B41: Canal Ranch Tract | C41: 60 | D41: 2936 | E41: Minimal | F41: MW | G41: Canal Ranch Tract | H41: =IF($F41="MW", $D41*$F$52, 0) -> 1031387.4 | I41: =IF($F41="MW", $D41*$F$53, 0) -> 831328.4 | J41: =IF($F41="MW", $D41*$F$54, 0) -> 1093630.6 | K41: =IF($F41="MW", $D41*$F$55, 0) -> 640165.44 | L41: =IF($F41="MW", $D41*$F$56, 0) -> 475690.72 | M41: =IF($F41="MW", $D41*$F$57, 0) -> 446771.12 | N41: =IF($F41="MW", $D41*$F$58, 0) -> 273400.32 | O41: =IF($F41="MW", $D41*$F$59, 0) -> 100029.52 | P41: =IF($F41="MW", $D41*$F$60, 0) -> 100029.52 | Q41: =IF($F41="MW", $D41*$F$61, 0) -> 31121.6 | R41: =IF($F41="MW", $D41*$F$62, 0) -> 5023554.7
A42: Upland | B42: Upper Bound | D42: 347591 | F42: Meadows | H42: =IF($F42="Meadows", $D42*$F$52, 0) -> 1.2210524e+08 | I42: =IF($F42="Meadows", $D42*$F$52, 0) -> 1.2210524e+08 | J42: =IF($F42="Meadows", $D42*$F$52, 0) -> 1.2210524e+08 | K42: =IF($F42="Meadows", $D42*$F$52, 0) -> 1.2210524e+08 | L42: =IF($F42="Meadows", $D42*$F$52, 0) -> 1.2210524e+08 | M42: =IF($F42="Meadows", $D42*$F$52, 0) -> 1.2210524e+08 | N42: =IF($F42="Meadows", $D42*$F$52, 0) -> 1.2210524e+08 | O42: =IF($F42="Meadows", $D42*$F$52, 0) -> 1.2210524e+08 | ... R42: =IF($F42="Meadows", $D42*$F$52, 0) -> 1.2210524e+08
A43: Upland | B43: Upper Bound | D43: 303372 | F43: Floodplain | G43: 0 | H43: =IF($F43="Floodplain", $D43*$F$52, 0) -> 1.0657155e+08 | I43: =IF($F43="Floodplain", $D43*$F$52, 0) -> 1.0657155e+08 | J43: =IF($F43="Floodplain", $D43*$F$52, 0) -> 1.0657155e+08 | K43: =IF($F43="Floodplain", $D43*$F$52, 0) -> 1.0657155e+08 | L43: =IF($F43="Floodplain", $D43*$F$52, 0) -> 1.0657155e+08 | M43: =IF($F43="Floodplain", $D43*$F$52, 0) -> 1.0657155e+08 | N43: =IF($F43="Floodplain", $D43*$F$52, 0) -> 1.0657155e+08 | O43: =IF($F43="Floodplain", $D43*$F$52, 0) -> 1.0657155e+08 | ... R43: =IF($F43="Floodplain", $D43*$F$52, 0) -> 1.0657155e+08
...

Sheet 50% Restoration ($)
H1: Benefits US$/acre/yr (2025)
A2: Region | B2: Island | C2: ArcGIS object ID | D2: Acres | E2: Elevation (categorical) | F2: 50/50 (R = Rice; MW = Managed Wetland) | G2: Wetland function | H2: Flood control | I2: Recreational fishing | J2: Amenity/recreation | K2: Water filtering | L2: Biodiversity | M2: Habitat nursery | N2: Recreational hunting | O2: Water supply | P2: Materials | Q2: Fuel wood | R2: Sum of all ten
A3: Suisun Marsh | B3: Suisun | D3: 41914 | F3: Tidal | H3: =IF($F3="Tidal", $D3*$F$49, 0) -> 14723969 | I3: =IF($F3="Tidal", $D3*$F$49, 0) -> 14723969 | J3: =IF($F3="Tidal", $D3*$F$49, 0) -> 14723969 | K3: =IF($F3="Tidal", $D3*$F$49, 0) -> 14723969 | L3: =IF($F3="Tidal", $D3*$F$49, 0) -> 14723969 | M3: =IF($F3="Tidal", $D3*$F$49, 0) -> 14723969 | N3: =IF($F3="Tidal", $D3*$F$49, 0) -> 14723969 | O3: =IF($F3="Tidal", $D3*$F$49, 0) -> 14723969 | ... R3: =IF($F3="Tidal", $D3*$F$49, 0) -> 14723969
A4: North Delta | B4: Grand Island | C4: 80 | D4: 16543 | E4: Mimimal | F4: R | G4: Grand Island | H4: =IF($F4="MW", $D4*$F$49, 0) -> 0 | I4: =IF($F4="MW", $D4*$F$50, 0) -> 0 | J4: =IF($F4="MW", $D4*$F$51, 0) -> 0 | K4: =IF($F4="MW", $D4*$F$52, 0) -> 0 | L4: =IF($F4="MW", $D4*$F$53, 0) -> 0 | M4: =IF($F4="MW", $D4*$F$54, 0) -> 0 | N4: =IF($F4="MW", $D4*$F$55, 0) -> 0 | O4: =IF($F4="MW", $D4*$F$56, 0) -> 0 | P4: =IF($F4="MW", $D4*$F$57, 0) -> 0 | Q4: =IF($F4="MW", $D4*$F$58, 0) -> 0 | R4: =IF($F4="MW", $D4*$F$59, 0) -> 0
A5: North Delta | B5: Ryer Island | C5: 76 | D5: 11798 | E5: Minimal | F5: R | G5: Ryer Island | H5: =IF($F5="MW", $D5*$F$49, 0) -> 0 | I5: =IF($F5="MW", $D5*$F$50, 0) -> 0 | J5: =IF($F5="MW", $D5*$F$51, 0) -> 0 | K5: =IF($F5="MW", $D5*$F$52, 0) -> 0 | L5: =IF($F5="MW", $D5*$F$53, 0) -> 0 | M5: =IF($F5="MW", $D5*$F$54, 0) -> 0 | N5: =IF($F5="MW", $D5*$F$55, 0) -> 0 | O5: =IF($F5="MW", $D5*$F$56, 0) -> 0 | P5: =IF($F5="MW", $D5*$F$57, 0) -> 0 | Q5: =IF($F5="MW", $D5*$F$58, 0) -> 0 | R5: =IF($F5="MW", $D5*$F$59, 0) -> 0
A6: North Delta | B6: Tyler Island | C6: 62 | D6: 8799 | E6: Minimal | F6: R | G6: Tyler Island | H6: =IF($F6="MW", $D6*$F$49, 0) -> 0 | I6: =IF($F6="MW", $D6*$F$50, 0) -> 0 | J6: =IF($F6="MW", $D6*$F$51, 0) -> 0 | K6: =IF($F6="MW", $D6*$F$52, 0) -> 0 | L6: =IF($F6="MW", $D6*$F$53, 0) -> 0 | M6: =IF($F6="MW", $D6*$F$54, 0) -> 0 | N6: =IF($F6="MW", $D6*$F$55, 0) -> 0 | O6: =IF($F6="MW", $D6*$F$56, 0) -> 0 | P6: =IF($F6="MW", $D6*$F$57, 0) -> 0 | Q6: =IF($F6="MW", $D6*$F$58, 0) -> 0 | R6: =IF($F6="MW", $D6*$F$59, 0) -> 0
A7: North Delta | B7: Staten Island | C7: 61 | D7: 9111 | E7: Moderate | F7: R | G7: Staten Island | H7: =IF($F7="MW", $D7*$F$49, 0) -> 0 | I7: =IF($F7="MW", $D7*$F$50, 0) -> 0 | J7: =IF($F7="MW", $D7*$F$51, 0) -> 0 | K7: =IF($F7="MW", $D7*$F$52, 0) -> 0 | L7: =IF($F7="MW", $D7*$F$53, 0) -> 0 | M7: =IF($F7="MW", $D7*$F$54, 0) -> 0 | N7: =IF($F7="MW", $D7*$F$55, 0) -> 0 | O7: =IF($F7="MW", $D7*$F$56, 0) -> 0 | P7: =IF($F7="MW", $D7*$F$57, 0) -> 0 | Q7: =IF($F7="MW", $D7*$F$58, 0) -> 0 | R7: =IF($F7="MW", $D7*$F$59, 0) -> 0
A8: North-Central | B8: Brannan Island | C8: 116 | D8: 12907 | E8: Severe | F8: MW | G8: Brannan Island | H8: =IF($F8="MW", $D8*$F$49, 0) -> 4534100 | I8: =IF($F8="MW", $D8*$F$50, 0) -> 3654617 | J8: =IF($F8="MW", $D8*$F$51, 0) -> 4807728.4 | K8: =IF($F8="MW", $D8*$F$52, 0) -> 2814242.3 | L8: =IF($F8="MW", $D8*$F$53, 0) -> 2091192.1 | M8: =IF($F8="MW", $D8*$F$54, 0) -> 1964058.2 | N8: =IF($F8="MW", $D8*$F$55, 0) -> 1201899.8 | O8: =IF($F8="MW", $D8*$F$56, 0) -> 439741.49 | P8: =IF($F8="MW", $D8*$F$57, 0) -> 439741.49 | Q8: =IF($F8="MW", $D8*$F$58, 0) -> 136814.2 | R8: =IF($F8="MW", $D8*$F$59, 0) -> 22084135
A9: South Delta | B9: Bouldin Island | C9: 57 | D9: 5936 | E9: Severe | F9: R | G9: Bouldin Island | H9: =IF($F9="MW", $D9*$F$49, 0) -> 0 | I9: =IF($F9="MW", $D9*$F$50, 0) -> 0 | J9: =IF($F9="MW", $D9*$F$51, 0) -> 0 | K9: =IF($F9="MW", $D9*$F$52, 0) -> 0 | L9: =IF($F9="MW", $D9*$F$53, 0) -> 0 | M9: =IF($F9="MW", $D9*$F$54, 0) -> 0 | N9: =IF($F9="MW", $D9*$F$55, 0) -> 0 | O9: =IF($F9="MW", $D9*$F$56, 0) -> 0 | P9: =IF($F9="MW", $D9*$F$57, 0) -> 0 | Q9: =IF($F9="MW", $D9*$F$58, 0) -> 0 | R9: =IF($F9="MW", $D9*$F$59, 0) -> 0
A10: South Delta | B10: Venice Island | C10: 49 | D10: 3094 | E10: Severe | F10: MW | G10: Venice Island | H10: =IF($F10="MW", $D10*$F$49, 0) -> 1086891.3 | I10: =IF($F10="MW", $D10*$F$50, 0) -> 876066.1 | J10: =IF($F10="MW", $D10*$F$51, 0) -> 1152484.1 | K10: =IF($F10="MW", $D10*$F$52, 0) -> 674615.76 | L10: =IF($F10="MW", $D10*$F$53, 0) -> 501289.88 | M10: =IF($F10="MW", $D10*$F$54, 0) -> 470813.98 | N10: =IF($F10="MW", $D10*$F$55, 0) -> 288113.28 | O10: =IF($F10="MW", $D10*$F$56, 0) -> 105412.58 | P10: =IF($F10="MW", $D10*$F$57, 0) -> 105412.58 | Q10: =IF($F10="MW", $D10*$F$58, 0) -> 32796.4 | R10: =IF($F10="MW", $D10*$F$59, 0) -> 5293895.9
A11: South Delta | B11: Medford Island | C11: 41 | D11: 1165 | E11: Moderate | F11: R | G11: Medford Island | H11: =IF($F11="MW", $D11*$F$49, 0) -> 0 | I11: =IF($F11="MW", $D11*$F$50, 0) -> 0 | J11: =IF($F11="MW", $D11*$F$51, 0) -> 0 | K11: =IF($F11="MW", $D11*$F$52, 0) -> 0 | L11: =IF($F11="MW", $D11*$F$53, 0) -> 0 | M11: =IF($F11="MW", $D11*$F$54, 0) -> 0 | N11: =IF($F11="MW", $D11*$F$55, 0) -> 0 | O11: =IF($F11="MW", $D11*$F$56, 0) -> 0 | P11: =IF($F11="MW", $D11*$F$57, 0) -> 0 | Q11: =IF($F11="MW", $D11*$F$58, 0) -> 0 | R11: =IF($F11="MW", $D11*$F$59, 0) -> 0
A12: South Delta | B12: Empire Tract | C12: 50 | D12: 3625 | E12: Moderate | F12: R | G12: Empire Tract | H12: =IF($F12="MW", $D12*$F$49, 0) -> 0 | I12: =IF($F12="MW", $D12*$F$50, 0) -> 0 | J12: =IF($F12="MW", $D12*$F$51, 0) -> 0 | K12: =IF($F12="MW", $D12*$F$52, 0) -> 0 | L12: =IF($F12="MW", $D12*$F$53, 0) -> 0 | M12: =IF($F12="MW", $D12*$F$54, 0) -> 0 | N12: =IF($F12="MW", $D12*$F$55, 0) -> 0 | O12: =IF($F12="MW", $D12*$F$56, 0) -> 0 | P12: =IF($F12="MW", $D12*$F$57, 0) -> 0 | Q12: =IF($F12="MW", $D12*$F$58, 0) -> 0 | R12: =IF($F12="MW", $D12*$F$59, 0) -> 0
A13: South Delta | B13: King Island | C13: 46 | D13: 3216 | E13: Minimal | F13: R | G13: King Island | H13: =IF($F13="MW", $D13*$F$49, 0) -> 0 | I13: =IF($F13="MW", $D13*$F$50, 0) -> 0 | J13: =IF($F13="MW", $D13*$F$51, 0) -> 0 | K13: =IF($F13="MW", $D13*$F$52, 0) -> 0 | L13: =IF($F13="MW", $D13*$F$53, 0) -> 0 | M13: =IF($F13="MW", $D13*$F$54, 0) -> 0 | N13: =IF($F13="MW", $D13*$F$55, 0) -> 0 | O13: =IF($F13="MW", $D13*$F$56, 0) -> 0 | P13: =IF($F13="MW", $D13*$F$57, 0) -> 0 | Q13: =IF($F13="MW", $D13*$F$58, 0) -> 0 | R13: =IF($F13="MW", $D13*$F$59, 0) -> 0
A14: North-South | B14: Terminous Tract | C14: 58 | D14: 10358 | E14: Minimal | F14: R | G14: Terminous Tract | H14: =IF($F14="MW", $D14*$F$49, 0) -> 0 | I14: =IF($F14="MW", $D14*$F$50, 0) -> 0 | J14: =IF($F14="MW", $D14*$F$51, 0) -> 0 | K14: =IF($F14="MW", $D14*$F$52, 0) -> 0 | L14: =IF($F14="MW", $D14*$F$53, 0) -> 0 | M14: =IF($F14="MW", $D14*$F$54, 0) -> 0 | N14: =IF($F14="MW", $D14*$F$55, 0) -> 0 | O14: =IF($F14="MW", $D14*$F$56, 0) -> 0 | P14: =IF($F14="MW", $D14*$F$57, 0) -> 0 | Q14: =IF($F14="MW", $D14*$F$58, 0) -> 0 | R14: =IF($F14="MW", $D14*$F$59, 0) -> 0
A15: South Delta | B15: Rindge Tract | C15: 40 | D15: 6743 | E15: Moderate | F15: MW | G15: Rindge Tract | H15: =IF($F15="MW", $D15*$F$49, 0) -> 2368748.5 | I15: =IF($F15="MW", $D15*$F$50, 0) -> 1909280.4 | J15: =IF($F15="MW", $D15*$F$51, 0) -> 2511700.1 | K15: =IF($F15="MW", $D15*$F$52, 0) -> 1470243.7 | L15: =IF($F15="MW", $D15*$F$53, 0) -> 1092500.9 | M15: =IF($F15="MW", $D15*$F$54, 0) -> 1026082.3 | N15: =IF($F15="MW", $D15*$F$55, 0) -> 627908.16 | O15: =IF($F15="MW", $D15*$F$56, 0) -> 229734.01 | P15: =IF($F15="MW", $D15*$F$57, 0) -> 229734.01 | Q15: =IF($F15="MW", $D15*$F$58, 0) -> 71475.8 | R15: =IF($F15="MW", $D15*$F$59, 0) -> 11537408
... A19: South Delta | B19: Rough and Ready | C19: 25 | D19: 1401 | E19: Minimal | F19: MW | G19: Rough and Ready | H19: =IF($F19="MW", $D19*$F$49, 0) -> 492157.29 | I19: =IF($F19="MW", $D19*$F$50, 0) -> 396693.15 | J19: =IF($F19="MW", $D19*$F$51, 0) -> 521858.49 | K19: =IF($F19="MW", $D19*$F$52, 0) -> 305474.04 | L19: =IF($F19="MW", $D19*$F$53, 0) -> 226990.02 | M19: =IF($F19="MW", $D19*$F$54, 0) -> 213190.17 | N19: =IF($F19="MW", $D19*$F$55, 0) -> 130461.12 | O19: =IF($F19="MW", $D19*$F$56, 0) -> 47732.07 | P19: =IF($F19="MW", $D19*$F$57, 0) -> 47732.07 | Q19: =IF($F19="MW", $D19*$F$58, 0) -> 14850.6 | R19: =IF($F19="MW", $D19*$F$59, 0) -> 2397139
A20: South Delta | B20: Roberts Island | C20: 31 + 22 + 12+23+ 8 | D20: 35663 | E20: Minimal | F20: R | G20: Roberts Island | H20: =IF($F20="MW", $D20*$F$49, 0) -> 0 | I20: =IF($F20="MW", $D20*$F$50, 0) -> 0 | J20: =IF($F20="MW", $D20*$F$51, 0) -> 0 | K20: =IF($F20="MW", $D20*$F$52, 0) -> 0 | L20: =IF($F20="MW", $D20*$F$53, 0) -> 0 | M20: =IF($F20="MW", $D20*$F$54, 0) -> 0 | N20: =IF($F20="MW", $D20*$F$55, 0) -> 0 | O20: =IF($F20="MW", $D20*$F$56, 0) -> 0 | P20: =IF($F20="MW", $D20*$F$57, 0) -> 0 | Q20: =IF($F20="MW", $D20*$F$58, 0) -> 0 | R20: =IF($F20="MW", $D20*$F$59, 0) -> 0
A21: South Delta | B21: Union Island | C21: 9 | D21: 24750 | E21: Minimal | F21: R | G21: Union Island | H21: =IF($F21="MW", $D21*$F$49, 0) -> 0 | I21: =IF($F21="MW", $D21*$F$50, 0) -> 0 | J21: =IF($F21="MW", $D21*$F$51, 0) -> 0 | K21: =IF($F21="MW", $D21*$F$52, 0) -> 0 | L21: =IF($F21="MW", $D21*$F$53, 0) -> 0 | M21: =IF($F21="MW", $D21*$F$54, 0) -> 0 | N21: =IF($F21="MW", $D21*$F$55, 0) -> 0 | O21: =IF($F21="MW", $D21*$F$56, 0) -> 0 | P21: =IF($F21="MW", $D21*$F$57, 0) -> 0 | Q21: =IF($F21="MW", $D21*$F$58, 0) -> 0 | R21: =IF($F21="MW", $D21*$F$59, 0) -> 0
A22: South Delta | B22: Victoria Island | C22: 10 | D22: 7193 | E22: Minimal | F22: MW | G22: Victoria Island | H22: =IF($F22="MW", $D22*$F$49, 0) -> 2526829 | I22: =IF($F22="MW", $D22*$F$50, 0) -> 2036697.9 | J22: =IF($F22="MW", $D22*$F$51, 0) -> 2679320.6 | K22: =IF($F22="MW", $D22*$F$52, 0) -> 1568361.7 | L22: =IF($F22="MW", $D22*$F$53, 0) -> 1165409.9 | M22: =IF($F22="MW", $D22*$F$54, 0) -> 1094558.8 | N22: =IF($F22="MW", $D22*$F$55, 0) -> 669812.16 | O22: =IF($F22="MW", $D22*$F$56, 0) -> 245065.51 | P22: =IF($F22="MW", $D22*$F$57, 0) -> 245065.51 | Q22: =IF($F22="MW", $D22*$F$58, 0) -> 76245.8 | R22: =IF($F22="MW", $D22*$F$59, 0) -> 12307367
A23: South Delta | B23: Woodward Island | C23: 18 | D23: 1809 | E23: Minimal | F23: MW | G23: Woodward Island | H23: =IF($F23="MW", $D23*$F$49, 0) -> 635483.61 | I23: =IF($F23="MW", $D23*$F$50, 0) -> 512218.35 | J23: =IF($F23="MW", $D23*$F$51, 0) -> 673834.41 | K23: =IF($F23="MW", $D23*$F$52, 0) -> 394434.36 | L23: =IF($F23="MW", $D23*$F$53, 0) -> 293094.18 | M23: =IF($F23="MW", $D23*$F$54, 0) -> 275275.53 | N23: =IF($F23="MW", $D23*$F$55, 0) -> 168454.08 | O23: =IF($F23="MW", $D23*$F$56, 0) -> 61632.63 | P23: =IF($F23="MW", $D23*$F$57, 0) -> 61632.63 | Q23: =IF($F23="MW", $D23*$F$58, 0) -> 19175.4 | R23: =IF($F23="MW", $D23*$F$59, 0) -> 3095235.2
A24: South Delta | B24: Coney Island | C24: 6 | D24: 965 | E24: Minimal | F24: MW | G24: Coney Island | H24: =IF($F24="MW", $D24*$F$49, 0) -> 338994.85 | I24: =IF($F24="MW", $D24*$F$50, 0) -> 273239.75 | J24: =IF($F24="MW", $D24*$F$51, 0) -> 359452.85 | K24: =IF($F24="MW", $D24*$F$52, 0) -> 210408.6 | L24: =IF($F24="MW", $D24*$F$53, 0) -> 156349.3 | M24: =IF($F24="MW", $D24*$F$54, 0) -> 146844.05 | N24: =IF($F24="MW", $D24*$F$55, 0) -> 89860.8 | O24: =IF($F24="MW", $D24*$F$56, 0) -> 32877.55 | P24: =IF($F24="MW", $D24*$F$57, 0) -> 32877.55 | Q24: =IF($F24="MW", $D24*$F$58, 0) -> 10229 | R24: =IF($F24="MW", $D24*$F$59, 0) -> 1651134.3
A25: South Delta | B25: Orowood Tract | C25: 20 | D25: 2383 | E25: Minimal | F25: MW | G25: Orowood Tract | H25: =IF($F25="MW", $D25*$F$49, 0) -> 837124.07 | I25: =IF($F25="MW", $D25*$F$50, 0) -> 674746.45 | J25: =IF($F25="MW", $D25*$F$51, 0) -> 887643.67 | K25: =IF($F25="MW", $D25*$F$52, 0) -> 519589.32 | L25: =IF($F25="MW", $D25*$F$53, 0) -> 386093.66 | M25: =IF($F25="MW", $D25*$F$54, 0) -> 362621.11 | N25: =IF($F25="MW", $D25*$F$55, 0) -> 221904.96 | O25: =IF($F25="MW", $D25*$F$56, 0) -> 81188.81 | P25: =IF($F25="MW", $D25*$F$57, 0) -> 81188.81 | Q25: =IF($F25="MW", $D25*$F$58, 0) -> 25259.8 | R25: =IF($F25="MW", $D25*$F$59, 0) -> 4077360.7
A26: South Delta | B26: Palm Tract | C26: 27 | D26: 2470 | E26: Minimal | F26: MW | G26: Palm Tract | H26: =IF($F26="MW", $D26*$F$49, 0) -> 867686.3 | I26: =IF($F26="MW", $D26*$F$50, 0) -> 699380.5 | J26: =IF($F26="MW", $D26*$F$51, 0) -> 920050.3 | K26: =IF($F26="MW", $D26*$F$52, 0) -> 538558.8 | L26: =IF($F26="MW", $D26*$F$53, 0) -> 400189.4 | M26: =IF($F26="MW", $D26*$F$54, 0) -> 375859.9 | N26: =IF($F26="MW", $D26*$F$55, 0) -> 230006.4 | O26: =IF($F26="MW", $D26*$F$56, 0) -> 84152.9 | P26: =IF($F26="MW", $D26*$F$57, 0) -> 84152.9 | Q26: =IF($F26="MW", $D26*$F$58, 0) -> 26182 | R26: =IF($F26="MW", $D26*$F$59, 0) -> 4226219.4
A27: South Delta | B27: Bacon Island | C27: 32 | D27: 5533 | E27: Severe | F27: MW | G27: Bacon Island | H27: =IF($F27="MW", $D27*$F$49, 0) -> 1943687.6 | I27: =IF($F27="MW", $D27*$F$50, 0) -> 1566668.9 | J27: =IF($F27="MW", $D27*$F$51, 0) -> 2060987.2 | K27: =IF($F27="MW", $D27*$F$52, 0) -> 1206415.3 | L27: =IF($F27="MW", $D27*$F$53, 0) -> 896456.66 | M27: =IF($F27="MW", $D27*$F$54, 0) -> 841956.61 | N27: =IF($F27="MW", $D27*$F$55, 0) -> 515232.96 | O27: =IF($F27="MW", $D27*$F$56, 0) -> 188509.31 | P27: =IF($F27="MW", $D27*$F$57, 0) -> 188509.31 | Q27: =IF($F27="MW", $D27*$F$58, 0) -> 58649.8 | R27: =IF($F27="MW", $D27*$F$59, 0) -> 9467073.7
A28: South Delta | B28: Holland Tract | C28: 35 | D28: 4214 | E28: Minimal | F28: MW | G28: Holland Tract | H28: =IF($F28="MW", $D28*$F$49, 0) -> 1480336.1 | I28: =IF($F28="MW", $D28*$F$50, 0) -> 1193194.1 | J28: =IF($F28="MW", $D28*$F$51, 0) -> 1569672.9 | K28: =IF($F28="MW", $D28*$F$52, 0) -> 918820.56 | L28: =IF($F28="MW", $D28*$F$53, 0) -> 682752.28 | M28: =IF($F28="MW", $D28*$F$54, 0) -> 641244.38 | N28: =IF($F28="MW", $D28*$F$55, 0) -> 392407.68 | O28: =IF($F28="MW", $D28*$F$56, 0) -> 143570.98 | P28: =IF($F28="MW", $D28*$F$57, 0) -> 143570.98 | Q28: =IF($F28="MW", $D28*$F$58, 0) -> 44668.4 | R28: =IF($F28="MW", $D28*$F$59, 0) -> 7210238.3
A29: South Delta | B29: Quinby Island | C29: 36 | D29: 774 | E29: Moderate | F29: MW | G29: Quinby Island | H29: =IF($F29="MW", $D29*$F$49, 0) -> 271898.46 | I29: =IF($F29="MW", $D29*$F$50, 0) -> 219158.1 | J29: =IF($F29="MW", $D29*$F$51, 0) -> 288307.26 | K29: =IF($F29="MW", $D29*$F$52, 0) -> 168762.96 | L29: =IF($F29="MW", $D29*$F$53, 0) -> 125403.48 | M29: =IF($F29="MW", $D29*$F$54, 0) -> 117779.58 | N29: =IF($F29="MW", $D29*$F$55, 0) -> 72074.88 | O29: =IF($F29="MW", $D29*$F$56, 0) -> 26370.18 | P29: =IF($F29="MW", $D29*$F$57, 0) -> 26370.18 | Q29: =IF($F29="MW", $D29*$F$58, 0) -> 8204.4 | R29: =IF($F29="MW", $D29*$F$59, 0) -> 1324329.5
